[2020-08-07 13:17:01,822] [autoreload.py:598] [autoreload:run_with_reloader] [INFO]- Watching for file changes with StatReloader
[2020-08-07 13:17:29,871] [basehttp.py:157] [basehttp:log_message] [INFO]- "GET /sys/api/user/role?username=wl&application=automation&type=button HTTP/1.1" 301 0
[2020-08-07 13:17:30,115] [log.py:222] [log:log_response] [WARNING]- Forbidden: /sys/api/user/role/
[2020-08-07 13:17:30,117] [log.py:222] [log:log_response] [WARNING]- Forbidden: /sys/api/user/role/
[2020-08-07 13:17:30,118] [basehttp.py:157] [basehttp:log_message] [WARNING]- "GET /sys/api/user/role/?username=wl&application=automation&type=button HTTP/1.1" 403 24
[2020-08-07 13:17:30,119] [basehttp.py:157] [basehttp:log_message] [WARNING]- "GET /sys/api/user/role/?username=wl&application=automation&type=menu HTTP/1.1" 403 24
[2020-08-07 13:17:37,200] [basehttp.py:157] [basehttp:log_message] [INFO]- "POST /sys/api/auth/ HTTP/1.1" 200 65
[2020-08-07 13:17:40,156] [basehttp.py:157] [basehttp:log_message] [INFO]- "GET /sys/api/user/role/?username=wl&application=automation&type=button HTTP/1.1" 200 2
[2020-08-07 13:17:40,157] [basehttp.py:157] [basehttp:log_message] [INFO]- "GET /sys/api/user/role/?username=wl&application=automation&type=menu HTTP/1.1" 200 3623
[2020-08-07 13:17:43,072] [basehttp.py:157] [basehttp:log_message] [INFO]- "POST /sys/api/auth/ HTTP/1.1" 200 65
[2020-08-07 13:17:44,785] [basehttp.py:157] [basehttp:log_message] [INFO]- "POST /sys/api/auth/ HTTP/1.1" 200 65
[2020-08-07 13:17:52,553] [basehttp.py:157] [basehttp:log_message] [INFO]- "POST /sys/api/auth/ HTTP/1.1" 200 65
[2020-08-07 13:22:14,014] [basehttp.py:157] [basehttp:log_message] [INFO]- "POST /sys/api/auth/ HTTP/1.1" 200 65
[2020-08-07 13:22:30,601] [basehttp.py:157] [basehttp:log_message] [INFO]- "POST /sys/api/auth/ HTTP/1.1" 200 65
[2020-08-07 13:24:00,165] [basehttp.py:157] [basehttp:log_message] [INFO]- "POST /sys/api/auth/ HTTP/1.1" 200 65
[2020-08-07 13:24:00,419] [basehttp.py:157] [basehttp:log_message] [INFO]- "GET /sys/api/user/role/?username=wl&application=automation&type=menu HTTP/1.1" 200 3623
[2020-08-07 13:24:00,420] [basehttp.py:157] [basehttp:log_message] [INFO]- "GET /sys/api/user/role/?username=wl&application=automation&type=button HTTP/1.1" 200 2
[2020-08-07 13:24:15,790] [basehttp.py:157] [basehttp:log_message] [INFO]- "POST /sys/api/auth/ HTTP/1.1" 200 65
[2020-08-07 13:24:16,001] [basehttp.py:157] [basehttp:log_message] [INFO]- "GET /sys/api/user/role/?username=wl&application=automation&type=menu HTTP/1.1" 200 3623
[2020-08-07 13:24:16,019] [basehttp.py:157] [basehttp:log_message] [INFO]- "GET /sys/api/user/role/?username=wl&application=automation&type=button HTTP/1.1" 200 2
[2020-08-07 13:32:56,256] [basehttp.py:157] [basehttp:log_message] [INFO]- "POST /sys/api/auth/ HTTP/1.1" 200 65
[2020-08-07 13:33:01,070] [basehttp.py:157] [basehttp:log_message] [INFO]- "POST /sys/api/auth/ HTTP/1.1" 200 65
[2020-08-07 13:33:13,807] [basehttp.py:157] [basehttp:log_message] [INFO]- "POST /sys/api/auth/ HTTP/1.1" 200 65
[2020-08-07 13:33:52,132] [basehttp.py:157] [basehttp:log_message] [INFO]- "POST /sys/api/auth/ HTTP/1.1" 200 65
[2020-08-07 13:33:52,320] [basehttp.py:157] [basehttp:log_message] [INFO]- "GET /sys/api/user/role/?username=wl&application=automation&type=menu HTTP/1.1" 200 3623
[2020-08-07 13:33:52,321] [basehttp.py:157] [basehttp:log_message] [INFO]- "GET /sys/api/user/role/?username=wl&application=automation&type=button HTTP/1.1" 200 2
[2020-08-07 13:35:11,571] [basehttp.py:157] [basehttp:log_message] [INFO]- "POST /sys/api/auth/ HTTP/1.1" 200 65
[2020-08-07 13:35:11,755] [basehttp.py:157] [basehttp:log_message] [INFO]- "GET /sys/api/user/role/?username=wl&application=automation&type=menu HTTP/1.1" 200 3623
[2020-08-07 13:35:11,772] [basehttp.py:157] [basehttp:log_message] [INFO]- "GET /sys/api/user/role/?username=wl&application=automation&type=button HTTP/1.1" 200 2
[2020-08-07 13:35:19,387] [basehttp.py:157] [basehttp:log_message] [INFO]- "POST /sys/api/auth/ HTTP/1.1" 200 65
[2020-08-07 13:35:19,597] [basehttp.py:157] [basehttp:log_message] [INFO]- "GET /sys/api/user/role/?username=wl&application=automation&type=menu HTTP/1.1" 200 3623
[2020-08-07 13:35:19,610] [basehttp.py:157] [basehttp:log_message] [INFO]- "GET /sys/api/user/role/?username=wl&application=automation&type=button HTTP/1.1" 200 2
[2020-08-07 14:21:49,470] [log.py:222] [log:log_response] [WARNING]- Unauthorized: /sys/api/auth/
[2020-08-07 14:21:49,472] [basehttp.py:157] [basehttp:log_message] [WARNING]- "POST /sys/api/auth/ HTTP/1.1" 401 39
[2020-08-07 14:21:56,299] [basehttp.py:157] [basehttp:log_message] [INFO]- "POST /sys/api/auth/ HTTP/1.1" 200 65
[2020-08-07 14:22:04,569] [basehttp.py:157] [basehttp:log_message] [INFO]- "GET /sys/api/user/role/?username=wl&application=automation&type=button HTTP/1.1" 200 2
[2020-08-07 14:22:04,570] [basehttp.py:157] [basehttp:log_message] [INFO]- "GET /sys/api/user/role/?username=wl&application=automation&type=menu HTTP/1.1" 200 3623
[2020-08-07 14:22:15,227] [basehttp.py:157] [basehttp:log_message] [INFO]- "POST /sys/api/auth/ HTTP/1.1" 200 65
[2020-08-07 14:22:52,675] [basehttp.py:157] [basehttp:log_message] [INFO]- "POST /sys/api/auth/ HTTP/1.1" 200 65
[2020-08-07 14:23:02,263] [basehttp.py:157] [basehttp:log_message] [INFO]- "POST /sys/api/auth/ HTTP/1.1" 200 65
[2020-08-07 15:26:02,976] [log.py:222] [log:log_response] [WARNING]- Forbidden: /sys/api/user/role/
[2020-08-07 15:26:02,988] [log.py:222] [log:log_response] [WARNING]- Unauthorized: /sys/api/auth/
[2020-08-07 15:26:02,999] [basehttp.py:157] [basehttp:log_message] [WARNING]- "GET /sys/api/user/role/?username=wl&application=automation&type=menu HTTP/1.1" 403 31
[2020-08-07 15:26:03,005] [basehttp.py:157] [basehttp:log_message] [WARNING]- "POST /sys/api/auth/ HTTP/1.1" 401 28
[2020-08-07 15:26:03,017] [log.py:222] [log:log_response] [WARNING]- Forbidden: /sys/api/user/role/
[2020-08-07 15:26:03,019] [basehttp.py:157] [basehttp:log_message] [WARNING]- "GET /sys/api/user/role/?username=wl&application=automation&type=button HTTP/1.1" 403 31
[2020-08-07 15:26:08,384] [basehttp.py:157] [basehttp:log_message] [INFO]- "POST /sys/api/auth/ HTTP/1.1" 200 65
[2020-08-07 15:26:11,382] [basehttp.py:157] [basehttp:log_message] [INFO]- "GET /sys/api/user/role/?username=wl&application=automation&type=button HTTP/1.1" 200 2
[2020-08-07 15:26:11,382] [basehttp.py:157] [basehttp:log_message] [INFO]- "GET /sys/api/user/role/?username=wl&application=automation&type=menu HTTP/1.1" 200 3623
[2020-08-07 15:26:14,078] [basehttp.py:157] [basehttp:log_message] [INFO]- "POST /sys/api/auth/ HTTP/1.1" 200 65
[2020-08-07 15:26:16,275] [basehttp.py:157] [basehttp:log_message] [INFO]- "POST /sys/api/auth/ HTTP/1.1" 200 65
[2020-08-07 15:28:36,117] [basehttp.py:157] [basehttp:log_message] [INFO]- "POST /sys/api/auth/ HTTP/1.1" 200 65
[2020-08-07 15:29:37,667] [basehttp.py:157] [basehttp:log_message] [INFO]- "POST /sys/api/auth/ HTTP/1.1" 200 65
[2020-08-07 15:29:42,405] [basehttp.py:157] [basehttp:log_message] [INFO]- "POST /sys/api/auth/ HTTP/1.1" 200 65
[2020-08-07 15:29:48,401] [basehttp.py:157] [basehttp:log_message] [INFO]- "POST /sys/api/auth/ HTTP/1.1" 200 65
[2020-08-07 15:32:16,581] [basehttp.py:157] [basehttp:log_message] [INFO]- "POST /sys/api/auth/ HTTP/1.1" 200 65
[2020-08-07 15:32:21,615] [basehttp.py:157] [basehttp:log_message] [INFO]- "POST /sys/api/auth/ HTTP/1.1" 200 65
[2020-08-07 15:32:27,281] [basehttp.py:157] [basehttp:log_message] [INFO]- "POST /sys/api/auth/ HTTP/1.1" 200 65
[2020-08-07 15:33:04,498] [basehttp.py:157] [basehttp:log_message] [INFO]- "POST /sys/api/auth/ HTTP/1.1" 200 65
[2020-08-07 15:33:13,263] [basehttp.py:157] [basehttp:log_message] [INFO]- "POST /sys/api/auth/ HTTP/1.1" 200 65
[2020-08-07 15:33:13,533] [basehttp.py:157] [basehttp:log_message] [INFO]- "GET /sys/api/user/role/?username=wl&application=automation&type=button HTTP/1.1" 200 2
[2020-08-07 15:33:13,599] [basehttp.py:157] [basehttp:log_message] [INFO]- "GET /sys/api/user/role/?username=wl&application=automation&type=menu HTTP/1.1" 200 3623
[2020-08-07 15:34:03,303] [basehttp.py:157] [basehttp:log_message] [INFO]- "POST /sys/api/auth/ HTTP/1.1" 200 65
[2020-08-07 15:34:08,157] [basehttp.py:157] [basehttp:log_message] [INFO]- "POST /sys/api/auth/ HTTP/1.1" 200 65
[2020-08-07 15:35:05,399] [basehttp.py:157] [basehttp:log_message] [INFO]- "POST /sys/api/auth/ HTTP/1.1" 200 65
[2020-08-07 15:35:48,288] [basehttp.py:157] [basehttp:log_message] [INFO]- "POST /sys/api/auth/ HTTP/1.1" 200 65
[2020-08-07 15:36:33,710] [basehttp.py:157] [basehttp:log_message] [INFO]- "POST /sys/api/auth/ HTTP/1.1" 200 65
[2020-08-07 15:36:37,080] [basehttp.py:157] [basehttp:log_message] [INFO]- "POST /sys/api/auth/ HTTP/1.1" 200 65
[2020-08-07 15:36:43,896] [basehttp.py:157] [basehttp:log_message] [INFO]- "POST /sys/api/auth/ HTTP/1.1" 200 65
[2020-08-07 15:37:30,015] [basehttp.py:157] [basehttp:log_message] [INFO]- "POST /sys/api/auth/ HTTP/1.1" 200 65
[2020-08-07 15:38:28,629] [basehttp.py:157] [basehttp:log_message] [INFO]- "POST /sys/api/auth/ HTTP/1.1" 200 65
[2020-08-07 15:38:28,849] [basehttp.py:157] [basehttp:log_message] [INFO]- "GET /sys/api/user/role/?username=wl&application=automation&type=button HTTP/1.1" 200 2
[2020-08-07 15:38:28,859] [basehttp.py:157] [basehttp:log_message] [INFO]- "GET /sys/api/user/role/?username=wl&application=automation&type=menu HTTP/1.1" 200 3623
[2020-08-07 15:38:30,767] [basehttp.py:157] [basehttp:log_message] [INFO]- "POST /sys/api/auth/ HTTP/1.1" 200 65
[2020-08-07 15:38:35,260] [basehttp.py:157] [basehttp:log_message] [INFO]- "POST /sys/api/auth/ HTTP/1.1" 200 65
[2020-08-07 17:11:04,356] [log.py:222] [log:log_response] [WARNING]- Unauthorized: /sys/api/auth/
[2020-08-07 17:11:04,380] [basehttp.py:157] [basehttp:log_message] [WARNING]- "POST /sys/api/auth/ HTTP/1.1" 401 39
[2020-08-07 17:11:12,978] [basehttp.py:157] [basehttp:log_message] [INFO]- "POST /sys/api/auth/ HTTP/1.1" 200 65
[2020-08-07 17:11:17,950] [basehttp.py:157] [basehttp:log_message] [INFO]- "GET /sys/api/user/role/?username=wl&application=automation&type=button HTTP/1.1" 200 2
[2020-08-07 17:11:17,955] [basehttp.py:157] [basehttp:log_message] [INFO]- "GET /sys/api/user/role/?username=wl&application=automation&type=menu HTTP/1.1" 200 3623
[2020-08-07 17:11:20,911] [basehttp.py:157] [basehttp:log_message] [INFO]- "POST /sys/api/auth/ HTTP/1.1" 200 65
[2020-08-07 17:11:25,263] [basehttp.py:157] [basehttp:log_message] [INFO]- "POST /sys/api/auth/ HTTP/1.1" 200 65
[2020-08-07 17:11:30,172] [basehttp.py:157] [basehttp:log_message] [INFO]- "POST /sys/api/auth/ HTTP/1.1" 200 65
[2020-08-07 17:12:23,180] [basehttp.py:157] [basehttp:log_message] [INFO]- "POST /sys/api/auth/ HTTP/1.1" 200 65
[2020-08-07 17:13:52,978] [log.py:222] [log:log_response] [ERROR]- Internal Server Error: /sys/api/auth/
Traceback (most recent call last):
  File "/home/rock/anaconda3/envs/venv/lib/python3.8/site-packages/django/db/backends/base/base.py", line 220, in ensure_connection
    self.connect()
  File "/home/rock/anaconda3/envs/venv/lib/python3.8/site-packages/django/utils/asyncio.py", line 26, in inner
    return func(*args, **kwargs)
  File "/home/rock/anaconda3/envs/venv/lib/python3.8/site-packages/django/db/backends/base/base.py", line 197, in connect
    self.connection = self.get_new_connection(conn_params)
  File "/home/rock/anaconda3/envs/venv/lib/python3.8/site-packages/django/utils/asyncio.py", line 26, in inner
    return func(*args, **kwargs)
  File "/home/rock/anaconda3/envs/venv/lib/python3.8/site-packages/django/db/backends/mysql/base.py", line 233, in get_new_connection
    return Database.connect(**conn_params)
  File "/home/rock/anaconda3/envs/venv/lib/python3.8/site-packages/MySQLdb/__init__.py", line 84, in Connect
    return Connection(*args, **kwargs)
  File "/home/rock/anaconda3/envs/venv/lib/python3.8/site-packages/MySQLdb/connections.py", line 179, in __init__
    super(Connection, self).__init__(*args, **kwargs2)
MySQLdb._exceptions.OperationalError: (1040, 'Too many connections')

The above exception was the direct cause of the following exception:

Traceback (most recent call last):
  File "/home/rock/quality_inspection/python-workspace/project-sys/sys_auth/views.py", line 80, in post
    token_obj = Token.objects.filter(token=token).first()
  File "/home/rock/anaconda3/envs/venv/lib/python3.8/site-packages/django/db/models/query.py", line 664, in first
    for obj in (self if self.ordered else self.order_by('pk'))[:1]:
  File "/home/rock/anaconda3/envs/venv/lib/python3.8/site-packages/django/db/models/query.py", line 276, in __iter__
    self._fetch_all()
  File "/home/rock/anaconda3/envs/venv/lib/python3.8/site-packages/django/db/models/query.py", line 1261, in _fetch_all
    self._result_cache = list(self._iterable_class(self))
  File "/home/rock/anaconda3/envs/venv/lib/python3.8/site-packages/django/db/models/query.py", line 57, in __iter__
    results = compiler.execute_sql(chunked_fetch=self.chunked_fetch, chunk_size=self.chunk_size)
  File "/home/rock/anaconda3/envs/venv/lib/python3.8/site-packages/django/db/models/sql/compiler.py", line 1149, in execute_sql
    cursor = self.connection.cursor()
  File "/home/rock/anaconda3/envs/venv/lib/python3.8/site-packages/django/utils/asyncio.py", line 26, in inner
    return func(*args, **kwargs)
  File "/home/rock/anaconda3/envs/venv/lib/python3.8/site-packages/django/db/backends/base/base.py", line 260, in cursor
    return self._cursor()
  File "/home/rock/anaconda3/envs/venv/lib/python3.8/site-packages/django/db/backends/base/base.py", line 236, in _cursor
    self.ensure_connection()
  File "/home/rock/anaconda3/envs/venv/lib/python3.8/site-packages/django/utils/asyncio.py", line 26, in inner
    return func(*args, **kwargs)
  File "/home/rock/anaconda3/envs/venv/lib/python3.8/site-packages/django/db/backends/base/base.py", line 220, in ensure_connection
    self.connect()
  File "/home/rock/anaconda3/envs/venv/lib/python3.8/site-packages/django/db/utils.py", line 90, in __exit__
    raise dj_exc_value.with_traceback(traceback) from exc_value
  File "/home/rock/anaconda3/envs/venv/lib/python3.8/site-packages/django/db/backends/base/base.py", line 220, in ensure_connection
    self.connect()
  File "/home/rock/anaconda3/envs/venv/lib/python3.8/site-packages/django/utils/asyncio.py", line 26, in inner
    return func(*args, **kwargs)
  File "/home/rock/anaconda3/envs/venv/lib/python3.8/site-packages/django/db/backends/base/base.py", line 197, in connect
    self.connection = self.get_new_connection(conn_params)
  File "/home/rock/anaconda3/envs/venv/lib/python3.8/site-packages/django/utils/asyncio.py", line 26, in inner
    return func(*args, **kwargs)
  File "/home/rock/anaconda3/envs/venv/lib/python3.8/site-packages/django/db/backends/mysql/base.py", line 233, in get_new_connection
    return Database.connect(**conn_params)
  File "/home/rock/anaconda3/envs/venv/lib/python3.8/site-packages/MySQLdb/__init__.py", line 84, in Connect
    return Connection(*args, **kwargs)
  File "/home/rock/anaconda3/envs/venv/lib/python3.8/site-packages/MySQLdb/connections.py", line 179, in __init__
    super(Connection, self).__init__(*args, **kwargs2)
django.db.utils.OperationalError: (1040, 'Too many connections')

During handling of the above exception, another exception occurred:

Traceback (most recent call last):
  File "/home/rock/anaconda3/envs/venv/lib/python3.8/site-packages/django/core/handlers/exception.py", line 34, in inner
    response = get_response(request)
  File "/home/rock/anaconda3/envs/venv/lib/python3.8/site-packages/django/core/handlers/base.py", line 115, in _get_response
    response = self.process_exception_by_middleware(e, request)
  File "/home/rock/anaconda3/envs/venv/lib/python3.8/site-packages/django/core/handlers/base.py", line 113, in _get_response
    response = wrapped_callback(request, *callback_args, **callback_kwargs)
  File "/home/rock/anaconda3/envs/venv/lib/python3.8/site-packages/django/views/decorators/csrf.py", line 54, in wrapped_view
    return view_func(*args, **kwargs)
  File "/home/rock/anaconda3/envs/venv/lib/python3.8/site-packages/django/views/generic/base.py", line 71, in view
    return self.dispatch(request, *args, **kwargs)
  File "/home/rock/anaconda3/envs/venv/lib/python3.8/site-packages/rest_framework/views.py", line 505, in dispatch
    response = self.handle_exception(exc)
  File "/home/rock/anaconda3/envs/venv/lib/python3.8/site-packages/rest_framework/views.py", line 465, in handle_exception
    self.raise_uncaught_exception(exc)
  File "/home/rock/anaconda3/envs/venv/lib/python3.8/site-packages/rest_framework/views.py", line 476, in raise_uncaught_exception
    raise exc
  File "/home/rock/anaconda3/envs/venv/lib/python3.8/site-packages/rest_framework/views.py", line 502, in dispatch
    response = handler(request, *args, **kwargs)
  File "/home/rock/quality_inspection/python-workspace/project-sys/sys_auth/views.py", line 116, in post
    except exceptions as e:
TypeError: catching classes that do not inherit from BaseException is not allowed
[2020-08-07 17:13:52,983] [basehttp.py:157] [basehttp:log_message] [ERROR]- "POST /sys/api/auth/ HTTP/1.1" 500 22890
[2020-08-07 17:14:57,924] [log.py:222] [log:log_response] [ERROR]- Internal Server Error: /sys/api/auth/
Traceback (most recent call last):
  File "/home/rock/anaconda3/envs/venv/lib/python3.8/site-packages/django/db/backends/base/base.py", line 220, in ensure_connection
    self.connect()
  File "/home/rock/anaconda3/envs/venv/lib/python3.8/site-packages/django/utils/asyncio.py", line 26, in inner
    return func(*args, **kwargs)
  File "/home/rock/anaconda3/envs/venv/lib/python3.8/site-packages/django/db/backends/base/base.py", line 197, in connect
    self.connection = self.get_new_connection(conn_params)
  File "/home/rock/anaconda3/envs/venv/lib/python3.8/site-packages/django/utils/asyncio.py", line 26, in inner
    return func(*args, **kwargs)
  File "/home/rock/anaconda3/envs/venv/lib/python3.8/site-packages/django/db/backends/mysql/base.py", line 233, in get_new_connection
    return Database.connect(**conn_params)
  File "/home/rock/anaconda3/envs/venv/lib/python3.8/site-packages/MySQLdb/__init__.py", line 84, in Connect
    return Connection(*args, **kwargs)
  File "/home/rock/anaconda3/envs/venv/lib/python3.8/site-packages/MySQLdb/connections.py", line 179, in __init__
    super(Connection, self).__init__(*args, **kwargs2)
MySQLdb._exceptions.OperationalError: (1040, 'Too many connections')

The above exception was the direct cause of the following exception:

Traceback (most recent call last):
  File "/home/rock/quality_inspection/python-workspace/project-sys/sys_auth/views.py", line 95, in post
    obj = User.objects.filter(username=user).first()
  File "/home/rock/anaconda3/envs/venv/lib/python3.8/site-packages/django/db/models/query.py", line 664, in first
    for obj in (self if self.ordered else self.order_by('pk'))[:1]:
  File "/home/rock/anaconda3/envs/venv/lib/python3.8/site-packages/django/db/models/query.py", line 276, in __iter__
    self._fetch_all()
  File "/home/rock/anaconda3/envs/venv/lib/python3.8/site-packages/django/db/models/query.py", line 1261, in _fetch_all
    self._result_cache = list(self._iterable_class(self))
  File "/home/rock/anaconda3/envs/venv/lib/python3.8/site-packages/django/db/models/query.py", line 57, in __iter__
    results = compiler.execute_sql(chunked_fetch=self.chunked_fetch, chunk_size=self.chunk_size)
  File "/home/rock/anaconda3/envs/venv/lib/python3.8/site-packages/django/db/models/sql/compiler.py", line 1149, in execute_sql
    cursor = self.connection.cursor()
  File "/home/rock/anaconda3/envs/venv/lib/python3.8/site-packages/django/utils/asyncio.py", line 26, in inner
    return func(*args, **kwargs)
  File "/home/rock/anaconda3/envs/venv/lib/python3.8/site-packages/django/db/backends/base/base.py", line 260, in cursor
    return self._cursor()
  File "/home/rock/anaconda3/envs/venv/lib/python3.8/site-packages/django/db/backends/base/base.py", line 236, in _cursor
    self.ensure_connection()
  File "/home/rock/anaconda3/envs/venv/lib/python3.8/site-packages/django/utils/asyncio.py", line 26, in inner
    return func(*args, **kwargs)
  File "/home/rock/anaconda3/envs/venv/lib/python3.8/site-packages/django/db/backends/base/base.py", line 220, in ensure_connection
    self.connect()
  File "/home/rock/anaconda3/envs/venv/lib/python3.8/site-packages/django/db/utils.py", line 90, in __exit__
    raise dj_exc_value.with_traceback(traceback) from exc_value
  File "/home/rock/anaconda3/envs/venv/lib/python3.8/site-packages/django/db/backends/base/base.py", line 220, in ensure_connection
    self.connect()
  File "/home/rock/anaconda3/envs/venv/lib/python3.8/site-packages/django/utils/asyncio.py", line 26, in inner
    return func(*args, **kwargs)
  File "/home/rock/anaconda3/envs/venv/lib/python3.8/site-packages/django/db/backends/base/base.py", line 197, in connect
    self.connection = self.get_new_connection(conn_params)
  File "/home/rock/anaconda3/envs/venv/lib/python3.8/site-packages/django/utils/asyncio.py", line 26, in inner
    return func(*args, **kwargs)
  File "/home/rock/anaconda3/envs/venv/lib/python3.8/site-packages/django/db/backends/mysql/base.py", line 233, in get_new_connection
    return Database.connect(**conn_params)
  File "/home/rock/anaconda3/envs/venv/lib/python3.8/site-packages/MySQLdb/__init__.py", line 84, in Connect
    return Connection(*args, **kwargs)
  File "/home/rock/anaconda3/envs/venv/lib/python3.8/site-packages/MySQLdb/connections.py", line 179, in __init__
    super(Connection, self).__init__(*args, **kwargs2)
django.db.utils.OperationalError: (1040, 'Too many connections')

During handling of the above exception, another exception occurred:

Traceback (most recent call last):
  File "/home/rock/anaconda3/envs/venv/lib/python3.8/site-packages/django/core/handlers/exception.py", line 34, in inner
    response = get_response(request)
  File "/home/rock/anaconda3/envs/venv/lib/python3.8/site-packages/django/core/handlers/base.py", line 115, in _get_response
    response = self.process_exception_by_middleware(e, request)
  File "/home/rock/anaconda3/envs/venv/lib/python3.8/site-packages/django/core/handlers/base.py", line 113, in _get_response
    response = wrapped_callback(request, *callback_args, **callback_kwargs)
  File "/home/rock/anaconda3/envs/venv/lib/python3.8/site-packages/django/views/decorators/csrf.py", line 54, in wrapped_view
    return view_func(*args, **kwargs)
  File "/home/rock/anaconda3/envs/venv/lib/python3.8/site-packages/django/views/generic/base.py", line 71, in view
    return self.dispatch(request, *args, **kwargs)
  File "/home/rock/anaconda3/envs/venv/lib/python3.8/site-packages/rest_framework/views.py", line 505, in dispatch
    response = self.handle_exception(exc)
  File "/home/rock/anaconda3/envs/venv/lib/python3.8/site-packages/rest_framework/views.py", line 465, in handle_exception
    self.raise_uncaught_exception(exc)
  File "/home/rock/anaconda3/envs/venv/lib/python3.8/site-packages/rest_framework/views.py", line 476, in raise_uncaught_exception
    raise exc
  File "/home/rock/anaconda3/envs/venv/lib/python3.8/site-packages/rest_framework/views.py", line 502, in dispatch
    response = handler(request, *args, **kwargs)
  File "/home/rock/quality_inspection/python-workspace/project-sys/sys_auth/views.py", line 116, in post
    except exceptions as e:
TypeError: catching classes that do not inherit from BaseException is not allowed
[2020-08-07 17:14:57,926] [basehttp.py:157] [basehttp:log_message] [ERROR]- "POST /sys/api/auth/ HTTP/1.1" 500 23739
[2020-08-07 17:15:04,059] [log.py:222] [log:log_response] [ERROR]- Internal Server Error: /sys/api/auth/
Traceback (most recent call last):
  File "/home/rock/anaconda3/envs/venv/lib/python3.8/site-packages/django/db/backends/base/base.py", line 220, in ensure_connection
    self.connect()
  File "/home/rock/anaconda3/envs/venv/lib/python3.8/site-packages/django/utils/asyncio.py", line 26, in inner
    return func(*args, **kwargs)
  File "/home/rock/anaconda3/envs/venv/lib/python3.8/site-packages/django/db/backends/base/base.py", line 197, in connect
    self.connection = self.get_new_connection(conn_params)
  File "/home/rock/anaconda3/envs/venv/lib/python3.8/site-packages/django/utils/asyncio.py", line 26, in inner
    return func(*args, **kwargs)
  File "/home/rock/anaconda3/envs/venv/lib/python3.8/site-packages/django/db/backends/mysql/base.py", line 233, in get_new_connection
    return Database.connect(**conn_params)
  File "/home/rock/anaconda3/envs/venv/lib/python3.8/site-packages/MySQLdb/__init__.py", line 84, in Connect
    return Connection(*args, **kwargs)
  File "/home/rock/anaconda3/envs/venv/lib/python3.8/site-packages/MySQLdb/connections.py", line 179, in __init__
    super(Connection, self).__init__(*args, **kwargs2)
MySQLdb._exceptions.OperationalError: (1040, 'Too many connections')

The above exception was the direct cause of the following exception:

Traceback (most recent call last):
  File "/home/rock/quality_inspection/python-workspace/project-sys/sys_auth/views.py", line 95, in post
    obj = User.objects.filter(username=user).first()
  File "/home/rock/anaconda3/envs/venv/lib/python3.8/site-packages/django/db/models/query.py", line 664, in first
    for obj in (self if self.ordered else self.order_by('pk'))[:1]:
  File "/home/rock/anaconda3/envs/venv/lib/python3.8/site-packages/django/db/models/query.py", line 276, in __iter__
    self._fetch_all()
  File "/home/rock/anaconda3/envs/venv/lib/python3.8/site-packages/django/db/models/query.py", line 1261, in _fetch_all
    self._result_cache = list(self._iterable_class(self))
  File "/home/rock/anaconda3/envs/venv/lib/python3.8/site-packages/django/db/models/query.py", line 57, in __iter__
    results = compiler.execute_sql(chunked_fetch=self.chunked_fetch, chunk_size=self.chunk_size)
  File "/home/rock/anaconda3/envs/venv/lib/python3.8/site-packages/django/db/models/sql/compiler.py", line 1149, in execute_sql
    cursor = self.connection.cursor()
  File "/home/rock/anaconda3/envs/venv/lib/python3.8/site-packages/django/utils/asyncio.py", line 26, in inner
    return func(*args, **kwargs)
  File "/home/rock/anaconda3/envs/venv/lib/python3.8/site-packages/django/db/backends/base/base.py", line 260, in cursor
    return self._cursor()
  File "/home/rock/anaconda3/envs/venv/lib/python3.8/site-packages/django/db/backends/base/base.py", line 236, in _cursor
    self.ensure_connection()
  File "/home/rock/anaconda3/envs/venv/lib/python3.8/site-packages/django/utils/asyncio.py", line 26, in inner
    return func(*args, **kwargs)
  File "/home/rock/anaconda3/envs/venv/lib/python3.8/site-packages/django/db/backends/base/base.py", line 220, in ensure_connection
    self.connect()
  File "/home/rock/anaconda3/envs/venv/lib/python3.8/site-packages/django/db/utils.py", line 90, in __exit__
    raise dj_exc_value.with_traceback(traceback) from exc_value
  File "/home/rock/anaconda3/envs/venv/lib/python3.8/site-packages/django/db/backends/base/base.py", line 220, in ensure_connection
    self.connect()
  File "/home/rock/anaconda3/envs/venv/lib/python3.8/site-packages/django/utils/asyncio.py", line 26, in inner
    return func(*args, **kwargs)
  File "/home/rock/anaconda3/envs/venv/lib/python3.8/site-packages/django/db/backends/base/base.py", line 197, in connect
    self.connection = self.get_new_connection(conn_params)
  File "/home/rock/anaconda3/envs/venv/lib/python3.8/site-packages/django/utils/asyncio.py", line 26, in inner
    return func(*args, **kwargs)
  File "/home/rock/anaconda3/envs/venv/lib/python3.8/site-packages/django/db/backends/mysql/base.py", line 233, in get_new_connection
    return Database.connect(**conn_params)
  File "/home/rock/anaconda3/envs/venv/lib/python3.8/site-packages/MySQLdb/__init__.py", line 84, in Connect
    return Connection(*args, **kwargs)
  File "/home/rock/anaconda3/envs/venv/lib/python3.8/site-packages/MySQLdb/connections.py", line 179, in __init__
    super(Connection, self).__init__(*args, **kwargs2)
django.db.utils.OperationalError: (1040, 'Too many connections')

During handling of the above exception, another exception occurred:

Traceback (most recent call last):
  File "/home/rock/anaconda3/envs/venv/lib/python3.8/site-packages/django/core/handlers/exception.py", line 34, in inner
    response = get_response(request)
  File "/home/rock/anaconda3/envs/venv/lib/python3.8/site-packages/django/core/handlers/base.py", line 115, in _get_response
    response = self.process_exception_by_middleware(e, request)
  File "/home/rock/anaconda3/envs/venv/lib/python3.8/site-packages/django/core/handlers/base.py", line 113, in _get_response
    response = wrapped_callback(request, *callback_args, **callback_kwargs)
  File "/home/rock/anaconda3/envs/venv/lib/python3.8/site-packages/django/views/decorators/csrf.py", line 54, in wrapped_view
    return view_func(*args, **kwargs)
  File "/home/rock/anaconda3/envs/venv/lib/python3.8/site-packages/django/views/generic/base.py", line 71, in view
    return self.dispatch(request, *args, **kwargs)
  File "/home/rock/anaconda3/envs/venv/lib/python3.8/site-packages/rest_framework/views.py", line 505, in dispatch
    response = self.handle_exception(exc)
  File "/home/rock/anaconda3/envs/venv/lib/python3.8/site-packages/rest_framework/views.py", line 465, in handle_exception
    self.raise_uncaught_exception(exc)
  File "/home/rock/anaconda3/envs/venv/lib/python3.8/site-packages/rest_framework/views.py", line 476, in raise_uncaught_exception
    raise exc
  File "/home/rock/anaconda3/envs/venv/lib/python3.8/site-packages/rest_framework/views.py", line 502, in dispatch
    response = handler(request, *args, **kwargs)
  File "/home/rock/quality_inspection/python-workspace/project-sys/sys_auth/views.py", line 116, in post
    except exceptions as e:
TypeError: catching classes that do not inherit from BaseException is not allowed
[2020-08-07 17:15:04,061] [basehttp.py:157] [basehttp:log_message] [ERROR]- "POST /sys/api/auth/ HTTP/1.1" 500 23739
[2020-08-07 17:15:29,051] [basehttp.py:157] [basehttp:log_message] [INFO]- "POST /sys/api/auth/ HTTP/1.1" 200 65
[2020-08-07 17:15:32,153] [basehttp.py:157] [basehttp:log_message] [INFO]- "GET /sys/api/user/role/?username=wl&application=automation&type=menu HTTP/1.1" 200 3623
[2020-08-07 17:15:32,313] [log.py:222] [log:log_response] [ERROR]- Internal Server Error: /sys/api/user/role/
Traceback (most recent call last):
  File "/home/rock/anaconda3/envs/venv/lib/python3.8/site-packages/django/db/backends/base/base.py", line 220, in ensure_connection
    self.connect()
  File "/home/rock/anaconda3/envs/venv/lib/python3.8/site-packages/django/utils/asyncio.py", line 26, in inner
    return func(*args, **kwargs)
  File "/home/rock/anaconda3/envs/venv/lib/python3.8/site-packages/django/db/backends/base/base.py", line 197, in connect
    self.connection = self.get_new_connection(conn_params)
  File "/home/rock/anaconda3/envs/venv/lib/python3.8/site-packages/django/utils/asyncio.py", line 26, in inner
    return func(*args, **kwargs)
  File "/home/rock/anaconda3/envs/venv/lib/python3.8/site-packages/django/db/backends/mysql/base.py", line 233, in get_new_connection
    return Database.connect(**conn_params)
  File "/home/rock/anaconda3/envs/venv/lib/python3.8/site-packages/MySQLdb/__init__.py", line 84, in Connect
    return Connection(*args, **kwargs)
  File "/home/rock/anaconda3/envs/venv/lib/python3.8/site-packages/MySQLdb/connections.py", line 179, in __init__
    super(Connection, self).__init__(*args, **kwargs2)
MySQLdb._exceptions.OperationalError: (1040, 'Too many connections')

The above exception was the direct cause of the following exception:

Traceback (most recent call last):
  File "/home/rock/anaconda3/envs/venv/lib/python3.8/site-packages/django/core/handlers/exception.py", line 34, in inner
    response = get_response(request)
  File "/home/rock/anaconda3/envs/venv/lib/python3.8/site-packages/django/core/handlers/base.py", line 115, in _get_response
    response = self.process_exception_by_middleware(e, request)
  File "/home/rock/anaconda3/envs/venv/lib/python3.8/site-packages/django/core/handlers/base.py", line 113, in _get_response
    response = wrapped_callback(request, *callback_args, **callback_kwargs)
  File "/home/rock/anaconda3/envs/venv/lib/python3.8/site-packages/django/views/decorators/csrf.py", line 54, in wrapped_view
    return view_func(*args, **kwargs)
  File "/home/rock/anaconda3/envs/venv/lib/python3.8/site-packages/rest_framework/viewsets.py", line 114, in view
    return self.dispatch(request, *args, **kwargs)
  File "/home/rock/anaconda3/envs/venv/lib/python3.8/site-packages/rest_framework/views.py", line 505, in dispatch
    response = self.handle_exception(exc)
  File "/home/rock/anaconda3/envs/venv/lib/python3.8/site-packages/rest_framework/views.py", line 465, in handle_exception
    self.raise_uncaught_exception(exc)
  File "/home/rock/anaconda3/envs/venv/lib/python3.8/site-packages/rest_framework/views.py", line 476, in raise_uncaught_exception
    raise exc
  File "/home/rock/anaconda3/envs/venv/lib/python3.8/site-packages/rest_framework/views.py", line 493, in dispatch
    self.initial(request, *args, **kwargs)
  File "/home/rock/anaconda3/envs/venv/lib/python3.8/site-packages/rest_framework/views.py", line 410, in initial
    self.perform_authentication(request)
  File "/home/rock/anaconda3/envs/venv/lib/python3.8/site-packages/rest_framework/views.py", line 324, in perform_authentication
    request.user
  File "/home/rock/anaconda3/envs/venv/lib/python3.8/site-packages/rest_framework/request.py", line 220, in user
    self._authenticate()
  File "/home/rock/anaconda3/envs/venv/lib/python3.8/site-packages/rest_framework/request.py", line 373, in _authenticate
    user_auth_tuple = authenticator.authenticate(self)
  File "/home/rock/quality_inspection/python-workspace/project-sys/sys_auth/views.py", line 39, in authenticate
    token_obj = Token.objects.filter(token=token).first()
  File "/home/rock/anaconda3/envs/venv/lib/python3.8/site-packages/django/db/models/query.py", line 664, in first
    for obj in (self if self.ordered else self.order_by('pk'))[:1]:
  File "/home/rock/anaconda3/envs/venv/lib/python3.8/site-packages/django/db/models/query.py", line 276, in __iter__
    self._fetch_all()
  File "/home/rock/anaconda3/envs/venv/lib/python3.8/site-packages/django/db/models/query.py", line 1261, in _fetch_all
    self._result_cache = list(self._iterable_class(self))
  File "/home/rock/anaconda3/envs/venv/lib/python3.8/site-packages/django/db/models/query.py", line 57, in __iter__
    results = compiler.execute_sql(chunked_fetch=self.chunked_fetch, chunk_size=self.chunk_size)
  File "/home/rock/anaconda3/envs/venv/lib/python3.8/site-packages/django/db/models/sql/compiler.py", line 1149, in execute_sql
    cursor = self.connection.cursor()
  File "/home/rock/anaconda3/envs/venv/lib/python3.8/site-packages/django/utils/asyncio.py", line 26, in inner
    return func(*args, **kwargs)
  File "/home/rock/anaconda3/envs/venv/lib/python3.8/site-packages/django/db/backends/base/base.py", line 260, in cursor
    return self._cursor()
  File "/home/rock/anaconda3/envs/venv/lib/python3.8/site-packages/django/db/backends/base/base.py", line 236, in _cursor
    self.ensure_connection()
  File "/home/rock/anaconda3/envs/venv/lib/python3.8/site-packages/django/utils/asyncio.py", line 26, in inner
    return func(*args, **kwargs)
  File "/home/rock/anaconda3/envs/venv/lib/python3.8/site-packages/django/db/backends/base/base.py", line 220, in ensure_connection
    self.connect()
  File "/home/rock/anaconda3/envs/venv/lib/python3.8/site-packages/django/db/utils.py", line 90, in __exit__
    raise dj_exc_value.with_traceback(traceback) from exc_value
  File "/home/rock/anaconda3/envs/venv/lib/python3.8/site-packages/django/db/backends/base/base.py", line 220, in ensure_connection
    self.connect()
  File "/home/rock/anaconda3/envs/venv/lib/python3.8/site-packages/django/utils/asyncio.py", line 26, in inner
    return func(*args, **kwargs)
  File "/home/rock/anaconda3/envs/venv/lib/python3.8/site-packages/django/db/backends/base/base.py", line 197, in connect
    self.connection = self.get_new_connection(conn_params)
  File "/home/rock/anaconda3/envs/venv/lib/python3.8/site-packages/django/utils/asyncio.py", line 26, in inner
    return func(*args, **kwargs)
  File "/home/rock/anaconda3/envs/venv/lib/python3.8/site-packages/django/db/backends/mysql/base.py", line 233, in get_new_connection
    return Database.connect(**conn_params)
  File "/home/rock/anaconda3/envs/venv/lib/python3.8/site-packages/MySQLdb/__init__.py", line 84, in Connect
    return Connection(*args, **kwargs)
  File "/home/rock/anaconda3/envs/venv/lib/python3.8/site-packages/MySQLdb/connections.py", line 179, in __init__
    super(Connection, self).__init__(*args, **kwargs2)
django.db.utils.OperationalError: (1040, 'Too many connections')
[2020-08-07 17:15:32,317] [basehttp.py:157] [basehttp:log_message] [ERROR]- "GET /sys/api/user/role/?username=wl&application=automation&type=button HTTP/1.1" 500 24158
[2020-08-07 17:18:18,446] [log.py:222] [log:log_response] [ERROR]- Internal Server Error: /sys/api/auth/
Traceback (most recent call last):
  File "/home/rock/anaconda3/envs/venv/lib/python3.8/site-packages/django/db/backends/base/base.py", line 220, in ensure_connection
    self.connect()
  File "/home/rock/anaconda3/envs/venv/lib/python3.8/site-packages/django/utils/asyncio.py", line 26, in inner
    return func(*args, **kwargs)
  File "/home/rock/anaconda3/envs/venv/lib/python3.8/site-packages/django/db/backends/base/base.py", line 197, in connect
    self.connection = self.get_new_connection(conn_params)
  File "/home/rock/anaconda3/envs/venv/lib/python3.8/site-packages/django/utils/asyncio.py", line 26, in inner
    return func(*args, **kwargs)
  File "/home/rock/anaconda3/envs/venv/lib/python3.8/site-packages/django/db/backends/mysql/base.py", line 233, in get_new_connection
    return Database.connect(**conn_params)
  File "/home/rock/anaconda3/envs/venv/lib/python3.8/site-packages/MySQLdb/__init__.py", line 84, in Connect
    return Connection(*args, **kwargs)
  File "/home/rock/anaconda3/envs/venv/lib/python3.8/site-packages/MySQLdb/connections.py", line 179, in __init__
    super(Connection, self).__init__(*args, **kwargs2)
MySQLdb._exceptions.OperationalError: (1040, 'Too many connections')

The above exception was the direct cause of the following exception:

Traceback (most recent call last):
  File "/home/rock/quality_inspection/python-workspace/project-sys/sys_auth/views.py", line 80, in post
    token_obj = Token.objects.filter(token=token).first()
  File "/home/rock/anaconda3/envs/venv/lib/python3.8/site-packages/django/db/models/query.py", line 664, in first
    for obj in (self if self.ordered else self.order_by('pk'))[:1]:
  File "/home/rock/anaconda3/envs/venv/lib/python3.8/site-packages/django/db/models/query.py", line 276, in __iter__
    self._fetch_all()
  File "/home/rock/anaconda3/envs/venv/lib/python3.8/site-packages/django/db/models/query.py", line 1261, in _fetch_all
    self._result_cache = list(self._iterable_class(self))
  File "/home/rock/anaconda3/envs/venv/lib/python3.8/site-packages/django/db/models/query.py", line 57, in __iter__
    results = compiler.execute_sql(chunked_fetch=self.chunked_fetch, chunk_size=self.chunk_size)
  File "/home/rock/anaconda3/envs/venv/lib/python3.8/site-packages/django/db/models/sql/compiler.py", line 1149, in execute_sql
    cursor = self.connection.cursor()
  File "/home/rock/anaconda3/envs/venv/lib/python3.8/site-packages/django/utils/asyncio.py", line 26, in inner
    return func(*args, **kwargs)
  File "/home/rock/anaconda3/envs/venv/lib/python3.8/site-packages/django/db/backends/base/base.py", line 260, in cursor
    return self._cursor()
  File "/home/rock/anaconda3/envs/venv/lib/python3.8/site-packages/django/db/backends/base/base.py", line 236, in _cursor
    self.ensure_connection()
  File "/home/rock/anaconda3/envs/venv/lib/python3.8/site-packages/django/utils/asyncio.py", line 26, in inner
    return func(*args, **kwargs)
  File "/home/rock/anaconda3/envs/venv/lib/python3.8/site-packages/django/db/backends/base/base.py", line 220, in ensure_connection
    self.connect()
  File "/home/rock/anaconda3/envs/venv/lib/python3.8/site-packages/django/db/utils.py", line 90, in __exit__
    raise dj_exc_value.with_traceback(traceback) from exc_value
  File "/home/rock/anaconda3/envs/venv/lib/python3.8/site-packages/django/db/backends/base/base.py", line 220, in ensure_connection
    self.connect()
  File "/home/rock/anaconda3/envs/venv/lib/python3.8/site-packages/django/utils/asyncio.py", line 26, in inner
    return func(*args, **kwargs)
  File "/home/rock/anaconda3/envs/venv/lib/python3.8/site-packages/django/db/backends/base/base.py", line 197, in connect
    self.connection = self.get_new_connection(conn_params)
  File "/home/rock/anaconda3/envs/venv/lib/python3.8/site-packages/django/utils/asyncio.py", line 26, in inner
    return func(*args, **kwargs)
  File "/home/rock/anaconda3/envs/venv/lib/python3.8/site-packages/django/db/backends/mysql/base.py", line 233, in get_new_connection
    return Database.connect(**conn_params)
  File "/home/rock/anaconda3/envs/venv/lib/python3.8/site-packages/MySQLdb/__init__.py", line 84, in Connect
    return Connection(*args, **kwargs)
  File "/home/rock/anaconda3/envs/venv/lib/python3.8/site-packages/MySQLdb/connections.py", line 179, in __init__
    super(Connection, self).__init__(*args, **kwargs2)
django.db.utils.OperationalError: (1040, 'Too many connections')

During handling of the above exception, another exception occurred:

Traceback (most recent call last):
  File "/home/rock/anaconda3/envs/venv/lib/python3.8/site-packages/django/core/handlers/exception.py", line 34, in inner
    response = get_response(request)
  File "/home/rock/anaconda3/envs/venv/lib/python3.8/site-packages/django/core/handlers/base.py", line 115, in _get_response
    response = self.process_exception_by_middleware(e, request)
  File "/home/rock/anaconda3/envs/venv/lib/python3.8/site-packages/django/core/handlers/base.py", line 113, in _get_response
    response = wrapped_callback(request, *callback_args, **callback_kwargs)
  File "/home/rock/anaconda3/envs/venv/lib/python3.8/site-packages/django/views/decorators/csrf.py", line 54, in wrapped_view
    return view_func(*args, **kwargs)
  File "/home/rock/anaconda3/envs/venv/lib/python3.8/site-packages/django/views/generic/base.py", line 71, in view
    return self.dispatch(request, *args, **kwargs)
  File "/home/rock/anaconda3/envs/venv/lib/python3.8/site-packages/rest_framework/views.py", line 505, in dispatch
    response = self.handle_exception(exc)
  File "/home/rock/anaconda3/envs/venv/lib/python3.8/site-packages/rest_framework/views.py", line 465, in handle_exception
    self.raise_uncaught_exception(exc)
  File "/home/rock/anaconda3/envs/venv/lib/python3.8/site-packages/rest_framework/views.py", line 476, in raise_uncaught_exception
    raise exc
  File "/home/rock/anaconda3/envs/venv/lib/python3.8/site-packages/rest_framework/views.py", line 502, in dispatch
    response = handler(request, *args, **kwargs)
  File "/home/rock/quality_inspection/python-workspace/project-sys/sys_auth/views.py", line 116, in post
    except exceptions as e:
TypeError: catching classes that do not inherit from BaseException is not allowed
[2020-08-07 17:18:18,449] [basehttp.py:157] [basehttp:log_message] [ERROR]- "POST /sys/api/auth/ HTTP/1.1" 500 22890
[2020-08-07 17:18:24,096] [log.py:222] [log:log_response] [ERROR]- Internal Server Error: /sys/api/auth/
Traceback (most recent call last):
  File "/home/rock/anaconda3/envs/venv/lib/python3.8/site-packages/django/db/backends/base/base.py", line 220, in ensure_connection
    self.connect()
  File "/home/rock/anaconda3/envs/venv/lib/python3.8/site-packages/django/utils/asyncio.py", line 26, in inner
    return func(*args, **kwargs)
  File "/home/rock/anaconda3/envs/venv/lib/python3.8/site-packages/django/db/backends/base/base.py", line 197, in connect
    self.connection = self.get_new_connection(conn_params)
  File "/home/rock/anaconda3/envs/venv/lib/python3.8/site-packages/django/utils/asyncio.py", line 26, in inner
    return func(*args, **kwargs)
  File "/home/rock/anaconda3/envs/venv/lib/python3.8/site-packages/django/db/backends/mysql/base.py", line 233, in get_new_connection
    return Database.connect(**conn_params)
  File "/home/rock/anaconda3/envs/venv/lib/python3.8/site-packages/MySQLdb/__init__.py", line 84, in Connect
    return Connection(*args, **kwargs)
  File "/home/rock/anaconda3/envs/venv/lib/python3.8/site-packages/MySQLdb/connections.py", line 179, in __init__
    super(Connection, self).__init__(*args, **kwargs2)
MySQLdb._exceptions.OperationalError: (1040, 'Too many connections')

The above exception was the direct cause of the following exception:

Traceback (most recent call last):
  File "/home/rock/quality_inspection/python-workspace/project-sys/sys_auth/views.py", line 95, in post
    obj = User.objects.filter(username=user).first()
  File "/home/rock/anaconda3/envs/venv/lib/python3.8/site-packages/django/db/models/query.py", line 664, in first
    for obj in (self if self.ordered else self.order_by('pk'))[:1]:
  File "/home/rock/anaconda3/envs/venv/lib/python3.8/site-packages/django/db/models/query.py", line 276, in __iter__
    self._fetch_all()
  File "/home/rock/anaconda3/envs/venv/lib/python3.8/site-packages/django/db/models/query.py", line 1261, in _fetch_all
    self._result_cache = list(self._iterable_class(self))
  File "/home/rock/anaconda3/envs/venv/lib/python3.8/site-packages/django/db/models/query.py", line 57, in __iter__
    results = compiler.execute_sql(chunked_fetch=self.chunked_fetch, chunk_size=self.chunk_size)
  File "/home/rock/anaconda3/envs/venv/lib/python3.8/site-packages/django/db/models/sql/compiler.py", line 1149, in execute_sql
    cursor = self.connection.cursor()
  File "/home/rock/anaconda3/envs/venv/lib/python3.8/site-packages/django/utils/asyncio.py", line 26, in inner
    return func(*args, **kwargs)
  File "/home/rock/anaconda3/envs/venv/lib/python3.8/site-packages/django/db/backends/base/base.py", line 260, in cursor
    return self._cursor()
  File "/home/rock/anaconda3/envs/venv/lib/python3.8/site-packages/django/db/backends/base/base.py", line 236, in _cursor
    self.ensure_connection()
  File "/home/rock/anaconda3/envs/venv/lib/python3.8/site-packages/django/utils/asyncio.py", line 26, in inner
    return func(*args, **kwargs)
  File "/home/rock/anaconda3/envs/venv/lib/python3.8/site-packages/django/db/backends/base/base.py", line 220, in ensure_connection
    self.connect()
  File "/home/rock/anaconda3/envs/venv/lib/python3.8/site-packages/django/db/utils.py", line 90, in __exit__
    raise dj_exc_value.with_traceback(traceback) from exc_value
  File "/home/rock/anaconda3/envs/venv/lib/python3.8/site-packages/django/db/backends/base/base.py", line 220, in ensure_connection
    self.connect()
  File "/home/rock/anaconda3/envs/venv/lib/python3.8/site-packages/django/utils/asyncio.py", line 26, in inner
    return func(*args, **kwargs)
  File "/home/rock/anaconda3/envs/venv/lib/python3.8/site-packages/django/db/backends/base/base.py", line 197, in connect
    self.connection = self.get_new_connection(conn_params)
  File "/home/rock/anaconda3/envs/venv/lib/python3.8/site-packages/django/utils/asyncio.py", line 26, in inner
    return func(*args, **kwargs)
  File "/home/rock/anaconda3/envs/venv/lib/python3.8/site-packages/django/db/backends/mysql/base.py", line 233, in get_new_connection
    return Database.connect(**conn_params)
  File "/home/rock/anaconda3/envs/venv/lib/python3.8/site-packages/MySQLdb/__init__.py", line 84, in Connect
    return Connection(*args, **kwargs)
  File "/home/rock/anaconda3/envs/venv/lib/python3.8/site-packages/MySQLdb/connections.py", line 179, in __init__
    super(Connection, self).__init__(*args, **kwargs2)
django.db.utils.OperationalError: (1040, 'Too many connections')

During handling of the above exception, another exception occurred:

Traceback (most recent call last):
  File "/home/rock/anaconda3/envs/venv/lib/python3.8/site-packages/django/core/handlers/exception.py", line 34, in inner
    response = get_response(request)
  File "/home/rock/anaconda3/envs/venv/lib/python3.8/site-packages/django/core/handlers/base.py", line 115, in _get_response
    response = self.process_exception_by_middleware(e, request)
  File "/home/rock/anaconda3/envs/venv/lib/python3.8/site-packages/django/core/handlers/base.py", line 113, in _get_response
    response = wrapped_callback(request, *callback_args, **callback_kwargs)
  File "/home/rock/anaconda3/envs/venv/lib/python3.8/site-packages/django/views/decorators/csrf.py", line 54, in wrapped_view
    return view_func(*args, **kwargs)
  File "/home/rock/anaconda3/envs/venv/lib/python3.8/site-packages/django/views/generic/base.py", line 71, in view
    return self.dispatch(request, *args, **kwargs)
  File "/home/rock/anaconda3/envs/venv/lib/python3.8/site-packages/rest_framework/views.py", line 505, in dispatch
    response = self.handle_exception(exc)
  File "/home/rock/anaconda3/envs/venv/lib/python3.8/site-packages/rest_framework/views.py", line 465, in handle_exception
    self.raise_uncaught_exception(exc)
  File "/home/rock/anaconda3/envs/venv/lib/python3.8/site-packages/rest_framework/views.py", line 476, in raise_uncaught_exception
    raise exc
  File "/home/rock/anaconda3/envs/venv/lib/python3.8/site-packages/rest_framework/views.py", line 502, in dispatch
    response = handler(request, *args, **kwargs)
  File "/home/rock/quality_inspection/python-workspace/project-sys/sys_auth/views.py", line 116, in post
    except exceptions as e:
TypeError: catching classes that do not inherit from BaseException is not allowed
[2020-08-07 17:18:24,098] [basehttp.py:157] [basehttp:log_message] [ERROR]- "POST /sys/api/auth/ HTTP/1.1" 500 23739
[2020-08-07 17:18:40,109] [log.py:222] [log:log_response] [ERROR]- Internal Server Error: /sys/api/auth/
Traceback (most recent call last):
  File "/home/rock/anaconda3/envs/venv/lib/python3.8/site-packages/django/db/backends/base/base.py", line 220, in ensure_connection
    self.connect()
  File "/home/rock/anaconda3/envs/venv/lib/python3.8/site-packages/django/utils/asyncio.py", line 26, in inner
    return func(*args, **kwargs)
  File "/home/rock/anaconda3/envs/venv/lib/python3.8/site-packages/django/db/backends/base/base.py", line 197, in connect
    self.connection = self.get_new_connection(conn_params)
  File "/home/rock/anaconda3/envs/venv/lib/python3.8/site-packages/django/utils/asyncio.py", line 26, in inner
    return func(*args, **kwargs)
  File "/home/rock/anaconda3/envs/venv/lib/python3.8/site-packages/django/db/backends/mysql/base.py", line 233, in get_new_connection
    return Database.connect(**conn_params)
  File "/home/rock/anaconda3/envs/venv/lib/python3.8/site-packages/MySQLdb/__init__.py", line 84, in Connect
    return Connection(*args, **kwargs)
  File "/home/rock/anaconda3/envs/venv/lib/python3.8/site-packages/MySQLdb/connections.py", line 179, in __init__
    super(Connection, self).__init__(*args, **kwargs2)
MySQLdb._exceptions.OperationalError: (1040, 'Too many connections')

The above exception was the direct cause of the following exception:

Traceback (most recent call last):
  File "/home/rock/quality_inspection/python-workspace/project-sys/sys_auth/views.py", line 95, in post
    obj = User.objects.filter(username=user).first()
  File "/home/rock/anaconda3/envs/venv/lib/python3.8/site-packages/django/db/models/query.py", line 664, in first
    for obj in (self if self.ordered else self.order_by('pk'))[:1]:
  File "/home/rock/anaconda3/envs/venv/lib/python3.8/site-packages/django/db/models/query.py", line 276, in __iter__
    self._fetch_all()
  File "/home/rock/anaconda3/envs/venv/lib/python3.8/site-packages/django/db/models/query.py", line 1261, in _fetch_all
    self._result_cache = list(self._iterable_class(self))
  File "/home/rock/anaconda3/envs/venv/lib/python3.8/site-packages/django/db/models/query.py", line 57, in __iter__
    results = compiler.execute_sql(chunked_fetch=self.chunked_fetch, chunk_size=self.chunk_size)
  File "/home/rock/anaconda3/envs/venv/lib/python3.8/site-packages/django/db/models/sql/compiler.py", line 1149, in execute_sql
    cursor = self.connection.cursor()
  File "/home/rock/anaconda3/envs/venv/lib/python3.8/site-packages/django/utils/asyncio.py", line 26, in inner
    return func(*args, **kwargs)
  File "/home/rock/anaconda3/envs/venv/lib/python3.8/site-packages/django/db/backends/base/base.py", line 260, in cursor
    return self._cursor()
  File "/home/rock/anaconda3/envs/venv/lib/python3.8/site-packages/django/db/backends/base/base.py", line 236, in _cursor
    self.ensure_connection()
  File "/home/rock/anaconda3/envs/venv/lib/python3.8/site-packages/django/utils/asyncio.py", line 26, in inner
    return func(*args, **kwargs)
  File "/home/rock/anaconda3/envs/venv/lib/python3.8/site-packages/django/db/backends/base/base.py", line 220, in ensure_connection
    self.connect()
  File "/home/rock/anaconda3/envs/venv/lib/python3.8/site-packages/django/db/utils.py", line 90, in __exit__
    raise dj_exc_value.with_traceback(traceback) from exc_value
  File "/home/rock/anaconda3/envs/venv/lib/python3.8/site-packages/django/db/backends/base/base.py", line 220, in ensure_connection
    self.connect()
  File "/home/rock/anaconda3/envs/venv/lib/python3.8/site-packages/django/utils/asyncio.py", line 26, in inner
    return func(*args, **kwargs)
  File "/home/rock/anaconda3/envs/venv/lib/python3.8/site-packages/django/db/backends/base/base.py", line 197, in connect
    self.connection = self.get_new_connection(conn_params)
  File "/home/rock/anaconda3/envs/venv/lib/python3.8/site-packages/django/utils/asyncio.py", line 26, in inner
    return func(*args, **kwargs)
  File "/home/rock/anaconda3/envs/venv/lib/python3.8/site-packages/django/db/backends/mysql/base.py", line 233, in get_new_connection
    return Database.connect(**conn_params)
  File "/home/rock/anaconda3/envs/venv/lib/python3.8/site-packages/MySQLdb/__init__.py", line 84, in Connect
    return Connection(*args, **kwargs)
  File "/home/rock/anaconda3/envs/venv/lib/python3.8/site-packages/MySQLdb/connections.py", line 179, in __init__
    super(Connection, self).__init__(*args, **kwargs2)
django.db.utils.OperationalError: (1040, 'Too many connections')

During handling of the above exception, another exception occurred:

Traceback (most recent call last):
  File "/home/rock/anaconda3/envs/venv/lib/python3.8/site-packages/django/core/handlers/exception.py", line 34, in inner
    response = get_response(request)
  File "/home/rock/anaconda3/envs/venv/lib/python3.8/site-packages/django/core/handlers/base.py", line 115, in _get_response
    response = self.process_exception_by_middleware(e, request)
  File "/home/rock/anaconda3/envs/venv/lib/python3.8/site-packages/django/core/handlers/base.py", line 113, in _get_response
    response = wrapped_callback(request, *callback_args, **callback_kwargs)
  File "/home/rock/anaconda3/envs/venv/lib/python3.8/site-packages/django/views/decorators/csrf.py", line 54, in wrapped_view
    return view_func(*args, **kwargs)
  File "/home/rock/anaconda3/envs/venv/lib/python3.8/site-packages/django/views/generic/base.py", line 71, in view
    return self.dispatch(request, *args, **kwargs)
  File "/home/rock/anaconda3/envs/venv/lib/python3.8/site-packages/rest_framework/views.py", line 505, in dispatch
    response = self.handle_exception(exc)
  File "/home/rock/anaconda3/envs/venv/lib/python3.8/site-packages/rest_framework/views.py", line 465, in handle_exception
    self.raise_uncaught_exception(exc)
  File "/home/rock/anaconda3/envs/venv/lib/python3.8/site-packages/rest_framework/views.py", line 476, in raise_uncaught_exception
    raise exc
  File "/home/rock/anaconda3/envs/venv/lib/python3.8/site-packages/rest_framework/views.py", line 502, in dispatch
    response = handler(request, *args, **kwargs)
  File "/home/rock/quality_inspection/python-workspace/project-sys/sys_auth/views.py", line 116, in post
    except exceptions as e:
TypeError: catching classes that do not inherit from BaseException is not allowed
[2020-08-07 17:18:40,111] [basehttp.py:157] [basehttp:log_message] [ERROR]- "POST /sys/api/auth/ HTTP/1.1" 500 23739
[2020-08-07 17:19:09,343] [log.py:222] [log:log_response] [ERROR]- Internal Server Error: /sys/api/auth/
Traceback (most recent call last):
  File "/home/rock/anaconda3/envs/venv/lib/python3.8/site-packages/django/db/backends/base/base.py", line 220, in ensure_connection
    self.connect()
  File "/home/rock/anaconda3/envs/venv/lib/python3.8/site-packages/django/utils/asyncio.py", line 26, in inner
    return func(*args, **kwargs)
  File "/home/rock/anaconda3/envs/venv/lib/python3.8/site-packages/django/db/backends/base/base.py", line 197, in connect
    self.connection = self.get_new_connection(conn_params)
  File "/home/rock/anaconda3/envs/venv/lib/python3.8/site-packages/django/utils/asyncio.py", line 26, in inner
    return func(*args, **kwargs)
  File "/home/rock/anaconda3/envs/venv/lib/python3.8/site-packages/django/db/backends/mysql/base.py", line 233, in get_new_connection
    return Database.connect(**conn_params)
  File "/home/rock/anaconda3/envs/venv/lib/python3.8/site-packages/MySQLdb/__init__.py", line 84, in Connect
    return Connection(*args, **kwargs)
  File "/home/rock/anaconda3/envs/venv/lib/python3.8/site-packages/MySQLdb/connections.py", line 179, in __init__
    super(Connection, self).__init__(*args, **kwargs2)
MySQLdb._exceptions.OperationalError: (1040, 'Too many connections')

The above exception was the direct cause of the following exception:

Traceback (most recent call last):
  File "/home/rock/quality_inspection/python-workspace/project-sys/sys_auth/views.py", line 95, in post
    obj = User.objects.filter(username=user).first()
  File "/home/rock/anaconda3/envs/venv/lib/python3.8/site-packages/django/db/models/query.py", line 664, in first
    for obj in (self if self.ordered else self.order_by('pk'))[:1]:
  File "/home/rock/anaconda3/envs/venv/lib/python3.8/site-packages/django/db/models/query.py", line 276, in __iter__
    self._fetch_all()
  File "/home/rock/anaconda3/envs/venv/lib/python3.8/site-packages/django/db/models/query.py", line 1261, in _fetch_all
    self._result_cache = list(self._iterable_class(self))
  File "/home/rock/anaconda3/envs/venv/lib/python3.8/site-packages/django/db/models/query.py", line 57, in __iter__
    results = compiler.execute_sql(chunked_fetch=self.chunked_fetch, chunk_size=self.chunk_size)
  File "/home/rock/anaconda3/envs/venv/lib/python3.8/site-packages/django/db/models/sql/compiler.py", line 1149, in execute_sql
    cursor = self.connection.cursor()
  File "/home/rock/anaconda3/envs/venv/lib/python3.8/site-packages/django/utils/asyncio.py", line 26, in inner
    return func(*args, **kwargs)
  File "/home/rock/anaconda3/envs/venv/lib/python3.8/site-packages/django/db/backends/base/base.py", line 260, in cursor
    return self._cursor()
  File "/home/rock/anaconda3/envs/venv/lib/python3.8/site-packages/django/db/backends/base/base.py", line 236, in _cursor
    self.ensure_connection()
  File "/home/rock/anaconda3/envs/venv/lib/python3.8/site-packages/django/utils/asyncio.py", line 26, in inner
    return func(*args, **kwargs)
  File "/home/rock/anaconda3/envs/venv/lib/python3.8/site-packages/django/db/backends/base/base.py", line 220, in ensure_connection
    self.connect()
  File "/home/rock/anaconda3/envs/venv/lib/python3.8/site-packages/django/db/utils.py", line 90, in __exit__
    raise dj_exc_value.with_traceback(traceback) from exc_value
  File "/home/rock/anaconda3/envs/venv/lib/python3.8/site-packages/django/db/backends/base/base.py", line 220, in ensure_connection
    self.connect()
  File "/home/rock/anaconda3/envs/venv/lib/python3.8/site-packages/django/utils/asyncio.py", line 26, in inner
    return func(*args, **kwargs)
  File "/home/rock/anaconda3/envs/venv/lib/python3.8/site-packages/django/db/backends/base/base.py", line 197, in connect
    self.connection = self.get_new_connection(conn_params)
  File "/home/rock/anaconda3/envs/venv/lib/python3.8/site-packages/django/utils/asyncio.py", line 26, in inner
    return func(*args, **kwargs)
  File "/home/rock/anaconda3/envs/venv/lib/python3.8/site-packages/django/db/backends/mysql/base.py", line 233, in get_new_connection
    return Database.connect(**conn_params)
  File "/home/rock/anaconda3/envs/venv/lib/python3.8/site-packages/MySQLdb/__init__.py", line 84, in Connect
    return Connection(*args, **kwargs)
  File "/home/rock/anaconda3/envs/venv/lib/python3.8/site-packages/MySQLdb/connections.py", line 179, in __init__
    super(Connection, self).__init__(*args, **kwargs2)
django.db.utils.OperationalError: (1040, 'Too many connections')

During handling of the above exception, another exception occurred:

Traceback (most recent call last):
  File "/home/rock/anaconda3/envs/venv/lib/python3.8/site-packages/django/core/handlers/exception.py", line 34, in inner
    response = get_response(request)
  File "/home/rock/anaconda3/envs/venv/lib/python3.8/site-packages/django/core/handlers/base.py", line 115, in _get_response
    response = self.process_exception_by_middleware(e, request)
  File "/home/rock/anaconda3/envs/venv/lib/python3.8/site-packages/django/core/handlers/base.py", line 113, in _get_response
    response = wrapped_callback(request, *callback_args, **callback_kwargs)
  File "/home/rock/anaconda3/envs/venv/lib/python3.8/site-packages/django/views/decorators/csrf.py", line 54, in wrapped_view
    return view_func(*args, **kwargs)
  File "/home/rock/anaconda3/envs/venv/lib/python3.8/site-packages/django/views/generic/base.py", line 71, in view
    return self.dispatch(request, *args, **kwargs)
  File "/home/rock/anaconda3/envs/venv/lib/python3.8/site-packages/rest_framework/views.py", line 505, in dispatch
    response = self.handle_exception(exc)
  File "/home/rock/anaconda3/envs/venv/lib/python3.8/site-packages/rest_framework/views.py", line 465, in handle_exception
    self.raise_uncaught_exception(exc)
  File "/home/rock/anaconda3/envs/venv/lib/python3.8/site-packages/rest_framework/views.py", line 476, in raise_uncaught_exception
    raise exc
  File "/home/rock/anaconda3/envs/venv/lib/python3.8/site-packages/rest_framework/views.py", line 502, in dispatch
    response = handler(request, *args, **kwargs)
  File "/home/rock/quality_inspection/python-workspace/project-sys/sys_auth/views.py", line 116, in post
    except exceptions as e:
TypeError: catching classes that do not inherit from BaseException is not allowed
[2020-08-07 17:19:09,350] [basehttp.py:157] [basehttp:log_message] [ERROR]- "POST /sys/api/auth/ HTTP/1.1" 500 23739
[2020-08-07 17:20:19,338] [log.py:222] [log:log_response] [ERROR]- Internal Server Error: /sys/api/auth/
Traceback (most recent call last):
  File "/home/rock/anaconda3/envs/venv/lib/python3.8/site-packages/django/db/backends/base/base.py", line 220, in ensure_connection
    self.connect()
  File "/home/rock/anaconda3/envs/venv/lib/python3.8/site-packages/django/utils/asyncio.py", line 26, in inner
    return func(*args, **kwargs)
  File "/home/rock/anaconda3/envs/venv/lib/python3.8/site-packages/django/db/backends/base/base.py", line 197, in connect
    self.connection = self.get_new_connection(conn_params)
  File "/home/rock/anaconda3/envs/venv/lib/python3.8/site-packages/django/utils/asyncio.py", line 26, in inner
    return func(*args, **kwargs)
  File "/home/rock/anaconda3/envs/venv/lib/python3.8/site-packages/django/db/backends/mysql/base.py", line 233, in get_new_connection
    return Database.connect(**conn_params)
  File "/home/rock/anaconda3/envs/venv/lib/python3.8/site-packages/MySQLdb/__init__.py", line 84, in Connect
    return Connection(*args, **kwargs)
  File "/home/rock/anaconda3/envs/venv/lib/python3.8/site-packages/MySQLdb/connections.py", line 179, in __init__
    super(Connection, self).__init__(*args, **kwargs2)
MySQLdb._exceptions.OperationalError: (1040, 'Too many connections')

The above exception was the direct cause of the following exception:

Traceback (most recent call last):
  File "/home/rock/quality_inspection/python-workspace/project-sys/sys_auth/views.py", line 95, in post
    obj = User.objects.filter(username=user).first()
  File "/home/rock/anaconda3/envs/venv/lib/python3.8/site-packages/django/db/models/query.py", line 664, in first
    for obj in (self if self.ordered else self.order_by('pk'))[:1]:
  File "/home/rock/anaconda3/envs/venv/lib/python3.8/site-packages/django/db/models/query.py", line 276, in __iter__
    self._fetch_all()
  File "/home/rock/anaconda3/envs/venv/lib/python3.8/site-packages/django/db/models/query.py", line 1261, in _fetch_all
    self._result_cache = list(self._iterable_class(self))
  File "/home/rock/anaconda3/envs/venv/lib/python3.8/site-packages/django/db/models/query.py", line 57, in __iter__
    results = compiler.execute_sql(chunked_fetch=self.chunked_fetch, chunk_size=self.chunk_size)
  File "/home/rock/anaconda3/envs/venv/lib/python3.8/site-packages/django/db/models/sql/compiler.py", line 1149, in execute_sql
    cursor = self.connection.cursor()
  File "/home/rock/anaconda3/envs/venv/lib/python3.8/site-packages/django/utils/asyncio.py", line 26, in inner
    return func(*args, **kwargs)
  File "/home/rock/anaconda3/envs/venv/lib/python3.8/site-packages/django/db/backends/base/base.py", line 260, in cursor
    return self._cursor()
  File "/home/rock/anaconda3/envs/venv/lib/python3.8/site-packages/django/db/backends/base/base.py", line 236, in _cursor
    self.ensure_connection()
  File "/home/rock/anaconda3/envs/venv/lib/python3.8/site-packages/django/utils/asyncio.py", line 26, in inner
    return func(*args, **kwargs)
  File "/home/rock/anaconda3/envs/venv/lib/python3.8/site-packages/django/db/backends/base/base.py", line 220, in ensure_connection
    self.connect()
  File "/home/rock/anaconda3/envs/venv/lib/python3.8/site-packages/django/db/utils.py", line 90, in __exit__
    raise dj_exc_value.with_traceback(traceback) from exc_value
  File "/home/rock/anaconda3/envs/venv/lib/python3.8/site-packages/django/db/backends/base/base.py", line 220, in ensure_connection
    self.connect()
  File "/home/rock/anaconda3/envs/venv/lib/python3.8/site-packages/django/utils/asyncio.py", line 26, in inner
    return func(*args, **kwargs)
  File "/home/rock/anaconda3/envs/venv/lib/python3.8/site-packages/django/db/backends/base/base.py", line 197, in connect
    self.connection = self.get_new_connection(conn_params)
  File "/home/rock/anaconda3/envs/venv/lib/python3.8/site-packages/django/utils/asyncio.py", line 26, in inner
    return func(*args, **kwargs)
  File "/home/rock/anaconda3/envs/venv/lib/python3.8/site-packages/django/db/backends/mysql/base.py", line 233, in get_new_connection
    return Database.connect(**conn_params)
  File "/home/rock/anaconda3/envs/venv/lib/python3.8/site-packages/MySQLdb/__init__.py", line 84, in Connect
    return Connection(*args, **kwargs)
  File "/home/rock/anaconda3/envs/venv/lib/python3.8/site-packages/MySQLdb/connections.py", line 179, in __init__
    super(Connection, self).__init__(*args, **kwargs2)
django.db.utils.OperationalError: (1040, 'Too many connections')

During handling of the above exception, another exception occurred:

Traceback (most recent call last):
  File "/home/rock/anaconda3/envs/venv/lib/python3.8/site-packages/django/core/handlers/exception.py", line 34, in inner
    response = get_response(request)
  File "/home/rock/anaconda3/envs/venv/lib/python3.8/site-packages/django/core/handlers/base.py", line 115, in _get_response
    response = self.process_exception_by_middleware(e, request)
  File "/home/rock/anaconda3/envs/venv/lib/python3.8/site-packages/django/core/handlers/base.py", line 113, in _get_response
    response = wrapped_callback(request, *callback_args, **callback_kwargs)
  File "/home/rock/anaconda3/envs/venv/lib/python3.8/site-packages/django/views/decorators/csrf.py", line 54, in wrapped_view
    return view_func(*args, **kwargs)
  File "/home/rock/anaconda3/envs/venv/lib/python3.8/site-packages/django/views/generic/base.py", line 71, in view
    return self.dispatch(request, *args, **kwargs)
  File "/home/rock/anaconda3/envs/venv/lib/python3.8/site-packages/rest_framework/views.py", line 505, in dispatch
    response = self.handle_exception(exc)
  File "/home/rock/anaconda3/envs/venv/lib/python3.8/site-packages/rest_framework/views.py", line 465, in handle_exception
    self.raise_uncaught_exception(exc)
  File "/home/rock/anaconda3/envs/venv/lib/python3.8/site-packages/rest_framework/views.py", line 476, in raise_uncaught_exception
    raise exc
  File "/home/rock/anaconda3/envs/venv/lib/python3.8/site-packages/rest_framework/views.py", line 502, in dispatch
    response = handler(request, *args, **kwargs)
  File "/home/rock/quality_inspection/python-workspace/project-sys/sys_auth/views.py", line 116, in post
    except exceptions as e:
TypeError: catching classes that do not inherit from BaseException is not allowed
[2020-08-07 17:20:19,339] [basehttp.py:157] [basehttp:log_message] [ERROR]- "POST /sys/api/auth/ HTTP/1.1" 500 23739
[2020-08-07 17:23:35,154] [log.py:222] [log:log_response] [ERROR]- Internal Server Error: /sys/api/auth/
Traceback (most recent call last):
  File "/home/rock/anaconda3/envs/venv/lib/python3.8/site-packages/django/db/backends/base/base.py", line 220, in ensure_connection
    self.connect()
  File "/home/rock/anaconda3/envs/venv/lib/python3.8/site-packages/django/utils/asyncio.py", line 26, in inner
    return func(*args, **kwargs)
  File "/home/rock/anaconda3/envs/venv/lib/python3.8/site-packages/django/db/backends/base/base.py", line 197, in connect
    self.connection = self.get_new_connection(conn_params)
  File "/home/rock/anaconda3/envs/venv/lib/python3.8/site-packages/django/utils/asyncio.py", line 26, in inner
    return func(*args, **kwargs)
  File "/home/rock/anaconda3/envs/venv/lib/python3.8/site-packages/django/db/backends/mysql/base.py", line 233, in get_new_connection
    return Database.connect(**conn_params)
  File "/home/rock/anaconda3/envs/venv/lib/python3.8/site-packages/MySQLdb/__init__.py", line 84, in Connect
    return Connection(*args, **kwargs)
  File "/home/rock/anaconda3/envs/venv/lib/python3.8/site-packages/MySQLdb/connections.py", line 179, in __init__
    super(Connection, self).__init__(*args, **kwargs2)
MySQLdb._exceptions.OperationalError: (1040, 'Too many connections')

The above exception was the direct cause of the following exception:

Traceback (most recent call last):
  File "/home/rock/quality_inspection/python-workspace/project-sys/sys_auth/views.py", line 95, in post
    obj = User.objects.filter(username=user).first()
  File "/home/rock/anaconda3/envs/venv/lib/python3.8/site-packages/django/db/models/query.py", line 664, in first
    for obj in (self if self.ordered else self.order_by('pk'))[:1]:
  File "/home/rock/anaconda3/envs/venv/lib/python3.8/site-packages/django/db/models/query.py", line 276, in __iter__
    self._fetch_all()
  File "/home/rock/anaconda3/envs/venv/lib/python3.8/site-packages/django/db/models/query.py", line 1261, in _fetch_all
    self._result_cache = list(self._iterable_class(self))
  File "/home/rock/anaconda3/envs/venv/lib/python3.8/site-packages/django/db/models/query.py", line 57, in __iter__
    results = compiler.execute_sql(chunked_fetch=self.chunked_fetch, chunk_size=self.chunk_size)
  File "/home/rock/anaconda3/envs/venv/lib/python3.8/site-packages/django/db/models/sql/compiler.py", line 1149, in execute_sql
    cursor = self.connection.cursor()
  File "/home/rock/anaconda3/envs/venv/lib/python3.8/site-packages/django/utils/asyncio.py", line 26, in inner
    return func(*args, **kwargs)
  File "/home/rock/anaconda3/envs/venv/lib/python3.8/site-packages/django/db/backends/base/base.py", line 260, in cursor
    return self._cursor()
  File "/home/rock/anaconda3/envs/venv/lib/python3.8/site-packages/django/db/backends/base/base.py", line 236, in _cursor
    self.ensure_connection()
  File "/home/rock/anaconda3/envs/venv/lib/python3.8/site-packages/django/utils/asyncio.py", line 26, in inner
    return func(*args, **kwargs)
  File "/home/rock/anaconda3/envs/venv/lib/python3.8/site-packages/django/db/backends/base/base.py", line 220, in ensure_connection
    self.connect()
  File "/home/rock/anaconda3/envs/venv/lib/python3.8/site-packages/django/db/utils.py", line 90, in __exit__
    raise dj_exc_value.with_traceback(traceback) from exc_value
  File "/home/rock/anaconda3/envs/venv/lib/python3.8/site-packages/django/db/backends/base/base.py", line 220, in ensure_connection
    self.connect()
  File "/home/rock/anaconda3/envs/venv/lib/python3.8/site-packages/django/utils/asyncio.py", line 26, in inner
    return func(*args, **kwargs)
  File "/home/rock/anaconda3/envs/venv/lib/python3.8/site-packages/django/db/backends/base/base.py", line 197, in connect
    self.connection = self.get_new_connection(conn_params)
  File "/home/rock/anaconda3/envs/venv/lib/python3.8/site-packages/django/utils/asyncio.py", line 26, in inner
    return func(*args, **kwargs)
  File "/home/rock/anaconda3/envs/venv/lib/python3.8/site-packages/django/db/backends/mysql/base.py", line 233, in get_new_connection
    return Database.connect(**conn_params)
  File "/home/rock/anaconda3/envs/venv/lib/python3.8/site-packages/MySQLdb/__init__.py", line 84, in Connect
    return Connection(*args, **kwargs)
  File "/home/rock/anaconda3/envs/venv/lib/python3.8/site-packages/MySQLdb/connections.py", line 179, in __init__
    super(Connection, self).__init__(*args, **kwargs2)
django.db.utils.OperationalError: (1040, 'Too many connections')

During handling of the above exception, another exception occurred:

Traceback (most recent call last):
  File "/home/rock/anaconda3/envs/venv/lib/python3.8/site-packages/django/core/handlers/exception.py", line 34, in inner
    response = get_response(request)
  File "/home/rock/anaconda3/envs/venv/lib/python3.8/site-packages/django/core/handlers/base.py", line 115, in _get_response
    response = self.process_exception_by_middleware(e, request)
  File "/home/rock/anaconda3/envs/venv/lib/python3.8/site-packages/django/core/handlers/base.py", line 113, in _get_response
    response = wrapped_callback(request, *callback_args, **callback_kwargs)
  File "/home/rock/anaconda3/envs/venv/lib/python3.8/site-packages/django/views/decorators/csrf.py", line 54, in wrapped_view
    return view_func(*args, **kwargs)
  File "/home/rock/anaconda3/envs/venv/lib/python3.8/site-packages/django/views/generic/base.py", line 71, in view
    return self.dispatch(request, *args, **kwargs)
  File "/home/rock/anaconda3/envs/venv/lib/python3.8/site-packages/rest_framework/views.py", line 505, in dispatch
    response = self.handle_exception(exc)
  File "/home/rock/anaconda3/envs/venv/lib/python3.8/site-packages/rest_framework/views.py", line 465, in handle_exception
    self.raise_uncaught_exception(exc)
  File "/home/rock/anaconda3/envs/venv/lib/python3.8/site-packages/rest_framework/views.py", line 476, in raise_uncaught_exception
    raise exc
  File "/home/rock/anaconda3/envs/venv/lib/python3.8/site-packages/rest_framework/views.py", line 502, in dispatch
    response = handler(request, *args, **kwargs)
  File "/home/rock/quality_inspection/python-workspace/project-sys/sys_auth/views.py", line 116, in post
    except exceptions as e:
TypeError: catching classes that do not inherit from BaseException is not allowed
[2020-08-07 17:23:35,157] [basehttp.py:157] [basehttp:log_message] [ERROR]- "POST /sys/api/auth/ HTTP/1.1" 500 23739
[2020-08-07 17:23:49,503] [basehttp.py:157] [basehttp:log_message] [INFO]- "POST /sys/api/auth/ HTTP/1.1" 200 65
[2020-08-07 17:23:52,374] [basehttp.py:157] [basehttp:log_message] [INFO]- "GET /sys/api/user/role/?username=wl&application=automation&type=menu HTTP/1.1" 200 3623
[2020-08-07 17:23:52,376] [basehttp.py:157] [basehttp:log_message] [INFO]- "GET /sys/api/user/role/?username=wl&application=automation&type=button HTTP/1.1" 200 2
[2020-08-07 17:24:23,367] [basehttp.py:157] [basehttp:log_message] [INFO]- "POST /sys/api/auth/ HTTP/1.1" 200 65
[2020-08-07 17:24:24,066] [basehttp.py:157] [basehttp:log_message] [INFO]- "POST /sys/api/auth/ HTTP/1.1" 200 65
[2020-08-07 17:24:25,766] [basehttp.py:157] [basehttp:log_message] [INFO]- "POST /sys/api/auth/ HTTP/1.1" 200 65
[2020-08-07 17:24:31,272] [basehttp.py:157] [basehttp:log_message] [INFO]- "POST /sys/api/auth/ HTTP/1.1" 200 65
[2020-08-07 17:24:32,978] [basehttp.py:157] [basehttp:log_message] [INFO]- "POST /sys/api/auth/ HTTP/1.1" 200 65
[2020-08-07 17:25:26,320] [basehttp.py:157] [basehttp:log_message] [INFO]- "POST /sys/api/auth/ HTTP/1.1" 200 65
[2020-08-07 17:25:41,359] [basehttp.py:157] [basehttp:log_message] [INFO]- "POST /sys/api/auth/ HTTP/1.1" 200 65
[2020-08-07 17:27:03,233] [basehttp.py:157] [basehttp:log_message] [INFO]- "POST /sys/api/auth/ HTTP/1.1" 200 65
[2020-08-07 17:29:32,428] [basehttp.py:157] [basehttp:log_message] [INFO]- "POST /sys/api/auth/ HTTP/1.1" 200 65
[2020-08-07 17:29:33,718] [basehttp.py:157] [basehttp:log_message] [INFO]- "POST /sys/api/auth/ HTTP/1.1" 200 65
[2020-08-07 17:29:36,282] [basehttp.py:157] [basehttp:log_message] [INFO]- "POST /sys/api/auth/ HTTP/1.1" 200 65
[2020-08-07 17:29:45,567] [basehttp.py:157] [basehttp:log_message] [INFO]- "POST /sys/api/auth/ HTTP/1.1" 200 65
[2020-08-07 17:32:09,741] [basehttp.py:157] [basehttp:log_message] [INFO]- "POST /sys/api/auth/ HTTP/1.1" 200 65
[2020-08-07 17:35:32,334] [basehttp.py:157] [basehttp:log_message] [INFO]- "POST /sys/api/auth/ HTTP/1.1" 200 65
[2020-08-07 17:36:21,229] [basehttp.py:157] [basehttp:log_message] [INFO]- "POST /sys/api/auth/ HTTP/1.1" 200 65
[2020-08-07 17:36:24,537] [basehttp.py:157] [basehttp:log_message] [INFO]- "POST /sys/api/auth/ HTTP/1.1" 200 65
[2020-08-07 17:36:25,352] [basehttp.py:157] [basehttp:log_message] [INFO]- "POST /sys/api/auth/ HTTP/1.1" 200 65
[2020-08-07 17:36:38,481] [basehttp.py:157] [basehttp:log_message] [INFO]- "POST /sys/api/auth/ HTTP/1.1" 200 65
[2020-08-07 17:36:45,376] [basehttp.py:157] [basehttp:log_message] [INFO]- "POST /sys/api/auth/ HTTP/1.1" 200 65
[2020-08-07 17:55:08,467] [log.py:222] [log:log_response] [ERROR]- Internal Server Error: /sys/api/auth/
Traceback (most recent call last):
  File "/home/rock/anaconda3/envs/venv/lib/python3.8/site-packages/django/db/backends/base/base.py", line 220, in ensure_connection
    self.connect()
  File "/home/rock/anaconda3/envs/venv/lib/python3.8/site-packages/django/utils/asyncio.py", line 26, in inner
    return func(*args, **kwargs)
  File "/home/rock/anaconda3/envs/venv/lib/python3.8/site-packages/django/db/backends/base/base.py", line 197, in connect
    self.connection = self.get_new_connection(conn_params)
  File "/home/rock/anaconda3/envs/venv/lib/python3.8/site-packages/django/utils/asyncio.py", line 26, in inner
    return func(*args, **kwargs)
  File "/home/rock/anaconda3/envs/venv/lib/python3.8/site-packages/django/db/backends/mysql/base.py", line 233, in get_new_connection
    return Database.connect(**conn_params)
  File "/home/rock/anaconda3/envs/venv/lib/python3.8/site-packages/MySQLdb/__init__.py", line 84, in Connect
    return Connection(*args, **kwargs)
  File "/home/rock/anaconda3/envs/venv/lib/python3.8/site-packages/MySQLdb/connections.py", line 179, in __init__
    super(Connection, self).__init__(*args, **kwargs2)
MySQLdb._exceptions.OperationalError: (1040, 'Too many connections')

The above exception was the direct cause of the following exception:

Traceback (most recent call last):
  File "/home/rock/quality_inspection/python-workspace/project-sys/sys_auth/views.py", line 80, in post
    token_obj = Token.objects.filter(token=token).first()
  File "/home/rock/anaconda3/envs/venv/lib/python3.8/site-packages/django/db/models/query.py", line 664, in first
    for obj in (self if self.ordered else self.order_by('pk'))[:1]:
  File "/home/rock/anaconda3/envs/venv/lib/python3.8/site-packages/django/db/models/query.py", line 276, in __iter__
    self._fetch_all()
  File "/home/rock/anaconda3/envs/venv/lib/python3.8/site-packages/django/db/models/query.py", line 1261, in _fetch_all
    self._result_cache = list(self._iterable_class(self))
  File "/home/rock/anaconda3/envs/venv/lib/python3.8/site-packages/django/db/models/query.py", line 57, in __iter__
    results = compiler.execute_sql(chunked_fetch=self.chunked_fetch, chunk_size=self.chunk_size)
  File "/home/rock/anaconda3/envs/venv/lib/python3.8/site-packages/django/db/models/sql/compiler.py", line 1149, in execute_sql
    cursor = self.connection.cursor()
  File "/home/rock/anaconda3/envs/venv/lib/python3.8/site-packages/django/utils/asyncio.py", line 26, in inner
    return func(*args, **kwargs)
  File "/home/rock/anaconda3/envs/venv/lib/python3.8/site-packages/django/db/backends/base/base.py", line 260, in cursor
    return self._cursor()
  File "/home/rock/anaconda3/envs/venv/lib/python3.8/site-packages/django/db/backends/base/base.py", line 236, in _cursor
    self.ensure_connection()
  File "/home/rock/anaconda3/envs/venv/lib/python3.8/site-packages/django/utils/asyncio.py", line 26, in inner
    return func(*args, **kwargs)
  File "/home/rock/anaconda3/envs/venv/lib/python3.8/site-packages/django/db/backends/base/base.py", line 220, in ensure_connection
    self.connect()
  File "/home/rock/anaconda3/envs/venv/lib/python3.8/site-packages/django/db/utils.py", line 90, in __exit__
    raise dj_exc_value.with_traceback(traceback) from exc_value
  File "/home/rock/anaconda3/envs/venv/lib/python3.8/site-packages/django/db/backends/base/base.py", line 220, in ensure_connection
    self.connect()
  File "/home/rock/anaconda3/envs/venv/lib/python3.8/site-packages/django/utils/asyncio.py", line 26, in inner
    return func(*args, **kwargs)
  File "/home/rock/anaconda3/envs/venv/lib/python3.8/site-packages/django/db/backends/base/base.py", line 197, in connect
    self.connection = self.get_new_connection(conn_params)
  File "/home/rock/anaconda3/envs/venv/lib/python3.8/site-packages/django/utils/asyncio.py", line 26, in inner
    return func(*args, **kwargs)
  File "/home/rock/anaconda3/envs/venv/lib/python3.8/site-packages/django/db/backends/mysql/base.py", line 233, in get_new_connection
    return Database.connect(**conn_params)
  File "/home/rock/anaconda3/envs/venv/lib/python3.8/site-packages/MySQLdb/__init__.py", line 84, in Connect
    return Connection(*args, **kwargs)
  File "/home/rock/anaconda3/envs/venv/lib/python3.8/site-packages/MySQLdb/connections.py", line 179, in __init__
    super(Connection, self).__init__(*args, **kwargs2)
django.db.utils.OperationalError: (1040, 'Too many connections')

During handling of the above exception, another exception occurred:

Traceback (most recent call last):
  File "/home/rock/anaconda3/envs/venv/lib/python3.8/site-packages/django/core/handlers/exception.py", line 34, in inner
    response = get_response(request)
  File "/home/rock/anaconda3/envs/venv/lib/python3.8/site-packages/django/core/handlers/base.py", line 115, in _get_response
    response = self.process_exception_by_middleware(e, request)
  File "/home/rock/anaconda3/envs/venv/lib/python3.8/site-packages/django/core/handlers/base.py", line 113, in _get_response
    response = wrapped_callback(request, *callback_args, **callback_kwargs)
  File "/home/rock/anaconda3/envs/venv/lib/python3.8/site-packages/django/views/decorators/csrf.py", line 54, in wrapped_view
    return view_func(*args, **kwargs)
  File "/home/rock/anaconda3/envs/venv/lib/python3.8/site-packages/django/views/generic/base.py", line 71, in view
    return self.dispatch(request, *args, **kwargs)
  File "/home/rock/anaconda3/envs/venv/lib/python3.8/site-packages/rest_framework/views.py", line 505, in dispatch
    response = self.handle_exception(exc)
  File "/home/rock/anaconda3/envs/venv/lib/python3.8/site-packages/rest_framework/views.py", line 465, in handle_exception
    self.raise_uncaught_exception(exc)
  File "/home/rock/anaconda3/envs/venv/lib/python3.8/site-packages/rest_framework/views.py", line 476, in raise_uncaught_exception
    raise exc
  File "/home/rock/anaconda3/envs/venv/lib/python3.8/site-packages/rest_framework/views.py", line 502, in dispatch
    response = handler(request, *args, **kwargs)
  File "/home/rock/quality_inspection/python-workspace/project-sys/sys_auth/views.py", line 116, in post
    except exceptions as e:
TypeError: catching classes that do not inherit from BaseException is not allowed
[2020-08-07 17:55:08,470] [basehttp.py:157] [basehttp:log_message] [ERROR]- "POST /sys/api/auth/ HTTP/1.1" 500 22890
[2020-08-07 17:55:14,851] [log.py:222] [log:log_response] [ERROR]- Internal Server Error: /sys/api/auth/
Traceback (most recent call last):
  File "/home/rock/anaconda3/envs/venv/lib/python3.8/site-packages/django/db/backends/base/base.py", line 220, in ensure_connection
    self.connect()
  File "/home/rock/anaconda3/envs/venv/lib/python3.8/site-packages/django/utils/asyncio.py", line 26, in inner
    return func(*args, **kwargs)
  File "/home/rock/anaconda3/envs/venv/lib/python3.8/site-packages/django/db/backends/base/base.py", line 197, in connect
    self.connection = self.get_new_connection(conn_params)
  File "/home/rock/anaconda3/envs/venv/lib/python3.8/site-packages/django/utils/asyncio.py", line 26, in inner
    return func(*args, **kwargs)
  File "/home/rock/anaconda3/envs/venv/lib/python3.8/site-packages/django/db/backends/mysql/base.py", line 233, in get_new_connection
    return Database.connect(**conn_params)
  File "/home/rock/anaconda3/envs/venv/lib/python3.8/site-packages/MySQLdb/__init__.py", line 84, in Connect
    return Connection(*args, **kwargs)
  File "/home/rock/anaconda3/envs/venv/lib/python3.8/site-packages/MySQLdb/connections.py", line 179, in __init__
    super(Connection, self).__init__(*args, **kwargs2)
MySQLdb._exceptions.OperationalError: (1040, 'Too many connections')

The above exception was the direct cause of the following exception:

Traceback (most recent call last):
  File "/home/rock/quality_inspection/python-workspace/project-sys/sys_auth/views.py", line 95, in post
    obj = User.objects.filter(username=user).first()
  File "/home/rock/anaconda3/envs/venv/lib/python3.8/site-packages/django/db/models/query.py", line 664, in first
    for obj in (self if self.ordered else self.order_by('pk'))[:1]:
  File "/home/rock/anaconda3/envs/venv/lib/python3.8/site-packages/django/db/models/query.py", line 276, in __iter__
    self._fetch_all()
  File "/home/rock/anaconda3/envs/venv/lib/python3.8/site-packages/django/db/models/query.py", line 1261, in _fetch_all
    self._result_cache = list(self._iterable_class(self))
  File "/home/rock/anaconda3/envs/venv/lib/python3.8/site-packages/django/db/models/query.py", line 57, in __iter__
    results = compiler.execute_sql(chunked_fetch=self.chunked_fetch, chunk_size=self.chunk_size)
  File "/home/rock/anaconda3/envs/venv/lib/python3.8/site-packages/django/db/models/sql/compiler.py", line 1149, in execute_sql
    cursor = self.connection.cursor()
  File "/home/rock/anaconda3/envs/venv/lib/python3.8/site-packages/django/utils/asyncio.py", line 26, in inner
    return func(*args, **kwargs)
  File "/home/rock/anaconda3/envs/venv/lib/python3.8/site-packages/django/db/backends/base/base.py", line 260, in cursor
    return self._cursor()
  File "/home/rock/anaconda3/envs/venv/lib/python3.8/site-packages/django/db/backends/base/base.py", line 236, in _cursor
    self.ensure_connection()
  File "/home/rock/anaconda3/envs/venv/lib/python3.8/site-packages/django/utils/asyncio.py", line 26, in inner
    return func(*args, **kwargs)
  File "/home/rock/anaconda3/envs/venv/lib/python3.8/site-packages/django/db/backends/base/base.py", line 220, in ensure_connection
    self.connect()
  File "/home/rock/anaconda3/envs/venv/lib/python3.8/site-packages/django/db/utils.py", line 90, in __exit__
    raise dj_exc_value.with_traceback(traceback) from exc_value
  File "/home/rock/anaconda3/envs/venv/lib/python3.8/site-packages/django/db/backends/base/base.py", line 220, in ensure_connection
    self.connect()
  File "/home/rock/anaconda3/envs/venv/lib/python3.8/site-packages/django/utils/asyncio.py", line 26, in inner
    return func(*args, **kwargs)
  File "/home/rock/anaconda3/envs/venv/lib/python3.8/site-packages/django/db/backends/base/base.py", line 197, in connect
    self.connection = self.get_new_connection(conn_params)
  File "/home/rock/anaconda3/envs/venv/lib/python3.8/site-packages/django/utils/asyncio.py", line 26, in inner
    return func(*args, **kwargs)
  File "/home/rock/anaconda3/envs/venv/lib/python3.8/site-packages/django/db/backends/mysql/base.py", line 233, in get_new_connection
    return Database.connect(**conn_params)
  File "/home/rock/anaconda3/envs/venv/lib/python3.8/site-packages/MySQLdb/__init__.py", line 84, in Connect
    return Connection(*args, **kwargs)
  File "/home/rock/anaconda3/envs/venv/lib/python3.8/site-packages/MySQLdb/connections.py", line 179, in __init__
    super(Connection, self).__init__(*args, **kwargs2)
django.db.utils.OperationalError: (1040, 'Too many connections')

During handling of the above exception, another exception occurred:

Traceback (most recent call last):
  File "/home/rock/anaconda3/envs/venv/lib/python3.8/site-packages/django/core/handlers/exception.py", line 34, in inner
    response = get_response(request)
  File "/home/rock/anaconda3/envs/venv/lib/python3.8/site-packages/django/core/handlers/base.py", line 115, in _get_response
    response = self.process_exception_by_middleware(e, request)
  File "/home/rock/anaconda3/envs/venv/lib/python3.8/site-packages/django/core/handlers/base.py", line 113, in _get_response
    response = wrapped_callback(request, *callback_args, **callback_kwargs)
  File "/home/rock/anaconda3/envs/venv/lib/python3.8/site-packages/django/views/decorators/csrf.py", line 54, in wrapped_view
    return view_func(*args, **kwargs)
  File "/home/rock/anaconda3/envs/venv/lib/python3.8/site-packages/django/views/generic/base.py", line 71, in view
    return self.dispatch(request, *args, **kwargs)
  File "/home/rock/anaconda3/envs/venv/lib/python3.8/site-packages/rest_framework/views.py", line 505, in dispatch
    response = self.handle_exception(exc)
  File "/home/rock/anaconda3/envs/venv/lib/python3.8/site-packages/rest_framework/views.py", line 465, in handle_exception
    self.raise_uncaught_exception(exc)
  File "/home/rock/anaconda3/envs/venv/lib/python3.8/site-packages/rest_framework/views.py", line 476, in raise_uncaught_exception
    raise exc
  File "/home/rock/anaconda3/envs/venv/lib/python3.8/site-packages/rest_framework/views.py", line 502, in dispatch
    response = handler(request, *args, **kwargs)
  File "/home/rock/quality_inspection/python-workspace/project-sys/sys_auth/views.py", line 116, in post
    except exceptions as e:
TypeError: catching classes that do not inherit from BaseException is not allowed
[2020-08-07 17:55:14,853] [basehttp.py:157] [basehttp:log_message] [ERROR]- "POST /sys/api/auth/ HTTP/1.1" 500 23739
