[2020-06-28 09:31:23,380] [autoreload.py:598] [autoreload:run_with_reloader] [INFO]- Watching for file changes with StatReloader
[2020-06-28 09:32:46,026] [basehttp.py:157] [basehttp:log_message] [INFO]- "OPTIONS /auth/ HTTP/1.1" 200 0
[2020-06-28 09:32:46,253] [basehttp.py:157] [basehttp:log_message] [INFO]- "POST /auth/ HTTP/1.1" 200 65
[2020-06-28 09:32:57,843] [basehttp.py:157] [basehttp:log_message] [INFO]- "OPTIONS /user/?current_page=1&pre_page=10 HTTP/1.1" 200 0
[2020-06-28 09:32:58,516] [basehttp.py:157] [basehttp:log_message] [INFO]- "GET /user/?current_page=1&pre_page=10 HTTP/1.1" 200 80410
[2020-06-28 09:33:00,198] [basehttp.py:157] [basehttp:log_message] [INFO]- "OPTIONS /role/ HTTP/1.1" 200 0
[2020-06-28 09:33:01,672] [basehttp.py:157] [basehttp:log_message] [INFO]- "GET /role/ HTTP/1.1" 200 30110
[2020-06-28 09:33:04,326] [basehttp.py:157] [basehttp:log_message] [INFO]- "GET /role/ HTTP/1.1" 200 30110
[2020-06-28 09:33:08,467] [basehttp.py:157] [basehttp:log_message] [INFO]- "GET /user/?current_page=1&pre_page=10 HTTP/1.1" 200 80410
[2020-06-28 09:33:09,803] [basehttp.py:157] [basehttp:log_message] [INFO]- "GET /role/ HTTP/1.1" 200 30110
[2020-06-28 09:39:29,045] [basehttp.py:157] [basehttp:log_message] [INFO]- "GET /role/ HTTP/1.1" 200 30110
[2020-06-28 09:39:32,353] [basehttp.py:157] [basehttp:log_message] [INFO]- "GET /role/ HTTP/1.1" 200 30110
[2020-06-28 09:39:35,584] [basehttp.py:157] [basehttp:log_message] [INFO]- "GET /role/ HTTP/1.1" 200 30110
[2020-06-28 09:39:40,968] [basehttp.py:157] [basehttp:log_message] [INFO]- "GET /user/?current_page=1&pre_page=10 HTTP/1.1" 200 80410
[2020-06-28 09:39:43,491] [basehttp.py:157] [basehttp:log_message] [INFO]- "GET /role/ HTTP/1.1" 200 30110
[2020-06-28 09:43:13,056] [basehttp.py:157] [basehttp:log_message] [INFO]- "OPTIONS /role/ HTTP/1.1" 200 0
[2020-06-28 09:43:13,380] [basehttp.py:157] [basehttp:log_message] [INFO]- "GET /role/ HTTP/1.1" 200 30110
[2020-06-28 09:47:03,435] [basehttp.py:157] [basehttp:log_message] [INFO]- "GET /role/ HTTP/1.1" 200 30110
[2020-06-28 09:48:43,156] [basehttp.py:157] [basehttp:log_message] [INFO]- "OPTIONS /user/?current_page=1&pre_page=10 HTTP/1.1" 200 0
[2020-06-28 09:48:43,782] [basehttp.py:157] [basehttp:log_message] [INFO]- "GET /user/?current_page=1&pre_page=10 HTTP/1.1" 200 80410
[2020-06-28 09:48:45,950] [basehttp.py:157] [basehttp:log_message] [INFO]- "GET /role/ HTTP/1.1" 200 30110
[2020-06-28 09:48:49,396] [basehttp.py:157] [basehttp:log_message] [INFO]- "GET /role/ HTTP/1.1" 200 30110
[2020-06-28 09:48:53,422] [basehttp.py:157] [basehttp:log_message] [INFO]- "GET /user/?current_page=1&pre_page=10 HTTP/1.1" 200 80410
[2020-06-28 09:48:58,874] [basehttp.py:157] [basehttp:log_message] [INFO]- "GET /role/ HTTP/1.1" 200 30110
[2020-06-28 09:49:01,619] [basehttp.py:157] [basehttp:log_message] [INFO]- "GET /role/ HTTP/1.1" 200 30110
[2020-06-28 09:49:06,937] [basehttp.py:157] [basehttp:log_message] [INFO]- "GET /user/?current_page=1&pre_page=10 HTTP/1.1" 200 80410
[2020-06-28 09:49:20,721] [basehttp.py:157] [basehttp:log_message] [INFO]- "GET /user/?current_page=1&pre_page=10 HTTP/1.1" 200 80410
[2020-06-28 09:49:23,254] [basehttp.py:157] [basehttp:log_message] [INFO]- "GET /role/ HTTP/1.1" 200 30110
[2020-06-28 09:49:26,440] [basehttp.py:157] [basehttp:log_message] [INFO]- "GET /user/?current_page=1&pre_page=10 HTTP/1.1" 200 80410
[2020-06-28 09:49:28,563] [basehttp.py:157] [basehttp:log_message] [INFO]- "GET /role/ HTTP/1.1" 200 30110
[2020-06-28 09:49:37,176] [basehttp.py:157] [basehttp:log_message] [INFO]- "GET /user/?current_page=1&pre_page=10 HTTP/1.1" 200 80410
[2020-06-28 09:49:39,420] [basehttp.py:157] [basehttp:log_message] [INFO]- "GET /role/ HTTP/1.1" 200 30110
[2020-06-28 09:49:41,765] [basehttp.py:157] [basehttp:log_message] [INFO]- "GET /user/?current_page=1&pre_page=10 HTTP/1.1" 200 80410
[2020-06-28 09:49:51,353] [basehttp.py:157] [basehttp:log_message] [INFO]- "GET /role/ HTTP/1.1" 200 30110
[2020-06-28 09:49:54,075] [basehttp.py:157] [basehttp:log_message] [INFO]- "GET /role/ HTTP/1.1" 200 30110
[2020-06-28 09:50:11,482] [basehttp.py:157] [basehttp:log_message] [INFO]- "GET /role/ HTTP/1.1" 200 30110
[2020-06-28 09:50:13,982] [basehttp.py:157] [basehttp:log_message] [INFO]- "GET /role/ HTTP/1.1" 200 30110
[2020-06-28 09:50:16,608] [basehttp.py:157] [basehttp:log_message] [INFO]- "GET /role/ HTTP/1.1" 200 30110
[2020-06-28 09:55:17,837] [basehttp.py:157] [basehttp:log_message] [INFO]- "GET /role/ HTTP/1.1" 200 30110
[2020-06-28 10:13:35,975] [basehttp.py:157] [basehttp:log_message] [INFO]- "OPTIONS /user/?current_page=1&pre_page=10 HTTP/1.1" 200 0
[2020-06-28 10:13:36,631] [basehttp.py:157] [basehttp:log_message] [INFO]- "GET /user/?current_page=1&pre_page=10 HTTP/1.1" 200 80410
[2020-06-28 10:19:47,814] [basehttp.py:157] [basehttp:log_message] [INFO]- "GET /user/?current_page=1&pre_page=10 HTTP/1.1" 200 80410
[2020-06-28 10:19:59,837] [basehttp.py:157] [basehttp:log_message] [INFO]- "OPTIONS /auth/ HTTP/1.1" 200 0
[2020-06-28 10:20:00,011] [basehttp.py:157] [basehttp:log_message] [INFO]- "POST /auth/ HTTP/1.1" 200 65
[2020-06-28 10:20:03,996] [basehttp.py:157] [basehttp:log_message] [INFO]- "OPTIONS /role/?current_page=1&pre_page=10 HTTP/1.1" 200 0
[2020-06-28 10:20:06,619] [basehttp.py:157] [basehttp:log_message] [INFO]- "GET /role/?current_page=1&pre_page=10 HTTP/1.1" 200 30181
[2020-06-28 10:20:07,090] [basehttp.py:157] [basehttp:log_message] [INFO]- "GET /user/?current_page=1&pre_page=10 HTTP/1.1" 200 80410
[2020-06-28 10:20:09,726] [basehttp.py:157] [basehttp:log_message] [INFO]- "OPTIONS /role/ HTTP/1.1" 200 0
[2020-06-28 10:20:10,063] [basehttp.py:157] [basehttp:log_message] [INFO]- "GET /role/ HTTP/1.1" 200 30110
[2020-06-28 10:20:17,833] [basehttp.py:157] [basehttp:log_message] [INFO]- "OPTIONS /user/29/assign_user/ HTTP/1.1" 200 0
[2020-06-28 10:20:18,348] [log.py:222] [log:log_response] [ERROR]- Internal Server Error: /user/29/assign_user/
Traceback (most recent call last):
  File "/home/rock/anaconda3/envs/venv/lib/python3.8/site-packages/django/core/handlers/exception.py", line 34, in inner
    response = get_response(request)
  File "/home/rock/anaconda3/envs/venv/lib/python3.8/site-packages/django/core/handlers/base.py", line 115, in _get_response
    response = self.process_exception_by_middleware(e, request)
  File "/home/rock/anaconda3/envs/venv/lib/python3.8/site-packages/django/core/handlers/base.py", line 113, in _get_response
    response = wrapped_callback(request, *callback_args, **callback_kwargs)
  File "/home/rock/anaconda3/envs/venv/lib/python3.8/site-packages/django/views/decorators/csrf.py", line 54, in wrapped_view
    return view_func(*args, **kwargs)
  File "/home/rock/anaconda3/envs/venv/lib/python3.8/site-packages/rest_framework/viewsets.py", line 114, in view
    return self.dispatch(request, *args, **kwargs)
  File "/home/rock/anaconda3/envs/venv/lib/python3.8/site-packages/rest_framework/views.py", line 505, in dispatch
    response = self.handle_exception(exc)
  File "/home/rock/anaconda3/envs/venv/lib/python3.8/site-packages/rest_framework/views.py", line 465, in handle_exception
    self.raise_uncaught_exception(exc)
  File "/home/rock/anaconda3/envs/venv/lib/python3.8/site-packages/rest_framework/views.py", line 476, in raise_uncaught_exception
    raise exc
  File "/home/rock/anaconda3/envs/venv/lib/python3.8/site-packages/rest_framework/views.py", line 502, in dispatch
    response = handler(request, *args, **kwargs)
  File "/home/rock/quality_inspection/python-workspace/project-sys/sys_auth/views.py", line 225, in assign_user
    role_ids = request.data.get("roles")
AttributeError: 'list' object has no attribute 'get'
[2020-06-28 10:20:18,349] [basehttp.py:157] [basehttp:log_message] [ERROR]- "PUT /user/29/assign_user/ HTTP/1.1" 500 18852
[2020-06-28 10:21:58,091] [basehttp.py:157] [basehttp:log_message] [INFO]- "GET /user/?current_page=1&pre_page=10 HTTP/1.1" 200 83910
[2020-06-28 10:22:29,511] [basehttp.py:157] [basehttp:log_message] [INFO]- "GET /role/?current_page=1&pre_page=10 HTTP/1.1" 200 30181
[2020-06-28 10:22:50,423] [basehttp.py:157] [basehttp:log_message] [INFO]- "GET /role/?current_page=1&pre_page=10 HTTP/1.1" 200 30181
[2020-06-28 10:22:54,290] [basehttp.py:157] [basehttp:log_message] [INFO]- "GET /user/?current_page=1&pre_page=10 HTTP/1.1" 200 83910
[2020-06-28 10:23:03,510] [basehttp.py:157] [basehttp:log_message] [INFO]- "GET /role/ HTTP/1.1" 200 30110
[2020-06-28 10:23:06,944] [basehttp.py:157] [basehttp:log_message] [INFO]- "OPTIONS /user/4/assign_user/ HTTP/1.1" 200 0
[2020-06-28 10:23:07,250] [basehttp.py:157] [basehttp:log_message] [INFO]- "PUT /user/4/assign_user/ HTTP/1.1" 200 10625
[2020-06-28 10:23:07,874] [basehttp.py:157] [basehttp:log_message] [INFO]- "GET /user/?current_page=1&pre_page=10 HTTP/1.1" 200 73634
[2020-06-28 10:23:16,561] [basehttp.py:157] [basehttp:log_message] [INFO]- "GET /user/?current_page=1&pre_page=10 HTTP/1.1" 200 73634
[2020-06-28 10:23:18,291] [basehttp.py:157] [basehttp:log_message] [INFO]- "GET /role/ HTTP/1.1" 200 30110
[2020-06-28 10:23:21,309] [basehttp.py:157] [basehttp:log_message] [INFO]- "GET /role/ HTTP/1.1" 200 30110
[2020-06-28 10:23:44,107] [basehttp.py:157] [basehttp:log_message] [INFO]- "OPTIONS /user/?current_page=1&pre_page=10 HTTP/1.1" 200 0
[2020-06-28 10:23:44,800] [basehttp.py:157] [basehttp:log_message] [INFO]- "GET /user/?current_page=1&pre_page=10 HTTP/1.1" 200 73634
[2020-06-28 10:23:59,753] [basehttp.py:157] [basehttp:log_message] [INFO]- "GET /user/?current_page=1&pre_page=10 HTTP/1.1" 200 73634
[2020-06-28 10:51:52,379] [basehttp.py:157] [basehttp:log_message] [INFO]- "OPTIONS /user/?current_page=1&pre_page=10 HTTP/1.1" 200 0
[2020-06-28 10:51:52,987] [basehttp.py:157] [basehttp:log_message] [INFO]- "GET /user/?current_page=1&pre_page=10 HTTP/1.1" 200 73634
[2020-06-28 10:52:04,882] [basehttp.py:157] [basehttp:log_message] [INFO]- "OPTIONS /auth/ HTTP/1.1" 200 0
[2020-06-28 10:52:05,063] [basehttp.py:157] [basehttp:log_message] [INFO]- "POST /auth/ HTTP/1.1" 200 65
[2020-06-28 10:52:08,826] [basehttp.py:157] [basehttp:log_message] [INFO]- "GET /user/?current_page=1&pre_page=10 HTTP/1.1" 200 73634
[2020-06-28 10:52:38,598] [basehttp.py:157] [basehttp:log_message] [INFO]- "GET /user/?current_page=1&pre_page=10 HTTP/1.1" 200 73634
[2020-06-28 10:52:59,066] [basehttp.py:157] [basehttp:log_message] [INFO]- "POST /auth/ HTTP/1.1" 200 65
[2020-06-28 10:53:06,716] [basehttp.py:157] [basehttp:log_message] [INFO]- "GET /user/?current_page=1&pre_page=10 HTTP/1.1" 200 73634
[2020-06-28 10:53:08,396] [basehttp.py:157] [basehttp:log_message] [INFO]- "OPTIONS /role/?current_page=1&pre_page=10 HTTP/1.1" 200 0
[2020-06-28 10:53:08,678] [basehttp.py:157] [basehttp:log_message] [INFO]- "GET /role/?current_page=1&pre_page=10 HTTP/1.1" 200 30181
[2020-06-28 10:53:12,428] [basehttp.py:157] [basehttp:log_message] [INFO]- "OPTIONS /role/4/to_menu/ HTTP/1.1" 200 0
[2020-06-28 10:53:12,431] [basehttp.py:157] [basehttp:log_message] [INFO]- "OPTIONS /role/4/menu/ HTTP/1.1" 200 0
[2020-06-28 10:53:12,626] [basehttp.py:157] [basehttp:log_message] [INFO]- "GET /role/4/menu/ HTTP/1.1" 200 2812
[2020-06-28 10:53:12,851] [basehttp.py:157] [basehttp:log_message] [INFO]- "GET /role/4/to_menu/ HTTP/1.1" 200 11386
[2020-06-28 10:53:16,556] [basehttp.py:157] [basehttp:log_message] [INFO]- "OPTIONS /role/7/menu/ HTTP/1.1" 200 0
[2020-06-28 10:53:16,557] [basehttp.py:157] [basehttp:log_message] [INFO]- "OPTIONS /role/7/to_menu/ HTTP/1.1" 200 0
[2020-06-28 10:53:16,782] [basehttp.py:157] [basehttp:log_message] [INFO]- "GET /role/7/menu/ HTTP/1.1" 200 3375
[2020-06-28 10:53:16,808] [basehttp.py:157] [basehttp:log_message] [INFO]- "GET /role/7/to_menu/ HTTP/1.1" 200 11393
[2020-06-28 10:53:23,390] [basehttp.py:157] [basehttp:log_message] [INFO]- "OPTIONS /role/1/to_menu/ HTTP/1.1" 200 0
[2020-06-28 10:53:23,391] [basehttp.py:157] [basehttp:log_message] [INFO]- "OPTIONS /role/1/menu/ HTTP/1.1" 200 0
[2020-06-28 10:53:23,642] [basehttp.py:157] [basehttp:log_message] [INFO]- "GET /role/1/menu/ HTTP/1.1" 200 13081
[2020-06-28 10:53:23,690] [basehttp.py:157] [basehttp:log_message] [INFO]- "GET /role/1/to_menu/ HTTP/1.1" 200 2
[2020-06-28 10:53:29,120] [basehttp.py:157] [basehttp:log_message] [INFO]- "GET /user/?current_page=1&pre_page=10 HTTP/1.1" 200 73634
[2020-06-28 10:53:31,629] [basehttp.py:157] [basehttp:log_message] [INFO]- "OPTIONS /role/ HTTP/1.1" 200 0
[2020-06-28 10:53:31,956] [basehttp.py:157] [basehttp:log_message] [INFO]- "GET /role/ HTTP/1.1" 200 30110
[2020-06-28 10:53:35,704] [basehttp.py:157] [basehttp:log_message] [INFO]- "OPTIONS /user/4/assign_user/ HTTP/1.1" 200 0
[2020-06-28 10:53:35,988] [basehttp.py:157] [basehttp:log_message] [INFO]- "PUT /user/4/assign_user/ HTTP/1.1" 200 20901
[2020-06-28 10:53:36,903] [basehttp.py:157] [basehttp:log_message] [INFO]- "GET /user/?current_page=1&pre_page=10 HTTP/1.1" 200 83910
[2020-06-28 10:53:40,929] [basehttp.py:157] [basehttp:log_message] [INFO]- "GET /user/?current_page=1&pre_page=10 HTTP/1.1" 200 83910
[2020-06-28 10:53:50,505] [basehttp.py:157] [basehttp:log_message] [INFO]- "POST /auth/ HTTP/1.1" 200 65
[2020-06-28 10:53:54,186] [basehttp.py:157] [basehttp:log_message] [INFO]- "GET /user/?current_page=1&pre_page=10 HTTP/1.1" 200 83910
[2020-06-28 10:53:58,643] [basehttp.py:157] [basehttp:log_message] [INFO]- "GET /role/ HTTP/1.1" 200 30110
[2020-06-28 10:54:02,817] [basehttp.py:157] [basehttp:log_message] [INFO]- "PUT /user/4/assign_user/ HTTP/1.1" 200 10625
[2020-06-28 10:54:03,457] [basehttp.py:157] [basehttp:log_message] [INFO]- "GET /user/?current_page=1&pre_page=10 HTTP/1.1" 200 73634
[2020-06-28 10:54:07,097] [basehttp.py:157] [basehttp:log_message] [INFO]- "GET /role/ HTTP/1.1" 200 30110
[2020-06-28 10:54:11,438] [basehttp.py:157] [basehttp:log_message] [INFO]- "GET /user/?current_page=1&pre_page=10 HTTP/1.1" 200 73634
[2020-06-28 10:54:47,189] [basehttp.py:157] [basehttp:log_message] [INFO]- "GET /role/?current_page=1&pre_page=10 HTTP/1.1" 200 30181
[2020-06-28 10:55:09,453] [basehttp.py:157] [basehttp:log_message] [INFO]- "GET /user/?current_page=1&pre_page=10 HTTP/1.1" 200 73634
[2020-06-28 10:55:09,944] [basehttp.py:157] [basehttp:log_message] [INFO]- "GET /role/?current_page=1&pre_page=10 HTTP/1.1" 200 30181
[2020-06-28 10:58:19,650] [basehttp.py:157] [basehttp:log_message] [INFO]- "POST /auth/ HTTP/1.1" 200 65
[2020-06-28 10:58:24,588] [basehttp.py:157] [basehttp:log_message] [INFO]- "GET /user/?current_page=1&pre_page=10 HTTP/1.1" 200 73634
[2020-06-28 10:58:26,114] [basehttp.py:157] [basehttp:log_message] [INFO]- "GET /role/ HTTP/1.1" 200 30110
[2020-06-28 10:58:29,114] [basehttp.py:157] [basehttp:log_message] [INFO]- "GET /role/ HTTP/1.1" 200 30110
[2020-06-28 10:58:32,024] [basehttp.py:157] [basehttp:log_message] [INFO]- "GET /role/ HTTP/1.1" 200 30110
[2020-06-28 10:58:38,455] [basehttp.py:157] [basehttp:log_message] [INFO]- "GET /user/?current_page=1&pre_page=10 HTTP/1.1" 200 73634
[2020-06-28 10:58:40,134] [basehttp.py:157] [basehttp:log_message] [INFO]- "GET /role/ HTTP/1.1" 200 30110
[2020-06-28 10:58:42,832] [basehttp.py:157] [basehttp:log_message] [INFO]- "GET /role/ HTTP/1.1" 200 30110
[2020-06-28 11:08:54,464] [basehttp.py:157] [basehttp:log_message] [INFO]- "OPTIONS /user/?current_page=1&pre_page=10 HTTP/1.1" 200 0
[2020-06-28 11:08:55,004] [basehttp.py:157] [basehttp:log_message] [INFO]- "GET /user/?current_page=1&pre_page=10 HTTP/1.1" 200 73634
[2020-06-28 11:09:03,916] [basehttp.py:157] [basehttp:log_message] [INFO]- "OPTIONS /menu/ HTTP/1.1" 200 0
[2020-06-28 11:09:04,224] [basehttp.py:157] [basehttp:log_message] [INFO]- "GET /menu/ HTTP/1.1" 200 13081
[2020-06-28 11:09:11,528] [basehttp.py:157] [basehttp:log_message] [INFO]- "OPTIONS /role/?current_page=1&pre_page=10 HTTP/1.1" 200 0
[2020-06-28 11:09:11,832] [basehttp.py:157] [basehttp:log_message] [INFO]- "GET /role/?current_page=1&pre_page=10 HTTP/1.1" 200 30181
[2020-06-28 11:09:15,680] [basehttp.py:157] [basehttp:log_message] [INFO]- "GET /user/?current_page=1&pre_page=10 HTTP/1.1" 200 73634
[2020-06-28 11:09:17,185] [basehttp.py:157] [basehttp:log_message] [INFO]- "GET /menu/ HTTP/1.1" 200 13081
[2020-06-28 11:09:19,436] [basehttp.py:157] [basehttp:log_message] [INFO]- "GET /user/?current_page=1&pre_page=10 HTTP/1.1" 200 73634
[2020-06-28 11:09:21,386] [basehttp.py:157] [basehttp:log_message] [INFO]- "GET /user/?current_page=1&pre_page=10 HTTP/1.1" 200 73634
[2020-06-28 11:09:56,207] [basehttp.py:157] [basehttp:log_message] [INFO]- "OPTIONS /auth/ HTTP/1.1" 200 0
[2020-06-28 11:09:56,404] [log.py:222] [log:log_response] [ERROR]- Internal Server Error: /auth/
Traceback (most recent call last):
  File "/home/rock/quality_inspection/python-workspace/project-sys/sys_auth/views.py", line 95, in post
    raise exceptions.AuthenticationFailed('未查询到用户信息！')
rest_framework.exceptions.AuthenticationFailed: 未查询到用户信息！

During handling of the above exception, another exception occurred:

Traceback (most recent call last):
  File "/home/rock/anaconda3/envs/venv/lib/python3.8/site-packages/django/core/handlers/exception.py", line 34, in inner
    response = get_response(request)
  File "/home/rock/anaconda3/envs/venv/lib/python3.8/site-packages/django/core/handlers/base.py", line 115, in _get_response
    response = self.process_exception_by_middleware(e, request)
  File "/home/rock/anaconda3/envs/venv/lib/python3.8/site-packages/django/core/handlers/base.py", line 113, in _get_response
    response = wrapped_callback(request, *callback_args, **callback_kwargs)
  File "/home/rock/anaconda3/envs/venv/lib/python3.8/site-packages/django/views/decorators/csrf.py", line 54, in wrapped_view
    return view_func(*args, **kwargs)
  File "/home/rock/anaconda3/envs/venv/lib/python3.8/site-packages/django/views/generic/base.py", line 71, in view
    return self.dispatch(request, *args, **kwargs)
  File "/home/rock/anaconda3/envs/venv/lib/python3.8/site-packages/rest_framework/views.py", line 505, in dispatch
    response = self.handle_exception(exc)
  File "/home/rock/anaconda3/envs/venv/lib/python3.8/site-packages/rest_framework/views.py", line 465, in handle_exception
    self.raise_uncaught_exception(exc)
  File "/home/rock/anaconda3/envs/venv/lib/python3.8/site-packages/rest_framework/views.py", line 476, in raise_uncaught_exception
    raise exc
  File "/home/rock/anaconda3/envs/venv/lib/python3.8/site-packages/rest_framework/views.py", line 502, in dispatch
    response = handler(request, *args, **kwargs)
  File "/home/rock/quality_inspection/python-workspace/project-sys/sys_auth/views.py", line 105, in post
    except exceptions as e:
TypeError: catching classes that do not inherit from BaseException is not allowed
[2020-06-28 11:09:56,406] [basehttp.py:157] [basehttp:log_message] [ERROR]- "POST /auth/ HTTP/1.1" 500 19107
[2020-06-28 11:10:48,764] [log.py:222] [log:log_response] [ERROR]- Internal Server Error: /auth/
Traceback (most recent call last):
  File "/home/rock/quality_inspection/python-workspace/project-sys/sys_auth/views.py", line 95, in post
    raise exceptions.AuthenticationFailed('未查询到用户信息！')
rest_framework.exceptions.AuthenticationFailed: 未查询到用户信息！

During handling of the above exception, another exception occurred:

Traceback (most recent call last):
  File "/home/rock/anaconda3/envs/venv/lib/python3.8/site-packages/django/core/handlers/exception.py", line 34, in inner
    response = get_response(request)
  File "/home/rock/anaconda3/envs/venv/lib/python3.8/site-packages/django/core/handlers/base.py", line 115, in _get_response
    response = self.process_exception_by_middleware(e, request)
  File "/home/rock/anaconda3/envs/venv/lib/python3.8/site-packages/django/core/handlers/base.py", line 113, in _get_response
    response = wrapped_callback(request, *callback_args, **callback_kwargs)
  File "/home/rock/anaconda3/envs/venv/lib/python3.8/site-packages/django/views/decorators/csrf.py", line 54, in wrapped_view
    return view_func(*args, **kwargs)
  File "/home/rock/anaconda3/envs/venv/lib/python3.8/site-packages/django/views/generic/base.py", line 71, in view
    return self.dispatch(request, *args, **kwargs)
  File "/home/rock/anaconda3/envs/venv/lib/python3.8/site-packages/rest_framework/views.py", line 505, in dispatch
    response = self.handle_exception(exc)
  File "/home/rock/anaconda3/envs/venv/lib/python3.8/site-packages/rest_framework/views.py", line 465, in handle_exception
    self.raise_uncaught_exception(exc)
  File "/home/rock/anaconda3/envs/venv/lib/python3.8/site-packages/rest_framework/views.py", line 476, in raise_uncaught_exception
    raise exc
  File "/home/rock/anaconda3/envs/venv/lib/python3.8/site-packages/rest_framework/views.py", line 502, in dispatch
    response = handler(request, *args, **kwargs)
  File "/home/rock/quality_inspection/python-workspace/project-sys/sys_auth/views.py", line 105, in post
    except exceptions as e:
TypeError: catching classes that do not inherit from BaseException is not allowed
[2020-06-28 11:10:48,766] [basehttp.py:157] [basehttp:log_message] [ERROR]- "POST /auth/ HTTP/1.1" 500 19109
[2020-06-28 11:11:41,029] [log.py:222] [log:log_response] [ERROR]- Internal Server Error: /auth/
Traceback (most recent call last):
  File "/home/rock/quality_inspection/python-workspace/project-sys/sys_auth/views.py", line 95, in post
    raise exceptions.AuthenticationFailed('未查询到用户信息！')
rest_framework.exceptions.AuthenticationFailed: 未查询到用户信息！

During handling of the above exception, another exception occurred:

Traceback (most recent call last):
  File "/home/rock/anaconda3/envs/venv/lib/python3.8/site-packages/django/core/handlers/exception.py", line 34, in inner
    response = get_response(request)
  File "/home/rock/anaconda3/envs/venv/lib/python3.8/site-packages/django/core/handlers/base.py", line 115, in _get_response
    response = self.process_exception_by_middleware(e, request)
  File "/home/rock/anaconda3/envs/venv/lib/python3.8/site-packages/django/core/handlers/base.py", line 113, in _get_response
    response = wrapped_callback(request, *callback_args, **callback_kwargs)
  File "/home/rock/anaconda3/envs/venv/lib/python3.8/site-packages/django/views/decorators/csrf.py", line 54, in wrapped_view
    return view_func(*args, **kwargs)
  File "/home/rock/anaconda3/envs/venv/lib/python3.8/site-packages/django/views/generic/base.py", line 71, in view
    return self.dispatch(request, *args, **kwargs)
  File "/home/rock/anaconda3/envs/venv/lib/python3.8/site-packages/rest_framework/views.py", line 505, in dispatch
    response = self.handle_exception(exc)
  File "/home/rock/anaconda3/envs/venv/lib/python3.8/site-packages/rest_framework/views.py", line 465, in handle_exception
    self.raise_uncaught_exception(exc)
  File "/home/rock/anaconda3/envs/venv/lib/python3.8/site-packages/rest_framework/views.py", line 476, in raise_uncaught_exception
    raise exc
  File "/home/rock/anaconda3/envs/venv/lib/python3.8/site-packages/rest_framework/views.py", line 502, in dispatch
    response = handler(request, *args, **kwargs)
  File "/home/rock/quality_inspection/python-workspace/project-sys/sys_auth/views.py", line 105, in post
    except exceptions as e:
TypeError: catching classes that do not inherit from BaseException is not allowed
[2020-06-28 11:11:41,030] [basehttp.py:157] [basehttp:log_message] [ERROR]- "POST /auth/ HTTP/1.1" 500 19109
[2020-06-28 11:12:13,791] [log.py:222] [log:log_response] [ERROR]- Internal Server Error: /auth/
Traceback (most recent call last):
  File "/home/rock/quality_inspection/python-workspace/project-sys/sys_auth/views.py", line 95, in post
    raise exceptions.AuthenticationFailed('未查询到用户信息！')
rest_framework.exceptions.AuthenticationFailed: 未查询到用户信息！

During handling of the above exception, another exception occurred:

Traceback (most recent call last):
  File "/home/rock/anaconda3/envs/venv/lib/python3.8/site-packages/django/core/handlers/exception.py", line 34, in inner
    response = get_response(request)
  File "/home/rock/anaconda3/envs/venv/lib/python3.8/site-packages/django/core/handlers/base.py", line 115, in _get_response
    response = self.process_exception_by_middleware(e, request)
  File "/home/rock/anaconda3/envs/venv/lib/python3.8/site-packages/django/core/handlers/base.py", line 113, in _get_response
    response = wrapped_callback(request, *callback_args, **callback_kwargs)
  File "/home/rock/anaconda3/envs/venv/lib/python3.8/site-packages/django/views/decorators/csrf.py", line 54, in wrapped_view
    return view_func(*args, **kwargs)
  File "/home/rock/anaconda3/envs/venv/lib/python3.8/site-packages/django/views/generic/base.py", line 71, in view
    return self.dispatch(request, *args, **kwargs)
  File "/home/rock/anaconda3/envs/venv/lib/python3.8/site-packages/rest_framework/views.py", line 505, in dispatch
    response = self.handle_exception(exc)
  File "/home/rock/anaconda3/envs/venv/lib/python3.8/site-packages/rest_framework/views.py", line 465, in handle_exception
    self.raise_uncaught_exception(exc)
  File "/home/rock/anaconda3/envs/venv/lib/python3.8/site-packages/rest_framework/views.py", line 476, in raise_uncaught_exception
    raise exc
  File "/home/rock/anaconda3/envs/venv/lib/python3.8/site-packages/rest_framework/views.py", line 502, in dispatch
    response = handler(request, *args, **kwargs)
  File "/home/rock/quality_inspection/python-workspace/project-sys/sys_auth/views.py", line 105, in post
    except exceptions as e:
TypeError: catching classes that do not inherit from BaseException is not allowed
[2020-06-28 11:12:13,792] [basehttp.py:157] [basehttp:log_message] [ERROR]- "POST /auth/ HTTP/1.1" 500 19109
[2020-06-28 11:13:05,862] [log.py:222] [log:log_response] [ERROR]- Internal Server Error: /auth/
Traceback (most recent call last):
  File "/home/rock/quality_inspection/python-workspace/project-sys/sys_auth/views.py", line 95, in post
    raise exceptions.AuthenticationFailed('未查询到用户信息！')
rest_framework.exceptions.AuthenticationFailed: 未查询到用户信息！

During handling of the above exception, another exception occurred:

Traceback (most recent call last):
  File "/home/rock/anaconda3/envs/venv/lib/python3.8/site-packages/django/core/handlers/exception.py", line 34, in inner
    response = get_response(request)
  File "/home/rock/anaconda3/envs/venv/lib/python3.8/site-packages/django/core/handlers/base.py", line 115, in _get_response
    response = self.process_exception_by_middleware(e, request)
  File "/home/rock/anaconda3/envs/venv/lib/python3.8/site-packages/django/core/handlers/base.py", line 113, in _get_response
    response = wrapped_callback(request, *callback_args, **callback_kwargs)
  File "/home/rock/anaconda3/envs/venv/lib/python3.8/site-packages/django/views/decorators/csrf.py", line 54, in wrapped_view
    return view_func(*args, **kwargs)
  File "/home/rock/anaconda3/envs/venv/lib/python3.8/site-packages/django/views/generic/base.py", line 71, in view
    return self.dispatch(request, *args, **kwargs)
  File "/home/rock/anaconda3/envs/venv/lib/python3.8/site-packages/rest_framework/views.py", line 505, in dispatch
    response = self.handle_exception(exc)
  File "/home/rock/anaconda3/envs/venv/lib/python3.8/site-packages/rest_framework/views.py", line 465, in handle_exception
    self.raise_uncaught_exception(exc)
  File "/home/rock/anaconda3/envs/venv/lib/python3.8/site-packages/rest_framework/views.py", line 476, in raise_uncaught_exception
    raise exc
  File "/home/rock/anaconda3/envs/venv/lib/python3.8/site-packages/rest_framework/views.py", line 502, in dispatch
    response = handler(request, *args, **kwargs)
  File "/home/rock/quality_inspection/python-workspace/project-sys/sys_auth/views.py", line 105, in post
    except exceptions as e:
TypeError: catching classes that do not inherit from BaseException is not allowed
[2020-06-28 11:13:05,864] [basehttp.py:157] [basehttp:log_message] [ERROR]- "POST /auth/ HTTP/1.1" 500 19109
[2020-06-28 11:13:45,309] [log.py:222] [log:log_response] [ERROR]- Internal Server Error: /auth/
Traceback (most recent call last):
  File "/home/rock/quality_inspection/python-workspace/project-sys/sys_auth/views.py", line 95, in post
    raise exceptions.AuthenticationFailed('未查询到用户信息！')
rest_framework.exceptions.AuthenticationFailed: 未查询到用户信息！

During handling of the above exception, another exception occurred:

Traceback (most recent call last):
  File "/home/rock/anaconda3/envs/venv/lib/python3.8/site-packages/django/core/handlers/exception.py", line 34, in inner
    response = get_response(request)
  File "/home/rock/anaconda3/envs/venv/lib/python3.8/site-packages/django/core/handlers/base.py", line 115, in _get_response
    response = self.process_exception_by_middleware(e, request)
  File "/home/rock/anaconda3/envs/venv/lib/python3.8/site-packages/django/core/handlers/base.py", line 113, in _get_response
    response = wrapped_callback(request, *callback_args, **callback_kwargs)
  File "/home/rock/anaconda3/envs/venv/lib/python3.8/site-packages/django/views/decorators/csrf.py", line 54, in wrapped_view
    return view_func(*args, **kwargs)
  File "/home/rock/anaconda3/envs/venv/lib/python3.8/site-packages/django/views/generic/base.py", line 71, in view
    return self.dispatch(request, *args, **kwargs)
  File "/home/rock/anaconda3/envs/venv/lib/python3.8/site-packages/rest_framework/views.py", line 505, in dispatch
    response = self.handle_exception(exc)
  File "/home/rock/anaconda3/envs/venv/lib/python3.8/site-packages/rest_framework/views.py", line 465, in handle_exception
    self.raise_uncaught_exception(exc)
  File "/home/rock/anaconda3/envs/venv/lib/python3.8/site-packages/rest_framework/views.py", line 476, in raise_uncaught_exception
    raise exc
  File "/home/rock/anaconda3/envs/venv/lib/python3.8/site-packages/rest_framework/views.py", line 502, in dispatch
    response = handler(request, *args, **kwargs)
  File "/home/rock/quality_inspection/python-workspace/project-sys/sys_auth/views.py", line 105, in post
    except exceptions as e:
TypeError: catching classes that do not inherit from BaseException is not allowed
[2020-06-28 11:13:45,310] [basehttp.py:157] [basehttp:log_message] [ERROR]- "POST /auth/ HTTP/1.1" 500 19109
[2020-06-28 11:14:47,636] [log.py:222] [log:log_response] [ERROR]- Internal Server Error: /auth/
Traceback (most recent call last):
  File "/home/rock/quality_inspection/python-workspace/project-sys/sys_auth/views.py", line 95, in post
    raise exceptions.AuthenticationFailed('未查询到用户信息！')
rest_framework.exceptions.AuthenticationFailed: 未查询到用户信息！

During handling of the above exception, another exception occurred:

Traceback (most recent call last):
  File "/home/rock/anaconda3/envs/venv/lib/python3.8/site-packages/django/core/handlers/exception.py", line 34, in inner
    response = get_response(request)
  File "/home/rock/anaconda3/envs/venv/lib/python3.8/site-packages/django/core/handlers/base.py", line 115, in _get_response
    response = self.process_exception_by_middleware(e, request)
  File "/home/rock/anaconda3/envs/venv/lib/python3.8/site-packages/django/core/handlers/base.py", line 113, in _get_response
    response = wrapped_callback(request, *callback_args, **callback_kwargs)
  File "/home/rock/anaconda3/envs/venv/lib/python3.8/site-packages/django/views/decorators/csrf.py", line 54, in wrapped_view
    return view_func(*args, **kwargs)
  File "/home/rock/anaconda3/envs/venv/lib/python3.8/site-packages/django/views/generic/base.py", line 71, in view
    return self.dispatch(request, *args, **kwargs)
  File "/home/rock/anaconda3/envs/venv/lib/python3.8/site-packages/rest_framework/views.py", line 505, in dispatch
    response = self.handle_exception(exc)
  File "/home/rock/anaconda3/envs/venv/lib/python3.8/site-packages/rest_framework/views.py", line 465, in handle_exception
    self.raise_uncaught_exception(exc)
  File "/home/rock/anaconda3/envs/venv/lib/python3.8/site-packages/rest_framework/views.py", line 476, in raise_uncaught_exception
    raise exc
  File "/home/rock/anaconda3/envs/venv/lib/python3.8/site-packages/rest_framework/views.py", line 502, in dispatch
    response = handler(request, *args, **kwargs)
  File "/home/rock/quality_inspection/python-workspace/project-sys/sys_auth/views.py", line 105, in post
    except exceptions as e:
TypeError: catching classes that do not inherit from BaseException is not allowed
[2020-06-28 11:14:47,637] [basehttp.py:157] [basehttp:log_message] [ERROR]- "POST /auth/ HTTP/1.1" 500 19109
[2020-06-28 11:16:15,930] [log.py:222] [log:log_response] [ERROR]- Internal Server Error: /auth/
Traceback (most recent call last):
  File "/home/rock/quality_inspection/python-workspace/project-sys/sys_auth/views.py", line 95, in post
    raise exceptions.AuthenticationFailed('未查询到用户信息！')
rest_framework.exceptions.AuthenticationFailed: 未查询到用户信息！

During handling of the above exception, another exception occurred:

Traceback (most recent call last):
  File "/home/rock/anaconda3/envs/venv/lib/python3.8/site-packages/django/core/handlers/exception.py", line 34, in inner
    response = get_response(request)
  File "/home/rock/anaconda3/envs/venv/lib/python3.8/site-packages/django/core/handlers/base.py", line 115, in _get_response
    response = self.process_exception_by_middleware(e, request)
  File "/home/rock/anaconda3/envs/venv/lib/python3.8/site-packages/django/core/handlers/base.py", line 113, in _get_response
    response = wrapped_callback(request, *callback_args, **callback_kwargs)
  File "/home/rock/anaconda3/envs/venv/lib/python3.8/site-packages/django/views/decorators/csrf.py", line 54, in wrapped_view
    return view_func(*args, **kwargs)
  File "/home/rock/anaconda3/envs/venv/lib/python3.8/site-packages/django/views/generic/base.py", line 71, in view
    return self.dispatch(request, *args, **kwargs)
  File "/home/rock/anaconda3/envs/venv/lib/python3.8/site-packages/rest_framework/views.py", line 505, in dispatch
    response = self.handle_exception(exc)
  File "/home/rock/anaconda3/envs/venv/lib/python3.8/site-packages/rest_framework/views.py", line 465, in handle_exception
    self.raise_uncaught_exception(exc)
  File "/home/rock/anaconda3/envs/venv/lib/python3.8/site-packages/rest_framework/views.py", line 476, in raise_uncaught_exception
    raise exc
  File "/home/rock/anaconda3/envs/venv/lib/python3.8/site-packages/rest_framework/views.py", line 502, in dispatch
    response = handler(request, *args, **kwargs)
  File "/home/rock/quality_inspection/python-workspace/project-sys/sys_auth/views.py", line 105, in post
    except exceptions as e:
TypeError: catching classes that do not inherit from BaseException is not allowed
[2020-06-28 11:16:15,932] [basehttp.py:157] [basehttp:log_message] [ERROR]- "POST /auth/ HTTP/1.1" 500 19109
[2020-06-28 11:17:07,433] [log.py:222] [log:log_response] [ERROR]- Internal Server Error: /auth/
Traceback (most recent call last):
  File "/home/rock/quality_inspection/python-workspace/project-sys/sys_auth/views.py", line 95, in post
    raise exceptions.AuthenticationFailed('未查询到用户信息！')
rest_framework.exceptions.AuthenticationFailed: 未查询到用户信息！

During handling of the above exception, another exception occurred:

Traceback (most recent call last):
  File "/home/rock/anaconda3/envs/venv/lib/python3.8/site-packages/django/core/handlers/exception.py", line 34, in inner
    response = get_response(request)
  File "/home/rock/anaconda3/envs/venv/lib/python3.8/site-packages/django/core/handlers/base.py", line 115, in _get_response
    response = self.process_exception_by_middleware(e, request)
  File "/home/rock/anaconda3/envs/venv/lib/python3.8/site-packages/django/core/handlers/base.py", line 113, in _get_response
    response = wrapped_callback(request, *callback_args, **callback_kwargs)
  File "/home/rock/anaconda3/envs/venv/lib/python3.8/site-packages/django/views/decorators/csrf.py", line 54, in wrapped_view
    return view_func(*args, **kwargs)
  File "/home/rock/anaconda3/envs/venv/lib/python3.8/site-packages/django/views/generic/base.py", line 71, in view
    return self.dispatch(request, *args, **kwargs)
  File "/home/rock/anaconda3/envs/venv/lib/python3.8/site-packages/rest_framework/views.py", line 505, in dispatch
    response = self.handle_exception(exc)
  File "/home/rock/anaconda3/envs/venv/lib/python3.8/site-packages/rest_framework/views.py", line 465, in handle_exception
    self.raise_uncaught_exception(exc)
  File "/home/rock/anaconda3/envs/venv/lib/python3.8/site-packages/rest_framework/views.py", line 476, in raise_uncaught_exception
    raise exc
  File "/home/rock/anaconda3/envs/venv/lib/python3.8/site-packages/rest_framework/views.py", line 502, in dispatch
    response = handler(request, *args, **kwargs)
  File "/home/rock/quality_inspection/python-workspace/project-sys/sys_auth/views.py", line 105, in post
    except exceptions as e:
TypeError: catching classes that do not inherit from BaseException is not allowed
[2020-06-28 11:17:07,435] [basehttp.py:157] [basehttp:log_message] [ERROR]- "POST /auth/ HTTP/1.1" 500 19109
[2020-06-28 11:36:52,861] [basehttp.py:157] [basehttp:log_message] [INFO]- "OPTIONS /auth/ HTTP/1.1" 200 0
[2020-06-28 11:36:53,068] [log.py:222] [log:log_response] [ERROR]- Internal Server Error: /auth/
Traceback (most recent call last):
  File "/home/rock/quality_inspection/python-workspace/project-sys/sys_auth/views.py", line 95, in post
    raise exceptions.AuthenticationFailed('未查询到用户信息！')
rest_framework.exceptions.AuthenticationFailed: 未查询到用户信息！

During handling of the above exception, another exception occurred:

Traceback (most recent call last):
  File "/home/rock/anaconda3/envs/venv/lib/python3.8/site-packages/django/core/handlers/exception.py", line 34, in inner
    response = get_response(request)
  File "/home/rock/anaconda3/envs/venv/lib/python3.8/site-packages/django/core/handlers/base.py", line 115, in _get_response
    response = self.process_exception_by_middleware(e, request)
  File "/home/rock/anaconda3/envs/venv/lib/python3.8/site-packages/django/core/handlers/base.py", line 113, in _get_response
    response = wrapped_callback(request, *callback_args, **callback_kwargs)
  File "/home/rock/anaconda3/envs/venv/lib/python3.8/site-packages/django/views/decorators/csrf.py", line 54, in wrapped_view
    return view_func(*args, **kwargs)
  File "/home/rock/anaconda3/envs/venv/lib/python3.8/site-packages/django/views/generic/base.py", line 71, in view
    return self.dispatch(request, *args, **kwargs)
  File "/home/rock/anaconda3/envs/venv/lib/python3.8/site-packages/rest_framework/views.py", line 505, in dispatch
    response = self.handle_exception(exc)
  File "/home/rock/anaconda3/envs/venv/lib/python3.8/site-packages/rest_framework/views.py", line 465, in handle_exception
    self.raise_uncaught_exception(exc)
  File "/home/rock/anaconda3/envs/venv/lib/python3.8/site-packages/rest_framework/views.py", line 476, in raise_uncaught_exception
    raise exc
  File "/home/rock/anaconda3/envs/venv/lib/python3.8/site-packages/rest_framework/views.py", line 502, in dispatch
    response = handler(request, *args, **kwargs)
  File "/home/rock/quality_inspection/python-workspace/project-sys/sys_auth/views.py", line 105, in post
    except exceptions as e:
TypeError: catching classes that do not inherit from BaseException is not allowed
[2020-06-28 11:36:53,069] [basehttp.py:157] [basehttp:log_message] [ERROR]- "POST /auth/ HTTP/1.1" 500 19109
[2020-06-28 11:37:17,795] [log.py:222] [log:log_response] [ERROR]- Internal Server Error: /auth/
Traceback (most recent call last):
  File "/home/rock/quality_inspection/python-workspace/project-sys/sys_auth/views.py", line 95, in post
    raise exceptions.AuthenticationFailed('未查询到用户信息！')
rest_framework.exceptions.AuthenticationFailed: 未查询到用户信息！

During handling of the above exception, another exception occurred:

Traceback (most recent call last):
  File "/home/rock/anaconda3/envs/venv/lib/python3.8/site-packages/django/core/handlers/exception.py", line 34, in inner
    response = get_response(request)
  File "/home/rock/anaconda3/envs/venv/lib/python3.8/site-packages/django/core/handlers/base.py", line 115, in _get_response
    response = self.process_exception_by_middleware(e, request)
  File "/home/rock/anaconda3/envs/venv/lib/python3.8/site-packages/django/core/handlers/base.py", line 113, in _get_response
    response = wrapped_callback(request, *callback_args, **callback_kwargs)
  File "/home/rock/anaconda3/envs/venv/lib/python3.8/site-packages/django/views/decorators/csrf.py", line 54, in wrapped_view
    return view_func(*args, **kwargs)
  File "/home/rock/anaconda3/envs/venv/lib/python3.8/site-packages/django/views/generic/base.py", line 71, in view
    return self.dispatch(request, *args, **kwargs)
  File "/home/rock/anaconda3/envs/venv/lib/python3.8/site-packages/rest_framework/views.py", line 505, in dispatch
    response = self.handle_exception(exc)
  File "/home/rock/anaconda3/envs/venv/lib/python3.8/site-packages/rest_framework/views.py", line 465, in handle_exception
    self.raise_uncaught_exception(exc)
  File "/home/rock/anaconda3/envs/venv/lib/python3.8/site-packages/rest_framework/views.py", line 476, in raise_uncaught_exception
    raise exc
  File "/home/rock/anaconda3/envs/venv/lib/python3.8/site-packages/rest_framework/views.py", line 502, in dispatch
    response = handler(request, *args, **kwargs)
  File "/home/rock/quality_inspection/python-workspace/project-sys/sys_auth/views.py", line 105, in post
    except exceptions as e:
TypeError: catching classes that do not inherit from BaseException is not allowed
[2020-06-28 11:37:17,796] [basehttp.py:157] [basehttp:log_message] [ERROR]- "POST /auth/ HTTP/1.1" 500 19109
[2020-06-28 11:39:05,767] [log.py:222] [log:log_response] [ERROR]- Internal Server Error: /auth/
Traceback (most recent call last):
  File "/home/rock/quality_inspection/python-workspace/project-sys/sys_auth/views.py", line 95, in post
    raise exceptions.AuthenticationFailed('未查询到用户信息！')
rest_framework.exceptions.AuthenticationFailed: 未查询到用户信息！

During handling of the above exception, another exception occurred:

Traceback (most recent call last):
  File "/home/rock/anaconda3/envs/venv/lib/python3.8/site-packages/django/core/handlers/exception.py", line 34, in inner
    response = get_response(request)
  File "/home/rock/anaconda3/envs/venv/lib/python3.8/site-packages/django/core/handlers/base.py", line 115, in _get_response
    response = self.process_exception_by_middleware(e, request)
  File "/home/rock/anaconda3/envs/venv/lib/python3.8/site-packages/django/core/handlers/base.py", line 113, in _get_response
    response = wrapped_callback(request, *callback_args, **callback_kwargs)
  File "/home/rock/anaconda3/envs/venv/lib/python3.8/site-packages/django/views/decorators/csrf.py", line 54, in wrapped_view
    return view_func(*args, **kwargs)
  File "/home/rock/anaconda3/envs/venv/lib/python3.8/site-packages/django/views/generic/base.py", line 71, in view
    return self.dispatch(request, *args, **kwargs)
  File "/home/rock/anaconda3/envs/venv/lib/python3.8/site-packages/rest_framework/views.py", line 505, in dispatch
    response = self.handle_exception(exc)
  File "/home/rock/anaconda3/envs/venv/lib/python3.8/site-packages/rest_framework/views.py", line 465, in handle_exception
    self.raise_uncaught_exception(exc)
  File "/home/rock/anaconda3/envs/venv/lib/python3.8/site-packages/rest_framework/views.py", line 476, in raise_uncaught_exception
    raise exc
  File "/home/rock/anaconda3/envs/venv/lib/python3.8/site-packages/rest_framework/views.py", line 502, in dispatch
    response = handler(request, *args, **kwargs)
  File "/home/rock/quality_inspection/python-workspace/project-sys/sys_auth/views.py", line 105, in post
    except exceptions as e:
TypeError: catching classes that do not inherit from BaseException is not allowed
[2020-06-28 11:39:05,769] [basehttp.py:157] [basehttp:log_message] [ERROR]- "POST /auth/ HTTP/1.1" 500 19109
[2020-06-28 11:39:37,400] [log.py:222] [log:log_response] [ERROR]- Internal Server Error: /auth/
Traceback (most recent call last):
  File "/home/rock/quality_inspection/python-workspace/project-sys/sys_auth/views.py", line 95, in post
    raise exceptions.AuthenticationFailed('未查询到用户信息！')
rest_framework.exceptions.AuthenticationFailed: 未查询到用户信息！

During handling of the above exception, another exception occurred:

Traceback (most recent call last):
  File "/home/rock/anaconda3/envs/venv/lib/python3.8/site-packages/django/core/handlers/exception.py", line 34, in inner
    response = get_response(request)
  File "/home/rock/anaconda3/envs/venv/lib/python3.8/site-packages/django/core/handlers/base.py", line 115, in _get_response
    response = self.process_exception_by_middleware(e, request)
  File "/home/rock/anaconda3/envs/venv/lib/python3.8/site-packages/django/core/handlers/base.py", line 113, in _get_response
    response = wrapped_callback(request, *callback_args, **callback_kwargs)
  File "/home/rock/anaconda3/envs/venv/lib/python3.8/site-packages/django/views/decorators/csrf.py", line 54, in wrapped_view
    return view_func(*args, **kwargs)
  File "/home/rock/anaconda3/envs/venv/lib/python3.8/site-packages/django/views/generic/base.py", line 71, in view
    return self.dispatch(request, *args, **kwargs)
  File "/home/rock/anaconda3/envs/venv/lib/python3.8/site-packages/rest_framework/views.py", line 505, in dispatch
    response = self.handle_exception(exc)
  File "/home/rock/anaconda3/envs/venv/lib/python3.8/site-packages/rest_framework/views.py", line 465, in handle_exception
    self.raise_uncaught_exception(exc)
  File "/home/rock/anaconda3/envs/venv/lib/python3.8/site-packages/rest_framework/views.py", line 476, in raise_uncaught_exception
    raise exc
  File "/home/rock/anaconda3/envs/venv/lib/python3.8/site-packages/rest_framework/views.py", line 502, in dispatch
    response = handler(request, *args, **kwargs)
  File "/home/rock/quality_inspection/python-workspace/project-sys/sys_auth/views.py", line 105, in post
    except exceptions as e:
TypeError: catching classes that do not inherit from BaseException is not allowed
[2020-06-28 11:39:37,401] [basehttp.py:157] [basehttp:log_message] [ERROR]- "POST /auth/ HTTP/1.1" 500 19109
[2020-06-28 11:40:52,215] [log.py:222] [log:log_response] [ERROR]- Internal Server Error: /auth/
Traceback (most recent call last):
  File "/home/rock/quality_inspection/python-workspace/project-sys/sys_auth/views.py", line 95, in post
    raise exceptions.AuthenticationFailed('未查询到用户信息！')
rest_framework.exceptions.AuthenticationFailed: 未查询到用户信息！

During handling of the above exception, another exception occurred:

Traceback (most recent call last):
  File "/home/rock/anaconda3/envs/venv/lib/python3.8/site-packages/django/core/handlers/exception.py", line 34, in inner
    response = get_response(request)
  File "/home/rock/anaconda3/envs/venv/lib/python3.8/site-packages/django/core/handlers/base.py", line 115, in _get_response
    response = self.process_exception_by_middleware(e, request)
  File "/home/rock/anaconda3/envs/venv/lib/python3.8/site-packages/django/core/handlers/base.py", line 113, in _get_response
    response = wrapped_callback(request, *callback_args, **callback_kwargs)
  File "/home/rock/anaconda3/envs/venv/lib/python3.8/site-packages/django/views/decorators/csrf.py", line 54, in wrapped_view
    return view_func(*args, **kwargs)
  File "/home/rock/anaconda3/envs/venv/lib/python3.8/site-packages/django/views/generic/base.py", line 71, in view
    return self.dispatch(request, *args, **kwargs)
  File "/home/rock/anaconda3/envs/venv/lib/python3.8/site-packages/rest_framework/views.py", line 505, in dispatch
    response = self.handle_exception(exc)
  File "/home/rock/anaconda3/envs/venv/lib/python3.8/site-packages/rest_framework/views.py", line 465, in handle_exception
    self.raise_uncaught_exception(exc)
  File "/home/rock/anaconda3/envs/venv/lib/python3.8/site-packages/rest_framework/views.py", line 476, in raise_uncaught_exception
    raise exc
  File "/home/rock/anaconda3/envs/venv/lib/python3.8/site-packages/rest_framework/views.py", line 502, in dispatch
    response = handler(request, *args, **kwargs)
  File "/home/rock/quality_inspection/python-workspace/project-sys/sys_auth/views.py", line 105, in post
    except exceptions as e:
TypeError: catching classes that do not inherit from BaseException is not allowed
[2020-06-28 11:40:52,217] [basehttp.py:157] [basehttp:log_message] [ERROR]- "POST /auth/ HTTP/1.1" 500 19106
[2020-06-28 11:43:42,961] [log.py:222] [log:log_response] [ERROR]- Internal Server Error: /auth/
Traceback (most recent call last):
  File "/home/rock/quality_inspection/python-workspace/project-sys/sys_auth/views.py", line 95, in post
    raise exceptions.AuthenticationFailed('未查询到用户信息！')
rest_framework.exceptions.AuthenticationFailed: 未查询到用户信息！

During handling of the above exception, another exception occurred:

Traceback (most recent call last):
  File "/home/rock/anaconda3/envs/venv/lib/python3.8/site-packages/django/core/handlers/exception.py", line 34, in inner
    response = get_response(request)
  File "/home/rock/anaconda3/envs/venv/lib/python3.8/site-packages/django/core/handlers/base.py", line 115, in _get_response
    response = self.process_exception_by_middleware(e, request)
  File "/home/rock/anaconda3/envs/venv/lib/python3.8/site-packages/django/core/handlers/base.py", line 113, in _get_response
    response = wrapped_callback(request, *callback_args, **callback_kwargs)
  File "/home/rock/anaconda3/envs/venv/lib/python3.8/site-packages/django/views/decorators/csrf.py", line 54, in wrapped_view
    return view_func(*args, **kwargs)
  File "/home/rock/anaconda3/envs/venv/lib/python3.8/site-packages/django/views/generic/base.py", line 71, in view
    return self.dispatch(request, *args, **kwargs)
  File "/home/rock/anaconda3/envs/venv/lib/python3.8/site-packages/rest_framework/views.py", line 505, in dispatch
    response = self.handle_exception(exc)
  File "/home/rock/anaconda3/envs/venv/lib/python3.8/site-packages/rest_framework/views.py", line 465, in handle_exception
    self.raise_uncaught_exception(exc)
  File "/home/rock/anaconda3/envs/venv/lib/python3.8/site-packages/rest_framework/views.py", line 476, in raise_uncaught_exception
    raise exc
  File "/home/rock/anaconda3/envs/venv/lib/python3.8/site-packages/rest_framework/views.py", line 502, in dispatch
    response = handler(request, *args, **kwargs)
  File "/home/rock/quality_inspection/python-workspace/project-sys/sys_auth/views.py", line 105, in post
    except exceptions as e:
TypeError: catching classes that do not inherit from BaseException is not allowed
[2020-06-28 11:43:42,963] [basehttp.py:157] [basehttp:log_message] [ERROR]- "POST /auth/ HTTP/1.1" 500 19108
[2020-06-28 11:43:57,578] [log.py:222] [log:log_response] [ERROR]- Internal Server Error: /auth/
Traceback (most recent call last):
  File "/home/rock/quality_inspection/python-workspace/project-sys/sys_auth/views.py", line 95, in post
    raise exceptions.AuthenticationFailed('未查询到用户信息！')
rest_framework.exceptions.AuthenticationFailed: 未查询到用户信息！

During handling of the above exception, another exception occurred:

Traceback (most recent call last):
  File "/home/rock/anaconda3/envs/venv/lib/python3.8/site-packages/django/core/handlers/exception.py", line 34, in inner
    response = get_response(request)
  File "/home/rock/anaconda3/envs/venv/lib/python3.8/site-packages/django/core/handlers/base.py", line 115, in _get_response
    response = self.process_exception_by_middleware(e, request)
  File "/home/rock/anaconda3/envs/venv/lib/python3.8/site-packages/django/core/handlers/base.py", line 113, in _get_response
    response = wrapped_callback(request, *callback_args, **callback_kwargs)
  File "/home/rock/anaconda3/envs/venv/lib/python3.8/site-packages/django/views/decorators/csrf.py", line 54, in wrapped_view
    return view_func(*args, **kwargs)
  File "/home/rock/anaconda3/envs/venv/lib/python3.8/site-packages/django/views/generic/base.py", line 71, in view
    return self.dispatch(request, *args, **kwargs)
  File "/home/rock/anaconda3/envs/venv/lib/python3.8/site-packages/rest_framework/views.py", line 505, in dispatch
    response = self.handle_exception(exc)
  File "/home/rock/anaconda3/envs/venv/lib/python3.8/site-packages/rest_framework/views.py", line 465, in handle_exception
    self.raise_uncaught_exception(exc)
  File "/home/rock/anaconda3/envs/venv/lib/python3.8/site-packages/rest_framework/views.py", line 476, in raise_uncaught_exception
    raise exc
  File "/home/rock/anaconda3/envs/venv/lib/python3.8/site-packages/rest_framework/views.py", line 502, in dispatch
    response = handler(request, *args, **kwargs)
  File "/home/rock/quality_inspection/python-workspace/project-sys/sys_auth/views.py", line 105, in post
    except exceptions as e:
TypeError: catching classes that do not inherit from BaseException is not allowed
[2020-06-28 11:43:57,580] [basehttp.py:157] [basehttp:log_message] [ERROR]- "POST /auth/ HTTP/1.1" 500 19110
[2020-06-28 11:44:16,390] [log.py:222] [log:log_response] [ERROR]- Internal Server Error: /auth/
Traceback (most recent call last):
  File "/home/rock/quality_inspection/python-workspace/project-sys/sys_auth/views.py", line 95, in post
    raise exceptions.AuthenticationFailed('未查询到用户信息！')
rest_framework.exceptions.AuthenticationFailed: 未查询到用户信息！

During handling of the above exception, another exception occurred:

Traceback (most recent call last):
  File "/home/rock/anaconda3/envs/venv/lib/python3.8/site-packages/django/core/handlers/exception.py", line 34, in inner
    response = get_response(request)
  File "/home/rock/anaconda3/envs/venv/lib/python3.8/site-packages/django/core/handlers/base.py", line 115, in _get_response
    response = self.process_exception_by_middleware(e, request)
  File "/home/rock/anaconda3/envs/venv/lib/python3.8/site-packages/django/core/handlers/base.py", line 113, in _get_response
    response = wrapped_callback(request, *callback_args, **callback_kwargs)
  File "/home/rock/anaconda3/envs/venv/lib/python3.8/site-packages/django/views/decorators/csrf.py", line 54, in wrapped_view
    return view_func(*args, **kwargs)
  File "/home/rock/anaconda3/envs/venv/lib/python3.8/site-packages/django/views/generic/base.py", line 71, in view
    return self.dispatch(request, *args, **kwargs)
  File "/home/rock/anaconda3/envs/venv/lib/python3.8/site-packages/rest_framework/views.py", line 505, in dispatch
    response = self.handle_exception(exc)
  File "/home/rock/anaconda3/envs/venv/lib/python3.8/site-packages/rest_framework/views.py", line 465, in handle_exception
    self.raise_uncaught_exception(exc)
  File "/home/rock/anaconda3/envs/venv/lib/python3.8/site-packages/rest_framework/views.py", line 476, in raise_uncaught_exception
    raise exc
  File "/home/rock/anaconda3/envs/venv/lib/python3.8/site-packages/rest_framework/views.py", line 502, in dispatch
    response = handler(request, *args, **kwargs)
  File "/home/rock/quality_inspection/python-workspace/project-sys/sys_auth/views.py", line 105, in post
    except exceptions as e:
TypeError: catching classes that do not inherit from BaseException is not allowed
[2020-06-28 11:44:16,391] [basehttp.py:157] [basehttp:log_message] [ERROR]- "POST /auth/ HTTP/1.1" 500 19109
[2020-06-28 11:44:33,322] [log.py:222] [log:log_response] [ERROR]- Internal Server Error: /auth/
Traceback (most recent call last):
  File "/home/rock/quality_inspection/python-workspace/project-sys/sys_auth/views.py", line 95, in post
    raise exceptions.AuthenticationFailed('未查询到用户信息！')
rest_framework.exceptions.AuthenticationFailed: 未查询到用户信息！

During handling of the above exception, another exception occurred:

Traceback (most recent call last):
  File "/home/rock/anaconda3/envs/venv/lib/python3.8/site-packages/django/core/handlers/exception.py", line 34, in inner
    response = get_response(request)
  File "/home/rock/anaconda3/envs/venv/lib/python3.8/site-packages/django/core/handlers/base.py", line 115, in _get_response
    response = self.process_exception_by_middleware(e, request)
  File "/home/rock/anaconda3/envs/venv/lib/python3.8/site-packages/django/core/handlers/base.py", line 113, in _get_response
    response = wrapped_callback(request, *callback_args, **callback_kwargs)
  File "/home/rock/anaconda3/envs/venv/lib/python3.8/site-packages/django/views/decorators/csrf.py", line 54, in wrapped_view
    return view_func(*args, **kwargs)
  File "/home/rock/anaconda3/envs/venv/lib/python3.8/site-packages/django/views/generic/base.py", line 71, in view
    return self.dispatch(request, *args, **kwargs)
  File "/home/rock/anaconda3/envs/venv/lib/python3.8/site-packages/rest_framework/views.py", line 505, in dispatch
    response = self.handle_exception(exc)
  File "/home/rock/anaconda3/envs/venv/lib/python3.8/site-packages/rest_framework/views.py", line 465, in handle_exception
    self.raise_uncaught_exception(exc)
  File "/home/rock/anaconda3/envs/venv/lib/python3.8/site-packages/rest_framework/views.py", line 476, in raise_uncaught_exception
    raise exc
  File "/home/rock/anaconda3/envs/venv/lib/python3.8/site-packages/rest_framework/views.py", line 502, in dispatch
    response = handler(request, *args, **kwargs)
  File "/home/rock/quality_inspection/python-workspace/project-sys/sys_auth/views.py", line 105, in post
    except exceptions as e:
TypeError: catching classes that do not inherit from BaseException is not allowed
[2020-06-28 11:44:33,323] [basehttp.py:157] [basehttp:log_message] [ERROR]- "POST /auth/ HTTP/1.1" 500 19110
[2020-06-28 11:47:24,806] [basehttp.py:157] [basehttp:log_message] [INFO]- "OPTIONS /auth/ HTTP/1.1" 200 0
[2020-06-28 11:47:24,982] [log.py:222] [log:log_response] [ERROR]- Internal Server Error: /auth/
Traceback (most recent call last):
  File "/home/rock/quality_inspection/python-workspace/project-sys/sys_auth/views.py", line 95, in post
    raise exceptions.AuthenticationFailed('未查询到用户信息！')
rest_framework.exceptions.AuthenticationFailed: 未查询到用户信息！

During handling of the above exception, another exception occurred:

Traceback (most recent call last):
  File "/home/rock/anaconda3/envs/venv/lib/python3.8/site-packages/django/core/handlers/exception.py", line 34, in inner
    response = get_response(request)
  File "/home/rock/anaconda3/envs/venv/lib/python3.8/site-packages/django/core/handlers/base.py", line 115, in _get_response
    response = self.process_exception_by_middleware(e, request)
  File "/home/rock/anaconda3/envs/venv/lib/python3.8/site-packages/django/core/handlers/base.py", line 113, in _get_response
    response = wrapped_callback(request, *callback_args, **callback_kwargs)
  File "/home/rock/anaconda3/envs/venv/lib/python3.8/site-packages/django/views/decorators/csrf.py", line 54, in wrapped_view
    return view_func(*args, **kwargs)
  File "/home/rock/anaconda3/envs/venv/lib/python3.8/site-packages/django/views/generic/base.py", line 71, in view
    return self.dispatch(request, *args, **kwargs)
  File "/home/rock/anaconda3/envs/venv/lib/python3.8/site-packages/rest_framework/views.py", line 505, in dispatch
    response = self.handle_exception(exc)
  File "/home/rock/anaconda3/envs/venv/lib/python3.8/site-packages/rest_framework/views.py", line 465, in handle_exception
    self.raise_uncaught_exception(exc)
  File "/home/rock/anaconda3/envs/venv/lib/python3.8/site-packages/rest_framework/views.py", line 476, in raise_uncaught_exception
    raise exc
  File "/home/rock/anaconda3/envs/venv/lib/python3.8/site-packages/rest_framework/views.py", line 502, in dispatch
    response = handler(request, *args, **kwargs)
  File "/home/rock/quality_inspection/python-workspace/project-sys/sys_auth/views.py", line 105, in post
    except exceptions as e:
TypeError: catching classes that do not inherit from BaseException is not allowed
[2020-06-28 11:47:24,984] [basehttp.py:157] [basehttp:log_message] [ERROR]- "POST /auth/ HTTP/1.1" 500 19109
[2020-06-28 11:47:57,944] [log.py:222] [log:log_response] [ERROR]- Internal Server Error: /auth/
Traceback (most recent call last):
  File "/home/rock/quality_inspection/python-workspace/project-sys/sys_auth/views.py", line 95, in post
    raise exceptions.AuthenticationFailed('未查询到用户信息！')
rest_framework.exceptions.AuthenticationFailed: 未查询到用户信息！

During handling of the above exception, another exception occurred:

Traceback (most recent call last):
  File "/home/rock/anaconda3/envs/venv/lib/python3.8/site-packages/django/core/handlers/exception.py", line 34, in inner
    response = get_response(request)
  File "/home/rock/anaconda3/envs/venv/lib/python3.8/site-packages/django/core/handlers/base.py", line 115, in _get_response
    response = self.process_exception_by_middleware(e, request)
  File "/home/rock/anaconda3/envs/venv/lib/python3.8/site-packages/django/core/handlers/base.py", line 113, in _get_response
    response = wrapped_callback(request, *callback_args, **callback_kwargs)
  File "/home/rock/anaconda3/envs/venv/lib/python3.8/site-packages/django/views/decorators/csrf.py", line 54, in wrapped_view
    return view_func(*args, **kwargs)
  File "/home/rock/anaconda3/envs/venv/lib/python3.8/site-packages/django/views/generic/base.py", line 71, in view
    return self.dispatch(request, *args, **kwargs)
  File "/home/rock/anaconda3/envs/venv/lib/python3.8/site-packages/rest_framework/views.py", line 505, in dispatch
    response = self.handle_exception(exc)
  File "/home/rock/anaconda3/envs/venv/lib/python3.8/site-packages/rest_framework/views.py", line 465, in handle_exception
    self.raise_uncaught_exception(exc)
  File "/home/rock/anaconda3/envs/venv/lib/python3.8/site-packages/rest_framework/views.py", line 476, in raise_uncaught_exception
    raise exc
  File "/home/rock/anaconda3/envs/venv/lib/python3.8/site-packages/rest_framework/views.py", line 502, in dispatch
    response = handler(request, *args, **kwargs)
  File "/home/rock/quality_inspection/python-workspace/project-sys/sys_auth/views.py", line 105, in post
    except exceptions as e:
TypeError: catching classes that do not inherit from BaseException is not allowed
[2020-06-28 11:47:57,946] [basehttp.py:157] [basehttp:log_message] [ERROR]- "POST /auth/ HTTP/1.1" 500 19112
[2020-06-28 11:48:13,085] [log.py:222] [log:log_response] [ERROR]- Internal Server Error: /auth/
Traceback (most recent call last):
  File "/home/rock/quality_inspection/python-workspace/project-sys/sys_auth/views.py", line 95, in post
    raise exceptions.AuthenticationFailed('未查询到用户信息！')
rest_framework.exceptions.AuthenticationFailed: 未查询到用户信息！

During handling of the above exception, another exception occurred:

Traceback (most recent call last):
  File "/home/rock/anaconda3/envs/venv/lib/python3.8/site-packages/django/core/handlers/exception.py", line 34, in inner
    response = get_response(request)
  File "/home/rock/anaconda3/envs/venv/lib/python3.8/site-packages/django/core/handlers/base.py", line 115, in _get_response
    response = self.process_exception_by_middleware(e, request)
  File "/home/rock/anaconda3/envs/venv/lib/python3.8/site-packages/django/core/handlers/base.py", line 113, in _get_response
    response = wrapped_callback(request, *callback_args, **callback_kwargs)
  File "/home/rock/anaconda3/envs/venv/lib/python3.8/site-packages/django/views/decorators/csrf.py", line 54, in wrapped_view
    return view_func(*args, **kwargs)
  File "/home/rock/anaconda3/envs/venv/lib/python3.8/site-packages/django/views/generic/base.py", line 71, in view
    return self.dispatch(request, *args, **kwargs)
  File "/home/rock/anaconda3/envs/venv/lib/python3.8/site-packages/rest_framework/views.py", line 505, in dispatch
    response = self.handle_exception(exc)
  File "/home/rock/anaconda3/envs/venv/lib/python3.8/site-packages/rest_framework/views.py", line 465, in handle_exception
    self.raise_uncaught_exception(exc)
  File "/home/rock/anaconda3/envs/venv/lib/python3.8/site-packages/rest_framework/views.py", line 476, in raise_uncaught_exception
    raise exc
  File "/home/rock/anaconda3/envs/venv/lib/python3.8/site-packages/rest_framework/views.py", line 502, in dispatch
    response = handler(request, *args, **kwargs)
  File "/home/rock/quality_inspection/python-workspace/project-sys/sys_auth/views.py", line 105, in post
    except exceptions as e:
TypeError: catching classes that do not inherit from BaseException is not allowed
[2020-06-28 11:48:13,086] [basehttp.py:157] [basehttp:log_message] [ERROR]- "POST /auth/ HTTP/1.1" 500 19111
[2020-06-28 13:43:43,645] [autoreload.py:598] [autoreload:run_with_reloader] [INFO]- Watching for file changes with StatReloader
[2020-06-28 13:44:23,280] [basehttp.py:157] [basehttp:log_message] [INFO]- "OPTIONS /auth/ HTTP/1.1" 200 0
[2020-06-28 13:44:23,538] [log.py:222] [log:log_response] [ERROR]- Internal Server Error: /auth/
Traceback (most recent call last):
  File "/home/rock/quality_inspection/python-workspace/project-sys/sys_auth/views.py", line 95, in post
    raise exceptions.AuthenticationFailed('未查询到用户信息！')
rest_framework.exceptions.AuthenticationFailed: 未查询到用户信息！

During handling of the above exception, another exception occurred:

Traceback (most recent call last):
  File "/home/rock/anaconda3/envs/venv/lib/python3.8/site-packages/django/core/handlers/exception.py", line 34, in inner
    response = get_response(request)
  File "/home/rock/anaconda3/envs/venv/lib/python3.8/site-packages/django/core/handlers/base.py", line 115, in _get_response
    response = self.process_exception_by_middleware(e, request)
  File "/home/rock/anaconda3/envs/venv/lib/python3.8/site-packages/django/core/handlers/base.py", line 113, in _get_response
    response = wrapped_callback(request, *callback_args, **callback_kwargs)
  File "/home/rock/anaconda3/envs/venv/lib/python3.8/site-packages/django/views/decorators/csrf.py", line 54, in wrapped_view
    return view_func(*args, **kwargs)
  File "/home/rock/anaconda3/envs/venv/lib/python3.8/site-packages/django/views/generic/base.py", line 71, in view
    return self.dispatch(request, *args, **kwargs)
  File "/home/rock/anaconda3/envs/venv/lib/python3.8/site-packages/rest_framework/views.py", line 505, in dispatch
    response = self.handle_exception(exc)
  File "/home/rock/anaconda3/envs/venv/lib/python3.8/site-packages/rest_framework/views.py", line 465, in handle_exception
    self.raise_uncaught_exception(exc)
  File "/home/rock/anaconda3/envs/venv/lib/python3.8/site-packages/rest_framework/views.py", line 476, in raise_uncaught_exception
    raise exc
  File "/home/rock/anaconda3/envs/venv/lib/python3.8/site-packages/rest_framework/views.py", line 502, in dispatch
    response = handler(request, *args, **kwargs)
  File "/home/rock/quality_inspection/python-workspace/project-sys/sys_auth/views.py", line 105, in post
    except exceptions as e:
TypeError: catching classes that do not inherit from BaseException is not allowed
[2020-06-28 13:44:23,540] [basehttp.py:157] [basehttp:log_message] [ERROR]- "POST /auth/ HTTP/1.1" 500 19114
[2020-06-28 13:45:30,541] [log.py:222] [log:log_response] [ERROR]- Internal Server Error: /auth/
Traceback (most recent call last):
  File "/home/rock/quality_inspection/python-workspace/project-sys/sys_auth/views.py", line 95, in post
    raise exceptions.AuthenticationFailed('未查询到用户信息！')
rest_framework.exceptions.AuthenticationFailed: 未查询到用户信息！

During handling of the above exception, another exception occurred:

Traceback (most recent call last):
  File "/home/rock/anaconda3/envs/venv/lib/python3.8/site-packages/django/core/handlers/exception.py", line 34, in inner
    response = get_response(request)
  File "/home/rock/anaconda3/envs/venv/lib/python3.8/site-packages/django/core/handlers/base.py", line 115, in _get_response
    response = self.process_exception_by_middleware(e, request)
  File "/home/rock/anaconda3/envs/venv/lib/python3.8/site-packages/django/core/handlers/base.py", line 113, in _get_response
    response = wrapped_callback(request, *callback_args, **callback_kwargs)
  File "/home/rock/anaconda3/envs/venv/lib/python3.8/site-packages/django/views/decorators/csrf.py", line 54, in wrapped_view
    return view_func(*args, **kwargs)
  File "/home/rock/anaconda3/envs/venv/lib/python3.8/site-packages/django/views/generic/base.py", line 71, in view
    return self.dispatch(request, *args, **kwargs)
  File "/home/rock/anaconda3/envs/venv/lib/python3.8/site-packages/rest_framework/views.py", line 505, in dispatch
    response = self.handle_exception(exc)
  File "/home/rock/anaconda3/envs/venv/lib/python3.8/site-packages/rest_framework/views.py", line 465, in handle_exception
    self.raise_uncaught_exception(exc)
  File "/home/rock/anaconda3/envs/venv/lib/python3.8/site-packages/rest_framework/views.py", line 476, in raise_uncaught_exception
    raise exc
  File "/home/rock/anaconda3/envs/venv/lib/python3.8/site-packages/rest_framework/views.py", line 502, in dispatch
    response = handler(request, *args, **kwargs)
  File "/home/rock/quality_inspection/python-workspace/project-sys/sys_auth/views.py", line 105, in post
    except exceptions as e:
TypeError: catching classes that do not inherit from BaseException is not allowed
[2020-06-28 13:45:30,542] [basehttp.py:157] [basehttp:log_message] [ERROR]- "POST /auth/ HTTP/1.1" 500 19101
[2020-06-28 14:30:35,802] [basehttp.py:157] [basehttp:log_message] [INFO]- "OPTIONS /auth/ HTTP/1.1" 200 0
[2020-06-28 14:30:35,993] [basehttp.py:157] [basehttp:log_message] [INFO]- "POST /auth/ HTTP/1.1" 200 65
[2020-06-28 14:33:06,221] [log.py:222] [log:log_response] [ERROR]- Internal Server Error: /auth/
Traceback (most recent call last):
  File "/home/rock/quality_inspection/python-workspace/project-sys/sys_auth/views.py", line 95, in post
    raise exceptions.AuthenticationFailed('未查询到用户信息！')
rest_framework.exceptions.AuthenticationFailed: 未查询到用户信息！

During handling of the above exception, another exception occurred:

Traceback (most recent call last):
  File "/home/rock/anaconda3/envs/venv/lib/python3.8/site-packages/django/core/handlers/exception.py", line 34, in inner
    response = get_response(request)
  File "/home/rock/anaconda3/envs/venv/lib/python3.8/site-packages/django/core/handlers/base.py", line 115, in _get_response
    response = self.process_exception_by_middleware(e, request)
  File "/home/rock/anaconda3/envs/venv/lib/python3.8/site-packages/django/core/handlers/base.py", line 113, in _get_response
    response = wrapped_callback(request, *callback_args, **callback_kwargs)
  File "/home/rock/anaconda3/envs/venv/lib/python3.8/site-packages/django/views/decorators/csrf.py", line 54, in wrapped_view
    return view_func(*args, **kwargs)
  File "/home/rock/anaconda3/envs/venv/lib/python3.8/site-packages/django/views/generic/base.py", line 71, in view
    return self.dispatch(request, *args, **kwargs)
  File "/home/rock/anaconda3/envs/venv/lib/python3.8/site-packages/rest_framework/views.py", line 505, in dispatch
    response = self.handle_exception(exc)
  File "/home/rock/anaconda3/envs/venv/lib/python3.8/site-packages/rest_framework/views.py", line 465, in handle_exception
    self.raise_uncaught_exception(exc)
  File "/home/rock/anaconda3/envs/venv/lib/python3.8/site-packages/rest_framework/views.py", line 476, in raise_uncaught_exception
    raise exc
  File "/home/rock/anaconda3/envs/venv/lib/python3.8/site-packages/rest_framework/views.py", line 502, in dispatch
    response = handler(request, *args, **kwargs)
  File "/home/rock/quality_inspection/python-workspace/project-sys/sys_auth/views.py", line 105, in post
    except exceptions as e:
TypeError: catching classes that do not inherit from BaseException is not allowed
[2020-06-28 14:33:06,222] [basehttp.py:157] [basehttp:log_message] [ERROR]- "POST /auth/ HTTP/1.1" 500 19107
[2020-06-28 14:33:51,191] [log.py:222] [log:log_response] [ERROR]- Internal Server Error: /auth/
Traceback (most recent call last):
  File "/home/rock/quality_inspection/python-workspace/project-sys/sys_auth/views.py", line 95, in post
    raise exceptions.AuthenticationFailed('未查询到用户信息！')
rest_framework.exceptions.AuthenticationFailed: 未查询到用户信息！

During handling of the above exception, another exception occurred:

Traceback (most recent call last):
  File "/home/rock/anaconda3/envs/venv/lib/python3.8/site-packages/django/core/handlers/exception.py", line 34, in inner
    response = get_response(request)
  File "/home/rock/anaconda3/envs/venv/lib/python3.8/site-packages/django/core/handlers/base.py", line 115, in _get_response
    response = self.process_exception_by_middleware(e, request)
  File "/home/rock/anaconda3/envs/venv/lib/python3.8/site-packages/django/core/handlers/base.py", line 113, in _get_response
    response = wrapped_callback(request, *callback_args, **callback_kwargs)
  File "/home/rock/anaconda3/envs/venv/lib/python3.8/site-packages/django/views/decorators/csrf.py", line 54, in wrapped_view
    return view_func(*args, **kwargs)
  File "/home/rock/anaconda3/envs/venv/lib/python3.8/site-packages/django/views/generic/base.py", line 71, in view
    return self.dispatch(request, *args, **kwargs)
  File "/home/rock/anaconda3/envs/venv/lib/python3.8/site-packages/rest_framework/views.py", line 505, in dispatch
    response = self.handle_exception(exc)
  File "/home/rock/anaconda3/envs/venv/lib/python3.8/site-packages/rest_framework/views.py", line 465, in handle_exception
    self.raise_uncaught_exception(exc)
  File "/home/rock/anaconda3/envs/venv/lib/python3.8/site-packages/rest_framework/views.py", line 476, in raise_uncaught_exception
    raise exc
  File "/home/rock/anaconda3/envs/venv/lib/python3.8/site-packages/rest_framework/views.py", line 502, in dispatch
    response = handler(request, *args, **kwargs)
  File "/home/rock/quality_inspection/python-workspace/project-sys/sys_auth/views.py", line 105, in post
    except exceptions as e:
TypeError: catching classes that do not inherit from BaseException is not allowed
[2020-06-28 14:33:51,192] [basehttp.py:157] [basehttp:log_message] [ERROR]- "POST /auth/ HTTP/1.1" 500 19107
[2020-06-28 14:37:28,571] [basehttp.py:157] [basehttp:log_message] [INFO]- "POST /auth/ HTTP/1.1" 200 65
[2020-06-28 14:37:34,017] [basehttp.py:157] [basehttp:log_message] [INFO]- "OPTIONS /user/?current_page=1&pre_page=10 HTTP/1.1" 200 0
[2020-06-28 14:37:34,749] [basehttp.py:157] [basehttp:log_message] [INFO]- "GET /user/?current_page=1&pre_page=10 HTTP/1.1" 200 73634
[2020-06-28 14:37:51,620] [basehttp.py:157] [basehttp:log_message] [INFO]- "OPTIONS /role/?current_page=1&pre_page=10 HTTP/1.1" 200 0
[2020-06-28 14:37:51,900] [basehttp.py:157] [basehttp:log_message] [INFO]- "GET /role/?current_page=1&pre_page=10 HTTP/1.1" 200 30181
[2020-06-28 14:38:19,966] [basehttp.py:157] [basehttp:log_message] [INFO]- "GET /role/?current_page=1&pre_page=10 HTTP/1.1" 200 30181
[2020-06-28 14:38:26,480] [basehttp.py:157] [basehttp:log_message] [INFO]- "GET /role/?current_page=1&pre_page=10 HTTP/1.1" 200 30181
[2020-06-28 14:38:49,481] [basehttp.py:157] [basehttp:log_message] [INFO]- "GET /role/?current_page=1&pre_page=10 HTTP/1.1" 200 30181
[2020-06-28 14:39:01,905] [basehttp.py:157] [basehttp:log_message] [INFO]- "GET /user/?current_page=1&pre_page=10 HTTP/1.1" 200 73634
[2020-06-28 14:39:29,064] [basehttp.py:157] [basehttp:log_message] [INFO]- "GET /user/?current_page=1&pre_page=10 HTTP/1.1" 200 73634
[2020-06-28 14:39:42,564] [basehttp.py:157] [basehttp:log_message] [INFO]- "GET /user/?current_page=1&pre_page=10 HTTP/1.1" 200 73634
[2020-06-28 14:40:54,853] [basehttp.py:157] [basehttp:log_message] [INFO]- "GET /user/?current_page=1&pre_page=10 HTTP/1.1" 200 73634
[2020-06-28 14:40:57,018] [basehttp.py:157] [basehttp:log_message] [INFO]- "GET /user/?current_page=1&pre_page=10 HTTP/1.1" 200 73634
[2020-06-28 14:41:00,538] [basehttp.py:157] [basehttp:log_message] [INFO]- "OPTIONS /role/ HTTP/1.1" 200 0
[2020-06-28 14:41:00,867] [basehttp.py:157] [basehttp:log_message] [INFO]- "GET /role/ HTTP/1.1" 200 30110
[2020-06-28 14:42:02,512] [basehttp.py:157] [basehttp:log_message] [INFO]- "GET /user/?current_page=1&pre_page=10 HTTP/1.1" 200 73634
[2020-06-28 14:42:04,657] [basehttp.py:157] [basehttp:log_message] [INFO]- "GET /user/?current_page=1&pre_page=10 HTTP/1.1" 200 73634
[2020-06-28 14:45:08,793] [basehttp.py:157] [basehttp:log_message] [INFO]- "GET /user/?current_page=1&pre_page=10 HTTP/1.1" 200 73634
[2020-06-28 14:51:08,399] [basehttp.py:157] [basehttp:log_message] [INFO]- "OPTIONS /auth/ HTTP/1.1" 200 0
[2020-06-28 14:51:08,616] [basehttp.py:157] [basehttp:log_message] [INFO]- "POST /auth/ HTTP/1.1" 200 65
[2020-06-28 14:59:33,758] [basehttp.py:157] [basehttp:log_message] [INFO]- "OPTIONS /menu/ HTTP/1.1" 200 0
[2020-06-28 14:59:43,338] [basehttp.py:157] [basehttp:log_message] [INFO]- "OPTIONS /role/?current_page=1&pre_page=10 HTTP/1.1" 200 0
[2020-06-28 14:59:56,455] [basehttp.py:157] [basehttp:log_message] [INFO]- "OPTIONS /role/?current_page=1&pre_page=10 HTTP/1.1" 200 0
[2020-06-28 15:00:15,265] [basehttp.py:157] [basehttp:log_message] [INFO]- "OPTIONS /menu/ HTTP/1.1" 200 0
[2020-06-28 15:02:44,673] [basehttp.py:157] [basehttp:log_message] [INFO]- "OPTIONS /auth/ HTTP/1.1" 200 0
[2020-06-28 15:02:44,943] [basehttp.py:157] [basehttp:log_message] [INFO]- "POST /auth/ HTTP/1.1" 200 65
[2020-06-28 15:02:47,099] [basehttp.py:157] [basehttp:log_message] [INFO]- "GET /role/?username=gzc&application=sys&type=menu HTTP/1.1" 200 30110
[2020-06-28 15:02:47,102] [basehttp.py:157] [basehttp:log_message] [INFO]- "GET /role/?username=gzc&application=sys&type=button HTTP/1.1" 200 30110
[2020-06-28 15:03:33,561] [basehttp.py:157] [basehttp:log_message] [INFO]- "GET /role/?username=gzc&application=sys&type=menu HTTP/1.1" 200 30110
[2020-06-28 15:03:33,573] [basehttp.py:157] [basehttp:log_message] [INFO]- "GET /role/?username=gzc&application=sys&type=button HTTP/1.1" 200 30110
[2020-06-28 15:03:45,524] [basehttp.py:157] [basehttp:log_message] [INFO]- "POST /auth/ HTTP/1.1" 200 65
[2020-06-28 15:03:47,528] [basehttp.py:157] [basehttp:log_message] [INFO]- "GET /role/?username=gzc&application=sys&type=button HTTP/1.1" 200 30110
[2020-06-28 15:03:47,540] [basehttp.py:157] [basehttp:log_message] [INFO]- "GET /role/?username=gzc&application=sys&type=menu HTTP/1.1" 200 30110
[2020-06-28 15:04:23,273] [basehttp.py:157] [basehttp:log_message] [INFO]- "POST /auth/ HTTP/1.1" 200 65
[2020-06-28 15:04:24,953] [basehttp.py:157] [basehttp:log_message] [INFO]- "GET /user/role/?username=gzc&application=sys&type=menu HTTP/1.1" 200 1161
[2020-06-28 15:04:24,957] [basehttp.py:157] [basehttp:log_message] [INFO]- "GET /user/role/?username=gzc&application=sys&type=button HTTP/1.1" 200 291
[2020-06-28 15:04:27,480] [basehttp.py:157] [basehttp:log_message] [INFO]- "GET /user/?current_page=1&pre_page=10 HTTP/1.1" 200 73634
[2020-06-28 15:04:28,359] [basehttp.py:157] [basehttp:log_message] [INFO]- "OPTIONS /role/?current_page=1&pre_page=10 HTTP/1.1" 200 0
[2020-06-28 15:08:44,006] [basehttp.py:157] [basehttp:log_message] [INFO]- "GET /user/role/?username=gzc&application=sys&type=menu HTTP/1.1" 200 1161
[2020-06-28 15:08:44,039] [basehttp.py:157] [basehttp:log_message] [INFO]- "GET /user/role/?username=gzc&application=sys&type=button HTTP/1.1" 200 291
[2020-06-28 15:09:44,117] [basehttp.py:157] [basehttp:log_message] [INFO]- "POST /auth/ HTTP/1.1" 200 65
[2020-06-28 15:09:46,128] [basehttp.py:157] [basehttp:log_message] [INFO]- "GET /user/role/?username=gzc&application=sys&type=menu HTTP/1.1" 200 1161
[2020-06-28 15:09:46,147] [basehttp.py:157] [basehttp:log_message] [INFO]- "GET /user/role/?username=gzc&application=sys&type=button HTTP/1.1" 200 291
[2020-06-28 15:09:47,407] [basehttp.py:157] [basehttp:log_message] [INFO]- "GET /role/?current_page=1&pre_page=10 HTTP/1.1" 200 30181
[2020-06-28 15:09:49,307] [basehttp.py:157] [basehttp:log_message] [INFO]- "GET /user/?current_page=1&pre_page=10 HTTP/1.1" 200 73634
[2020-06-28 15:09:50,383] [basehttp.py:157] [basehttp:log_message] [INFO]- "GET /menu/ HTTP/1.1" 200 13081
[2020-06-28 15:09:52,824] [basehttp.py:157] [basehttp:log_message] [INFO]- "GET /role/?current_page=1&pre_page=10 HTTP/1.1" 200 30181
[2020-06-28 15:09:55,589] [basehttp.py:157] [basehttp:log_message] [INFO]- "GET /role/2/menu/ HTTP/1.1" 200 7368
[2020-06-28 15:09:55,627] [basehttp.py:157] [basehttp:log_message] [INFO]- "GET /role/2/to_menu/ HTTP/1.1" 200 7682
[2020-06-28 15:10:00,363] [basehttp.py:157] [basehttp:log_message] [INFO]- "GET /menu/ HTTP/1.1" 200 13081
[2020-06-28 15:10:10,098] [basehttp.py:157] [basehttp:log_message] [INFO]- "GET /role/?current_page=1&pre_page=10 HTTP/1.1" 200 30181
[2020-06-28 15:17:40,820] [basehttp.py:157] [basehttp:log_message] [INFO]- "GET /user/role/?username=gzc&application=sys&type=menu HTTP/1.1" 200 1161
[2020-06-28 15:17:40,864] [basehttp.py:157] [basehttp:log_message] [INFO]- "GET /role/?current_page=1&pre_page=10 HTTP/1.1" 200 30181
[2020-06-28 15:17:40,865] [basehttp.py:157] [basehttp:log_message] [INFO]- "GET /user/role/?username=gzc&application=sys&type=button HTTP/1.1" 200 291
[2020-06-28 15:22:27,332] [basehttp.py:157] [basehttp:log_message] [INFO]- "OPTIONS /auth/ HTTP/1.1" 200 0
[2020-06-28 15:22:27,493] [log.py:222] [log:log_response] [ERROR]- Internal Server Error: /auth/
Traceback (most recent call last):
  File "/home/rock/quality_inspection/python-workspace/project-sys/sys_auth/views.py", line 95, in post
    raise exceptions.AuthenticationFailed('未查询到用户信息！')
rest_framework.exceptions.AuthenticationFailed: 未查询到用户信息！

During handling of the above exception, another exception occurred:

Traceback (most recent call last):
  File "/home/rock/anaconda3/envs/venv/lib/python3.8/site-packages/django/core/handlers/exception.py", line 34, in inner
    response = get_response(request)
  File "/home/rock/anaconda3/envs/venv/lib/python3.8/site-packages/django/core/handlers/base.py", line 115, in _get_response
    response = self.process_exception_by_middleware(e, request)
  File "/home/rock/anaconda3/envs/venv/lib/python3.8/site-packages/django/core/handlers/base.py", line 113, in _get_response
    response = wrapped_callback(request, *callback_args, **callback_kwargs)
  File "/home/rock/anaconda3/envs/venv/lib/python3.8/site-packages/django/views/decorators/csrf.py", line 54, in wrapped_view
    return view_func(*args, **kwargs)
  File "/home/rock/anaconda3/envs/venv/lib/python3.8/site-packages/django/views/generic/base.py", line 71, in view
    return self.dispatch(request, *args, **kwargs)
  File "/home/rock/anaconda3/envs/venv/lib/python3.8/site-packages/rest_framework/views.py", line 505, in dispatch
    response = self.handle_exception(exc)
  File "/home/rock/anaconda3/envs/venv/lib/python3.8/site-packages/rest_framework/views.py", line 465, in handle_exception
    self.raise_uncaught_exception(exc)
  File "/home/rock/anaconda3/envs/venv/lib/python3.8/site-packages/rest_framework/views.py", line 476, in raise_uncaught_exception
    raise exc
  File "/home/rock/anaconda3/envs/venv/lib/python3.8/site-packages/rest_framework/views.py", line 502, in dispatch
    response = handler(request, *args, **kwargs)
  File "/home/rock/quality_inspection/python-workspace/project-sys/sys_auth/views.py", line 105, in post
    except exceptions as e:
TypeError: catching classes that do not inherit from BaseException is not allowed
[2020-06-28 15:22:27,494] [basehttp.py:157] [basehttp:log_message] [ERROR]- "POST /auth/ HTTP/1.1" 500 19112
[2020-06-28 15:22:32,577] [basehttp.py:157] [basehttp:log_message] [INFO]- "POST /auth/ HTTP/1.1" 200 65
[2020-06-28 15:22:35,193] [basehttp.py:157] [basehttp:log_message] [INFO]- "GET /user/role/?username=admin&application=sys&type=menu HTTP/1.1" 200 1161
[2020-06-28 15:22:35,208] [basehttp.py:157] [basehttp:log_message] [INFO]- "GET /user/role/?username=admin&application=sys&type=button HTTP/1.1" 200 291
[2020-06-28 15:24:44,479] [basehttp.py:157] [basehttp:log_message] [INFO]- "GET /user/?current_page=1&pre_page=10 HTTP/1.1" 200 73634
[2020-06-28 15:24:46,274] [basehttp.py:157] [basehttp:log_message] [INFO]- "GET /user/role/?username=admin&application=sys&type=menu HTTP/1.1" 200 1161
[2020-06-28 15:24:46,275] [basehttp.py:157] [basehttp:log_message] [INFO]- "GET /user/role/?username=admin&application=sys&type=button HTTP/1.1" 200 291
[2020-06-28 15:24:46,570] [basehttp.py:157] [basehttp:log_message] [INFO]- "GET /user/?current_page=1&pre_page=10 HTTP/1.1" 200 73634
[2020-06-28 15:25:14,388] [basehttp.py:157] [basehttp:log_message] [INFO]- "GET /user/role/?username=admin&application=sys&type=menu HTTP/1.1" 200 1161
[2020-06-28 15:25:14,446] [basehttp.py:157] [basehttp:log_message] [INFO]- "GET /user/role/?username=admin&application=sys&type=button HTTP/1.1" 200 291
[2020-06-28 15:25:14,755] [basehttp.py:157] [basehttp:log_message] [INFO]- "GET /user/?current_page=1&pre_page=10 HTTP/1.1" 200 73634
[2020-06-28 15:25:29,287] [basehttp.py:157] [basehttp:log_message] [INFO]- "GET /user/role/?username=admin&application=sys&type=button HTTP/1.1" 200 291
[2020-06-28 15:25:29,289] [basehttp.py:157] [basehttp:log_message] [INFO]- "GET /user/role/?username=admin&application=sys&type=menu HTTP/1.1" 200 1161
[2020-06-28 15:25:29,749] [basehttp.py:157] [basehttp:log_message] [INFO]- "GET /user/?current_page=1&pre_page=10 HTTP/1.1" 200 73634
[2020-06-28 15:25:37,277] [log.py:222] [log:log_response] [WARNING]- Forbidden: /user/
[2020-06-28 15:25:37,279] [basehttp.py:157] [basehttp:log_message] [WARNING]- "GET /user/?current_page=1&pre_page=10 HTTP/1.1" 403 24
[2020-06-28 15:25:37,296] [log.py:222] [log:log_response] [WARNING]- Forbidden: /user/role/
[2020-06-28 15:25:37,300] [basehttp.py:157] [basehttp:log_message] [WARNING]- "GET /user/role/?username=admin&application=sys&type=menu HTTP/1.1" 403 24
[2020-06-28 15:25:37,476] [log.py:222] [log:log_response] [WARNING]- Forbidden: /user/role/
[2020-06-28 15:25:37,477] [basehttp.py:157] [basehttp:log_message] [WARNING]- "GET /user/role/?username=admin&application=sys&type=button HTTP/1.1" 403 24
[2020-06-28 15:27:47,588] [log.py:222] [log:log_response] [WARNING]- Forbidden: /user/
[2020-06-28 15:27:47,588] [basehttp.py:157] [basehttp:log_message] [WARNING]- "GET /user/?current_page=1&pre_page=10 HTTP/1.1" 403 24
[2020-06-28 15:29:03,914] [log.py:222] [log:log_response] [WARNING]- Forbidden: /user/
[2020-06-28 15:29:03,917] [basehttp.py:157] [basehttp:log_message] [WARNING]- "GET /user/?current_page=1&pre_page=10 HTTP/1.1" 403 24
[2020-06-28 15:29:06,050] [log.py:222] [log:log_response] [WARNING]- Forbidden: /user/
[2020-06-28 15:29:06,052] [basehttp.py:157] [basehttp:log_message] [WARNING]- "GET /user/?current_page=1&pre_page=10 HTTP/1.1" 403 24
[2020-06-28 15:29:10,262] [log.py:222] [log:log_response] [WARNING]- Forbidden: /user/
[2020-06-28 15:29:10,263] [basehttp.py:157] [basehttp:log_message] [WARNING]- "GET /user/?current_page=1&pre_page=10 HTTP/1.1" 403 24
[2020-06-28 15:29:10,289] [log.py:222] [log:log_response] [WARNING]- Forbidden: /user/role/
[2020-06-28 15:29:10,290] [basehttp.py:157] [basehttp:log_message] [WARNING]- "GET /user/role/?username=admin&application=sys&type=menu HTTP/1.1" 403 24
[2020-06-28 15:29:10,298] [log.py:222] [log:log_response] [WARNING]- Forbidden: /user/role/
[2020-06-28 15:29:10,303] [basehttp.py:157] [basehttp:log_message] [WARNING]- "GET /user/role/?username=admin&application=sys&type=button HTTP/1.1" 403 24
[2020-06-28 15:29:58,000] [log.py:222] [log:log_response] [WARNING]- Forbidden: /user/role/
[2020-06-28 15:29:58,002] [basehttp.py:157] [basehttp:log_message] [WARNING]- "GET /user/role/?username=admin&application=sys&type=button HTTP/1.1" 403 24
[2020-06-28 15:29:58,012] [log.py:222] [log:log_response] [WARNING]- Forbidden: /user/role/
[2020-06-28 15:29:58,014] [basehttp.py:157] [basehttp:log_message] [WARNING]- "GET /user/role/?username=admin&application=sys&type=menu HTTP/1.1" 403 24
[2020-06-28 15:30:02,404] [log.py:222] [log:log_response] [WARNING]- Forbidden: /user/
[2020-06-28 15:30:02,405] [basehttp.py:157] [basehttp:log_message] [WARNING]- "GET /user/?current_page=1&pre_page=10 HTTP/1.1" 403 24
[2020-06-28 15:30:02,438] [log.py:222] [log:log_response] [WARNING]- Forbidden: /user/role/
[2020-06-28 15:30:02,441] [basehttp.py:157] [basehttp:log_message] [WARNING]- "GET /user/role/?username=admin&application=sys&type=menu HTTP/1.1" 403 24
[2020-06-28 15:30:02,446] [log.py:222] [log:log_response] [WARNING]- Forbidden: /user/role/
[2020-06-28 15:30:02,446] [basehttp.py:157] [basehttp:log_message] [WARNING]- "GET /user/role/?username=admin&application=sys&type=button HTTP/1.1" 403 24
[2020-06-28 15:30:31,206] [log.py:222] [log:log_response] [WARNING]- Forbidden: /user/
[2020-06-28 15:30:31,210] [basehttp.py:157] [basehttp:log_message] [WARNING]- "GET /user/?current_page=1&pre_page=10 HTTP/1.1" 403 24
[2020-06-28 15:30:33,859] [log.py:222] [log:log_response] [WARNING]- Forbidden: /user/
[2020-06-28 15:30:33,860] [basehttp.py:157] [basehttp:log_message] [WARNING]- "GET /user/?current_page=1&pre_page=10 HTTP/1.1" 403 24
[2020-06-28 15:30:33,868] [log.py:222] [log:log_response] [WARNING]- Forbidden: /user/role/
[2020-06-28 15:30:33,869] [log.py:222] [log:log_response] [WARNING]- Forbidden: /user/role/
[2020-06-28 15:30:33,870] [basehttp.py:157] [basehttp:log_message] [WARNING]- "GET /user/role/?username=admin&application=sys&type=menu HTTP/1.1" 403 24
[2020-06-28 15:30:33,870] [basehttp.py:157] [basehttp:log_message] [WARNING]- "GET /user/role/?username=admin&application=sys&type=button HTTP/1.1" 403 24
[2020-06-28 15:30:39,745] [log.py:222] [log:log_response] [WARNING]- Forbidden: /user/
[2020-06-28 15:30:39,746] [basehttp.py:157] [basehttp:log_message] [WARNING]- "GET /user/?current_page=1&pre_page=10 HTTP/1.1" 403 24
[2020-06-28 15:30:39,775] [log.py:222] [log:log_response] [WARNING]- Forbidden: /user/role/
[2020-06-28 15:30:39,776] [basehttp.py:157] [basehttp:log_message] [WARNING]- "GET /user/role/?username=admin&application=sys&type=menu HTTP/1.1" 403 24
[2020-06-28 15:30:39,814] [log.py:222] [log:log_response] [WARNING]- Forbidden: /user/role/
[2020-06-28 15:30:39,816] [basehttp.py:157] [basehttp:log_message] [WARNING]- "GET /user/role/?username=admin&application=sys&type=button HTTP/1.1" 403 24
[2020-06-28 15:30:50,380] [log.py:222] [log:log_response] [WARNING]- Forbidden: /user/
[2020-06-28 15:30:50,383] [basehttp.py:157] [basehttp:log_message] [WARNING]- "GET /user/?current_page=1&pre_page=10 HTTP/1.1" 403 24
[2020-06-28 15:30:52,541] [log.py:222] [log:log_response] [WARNING]- Forbidden: /user/
[2020-06-28 15:30:52,542] [basehttp.py:157] [basehttp:log_message] [WARNING]- "GET /user/?current_page=1&pre_page=10 HTTP/1.1" 403 24
[2020-06-28 15:30:52,560] [log.py:222] [log:log_response] [WARNING]- Forbidden: /user/role/
[2020-06-28 15:30:52,561] [basehttp.py:157] [basehttp:log_message] [WARNING]- "GET /user/role/?username=admin&application=sys&type=menu HTTP/1.1" 403 24
[2020-06-28 15:30:52,572] [log.py:222] [log:log_response] [WARNING]- Forbidden: /user/role/
[2020-06-28 15:30:52,573] [basehttp.py:157] [basehttp:log_message] [WARNING]- "GET /user/role/?username=admin&application=sys&type=button HTTP/1.1" 403 24
[2020-06-28 15:31:03,868] [log.py:222] [log:log_response] [WARNING]- Forbidden: /user/
[2020-06-28 15:31:03,871] [basehttp.py:157] [basehttp:log_message] [WARNING]- "GET /user/?current_page=1&pre_page=10 HTTP/1.1" 403 24
[2020-06-28 15:31:24,786] [log.py:222] [log:log_response] [WARNING]- Forbidden: /user/
[2020-06-28 15:31:24,787] [basehttp.py:157] [basehttp:log_message] [WARNING]- "GET /user/?current_page=1&pre_page=10 HTTP/1.1" 403 24
[2020-06-28 15:31:24,824] [log.py:222] [log:log_response] [WARNING]- Forbidden: /user/role/
[2020-06-28 15:31:24,825] [basehttp.py:157] [basehttp:log_message] [WARNING]- "GET /user/role/?username=admin&application=sys&type=menu HTTP/1.1" 403 24
[2020-06-28 15:31:24,838] [log.py:222] [log:log_response] [WARNING]- Forbidden: /user/role/
[2020-06-28 15:31:24,839] [basehttp.py:157] [basehttp:log_message] [WARNING]- "GET /user/role/?username=admin&application=sys&type=button HTTP/1.1" 403 24
[2020-06-28 15:31:31,384] [log.py:222] [log:log_response] [WARNING]- Forbidden: /user/
[2020-06-28 15:31:31,385] [basehttp.py:157] [basehttp:log_message] [WARNING]- "GET /user/?current_page=1&pre_page=10 HTTP/1.1" 403 24
[2020-06-28 15:31:31,414] [log.py:222] [log:log_response] [WARNING]- Forbidden: /user/role/
[2020-06-28 15:31:31,415] [basehttp.py:157] [basehttp:log_message] [WARNING]- "GET /user/role/?username=admin&application=sys&type=menu HTTP/1.1" 403 24
[2020-06-28 15:31:31,421] [log.py:222] [log:log_response] [WARNING]- Forbidden: /user/role/
[2020-06-28 15:31:31,421] [basehttp.py:157] [basehttp:log_message] [WARNING]- "GET /user/role/?username=admin&application=sys&type=button HTTP/1.1" 403 24
[2020-06-28 15:38:56,382] [log.py:222] [log:log_response] [WARNING]- Forbidden: /user/role/
[2020-06-28 15:38:56,385] [log.py:222] [log:log_response] [WARNING]- Forbidden: /user/role/
[2020-06-28 15:38:56,387] [basehttp.py:157] [basehttp:log_message] [WARNING]- "GET /user/role/?username=admin&application=sys&type=button HTTP/1.1" 403 24
[2020-06-28 15:38:56,389] [basehttp.py:157] [basehttp:log_message] [WARNING]- "GET /user/role/?username=admin&application=sys&type=menu HTTP/1.1" 403 24
[2020-06-28 15:43:40,485] [log.py:222] [log:log_response] [WARNING]- Forbidden: /user/
[2020-06-28 15:43:40,488] [basehttp.py:157] [basehttp:log_message] [WARNING]- "GET /user/?current_page=1&pre_page=10 HTTP/1.1" 403 24
[2020-06-28 15:43:47,836] [log.py:222] [log:log_response] [WARNING]- Forbidden: /user/
[2020-06-28 15:43:47,837] [basehttp.py:157] [basehttp:log_message] [WARNING]- "GET /user/?current_page=1&pre_page=10 HTTP/1.1" 403 24
[2020-06-28 15:43:47,874] [log.py:222] [log:log_response] [WARNING]- Forbidden: /user/role/
[2020-06-28 15:43:47,876] [basehttp.py:157] [basehttp:log_message] [WARNING]- "GET /user/role/?username=admin&application=sys&type=menu HTTP/1.1" 403 24
[2020-06-28 15:43:47,880] [log.py:222] [log:log_response] [WARNING]- Forbidden: /user/role/
[2020-06-28 15:43:47,881] [basehttp.py:157] [basehttp:log_message] [WARNING]- "GET /user/role/?username=admin&application=sys&type=button HTTP/1.1" 403 24
[2020-06-28 15:44:42,707] [log.py:222] [log:log_response] [WARNING]- Forbidden: /user/
[2020-06-28 15:44:42,708] [basehttp.py:157] [basehttp:log_message] [WARNING]- "GET /user/?current_page=1&pre_page=10 HTTP/1.1" 403 24
[2020-06-28 15:44:42,749] [log.py:222] [log:log_response] [WARNING]- Forbidden: /user/role/
[2020-06-28 15:44:42,750] [basehttp.py:157] [basehttp:log_message] [WARNING]- "GET /user/role/?username=admin&application=sys&type=menu HTTP/1.1" 403 24
[2020-06-28 15:44:42,754] [log.py:222] [log:log_response] [WARNING]- Forbidden: /user/role/
[2020-06-28 15:44:42,756] [basehttp.py:157] [basehttp:log_message] [WARNING]- "GET /user/role/?username=admin&application=sys&type=button HTTP/1.1" 403 24
[2020-06-28 15:51:09,170] [log.py:222] [log:log_response] [WARNING]- Forbidden: /user/
[2020-06-28 15:51:09,179] [basehttp.py:157] [basehttp:log_message] [WARNING]- "GET /user/?current_page=1&pre_page=10 HTTP/1.1" 403 24
[2020-06-28 15:51:09,189] [log.py:222] [log:log_response] [WARNING]- Forbidden: /user/role/
[2020-06-28 15:51:09,189] [basehttp.py:157] [basehttp:log_message] [WARNING]- "GET /user/role/?username=admin&application=sys&type=menu HTTP/1.1" 403 24
[2020-06-28 15:51:09,204] [log.py:222] [log:log_response] [WARNING]- Forbidden: /user/role/
[2020-06-28 15:51:09,205] [basehttp.py:157] [basehttp:log_message] [WARNING]- "GET /user/role/?username=admin&application=sys&type=button HTTP/1.1" 403 24
[2020-06-28 15:52:41,490] [log.py:222] [log:log_response] [WARNING]- Forbidden: /user/
[2020-06-28 15:52:41,491] [basehttp.py:157] [basehttp:log_message] [WARNING]- "GET /user/?current_page=1&pre_page=10 HTTP/1.1" 403 24
[2020-06-28 15:52:41,508] [log.py:222] [log:log_response] [WARNING]- Forbidden: /user/role/
[2020-06-28 15:52:41,509] [basehttp.py:157] [basehttp:log_message] [WARNING]- "GET /user/role/?username=admin&application=sys&type=menu HTTP/1.1" 403 24
[2020-06-28 15:52:41,523] [log.py:222] [log:log_response] [WARNING]- Forbidden: /user/role/
[2020-06-28 15:52:41,524] [basehttp.py:157] [basehttp:log_message] [WARNING]- "GET /user/role/?username=admin&application=sys&type=button HTTP/1.1" 403 24
[2020-06-28 15:52:46,807] [log.py:222] [log:log_response] [WARNING]- Forbidden: /user/
[2020-06-28 15:52:46,808] [basehttp.py:157] [basehttp:log_message] [WARNING]- "GET /user/?current_page=1&pre_page=10 HTTP/1.1" 403 24
[2020-06-28 15:52:46,830] [log.py:222] [log:log_response] [WARNING]- Forbidden: /user/role/
[2020-06-28 15:52:46,833] [basehttp.py:157] [basehttp:log_message] [WARNING]- "GET /user/role/?username=admin&application=sys&type=menu HTTP/1.1" 403 24
[2020-06-28 15:52:46,842] [log.py:222] [log:log_response] [WARNING]- Forbidden: /user/role/
[2020-06-28 15:52:46,843] [basehttp.py:157] [basehttp:log_message] [WARNING]- "GET /user/role/?username=admin&application=sys&type=button HTTP/1.1" 403 24
[2020-06-28 15:53:02,660] [log.py:222] [log:log_response] [WARNING]- Forbidden: /user/
[2020-06-28 15:53:02,662] [basehttp.py:157] [basehttp:log_message] [WARNING]- "GET /user/?current_page=1&pre_page=10 HTTP/1.1" 403 24
[2020-06-28 15:53:02,682] [log.py:222] [log:log_response] [WARNING]- Forbidden: /user/role/
[2020-06-28 15:53:02,686] [log.py:222] [log:log_response] [WARNING]- Forbidden: /user/role/
[2020-06-28 15:53:02,686] [basehttp.py:157] [basehttp:log_message] [WARNING]- "GET /user/role/?username=admin&application=sys&type=button HTTP/1.1" 403 24
[2020-06-28 15:53:02,688] [basehttp.py:157] [basehttp:log_message] [WARNING]- "GET /user/role/?username=admin&application=sys&type=menu HTTP/1.1" 403 24
[2020-06-28 15:58:18,465] [autoreload.py:222] [autoreload:trigger_reload] [INFO]- /home/rock/quality_inspection/python-workspace/project-sys/sys_auth/views.py changed, reloading.
[2020-06-28 16:02:05,242] [autoreload.py:598] [autoreload:run_with_reloader] [INFO]- Watching for file changes with StatReloader
[2020-06-28 16:02:18,018] [log.py:222] [log:log_response] [WARNING]- Forbidden: /user/
[2020-06-28 16:02:18,025] [log.py:222] [log:log_response] [WARNING]- Forbidden: /user/role/
[2020-06-28 16:02:18,029] [basehttp.py:157] [basehttp:log_message] [WARNING]- "GET /user/?current_page=1&pre_page=10 HTTP/1.1" 403 31
[2020-06-28 16:02:18,036] [log.py:222] [log:log_response] [WARNING]- Forbidden: /user/role/
[2020-06-28 16:02:18,041] [basehttp.py:157] [basehttp:log_message] [WARNING]- "GET /user/role/?username=admin&application=sys&type=button HTTP/1.1" 403 31
[2020-06-28 16:02:18,044] [basehttp.py:157] [basehttp:log_message] [WARNING]- "GET /user/role/?username=admin&application=sys&type=menu HTTP/1.1" 403 31
[2020-06-28 16:14:01,035] [autoreload.py:222] [autoreload:trigger_reload] [INFO]- /home/rock/quality_inspection/python-workspace/project-sys/sys_auth/views.py changed, reloading.
[2020-06-28 16:14:02,003] [autoreload.py:598] [autoreload:run_with_reloader] [INFO]- Watching for file changes with StatReloader
[2020-06-28 16:14:22,850] [basehttp.py:157] [basehttp:log_message] [INFO]- "OPTIONS /auth/ HTTP/1.1" 200 0
[2020-06-28 16:14:23,084] [basehttp.py:157] [basehttp:log_message] [INFO]- "POST /auth/ HTTP/1.1" 200 65
[2020-06-28 16:14:24,985] [basehttp.py:157] [basehttp:log_message] [INFO]- "GET /user/role/?username=admin&application=sys&type=button HTTP/1.1" 200 291
[2020-06-28 16:14:24,997] [basehttp.py:157] [basehttp:log_message] [INFO]- "GET /user/role/?username=admin&application=sys&type=menu HTTP/1.1" 200 1161
[2020-06-28 16:14:27,548] [basehttp.py:157] [basehttp:log_message] [INFO]- "GET /user/?current_page=1&pre_page=10 HTTP/1.1" 200 73634
[2020-06-28 16:14:35,709] [basehttp.py:157] [basehttp:log_message] [INFO]- "GET /user/role/?username=admin&application=sys&type=button HTTP/1.1" 200 291
[2020-06-28 16:14:35,712] [basehttp.py:157] [basehttp:log_message] [INFO]- "GET /user/role/?username=admin&application=sys&type=menu HTTP/1.1" 200 1161
[2020-06-28 16:18:52,618] [log.py:222] [log:log_response] [ERROR]- Internal Server Error: /user/role/
Traceback (most recent call last):
  File "/home/rock/anaconda3/envs/venv/lib/python3.8/site-packages/django/core/handlers/exception.py", line 34, in inner
    response = get_response(request)
  File "/home/rock/anaconda3/envs/venv/lib/python3.8/site-packages/django/core/handlers/base.py", line 115, in _get_response
    response = self.process_exception_by_middleware(e, request)
  File "/home/rock/anaconda3/envs/venv/lib/python3.8/site-packages/django/core/handlers/base.py", line 113, in _get_response
    response = wrapped_callback(request, *callback_args, **callback_kwargs)
  File "/home/rock/anaconda3/envs/venv/lib/python3.8/site-packages/django/views/decorators/csrf.py", line 54, in wrapped_view
    return view_func(*args, **kwargs)
  File "/home/rock/anaconda3/envs/venv/lib/python3.8/site-packages/rest_framework/viewsets.py", line 114, in view
    return self.dispatch(request, *args, **kwargs)
  File "/home/rock/anaconda3/envs/venv/lib/python3.8/site-packages/rest_framework/views.py", line 505, in dispatch
    response = self.handle_exception(exc)
  File "/home/rock/anaconda3/envs/venv/lib/python3.8/site-packages/rest_framework/views.py", line 465, in handle_exception
    self.raise_uncaught_exception(exc)
  File "/home/rock/anaconda3/envs/venv/lib/python3.8/site-packages/rest_framework/views.py", line 476, in raise_uncaught_exception
    raise exc
  File "/home/rock/anaconda3/envs/venv/lib/python3.8/site-packages/rest_framework/views.py", line 493, in dispatch
    self.initial(request, *args, **kwargs)
  File "/home/rock/anaconda3/envs/venv/lib/python3.8/site-packages/rest_framework/views.py", line 410, in initial
    self.perform_authentication(request)
  File "/home/rock/anaconda3/envs/venv/lib/python3.8/site-packages/rest_framework/views.py", line 324, in perform_authentication
    request.user
  File "/home/rock/anaconda3/envs/venv/lib/python3.8/site-packages/rest_framework/request.py", line 220, in user
    self._authenticate()
  File "/home/rock/anaconda3/envs/venv/lib/python3.8/site-packages/rest_framework/request.py", line 380, in _authenticate
    self.user, self.auth = user_auth_tuple
  File "/home/rock/anaconda3/envs/venv/lib/python3.8/site-packages/django/template/response.py", line 118, in __iter__
    raise ContentNotRenderedError(
django.template.response.ContentNotRenderedError: The response content must be rendered before it can be iterated over.
[2020-06-28 16:18:52,625] [log.py:222] [log:log_response] [ERROR]- Internal Server Error: /user/role/
Traceback (most recent call last):
  File "/home/rock/anaconda3/envs/venv/lib/python3.8/site-packages/django/core/handlers/exception.py", line 34, in inner
    response = get_response(request)
  File "/home/rock/anaconda3/envs/venv/lib/python3.8/site-packages/django/core/handlers/base.py", line 115, in _get_response
    response = self.process_exception_by_middleware(e, request)
  File "/home/rock/anaconda3/envs/venv/lib/python3.8/site-packages/django/core/handlers/base.py", line 113, in _get_response
    response = wrapped_callback(request, *callback_args, **callback_kwargs)
  File "/home/rock/anaconda3/envs/venv/lib/python3.8/site-packages/django/views/decorators/csrf.py", line 54, in wrapped_view
    return view_func(*args, **kwargs)
  File "/home/rock/anaconda3/envs/venv/lib/python3.8/site-packages/rest_framework/viewsets.py", line 114, in view
    return self.dispatch(request, *args, **kwargs)
  File "/home/rock/anaconda3/envs/venv/lib/python3.8/site-packages/rest_framework/views.py", line 505, in dispatch
    response = self.handle_exception(exc)
  File "/home/rock/anaconda3/envs/venv/lib/python3.8/site-packages/rest_framework/views.py", line 465, in handle_exception
    self.raise_uncaught_exception(exc)
  File "/home/rock/anaconda3/envs/venv/lib/python3.8/site-packages/rest_framework/views.py", line 476, in raise_uncaught_exception
    raise exc
  File "/home/rock/anaconda3/envs/venv/lib/python3.8/site-packages/rest_framework/views.py", line 493, in dispatch
    self.initial(request, *args, **kwargs)
  File "/home/rock/anaconda3/envs/venv/lib/python3.8/site-packages/rest_framework/views.py", line 410, in initial
    self.perform_authentication(request)
  File "/home/rock/anaconda3/envs/venv/lib/python3.8/site-packages/rest_framework/views.py", line 324, in perform_authentication
    request.user
  File "/home/rock/anaconda3/envs/venv/lib/python3.8/site-packages/rest_framework/request.py", line 220, in user
    self._authenticate()
  File "/home/rock/anaconda3/envs/venv/lib/python3.8/site-packages/rest_framework/request.py", line 380, in _authenticate
    self.user, self.auth = user_auth_tuple
  File "/home/rock/anaconda3/envs/venv/lib/python3.8/site-packages/django/template/response.py", line 118, in __iter__
    raise ContentNotRenderedError(
django.template.response.ContentNotRenderedError: The response content must be rendered before it can be iterated over.
[2020-06-28 16:18:52,627] [basehttp.py:157] [basehttp:log_message] [ERROR]- "GET /user/role/?username=admin&application=sys&type=button HTTP/1.1" 500 20161
[2020-06-28 16:18:52,628] [basehttp.py:157] [basehttp:log_message] [ERROR]- "GET /user/role/?username=admin&application=sys&type=menu HTTP/1.1" 500 20155
[2020-06-28 16:23:03,176] [log.py:222] [log:log_response] [ERROR]- Internal Server Error: /user/role/
Traceback (most recent call last):
  File "/home/rock/anaconda3/envs/venv/lib/python3.8/site-packages/django/core/handlers/exception.py", line 34, in inner
    response = get_response(request)
  File "/home/rock/anaconda3/envs/venv/lib/python3.8/site-packages/django/core/handlers/base.py", line 115, in _get_response
    response = self.process_exception_by_middleware(e, request)
  File "/home/rock/anaconda3/envs/venv/lib/python3.8/site-packages/django/core/handlers/base.py", line 113, in _get_response
    response = wrapped_callback(request, *callback_args, **callback_kwargs)
  File "/home/rock/anaconda3/envs/venv/lib/python3.8/site-packages/django/views/decorators/csrf.py", line 54, in wrapped_view
    return view_func(*args, **kwargs)
  File "/home/rock/anaconda3/envs/venv/lib/python3.8/site-packages/rest_framework/viewsets.py", line 114, in view
    return self.dispatch(request, *args, **kwargs)
  File "/home/rock/anaconda3/envs/venv/lib/python3.8/site-packages/rest_framework/views.py", line 505, in dispatch
    response = self.handle_exception(exc)
  File "/home/rock/anaconda3/envs/venv/lib/python3.8/site-packages/rest_framework/views.py", line 465, in handle_exception
    self.raise_uncaught_exception(exc)
  File "/home/rock/anaconda3/envs/venv/lib/python3.8/site-packages/rest_framework/views.py", line 476, in raise_uncaught_exception
    raise exc
  File "/home/rock/anaconda3/envs/venv/lib/python3.8/site-packages/rest_framework/views.py", line 493, in dispatch
    self.initial(request, *args, **kwargs)
  File "/home/rock/anaconda3/envs/venv/lib/python3.8/site-packages/rest_framework/views.py", line 410, in initial
    self.perform_authentication(request)
  File "/home/rock/anaconda3/envs/venv/lib/python3.8/site-packages/rest_framework/views.py", line 324, in perform_authentication
    request.user
  File "/home/rock/anaconda3/envs/venv/lib/python3.8/site-packages/rest_framework/request.py", line 220, in user
    self._authenticate()
  File "/home/rock/anaconda3/envs/venv/lib/python3.8/site-packages/rest_framework/request.py", line 380, in _authenticate
    self.user, self.auth = user_auth_tuple
  File "/home/rock/anaconda3/envs/venv/lib/python3.8/site-packages/django/template/response.py", line 118, in __iter__
    raise ContentNotRenderedError(
django.template.response.ContentNotRenderedError: The response content must be rendered before it can be iterated over.
[2020-06-28 16:23:03,182] [basehttp.py:157] [basehttp:log_message] [ERROR]- "GET /user/role/?username=admin&application=sys&type=button HTTP/1.1" 500 20161
[2020-06-28 16:23:03,213] [log.py:222] [log:log_response] [ERROR]- Internal Server Error: /user/role/
Traceback (most recent call last):
  File "/home/rock/anaconda3/envs/venv/lib/python3.8/site-packages/django/core/handlers/exception.py", line 34, in inner
    response = get_response(request)
  File "/home/rock/anaconda3/envs/venv/lib/python3.8/site-packages/django/core/handlers/base.py", line 115, in _get_response
    response = self.process_exception_by_middleware(e, request)
  File "/home/rock/anaconda3/envs/venv/lib/python3.8/site-packages/django/core/handlers/base.py", line 113, in _get_response
    response = wrapped_callback(request, *callback_args, **callback_kwargs)
  File "/home/rock/anaconda3/envs/venv/lib/python3.8/site-packages/django/views/decorators/csrf.py", line 54, in wrapped_view
    return view_func(*args, **kwargs)
  File "/home/rock/anaconda3/envs/venv/lib/python3.8/site-packages/rest_framework/viewsets.py", line 114, in view
    return self.dispatch(request, *args, **kwargs)
  File "/home/rock/anaconda3/envs/venv/lib/python3.8/site-packages/rest_framework/views.py", line 505, in dispatch
    response = self.handle_exception(exc)
  File "/home/rock/anaconda3/envs/venv/lib/python3.8/site-packages/rest_framework/views.py", line 465, in handle_exception
    self.raise_uncaught_exception(exc)
  File "/home/rock/anaconda3/envs/venv/lib/python3.8/site-packages/rest_framework/views.py", line 476, in raise_uncaught_exception
    raise exc
  File "/home/rock/anaconda3/envs/venv/lib/python3.8/site-packages/rest_framework/views.py", line 493, in dispatch
    self.initial(request, *args, **kwargs)
  File "/home/rock/anaconda3/envs/venv/lib/python3.8/site-packages/rest_framework/views.py", line 410, in initial
    self.perform_authentication(request)
  File "/home/rock/anaconda3/envs/venv/lib/python3.8/site-packages/rest_framework/views.py", line 324, in perform_authentication
    request.user
  File "/home/rock/anaconda3/envs/venv/lib/python3.8/site-packages/rest_framework/request.py", line 220, in user
    self._authenticate()
  File "/home/rock/anaconda3/envs/venv/lib/python3.8/site-packages/rest_framework/request.py", line 380, in _authenticate
    self.user, self.auth = user_auth_tuple
  File "/home/rock/anaconda3/envs/venv/lib/python3.8/site-packages/django/template/response.py", line 118, in __iter__
    raise ContentNotRenderedError(
django.template.response.ContentNotRenderedError: The response content must be rendered before it can be iterated over.
[2020-06-28 16:23:03,217] [basehttp.py:157] [basehttp:log_message] [ERROR]- "GET /user/role/?username=admin&application=sys&type=menu HTTP/1.1" 500 20155
[2020-06-28 16:26:08,562] [autoreload.py:598] [autoreload:run_with_reloader] [INFO]- Watching for file changes with StatReloader
[2020-06-28 16:33:07,899] [basehttp.py:157] [basehttp:log_message] [INFO]- "OPTIONS /auth/ HTTP/1.1" 200 0
[2020-06-28 16:33:08,242] [basehttp.py:157] [basehttp:log_message] [INFO]- "POST /auth/ HTTP/1.1" 200 65
[2020-06-28 16:33:10,567] [basehttp.py:157] [basehttp:log_message] [INFO]- "GET /user/role/?username=admin&application=sys&type=button HTTP/1.1" 200 291
[2020-06-28 16:33:10,597] [basehttp.py:157] [basehttp:log_message] [INFO]- "GET /user/role/?username=admin&application=sys&type=menu HTTP/1.1" 200 1161
[2020-06-28 16:33:45,918] [basehttp.py:157] [basehttp:log_message] [INFO]- "GET /user/role/?username=admin&application=sys&type=menu HTTP/1.1" 200 1161
[2020-06-28 16:33:45,925] [basehttp.py:157] [basehttp:log_message] [INFO]- "GET /user/role/?username=admin&application=sys&type=button HTTP/1.1" 200 291
[2020-06-28 16:33:49,144] [basehttp.py:157] [basehttp:log_message] [INFO]- "GET /user/role/?username=admin&application=sys&type=menu HTTP/1.1" 200 1161
[2020-06-28 16:33:49,191] [basehttp.py:157] [basehttp:log_message] [INFO]- "GET /user/role/?username=admin&application=sys&type=button HTTP/1.1" 200 291
[2020-06-28 16:34:16,378] [log.py:222] [log:log_response] [WARNING]- Forbidden: /user/role/
[2020-06-28 16:34:16,379] [basehttp.py:157] [basehttp:log_message] [WARNING]- "GET /user/role/?username=admin&application=sys&type=menu HTTP/1.1" 403 24
[2020-06-28 16:34:16,392] [log.py:222] [log:log_response] [WARNING]- Forbidden: /user/role/
[2020-06-28 16:34:16,393] [basehttp.py:157] [basehttp:log_message] [WARNING]- "GET /user/role/?username=admin&application=sys&type=button HTTP/1.1" 403 24
[2020-06-28 16:34:30,549] [log.py:222] [log:log_response] [WARNING]- Forbidden: /user/role/
[2020-06-28 16:34:30,549] [basehttp.py:157] [basehttp:log_message] [WARNING]- "GET /user/role/?username=admin&application=sys&type=menu HTTP/1.1" 403 24
[2020-06-28 16:34:30,554] [log.py:222] [log:log_response] [WARNING]- Forbidden: /user/role/
[2020-06-28 16:34:30,554] [basehttp.py:157] [basehttp:log_message] [WARNING]- "GET /user/role/?username=admin&application=sys&type=button HTTP/1.1" 403 24
[2020-06-28 16:34:53,465] [log.py:222] [log:log_response] [WARNING]- Forbidden: /user/role/
[2020-06-28 16:34:53,469] [log.py:222] [log:log_response] [WARNING]- Forbidden: /user/role/
[2020-06-28 16:34:53,472] [basehttp.py:157] [basehttp:log_message] [WARNING]- "GET /user/role/?username=admin&application=sys&type=button HTTP/1.1" 403 24
[2020-06-28 16:34:53,474] [basehttp.py:157] [basehttp:log_message] [WARNING]- "GET /user/role/?username=admin&application=sys&type=menu HTTP/1.1" 403 24
[2020-06-28 16:35:01,111] [log.py:222] [log:log_response] [WARNING]- Forbidden: /user/role/
[2020-06-28 16:35:01,112] [log.py:222] [log:log_response] [WARNING]- Forbidden: /user/role/
[2020-06-28 16:35:01,113] [basehttp.py:157] [basehttp:log_message] [WARNING]- "GET /user/role/?username=admin&application=sys&type=menu HTTP/1.1" 403 24
[2020-06-28 16:35:01,114] [basehttp.py:157] [basehttp:log_message] [WARNING]- "GET /user/role/?username=admin&application=sys&type=button HTTP/1.1" 403 24
[2020-06-28 16:35:20,443] [log.py:222] [log:log_response] [WARNING]- Forbidden: /user/role/
[2020-06-28 16:35:20,446] [basehttp.py:157] [basehttp:log_message] [WARNING]- "GET /user/role/?username=admin&application=sys&type=menu HTTP/1.1" 403 24
[2020-06-28 16:35:20,460] [log.py:222] [log:log_response] [WARNING]- Forbidden: /user/role/
[2020-06-28 16:35:20,463] [basehttp.py:157] [basehttp:log_message] [WARNING]- "GET /user/role/?username=admin&application=sys&type=button HTTP/1.1" 403 24
[2020-06-28 16:35:22,602] [log.py:222] [log:log_response] [WARNING]- Forbidden: /user/role/
[2020-06-28 16:35:22,603] [basehttp.py:157] [basehttp:log_message] [WARNING]- "GET /user/role/?username=admin&application=sys&type=menu HTTP/1.1" 403 24
[2020-06-28 16:35:22,618] [log.py:222] [log:log_response] [WARNING]- Forbidden: /user/role/
[2020-06-28 16:35:22,619] [basehttp.py:157] [basehttp:log_message] [WARNING]- "GET /user/role/?username=admin&application=sys&type=button HTTP/1.1" 403 24
[2020-06-28 16:35:46,582] [log.py:222] [log:log_response] [WARNING]- Forbidden: /user/role/
[2020-06-28 16:35:46,583] [basehttp.py:157] [basehttp:log_message] [WARNING]- "GET /user/role/?username=admin&application=sys&type=button HTTP/1.1" 403 24
[2020-06-28 16:35:46,590] [log.py:222] [log:log_response] [WARNING]- Forbidden: /user/role/
[2020-06-28 16:35:46,591] [basehttp.py:157] [basehttp:log_message] [WARNING]- "GET /user/role/?username=admin&application=sys&type=menu HTTP/1.1" 403 24
[2020-06-28 16:35:55,037] [log.py:222] [log:log_response] [WARNING]- Forbidden: /user/role/
[2020-06-28 16:35:55,038] [basehttp.py:157] [basehttp:log_message] [WARNING]- "GET /user/role/?username=admin&application=sys&type=menu HTTP/1.1" 403 24
[2020-06-28 16:35:55,042] [log.py:222] [log:log_response] [WARNING]- Forbidden: /user/role/
[2020-06-28 16:35:55,044] [basehttp.py:157] [basehttp:log_message] [WARNING]- "GET /user/role/?username=admin&application=sys&type=button HTTP/1.1" 403 24
[2020-06-28 16:35:59,975] [log.py:222] [log:log_response] [WARNING]- Forbidden: /user/role/
[2020-06-28 16:35:59,976] [basehttp.py:157] [basehttp:log_message] [WARNING]- "GET /user/role/?username=admin&application=sys&type=button HTTP/1.1" 403 24
[2020-06-28 16:35:59,982] [log.py:222] [log:log_response] [WARNING]- Forbidden: /user/role/
[2020-06-28 16:35:59,985] [basehttp.py:157] [basehttp:log_message] [WARNING]- "GET /user/role/?username=admin&application=sys&type=menu HTTP/1.1" 403 24
[2020-06-28 16:36:21,667] [log.py:222] [log:log_response] [WARNING]- Forbidden: /user/role/
[2020-06-28 16:36:21,668] [basehttp.py:157] [basehttp:log_message] [WARNING]- "GET /user/role/?username=admin&application=sys&type=menu HTTP/1.1" 403 24
[2020-06-28 16:36:21,679] [log.py:222] [log:log_response] [WARNING]- Forbidden: /user/role/
[2020-06-28 16:36:21,680] [basehttp.py:157] [basehttp:log_message] [WARNING]- "GET /user/role/?username=admin&application=sys&type=button HTTP/1.1" 403 24
[2020-06-28 16:36:57,500] [log.py:222] [log:log_response] [WARNING]- Forbidden: /user/role/
[2020-06-28 16:36:57,501] [basehttp.py:157] [basehttp:log_message] [WARNING]- "GET /user/role/?username=admin&application=sys&type=menu HTTP/1.1" 403 24
[2020-06-28 16:36:57,512] [log.py:222] [log:log_response] [WARNING]- Forbidden: /user/role/
[2020-06-28 16:36:57,512] [basehttp.py:157] [basehttp:log_message] [WARNING]- "GET /user/role/?username=admin&application=sys&type=button HTTP/1.1" 403 24
[2020-06-28 16:37:14,781] [log.py:222] [log:log_response] [WARNING]- Forbidden: /user/role/
[2020-06-28 16:37:14,781] [basehttp.py:157] [basehttp:log_message] [WARNING]- "GET /user/role/?username=admin&application=sys&type=menu HTTP/1.1" 403 24
[2020-06-28 16:37:14,805] [log.py:222] [log:log_response] [WARNING]- Forbidden: /user/role/
[2020-06-28 16:37:14,805] [basehttp.py:157] [basehttp:log_message] [WARNING]- "GET /user/role/?username=admin&application=sys&type=button HTTP/1.1" 403 24
[2020-06-28 16:37:28,034] [log.py:222] [log:log_response] [WARNING]- Forbidden: /user/role/
[2020-06-28 16:37:28,037] [log.py:222] [log:log_response] [WARNING]- Forbidden: /user/role/
[2020-06-28 16:37:28,038] [basehttp.py:157] [basehttp:log_message] [WARNING]- "GET /user/role/?username=admin&application=sys&type=button HTTP/1.1" 403 24
[2020-06-28 16:37:28,040] [basehttp.py:157] [basehttp:log_message] [WARNING]- "GET /user/role/?username=admin&application=sys&type=menu HTTP/1.1" 403 24
[2020-06-28 17:11:51,951] [basehttp.py:157] [basehttp:log_message] [INFO]- "OPTIONS /auth/ HTTP/1.1" 200 0
[2020-06-28 17:11:52,397] [log.py:222] [log:log_response] [ERROR]- Internal Server Error: /auth/
Traceback (most recent call last):
  File "/home/rock/quality_inspection/python-workspace/project-sys/sys_auth/views.py", line 95, in post
    raise exceptions.AuthenticationFailed('未查询到用户信息！')
rest_framework.exceptions.AuthenticationFailed: 未查询到用户信息！

During handling of the above exception, another exception occurred:

Traceback (most recent call last):
  File "/home/rock/anaconda3/envs/venv/lib/python3.8/site-packages/django/core/handlers/exception.py", line 34, in inner
    response = get_response(request)
  File "/home/rock/anaconda3/envs/venv/lib/python3.8/site-packages/django/core/handlers/base.py", line 115, in _get_response
    response = self.process_exception_by_middleware(e, request)
  File "/home/rock/anaconda3/envs/venv/lib/python3.8/site-packages/django/core/handlers/base.py", line 113, in _get_response
    response = wrapped_callback(request, *callback_args, **callback_kwargs)
  File "/home/rock/anaconda3/envs/venv/lib/python3.8/site-packages/django/views/decorators/csrf.py", line 54, in wrapped_view
    return view_func(*args, **kwargs)
  File "/home/rock/anaconda3/envs/venv/lib/python3.8/site-packages/django/views/generic/base.py", line 71, in view
    return self.dispatch(request, *args, **kwargs)
  File "/home/rock/anaconda3/envs/venv/lib/python3.8/site-packages/rest_framework/views.py", line 505, in dispatch
    response = self.handle_exception(exc)
  File "/home/rock/anaconda3/envs/venv/lib/python3.8/site-packages/rest_framework/views.py", line 465, in handle_exception
    self.raise_uncaught_exception(exc)
  File "/home/rock/anaconda3/envs/venv/lib/python3.8/site-packages/rest_framework/views.py", line 476, in raise_uncaught_exception
    raise exc
  File "/home/rock/anaconda3/envs/venv/lib/python3.8/site-packages/rest_framework/views.py", line 502, in dispatch
    response = handler(request, *args, **kwargs)
  File "/home/rock/quality_inspection/python-workspace/project-sys/sys_auth/views.py", line 105, in post
    except exceptions as e:
TypeError: catching classes that do not inherit from BaseException is not allowed
[2020-06-28 17:11:52,399] [basehttp.py:157] [basehttp:log_message] [ERROR]- "POST /auth/ HTTP/1.1" 500 19109
[2020-06-28 17:14:49,707] [log.py:222] [log:log_response] [ERROR]- Internal Server Error: /auth/
Traceback (most recent call last):
  File "/home/rock/quality_inspection/python-workspace/project-sys/sys_auth/views.py", line 95, in post
    raise exceptions.AuthenticationFailed('未查询到用户信息！')
rest_framework.exceptions.AuthenticationFailed: 未查询到用户信息！

During handling of the above exception, another exception occurred:

Traceback (most recent call last):
  File "/home/rock/anaconda3/envs/venv/lib/python3.8/site-packages/django/core/handlers/exception.py", line 34, in inner
    response = get_response(request)
  File "/home/rock/anaconda3/envs/venv/lib/python3.8/site-packages/django/core/handlers/base.py", line 115, in _get_response
    response = self.process_exception_by_middleware(e, request)
  File "/home/rock/anaconda3/envs/venv/lib/python3.8/site-packages/django/core/handlers/base.py", line 113, in _get_response
    response = wrapped_callback(request, *callback_args, **callback_kwargs)
  File "/home/rock/anaconda3/envs/venv/lib/python3.8/site-packages/django/views/decorators/csrf.py", line 54, in wrapped_view
    return view_func(*args, **kwargs)
  File "/home/rock/anaconda3/envs/venv/lib/python3.8/site-packages/django/views/generic/base.py", line 71, in view
    return self.dispatch(request, *args, **kwargs)
  File "/home/rock/anaconda3/envs/venv/lib/python3.8/site-packages/rest_framework/views.py", line 505, in dispatch
    response = self.handle_exception(exc)
  File "/home/rock/anaconda3/envs/venv/lib/python3.8/site-packages/rest_framework/views.py", line 465, in handle_exception
    self.raise_uncaught_exception(exc)
  File "/home/rock/anaconda3/envs/venv/lib/python3.8/site-packages/rest_framework/views.py", line 476, in raise_uncaught_exception
    raise exc
  File "/home/rock/anaconda3/envs/venv/lib/python3.8/site-packages/rest_framework/views.py", line 502, in dispatch
    response = handler(request, *args, **kwargs)
  File "/home/rock/quality_inspection/python-workspace/project-sys/sys_auth/views.py", line 105, in post
    except exceptions as e:
TypeError: catching classes that do not inherit from BaseException is not allowed
[2020-06-28 17:14:49,708] [basehttp.py:157] [basehttp:log_message] [ERROR]- "POST /auth/ HTTP/1.1" 500 19112
[2020-06-28 17:14:54,504] [basehttp.py:157] [basehttp:log_message] [INFO]- "POST /auth/ HTTP/1.1" 200 65
[2020-06-28 17:15:00,164] [basehttp.py:157] [basehttp:log_message] [INFO]- "POST /auth/ HTTP/1.1" 200 65
[2020-06-28 17:15:10,662] [basehttp.py:157] [basehttp:log_message] [INFO]- "POST /auth/ HTTP/1.1" 200 65
[2020-06-28 17:15:39,746] [basehttp.py:157] [basehttp:log_message] [INFO]- "POST /auth/ HTTP/1.1" 200 65
[2020-06-28 17:18:16,536] [basehttp.py:157] [basehttp:log_message] [INFO]- "POST /auth/ HTTP/1.1" 200 65
[2020-06-28 17:18:19,169] [basehttp.py:157] [basehttp:log_message] [INFO]- "GET /user/role/?username=admin&application=sys&type=button HTTP/1.1" 200 291
[2020-06-28 17:18:19,201] [basehttp.py:157] [basehttp:log_message] [INFO]- "GET /user/role/?username=admin&application=sys&type=menu HTTP/1.1" 200 1161
[2020-06-28 17:20:08,009] [basehttp.py:157] [basehttp:log_message] [INFO]- "GET /user/role/?username=admin&application=sys&type=button HTTP/1.1" 200 291
[2020-06-28 17:20:08,010] [basehttp.py:157] [basehttp:log_message] [INFO]- "GET /user/role/?username=admin&application=sys&type=menu HTTP/1.1" 200 1161
[2020-06-28 17:20:11,768] [basehttp.py:157] [basehttp:log_message] [INFO]- "GET /user/role/?username=admin&application=sys&type=button HTTP/1.1" 200 291
[2020-06-28 17:20:11,771] [basehttp.py:157] [basehttp:log_message] [INFO]- "GET /user/role/?username=admin&application=sys&type=menu HTTP/1.1" 200 1161
[2020-06-28 17:20:14,577] [basehttp.py:157] [basehttp:log_message] [INFO]- "GET /user/role/?username=admin&application=sys&type=menu HTTP/1.1" 200 1161
[2020-06-28 17:20:14,578] [basehttp.py:157] [basehttp:log_message] [INFO]- "GET /user/role/?username=admin&application=sys&type=button HTTP/1.1" 200 291
[2020-06-28 17:20:17,522] [log.py:222] [log:log_response] [WARNING]- Forbidden: /user/role/
[2020-06-28 17:20:17,523] [basehttp.py:157] [basehttp:log_message] [WARNING]- "GET /user/role/?username=admin&application=sys&type=menu HTTP/1.1" 403 24
[2020-06-28 17:20:17,524] [log.py:222] [log:log_response] [WARNING]- Forbidden: /user/role/
[2020-06-28 17:20:17,525] [basehttp.py:157] [basehttp:log_message] [WARNING]- "GET /user/role/?username=admin&application=sys&type=button HTTP/1.1" 403 24
[2020-06-28 17:21:15,573] [log.py:222] [log:log_response] [WARNING]- Forbidden: /user/role/
[2020-06-28 17:21:15,576] [basehttp.py:157] [basehttp:log_message] [WARNING]- "GET /user/role/?username=admin&application=sys&type=menu HTTP/1.1" 403 24
[2020-06-28 17:21:15,585] [log.py:222] [log:log_response] [WARNING]- Forbidden: /user/role/
[2020-06-28 17:21:15,586] [basehttp.py:157] [basehttp:log_message] [WARNING]- "GET /user/role/?username=admin&application=sys&type=button HTTP/1.1" 403 24
[2020-06-28 17:22:05,238] [log.py:222] [log:log_response] [WARNING]- Forbidden: /user/role/
[2020-06-28 17:22:05,241] [basehttp.py:157] [basehttp:log_message] [WARNING]- "GET /user/role/?username=admin&application=sys&type=menu HTTP/1.1" 403 24
[2020-06-28 17:22:07,668] [log.py:222] [log:log_response] [WARNING]- Forbidden: /user/role/
[2020-06-28 17:22:07,668] [basehttp.py:157] [basehttp:log_message] [WARNING]- "GET /user/role/?username=admin&application=sys&type=menu HTTP/1.1" 403 24
[2020-06-28 17:22:15,946] [log.py:222] [log:log_response] [WARNING]- Forbidden: /user/role/
[2020-06-28 17:22:15,947] [basehttp.py:157] [basehttp:log_message] [WARNING]- "GET /user/role/?username=admin&application=sys&type=menu HTTP/1.1" 403 24
[2020-06-28 17:23:14,422] [log.py:222] [log:log_response] [WARNING]- Forbidden: /user/role/
[2020-06-28 17:23:14,423] [basehttp.py:157] [basehttp:log_message] [WARNING]- "GET /user/role/?username=admin&application=sys&type=menu HTTP/1.1" 403 24
[2020-06-28 17:24:03,701] [log.py:222] [log:log_response] [WARNING]- Forbidden: /user/role/
[2020-06-28 17:24:03,702] [basehttp.py:157] [basehttp:log_message] [WARNING]- "GET /user/role/?username=admin&application=sys&type=menu HTTP/1.1" 403 24
[2020-06-28 17:24:08,096] [log.py:222] [log:log_response] [WARNING]- Forbidden: /user/role/
[2020-06-28 17:24:08,097] [basehttp.py:157] [basehttp:log_message] [WARNING]- "GET /user/role/?username=admin&application=sys&type=menu HTTP/1.1" 403 24
[2020-06-28 17:25:05,072] [log.py:222] [log:log_response] [WARNING]- Forbidden: /user/role/
[2020-06-28 17:25:05,073] [basehttp.py:157] [basehttp:log_message] [WARNING]- "GET /user/role/?username=admin&application=sys&type=menu HTTP/1.1" 403 24
[2020-06-28 17:25:42,191] [log.py:222] [log:log_response] [WARNING]- Forbidden: /user/role/
[2020-06-28 17:25:42,191] [basehttp.py:157] [basehttp:log_message] [WARNING]- "GET /user/role/?username=admin&application=sys&type=menu HTTP/1.1" 403 24
[2020-06-28 17:26:50,349] [log.py:222] [log:log_response] [WARNING]- Forbidden: /user/role/
[2020-06-28 17:26:50,350] [basehttp.py:157] [basehttp:log_message] [WARNING]- "GET /user/role/?username=admin&application=sys&type=menu HTTP/1.1" 403 24
[2020-06-28 17:27:19,628] [log.py:222] [log:log_response] [WARNING]- Forbidden: /user/role/
[2020-06-28 17:27:20,806] [log.py:222] [log:log_response] [WARNING]- Forbidden: /user/role/
[2020-06-28 17:27:20,807] [basehttp.py:157] [basehttp:log_message] [WARNING]- "GET /user/role/?username=admin&application=sys&type=menu HTTP/1.1" 403 24
[2020-06-28 17:27:27,621] [log.py:222] [log:log_response] [WARNING]- Forbidden: /user/role/
[2020-06-28 17:27:27,621] [basehttp.py:157] [basehttp:log_message] [WARNING]- "GET /user/role/?username=admin&application=sys&type=menu HTTP/1.1" 403 24
[2020-06-28 17:27:33,725] [log.py:222] [log:log_response] [WARNING]- Forbidden: /user/role/
[2020-06-28 17:27:33,726] [basehttp.py:157] [basehttp:log_message] [WARNING]- "GET /user/role/?username=admin&application=sys&type=menu HTTP/1.1" 403 24
[2020-06-28 17:27:49,798] [log.py:222] [log:log_response] [WARNING]- Forbidden: /user/role/
[2020-06-28 17:27:49,830] [basehttp.py:157] [basehttp:log_message] [WARNING]- "GET /user/role/?username=admin&application=sys&type=menu HTTP/1.1" 403 24
[2020-06-28 17:27:56,977] [log.py:222] [log:log_response] [WARNING]- Forbidden: /user/role/
[2020-06-28 17:27:56,977] [basehttp.py:157] [basehttp:log_message] [WARNING]- "GET /user/role/?username=admin&application=sys&type=menu HTTP/1.1" 403 24
[2020-06-28 17:28:27,264] [log.py:222] [log:log_response] [WARNING]- Forbidden: /user/role/
[2020-06-28 17:28:27,266] [basehttp.py:157] [basehttp:log_message] [WARNING]- "GET /user/role/?username=admin&application=sys&type=menu HTTP/1.1" 403 24
[2020-06-28 17:28:28,891] [log.py:222] [log:log_response] [WARNING]- Forbidden: /user/role/
[2020-06-28 17:28:28,893] [basehttp.py:157] [basehttp:log_message] [WARNING]- "GET /user/role/?username=admin&application=sys&type=menu HTTP/1.1" 403 24
[2020-06-28 17:29:59,614] [log.py:222] [log:log_response] [WARNING]- Forbidden: /user/role/
[2020-06-28 17:29:59,617] [basehttp.py:157] [basehttp:log_message] [WARNING]- "GET /user/role/?username=admin&application=sys&type=menu HTTP/1.1" 403 24
[2020-06-28 17:30:05,485] [log.py:222] [log:log_response] [WARNING]- Forbidden: /user/role/
[2020-06-28 17:30:05,485] [basehttp.py:157] [basehttp:log_message] [WARNING]- "GET /user/role/?username=admin&application=sys&type=menu HTTP/1.1" 403 24
[2020-06-28 17:30:10,569] [log.py:222] [log:log_response] [WARNING]- Forbidden: /user/role/
[2020-06-28 17:30:10,569] [basehttp.py:157] [basehttp:log_message] [WARNING]- "GET /user/role/?username=admin&application=sys&type=menu HTTP/1.1" 403 24
[2020-06-28 17:31:18,837] [log.py:222] [log:log_response] [WARNING]- Forbidden: /user/role/
[2020-06-28 17:31:18,839] [basehttp.py:157] [basehttp:log_message] [WARNING]- "GET /user/role/?username=admin&application=sys&type=menu HTTP/1.1" 403 24
[2020-06-28 17:31:46,570] [log.py:222] [log:log_response] [WARNING]- Forbidden: /user/role/
[2020-06-28 17:31:46,571] [basehttp.py:157] [basehttp:log_message] [WARNING]- "GET /user/role/?username=admin&application=sys&type=menu HTTP/1.1" 403 24
[2020-06-28 17:32:52,233] [log.py:222] [log:log_response] [WARNING]- Forbidden: /user/role/
[2020-06-28 17:32:52,235] [basehttp.py:157] [basehttp:log_message] [WARNING]- "GET /user/role/?username=admin&application=sys&type=menu HTTP/1.1" 403 24
[2020-06-28 17:32:54,118] [log.py:222] [log:log_response] [WARNING]- Forbidden: /user/role/
[2020-06-28 17:32:54,118] [basehttp.py:157] [basehttp:log_message] [WARNING]- "GET /user/role/?username=admin&application=sys&type=menu HTTP/1.1" 403 24
[2020-06-28 17:33:03,070] [log.py:222] [log:log_response] [WARNING]- Forbidden: /user/role/
[2020-06-28 17:33:03,070] [basehttp.py:157] [basehttp:log_message] [WARNING]- "GET /user/role/?username=admin&application=sys&type=menu HTTP/1.1" 403 24
[2020-06-28 17:33:17,929] [log.py:222] [log:log_response] [WARNING]- Forbidden: /user/role/
[2020-06-28 17:33:17,930] [basehttp.py:157] [basehttp:log_message] [WARNING]- "GET /user/role/?username=admin&application=sys&type=menu HTTP/1.1" 403 24
[2020-06-28 17:33:21,105] [log.py:222] [log:log_response] [WARNING]- Forbidden: /user/role/
[2020-06-28 17:33:21,105] [basehttp.py:157] [basehttp:log_message] [WARNING]- "GET /user/role/?username=admin&application=sys&type=menu HTTP/1.1" 403 24
[2020-06-28 21:23:48,225] [log.py:222] [log:log_response] [WARNING]- Forbidden: /user/role/
[2020-06-28 21:23:48,225] [basehttp.py:157] [basehttp:log_message] [WARNING]- "GET /user/role/?username=admin&application=sys&type=menu HTTP/1.1" 403 24
[2020-06-28 21:23:52,469] [log.py:222] [log:log_response] [WARNING]- Forbidden: /user/role/
[2020-06-28 21:23:52,470] [basehttp.py:157] [basehttp:log_message] [WARNING]- "GET /user/role/?username=admin&application=sys&type=menu HTTP/1.1" 403 24
[2020-06-28 21:24:33,990] [log.py:222] [log:log_response] [WARNING]- Forbidden: /user/role/
[2020-06-28 21:24:33,990] [basehttp.py:157] [basehttp:log_message] [WARNING]- "GET /user/role/?username=admin&application=sys&type=menu HTTP/1.1" 403 24
[2020-06-28 21:24:37,831] [log.py:222] [log:log_response] [WARNING]- Forbidden: /user/role/
[2020-06-28 21:24:37,832] [basehttp.py:157] [basehttp:log_message] [WARNING]- "GET /user/role/?username=admin&application=sys&type=menu HTTP/1.1" 403 24
[2020-06-28 21:24:49,805] [log.py:222] [log:log_response] [WARNING]- Forbidden: /user/role/
[2020-06-28 21:24:49,807] [basehttp.py:157] [basehttp:log_message] [WARNING]- "GET /user/role/?username=admin&application=sys&type=menu HTTP/1.1" 403 24
[2020-06-28 21:25:31,736] [log.py:222] [log:log_response] [WARNING]- Forbidden: /user/role/
[2020-06-28 21:25:31,738] [basehttp.py:157] [basehttp:log_message] [WARNING]- "GET /user/role/?username=admin&application=sys&type=menu HTTP/1.1" 403 24
[2020-06-28 21:28:17,183] [log.py:222] [log:log_response] [WARNING]- Forbidden: /user/role/
[2020-06-28 21:28:17,192] [basehttp.py:157] [basehttp:log_message] [WARNING]- "GET /user/role/?username=admin&application=sys&type=menu HTTP/1.1" 403 24
[2020-06-28 21:28:21,677] [log.py:222] [log:log_response] [WARNING]- Forbidden: /user/role/
[2020-06-28 21:28:21,678] [basehttp.py:157] [basehttp:log_message] [WARNING]- "GET /user/role/?username=admin&application=sys&type=menu HTTP/1.1" 403 24
[2020-06-28 21:28:59,421] [log.py:222] [log:log_response] [WARNING]- Forbidden: /user/role/
[2020-06-28 21:28:59,422] [basehttp.py:157] [basehttp:log_message] [WARNING]- "GET /user/role/?username=admin&application=sys&type=menu HTTP/1.1" 403 24
[2020-06-28 21:30:43,372] [log.py:222] [log:log_response] [WARNING]- Forbidden: /user/role/
[2020-06-28 21:30:43,373] [basehttp.py:157] [basehttp:log_message] [WARNING]- "GET /user/role/?username=admin&application=sys&type=menu HTTP/1.1" 403 24
[2020-06-28 21:30:52,509] [log.py:222] [log:log_response] [WARNING]- Forbidden: /user/role/
[2020-06-28 21:30:52,510] [basehttp.py:157] [basehttp:log_message] [WARNING]- "GET /user/role/?username=admin&application=sys&type=menu HTTP/1.1" 403 24
[2020-06-28 21:31:28,379] [log.py:222] [log:log_response] [WARNING]- Forbidden: /user/role/
[2020-06-28 21:31:28,381] [basehttp.py:157] [basehttp:log_message] [WARNING]- "GET /user/role/?username=admin&application=sys&type=menu HTTP/1.1" 403 24
[2020-06-28 21:31:30,924] [log.py:222] [log:log_response] [WARNING]- Forbidden: /user/role/
[2020-06-28 21:31:30,925] [basehttp.py:157] [basehttp:log_message] [WARNING]- "GET /user/role/?username=admin&application=sys&type=menu HTTP/1.1" 403 24
[2020-06-28 21:31:40,424] [log.py:222] [log:log_response] [WARNING]- Forbidden: /user/role/
[2020-06-28 21:31:40,426] [basehttp.py:157] [basehttp:log_message] [WARNING]- "GET /user/role/?username=admin&application=sys&type=menu HTTP/1.1" 403 24
[2020-06-28 21:31:44,432] [log.py:222] [log:log_response] [WARNING]- Forbidden: /user/role/
[2020-06-28 21:31:44,432] [basehttp.py:157] [basehttp:log_message] [WARNING]- "GET /user/role/?username=admin&application=sys&type=menu HTTP/1.1" 403 24
[2020-06-28 21:32:07,495] [log.py:222] [log:log_response] [WARNING]- Forbidden: /user/role/
[2020-06-28 21:32:07,496] [basehttp.py:157] [basehttp:log_message] [WARNING]- "GET /user/role/?username=admin&application=sys&type=menu HTTP/1.1" 403 24
[2020-06-28 21:32:07,510] [log.py:222] [log:log_response] [WARNING]- Forbidden: /user/role/
[2020-06-28 21:32:07,511] [basehttp.py:157] [basehttp:log_message] [WARNING]- "GET /user/role/?username=admin&application=sys&type=button HTTP/1.1" 403 24
[2020-06-28 21:32:14,015] [log.py:222] [log:log_response] [WARNING]- Forbidden: /user/role/
[2020-06-28 21:32:14,015] [basehttp.py:157] [basehttp:log_message] [WARNING]- "GET /user/role/?username=admin&application=sys&type=menu HTTP/1.1" 403 24
[2020-06-28 21:32:14,023] [log.py:222] [log:log_response] [WARNING]- Forbidden: /user/role/
[2020-06-28 21:32:14,023] [basehttp.py:157] [basehttp:log_message] [WARNING]- "GET /user/role/?username=admin&application=sys&type=button HTTP/1.1" 403 24
[2020-06-28 21:34:28,426] [log.py:222] [log:log_response] [WARNING]- Forbidden: /user/role/
[2020-06-28 21:34:28,426] [basehttp.py:157] [basehttp:log_message] [WARNING]- "GET /user/role/?username=admin&application=sys&type=menu HTTP/1.1" 403 24
[2020-06-28 21:34:28,432] [log.py:222] [log:log_response] [WARNING]- Forbidden: /user/role/
[2020-06-28 21:34:28,433] [basehttp.py:157] [basehttp:log_message] [WARNING]- "GET /user/role/?username=admin&application=sys&type=button HTTP/1.1" 403 24
[2020-06-28 21:34:33,403] [log.py:222] [log:log_response] [WARNING]- Forbidden: /user/role/
[2020-06-28 21:34:33,405] [log.py:222] [log:log_response] [WARNING]- Forbidden: /user/role/
[2020-06-28 21:34:33,406] [basehttp.py:157] [basehttp:log_message] [WARNING]- "GET /user/role/?username=admin&application=sys&type=menu HTTP/1.1" 403 24
[2020-06-28 21:34:33,409] [basehttp.py:157] [basehttp:log_message] [WARNING]- "GET /user/role/?username=admin&application=sys&type=button HTTP/1.1" 403 24
[2020-06-28 21:38:54,588] [log.py:222] [log:log_response] [WARNING]- Forbidden: /user/role/
[2020-06-28 21:38:54,591] [basehttp.py:157] [basehttp:log_message] [WARNING]- "GET /user/role/?username=admin&application=sys&type=button HTTP/1.1" 403 24
[2020-06-28 21:38:54,615] [log.py:222] [log:log_response] [WARNING]- Forbidden: /user/role/
[2020-06-28 21:38:54,621] [basehttp.py:157] [basehttp:log_message] [WARNING]- "GET /user/role/?username=admin&application=sys&type=menu HTTP/1.1" 403 24
[2020-06-28 21:38:54,769] [log.py:222] [log:log_response] [WARNING]- Forbidden: /user/role/
[2020-06-28 21:38:54,771] [basehttp.py:157] [basehttp:log_message] [WARNING]- "GET /user/role/?username=admin&application=sys&type=button HTTP/1.1" 403 24
[2020-06-28 21:38:54,792] [log.py:222] [log:log_response] [WARNING]- Forbidden: /user/role/
[2020-06-28 21:38:54,794] [basehttp.py:157] [basehttp:log_message] [WARNING]- "GET /user/role/?username=admin&application=sys&type=menu HTTP/1.1" 403 24
[2020-06-28 21:39:04,558] [log.py:222] [log:log_response] [WARNING]- Forbidden: /user/role/
[2020-06-28 21:39:04,558] [basehttp.py:157] [basehttp:log_message] [WARNING]- "GET /user/role/?username=admin&application=sys&type=menu HTTP/1.1" 403 24
[2020-06-28 21:39:04,563] [log.py:222] [log:log_response] [WARNING]- Forbidden: /user/role/
[2020-06-28 21:39:04,564] [basehttp.py:157] [basehttp:log_message] [WARNING]- "GET /user/role/?username=admin&application=sys&type=button HTTP/1.1" 403 24
[2020-06-28 21:39:27,282] [log.py:222] [log:log_response] [WARNING]- Forbidden: /user/role/
[2020-06-28 21:39:27,289] [log.py:222] [log:log_response] [WARNING]- Forbidden: /user/role/
[2020-06-28 21:39:27,293] [basehttp.py:157] [basehttp:log_message] [WARNING]- "GET /user/role/?username=admin&application=sys&type=menu HTTP/1.1" 403 24
[2020-06-28 21:39:30,557] [log.py:222] [log:log_response] [WARNING]- Forbidden: /user/role/
[2020-06-28 21:39:30,558] [log.py:222] [log:log_response] [WARNING]- Forbidden: /user/role/
[2020-06-28 21:39:30,559] [basehttp.py:157] [basehttp:log_message] [WARNING]- "GET /user/role/?username=admin&application=sys&type=menu HTTP/1.1" 403 24
[2020-06-28 21:39:30,560] [basehttp.py:157] [basehttp:log_message] [WARNING]- "GET /user/role/?username=admin&application=sys&type=button HTTP/1.1" 403 24
[2020-06-28 21:39:42,765] [log.py:222] [log:log_response] [WARNING]- Forbidden: /user/role/
[2020-06-28 21:39:42,767] [basehttp.py:157] [basehttp:log_message] [WARNING]- "GET /user/role/?username=admin&application=sys&type=menu HTTP/1.1" 403 24
[2020-06-28 21:39:42,794] [log.py:222] [log:log_response] [WARNING]- Forbidden: /user/role/
[2020-06-28 21:39:42,797] [basehttp.py:157] [basehttp:log_message] [WARNING]- "GET /user/role/?username=admin&application=sys&type=button HTTP/1.1" 403 24
[2020-06-28 21:39:46,248] [log.py:222] [log:log_response] [WARNING]- Forbidden: /user/role/
[2020-06-28 21:39:46,249] [basehttp.py:157] [basehttp:log_message] [WARNING]- "GET /user/role/?username=admin&application=sys&type=menu HTTP/1.1" 403 24
[2020-06-28 21:39:46,260] [log.py:222] [log:log_response] [WARNING]- Forbidden: /user/role/
[2020-06-28 21:39:46,261] [basehttp.py:157] [basehttp:log_message] [WARNING]- "GET /user/role/?username=admin&application=sys&type=button HTTP/1.1" 403 24
[2020-06-28 21:39:51,671] [log.py:222] [log:log_response] [WARNING]- Forbidden: /user/role/
[2020-06-28 21:39:51,673] [log.py:222] [log:log_response] [WARNING]- Forbidden: /user/role/
[2020-06-28 21:39:51,675] [basehttp.py:157] [basehttp:log_message] [WARNING]- "GET /user/role/?username=admin&application=sys&type=menu HTTP/1.1" 403 24
[2020-06-28 21:39:51,675] [basehttp.py:157] [basehttp:log_message] [WARNING]- "GET /user/role/?username=admin&application=sys&type=button HTTP/1.1" 403 24
[2020-06-28 21:40:18,710] [log.py:222] [log:log_response] [WARNING]- Forbidden: /user/role/
[2020-06-28 21:40:18,713] [basehttp.py:157] [basehttp:log_message] [WARNING]- "GET /user/role/?username=admin&application=sys&type=menu HTTP/1.1" 403 24
[2020-06-28 21:40:18,725] [log.py:222] [log:log_response] [WARNING]- Forbidden: /user/role/
[2020-06-28 21:40:18,728] [basehttp.py:157] [basehttp:log_message] [WARNING]- "GET /user/role/?username=admin&application=sys&type=button HTTP/1.1" 403 24
[2020-06-28 21:40:51,733] [log.py:222] [log:log_response] [WARNING]- Forbidden: /user/role/
[2020-06-28 21:40:51,738] [log.py:222] [log:log_response] [WARNING]- Forbidden: /user/role/
[2020-06-28 21:40:51,741] [basehttp.py:157] [basehttp:log_message] [WARNING]- "GET /user/role/?username=admin&application=sys&type=button HTTP/1.1" 403 24
[2020-06-28 21:40:51,745] [basehttp.py:157] [basehttp:log_message] [WARNING]- "GET /user/role/?username=admin&application=sys&type=menu HTTP/1.1" 403 24
[2020-06-28 21:41:34,849] [log.py:222] [log:log_response] [WARNING]- Forbidden: /user/role/
[2020-06-28 21:41:34,850] [basehttp.py:157] [basehttp:log_message] [WARNING]- "GET /user/role/?username=admin&application=sys&type=button HTTP/1.1" 403 24
[2020-06-28 21:41:34,857] [log.py:222] [log:log_response] [WARNING]- Forbidden: /user/role/
[2020-06-28 21:41:34,858] [basehttp.py:157] [basehttp:log_message] [WARNING]- "GET /user/role/?username=admin&application=sys&type=menu HTTP/1.1" 403 24
[2020-06-28 21:41:40,368] [log.py:222] [log:log_response] [WARNING]- Forbidden: /user/role/
[2020-06-28 21:41:40,371] [log.py:222] [log:log_response] [WARNING]- Forbidden: /user/role/
[2020-06-28 21:41:40,375] [basehttp.py:157] [basehttp:log_message] [WARNING]- "GET /user/role/?username=admin&application=sys&type=menu HTTP/1.1" 403 24
[2020-06-28 21:41:40,379] [basehttp.py:157] [basehttp:log_message] [WARNING]- "GET /user/role/?username=admin&application=sys&type=button HTTP/1.1" 403 24
[2020-06-28 21:44:33,504] [log.py:222] [log:log_response] [WARNING]- Forbidden: /user/role/
[2020-06-28 21:44:33,507] [log.py:222] [log:log_response] [WARNING]- Forbidden: /user/role/
[2020-06-28 21:44:33,510] [basehttp.py:157] [basehttp:log_message] [WARNING]- "GET /user/role/?username=admin&application=sys&type=menu HTTP/1.1" 403 24
[2020-06-28 21:44:33,510] [basehttp.py:157] [basehttp:log_message] [WARNING]- "GET /user/role/?username=admin&application=sys&type=button HTTP/1.1" 403 24
[2020-06-28 21:45:13,689] [basehttp.py:157] [basehttp:log_message] [INFO]- "OPTIONS /auth/ HTTP/1.1" 200 0
[2020-06-28 21:45:13,991] [basehttp.py:157] [basehttp:log_message] [INFO]- "POST /auth/ HTTP/1.1" 200 65
[2020-06-28 21:45:18,423] [basehttp.py:157] [basehttp:log_message] [INFO]- "GET /user/role/?username=admin&application=sys&type=button HTTP/1.1" 200 291
[2020-06-28 21:45:18,453] [basehttp.py:157] [basehttp:log_message] [INFO]- "GET /user/role/?username=admin&application=sys&type=menu HTTP/1.1" 200 1161
[2020-06-28 21:48:03,462] [log.py:222] [log:log_response] [WARNING]- Forbidden: /user/role/
[2020-06-28 21:48:03,470] [log.py:222] [log:log_response] [WARNING]- Forbidden: /user/role/
[2020-06-28 21:48:03,475] [basehttp.py:157] [basehttp:log_message] [WARNING]- "GET /user/role/?username=admin&application=sys&type=button HTTP/1.1" 403 24
[2020-06-28 21:48:03,476] [basehttp.py:157] [basehttp:log_message] [WARNING]- "GET /user/role/?username=admin&application=sys&type=menu HTTP/1.1" 403 24
[2020-06-28 21:48:55,761] [log.py:222] [log:log_response] [ERROR]- Internal Server Error: /auth/
Traceback (most recent call last):
  File "/home/rock/quality_inspection/python-workspace/project-sys/sys_auth/views.py", line 95, in post
    raise exceptions.AuthenticationFailed('未查询到用户信息！')
rest_framework.exceptions.AuthenticationFailed: 未查询到用户信息！

During handling of the above exception, another exception occurred:

Traceback (most recent call last):
  File "/home/rock/anaconda3/envs/venv/lib/python3.8/site-packages/django/core/handlers/exception.py", line 34, in inner
    response = get_response(request)
  File "/home/rock/anaconda3/envs/venv/lib/python3.8/site-packages/django/core/handlers/base.py", line 115, in _get_response
    response = self.process_exception_by_middleware(e, request)
  File "/home/rock/anaconda3/envs/venv/lib/python3.8/site-packages/django/core/handlers/base.py", line 113, in _get_response
    response = wrapped_callback(request, *callback_args, **callback_kwargs)
  File "/home/rock/anaconda3/envs/venv/lib/python3.8/site-packages/django/views/decorators/csrf.py", line 54, in wrapped_view
    return view_func(*args, **kwargs)
  File "/home/rock/anaconda3/envs/venv/lib/python3.8/site-packages/django/views/generic/base.py", line 71, in view
    return self.dispatch(request, *args, **kwargs)
  File "/home/rock/anaconda3/envs/venv/lib/python3.8/site-packages/rest_framework/views.py", line 505, in dispatch
    response = self.handle_exception(exc)
  File "/home/rock/anaconda3/envs/venv/lib/python3.8/site-packages/rest_framework/views.py", line 465, in handle_exception
    self.raise_uncaught_exception(exc)
  File "/home/rock/anaconda3/envs/venv/lib/python3.8/site-packages/rest_framework/views.py", line 476, in raise_uncaught_exception
    raise exc
  File "/home/rock/anaconda3/envs/venv/lib/python3.8/site-packages/rest_framework/views.py", line 502, in dispatch
    response = handler(request, *args, **kwargs)
  File "/home/rock/quality_inspection/python-workspace/project-sys/sys_auth/views.py", line 105, in post
    except exceptions as e:
TypeError: catching classes that do not inherit from BaseException is not allowed
[2020-06-28 21:48:55,762] [basehttp.py:157] [basehttp:log_message] [ERROR]- "POST /auth/ HTTP/1.1" 500 19113
[2020-06-28 21:49:00,876] [basehttp.py:157] [basehttp:log_message] [INFO]- "POST /auth/ HTTP/1.1" 200 65
[2020-06-28 21:49:19,376] [log.py:222] [log:log_response] [WARNING]- Forbidden: /user/role/
[2020-06-28 21:49:19,378] [log.py:222] [log:log_response] [WARNING]- Forbidden: /user/role/
[2020-06-28 21:49:19,379] [basehttp.py:157] [basehttp:log_message] [WARNING]- "GET /user/role/?username=admin&application=sys&type=button HTTP/1.1" 403 24
[2020-06-28 21:49:19,380] [basehttp.py:157] [basehttp:log_message] [WARNING]- "GET /user/role/?username=admin&application=sys&type=menu HTTP/1.1" 403 24
[2020-06-28 21:50:28,077] [basehttp.py:157] [basehttp:log_message] [INFO]- "POST /auth/ HTTP/1.1" 200 65
[2020-06-28 21:50:45,145] [log.py:222] [log:log_response] [WARNING]- Forbidden: /user/role/
[2020-06-28 21:50:45,150] [log.py:222] [log:log_response] [WARNING]- Forbidden: /user/role/
[2020-06-28 21:50:45,152] [basehttp.py:157] [basehttp:log_message] [WARNING]- "GET /user/role/?username=admin&application=sys&type=menu HTTP/1.1" 403 24
[2020-06-28 21:50:45,152] [basehttp.py:157] [basehttp:log_message] [WARNING]- "GET /user/role/?username=admin&application=sys&type=button HTTP/1.1" 403 24
[2020-06-28 21:56:45,206] [basehttp.py:157] [basehttp:log_message] [INFO]- "OPTIONS /auth/ HTTP/1.1" 200 0
[2020-06-28 21:56:45,412] [basehttp.py:157] [basehttp:log_message] [INFO]- "POST /auth/ HTTP/1.1" 200 65
[2020-06-28 21:57:00,099] [log.py:222] [log:log_response] [WARNING]- Forbidden: /user/role/
[2020-06-28 21:57:00,100] [basehttp.py:157] [basehttp:log_message] [WARNING]- "GET /user/role/?username=admin&application=sys&type=menu HTTP/1.1" 403 24
[2020-06-28 21:57:00,120] [log.py:222] [log:log_response] [WARNING]- Forbidden: /user/role/
[2020-06-28 21:57:00,122] [basehttp.py:157] [basehttp:log_message] [WARNING]- "GET /user/role/?username=admin&application=sys&type=button HTTP/1.1" 403 24
[2020-06-28 21:57:14,093] [basehttp.py:157] [basehttp:log_message] [INFO]- "POST /auth/ HTTP/1.1" 200 65
[2020-06-28 21:57:25,487] [basehttp.py:157] [basehttp:log_message] [INFO]- "GET /user/role/?username=admin&application=sys&type=menu HTTP/1.1" 200 1161
[2020-06-28 21:57:25,488] [basehttp.py:157] [basehttp:log_message] [INFO]- "GET /user/role/?username=admin&application=sys&type=button HTTP/1.1" 200 291
[2020-06-28 21:57:29,519] [basehttp.py:157] [basehttp:log_message] [INFO]- "GET /user/?current_page=1&pre_page=10 HTTP/1.1" 200 73634
[2020-06-28 21:57:41,755] [log.py:222] [log:log_response] [WARNING]- Forbidden: /user/
[2020-06-28 21:57:41,757] [log.py:222] [log:log_response] [WARNING]- Forbidden: /user/role/
[2020-06-28 21:57:41,757] [basehttp.py:157] [basehttp:log_message] [WARNING]- "GET /user/?current_page=1&pre_page=10 HTTP/1.1" 403 24
[2020-06-28 21:57:41,758] [basehttp.py:157] [basehttp:log_message] [WARNING]- "GET /user/role/?username=admin&application=sys&type=menu HTTP/1.1" 403 24
[2020-06-28 21:57:41,775] [log.py:222] [log:log_response] [WARNING]- Forbidden: /user/role/
[2020-06-28 21:57:41,776] [basehttp.py:157] [basehttp:log_message] [WARNING]- "GET /user/role/?username=admin&application=sys&type=button HTTP/1.1" 403 24
[2020-06-28 22:20:19,607] [basehttp.py:157] [basehttp:log_message] [INFO]- "OPTIONS /auth/ HTTP/1.1" 200 0
[2020-06-28 22:20:19,809] [basehttp.py:157] [basehttp:log_message] [INFO]- "POST /auth/ HTTP/1.1" 200 65
[2020-06-28 22:20:22,024] [basehttp.py:157] [basehttp:log_message] [INFO]- "GET /user/role/?username=admin&application=sys&type=menu HTTP/1.1" 200 1161
[2020-06-28 22:20:22,025] [basehttp.py:157] [basehttp:log_message] [INFO]- "GET /user/role/?username=admin&application=sys&type=button HTTP/1.1" 200 291
[2020-06-28 22:20:23,665] [basehttp.py:157] [basehttp:log_message] [INFO]- "GET /user/?current_page=1&pre_page=10 HTTP/1.1" 200 73634
[2020-06-28 22:21:57,237] [log.py:222] [log:log_response] [WARNING]- Forbidden: /user/
[2020-06-28 22:21:57,246] [log.py:222] [log:log_response] [WARNING]- Forbidden: /user/role/
[2020-06-28 22:21:57,248] [log.py:222] [log:log_response] [WARNING]- Forbidden: /user/role/
[2020-06-28 22:21:57,250] [basehttp.py:157] [basehttp:log_message] [WARNING]- "GET /user/?current_page=1&pre_page=10 HTTP/1.1" 403 24
[2020-06-28 22:21:57,253] [basehttp.py:157] [basehttp:log_message] [WARNING]- "GET /user/role/?username=admin&application=sys&type=menu HTTP/1.1" 403 24
[2020-06-28 22:21:57,253] [basehttp.py:157] [basehttp:log_message] [WARNING]- "GET /user/role/?username=admin&application=sys&type=button HTTP/1.1" 403 24
[2020-06-28 22:34:50,473] [basehttp.py:157] [basehttp:log_message] [INFO]- "OPTIONS /auth/ HTTP/1.1" 200 0
[2020-06-28 22:34:50,880] [basehttp.py:157] [basehttp:log_message] [INFO]- "POST /auth/ HTTP/1.1" 200 65
[2020-06-28 22:35:07,927] [log.py:222] [log:log_response] [WARNING]- Forbidden: /user/role/
[2020-06-28 22:35:07,928] [basehttp.py:157] [basehttp:log_message] [WARNING]- "GET /user/role/?username=admin&application=sys&type=menu HTTP/1.1" 403 24
[2020-06-28 22:35:07,932] [log.py:222] [log:log_response] [WARNING]- Forbidden: /user/role/
[2020-06-28 22:35:07,933] [basehttp.py:157] [basehttp:log_message] [WARNING]- "GET /user/role/?username=admin&application=sys&type=button HTTP/1.1" 403 24
[2020-06-28 22:36:48,341] [basehttp.py:157] [basehttp:log_message] [INFO]- "POST /auth/ HTTP/1.1" 200 65
[2020-06-28 22:36:50,054] [basehttp.py:157] [basehttp:log_message] [INFO]- "GET /user/role/?username=admin&application=sys&type=button HTTP/1.1" 200 291
[2020-06-28 22:36:50,055] [basehttp.py:157] [basehttp:log_message] [INFO]- "GET /user/role/?username=admin&application=sys&type=menu HTTP/1.1" 200 1161
[2020-06-28 22:36:51,713] [basehttp.py:157] [basehttp:log_message] [INFO]- "GET /user/?current_page=1&pre_page=10 HTTP/1.1" 200 73634
[2020-06-28 22:37:05,343] [log.py:222] [log:log_response] [WARNING]- Forbidden: /user/
[2020-06-28 22:37:05,344] [basehttp.py:157] [basehttp:log_message] [WARNING]- "GET /user/?current_page=1&pre_page=10 HTTP/1.1" 403 24
[2020-06-28 22:37:05,376] [log.py:222] [log:log_response] [WARNING]- Forbidden: /user/role/
[2020-06-28 22:37:05,376] [basehttp.py:157] [basehttp:log_message] [WARNING]- "GET /user/role/?username=admin&application=sys&type=menu HTTP/1.1" 403 24
[2020-06-28 22:37:05,405] [log.py:222] [log:log_response] [WARNING]- Forbidden: /user/role/
[2020-06-28 22:37:05,405] [basehttp.py:157] [basehttp:log_message] [WARNING]- "GET /user/role/?username=admin&application=sys&type=button HTTP/1.1" 403 24
[2020-06-28 22:37:39,165] [basehttp.py:157] [basehttp:log_message] [INFO]- "POST /auth/ HTTP/1.1" 200 65
[2020-06-28 22:37:41,009] [basehttp.py:157] [basehttp:log_message] [INFO]- "GET /user/role/?username=admin&application=sys&type=button HTTP/1.1" 200 291
[2020-06-28 22:37:41,025] [basehttp.py:157] [basehttp:log_message] [INFO]- "GET /user/role/?username=admin&application=sys&type=menu HTTP/1.1" 200 1161
[2020-06-28 22:37:42,549] [basehttp.py:157] [basehttp:log_message] [INFO]- "GET /user/?current_page=1&pre_page=10 HTTP/1.1" 200 73634
[2020-06-28 22:37:51,089] [basehttp.py:157] [basehttp:log_message] [INFO]- "GET /role/ HTTP/1.1" 200 30110
[2020-06-28 22:37:51,465] [basehttp.py:157] [basehttp:log_message] [INFO]- "GET /role/ HTTP/1.1" 200 30110
[2020-06-28 22:37:55,836] [basehttp.py:157] [basehttp:log_message] [INFO]- "GET /user/role/?username=admin&application=sys&type=menu HTTP/1.1" 200 1161
[2020-06-28 22:37:55,841] [basehttp.py:157] [basehttp:log_message] [INFO]- "GET /user/role/?username=admin&application=sys&type=button HTTP/1.1" 200 291
[2020-06-28 22:37:56,138] [basehttp.py:157] [basehttp:log_message] [INFO]- "GET /user/?current_page=1&pre_page=10 HTTP/1.1" 200 73634
[2020-06-28 22:37:57,322] [basehttp.py:157] [basehttp:log_message] [INFO]- "GET /role/ HTTP/1.1" 200 30110
[2020-06-28 22:38:01,028] [basehttp.py:157] [basehttp:log_message] [INFO]- "GET /user/role/?username=admin&application=sys&type=menu HTTP/1.1" 200 1161
[2020-06-28 22:38:01,070] [basehttp.py:157] [basehttp:log_message] [INFO]- "GET /user/role/?username=admin&application=sys&type=button HTTP/1.1" 200 291
[2020-06-28 22:38:01,322] [basehttp.py:157] [basehttp:log_message] [INFO]- "GET /user/?current_page=1&pre_page=10 HTTP/1.1" 200 73634
[2020-06-28 22:38:03,451] [basehttp.py:157] [basehttp:log_message] [INFO]- "GET /role/ HTTP/1.1" 200 30110
[2020-06-28 22:38:06,612] [basehttp.py:157] [basehttp:log_message] [INFO]- "GET /role/ HTTP/1.1" 200 30110
[2020-06-28 22:38:09,945] [basehttp.py:157] [basehttp:log_message] [INFO]- "GET /role/ HTTP/1.1" 200 30110
[2020-06-28 22:38:13,608] [basehttp.py:157] [basehttp:log_message] [INFO]- "GET /role/ HTTP/1.1" 200 30110
[2020-06-28 22:38:28,370] [log.py:222] [log:log_response] [WARNING]- Forbidden: /role/
[2020-06-28 22:38:28,372] [basehttp.py:157] [basehttp:log_message] [WARNING]- "GET /role/ HTTP/1.1" 403 24
[2020-06-28 22:39:28,321] [log.py:222] [log:log_response] [WARNING]- Forbidden: /user/
[2020-06-28 22:39:28,321] [basehttp.py:157] [basehttp:log_message] [WARNING]- "GET /user/?current_page=1&pre_page=10 HTTP/1.1" 403 24
[2020-06-28 22:39:28,355] [log.py:222] [log:log_response] [WARNING]- Forbidden: /user/role/
[2020-06-28 22:39:28,355] [basehttp.py:157] [basehttp:log_message] [WARNING]- "GET /user/role/?username=admin&application=sys&type=menu HTTP/1.1" 403 24
[2020-06-28 22:39:28,363] [log.py:222] [log:log_response] [WARNING]- Forbidden: /user/role/
[2020-06-28 22:39:28,364] [basehttp.py:157] [basehttp:log_message] [WARNING]- "GET /user/role/?username=admin&application=sys&type=button HTTP/1.1" 403 24
[2020-06-28 22:39:38,709] [log.py:222] [log:log_response] [ERROR]- Internal Server Error: /auth/
Traceback (most recent call last):
  File "/home/rock/quality_inspection/python-workspace/project-sys/sys_auth/views.py", line 95, in post
    raise exceptions.AuthenticationFailed('未查询到用户信息！')
rest_framework.exceptions.AuthenticationFailed: 未查询到用户信息！

During handling of the above exception, another exception occurred:

Traceback (most recent call last):
  File "/home/rock/anaconda3/envs/venv/lib/python3.8/site-packages/django/core/handlers/exception.py", line 34, in inner
    response = get_response(request)
  File "/home/rock/anaconda3/envs/venv/lib/python3.8/site-packages/django/core/handlers/base.py", line 115, in _get_response
    response = self.process_exception_by_middleware(e, request)
  File "/home/rock/anaconda3/envs/venv/lib/python3.8/site-packages/django/core/handlers/base.py", line 113, in _get_response
    response = wrapped_callback(request, *callback_args, **callback_kwargs)
  File "/home/rock/anaconda3/envs/venv/lib/python3.8/site-packages/django/views/decorators/csrf.py", line 54, in wrapped_view
    return view_func(*args, **kwargs)
  File "/home/rock/anaconda3/envs/venv/lib/python3.8/site-packages/django/views/generic/base.py", line 71, in view
    return self.dispatch(request, *args, **kwargs)
  File "/home/rock/anaconda3/envs/venv/lib/python3.8/site-packages/rest_framework/views.py", line 505, in dispatch
    response = self.handle_exception(exc)
  File "/home/rock/anaconda3/envs/venv/lib/python3.8/site-packages/rest_framework/views.py", line 465, in handle_exception
    self.raise_uncaught_exception(exc)
  File "/home/rock/anaconda3/envs/venv/lib/python3.8/site-packages/rest_framework/views.py", line 476, in raise_uncaught_exception
    raise exc
  File "/home/rock/anaconda3/envs/venv/lib/python3.8/site-packages/rest_framework/views.py", line 502, in dispatch
    response = handler(request, *args, **kwargs)
  File "/home/rock/quality_inspection/python-workspace/project-sys/sys_auth/views.py", line 105, in post
    except exceptions as e:
TypeError: catching classes that do not inherit from BaseException is not allowed
[2020-06-28 22:39:38,710] [basehttp.py:157] [basehttp:log_message] [ERROR]- "POST /auth/ HTTP/1.1" 500 19112
[2020-06-28 22:39:45,133] [basehttp.py:157] [basehttp:log_message] [INFO]- "POST /auth/ HTTP/1.1" 200 65
[2020-06-28 22:39:46,786] [basehttp.py:157] [basehttp:log_message] [INFO]- "GET /user/role/?username=admin&application=sys&type=menu HTTP/1.1" 200 1161
[2020-06-28 22:39:46,789] [basehttp.py:157] [basehttp:log_message] [INFO]- "GET /user/role/?username=admin&application=sys&type=button HTTP/1.1" 200 291
[2020-06-28 22:39:48,657] [basehttp.py:157] [basehttp:log_message] [INFO]- "GET /user/?current_page=1&pre_page=10 HTTP/1.1" 200 73634
[2020-06-28 22:39:51,675] [basehttp.py:157] [basehttp:log_message] [INFO]- "GET /role/ HTTP/1.1" 200 30110
[2020-06-28 22:40:10,083] [log.py:222] [log:log_response] [WARNING]- Forbidden: /user/
[2020-06-28 22:40:10,084] [basehttp.py:157] [basehttp:log_message] [WARNING]- "GET /user/?current_page=1&pre_page=10 HTTP/1.1" 403 24
[2020-06-28 22:40:10,105] [log.py:222] [log:log_response] [WARNING]- Forbidden: /user/role/
[2020-06-28 22:40:10,106] [basehttp.py:157] [basehttp:log_message] [WARNING]- "GET /user/role/?username=admin&application=sys&type=menu HTTP/1.1" 403 24
[2020-06-28 22:40:10,113] [log.py:222] [log:log_response] [WARNING]- Forbidden: /user/role/
[2020-06-28 22:40:10,113] [basehttp.py:157] [basehttp:log_message] [WARNING]- "GET /user/role/?username=admin&application=sys&type=button HTTP/1.1" 403 24
[2020-06-28 22:40:25,301] [basehttp.py:157] [basehttp:log_message] [INFO]- "POST /auth/ HTTP/1.1" 200 65
[2020-06-28 22:40:27,425] [basehttp.py:157] [basehttp:log_message] [INFO]- "GET /user/role/?username=admin&application=sys&type=menu HTTP/1.1" 200 1161
[2020-06-28 22:40:27,428] [basehttp.py:157] [basehttp:log_message] [INFO]- "GET /user/role/?username=admin&application=sys&type=button HTTP/1.1" 200 291
[2020-06-28 22:40:43,496] [log.py:222] [log:log_response] [WARNING]- Forbidden: /user/
[2020-06-28 22:40:43,497] [basehttp.py:157] [basehttp:log_message] [WARNING]- "GET /user/?current_page=1&pre_page=10 HTTP/1.1" 403 24
[2020-06-28 22:41:28,991] [log.py:222] [log:log_response] [WARNING]- Forbidden: /user/
[2020-06-28 22:41:28,992] [basehttp.py:157] [basehttp:log_message] [WARNING]- "GET /user/?current_page=1&pre_page=10 HTTP/1.1" 403 24
[2020-06-28 22:41:29,032] [log.py:222] [log:log_response] [WARNING]- Forbidden: /user/role/
[2020-06-28 22:41:29,033] [basehttp.py:157] [basehttp:log_message] [WARNING]- "GET /user/role/?username=admin&application=sys&type=button HTTP/1.1" 403 24
[2020-06-28 22:41:29,035] [log.py:222] [log:log_response] [WARNING]- Forbidden: /user/role/
[2020-06-28 22:41:29,037] [basehttp.py:157] [basehttp:log_message] [WARNING]- "GET /user/role/?username=admin&application=sys&type=menu HTTP/1.1" 403 24
[2020-06-28 22:49:32,783] [basehttp.py:157] [basehttp:log_message] [INFO]- "OPTIONS /auth/ HTTP/1.1" 200 0
[2020-06-28 22:49:33,451] [basehttp.py:157] [basehttp:log_message] [INFO]- "POST /auth/ HTTP/1.1" 200 65
[2020-06-28 22:49:46,072] [log.py:222] [log:log_response] [WARNING]- Forbidden: /user/role/
[2020-06-28 22:49:46,075] [basehttp.py:157] [basehttp:log_message] [WARNING]- "GET /user/role/?username=admin&application=sys&type=menu HTTP/1.1" 403 24
[2020-06-28 22:49:46,103] [log.py:222] [log:log_response] [WARNING]- Forbidden: /user/role/
[2020-06-28 22:49:46,105] [basehttp.py:157] [basehttp:log_message] [WARNING]- "GET /user/role/?username=admin&application=sys&type=button HTTP/1.1" 403 24
[2020-06-28 22:53:08,888] [basehttp.py:157] [basehttp:log_message] [INFO]- "POST /auth/ HTTP/1.1" 200 65
[2020-06-28 22:53:22,586] [log.py:222] [log:log_response] [WARNING]- Forbidden: /user/role/
[2020-06-28 22:53:22,594] [log.py:222] [log:log_response] [WARNING]- Forbidden: /user/role/
[2020-06-28 22:53:22,598] [basehttp.py:157] [basehttp:log_message] [WARNING]- "GET /user/role/?username=admin&application=sys&type=menu HTTP/1.1" 403 24
[2020-06-28 22:53:22,599] [basehttp.py:157] [basehttp:log_message] [WARNING]- "GET /user/role/?username=admin&application=sys&type=button HTTP/1.1" 403 24
[2020-06-28 22:56:05,780] [basehttp.py:157] [basehttp:log_message] [INFO]- "POST /auth/ HTTP/1.1" 200 65
[2020-06-28 22:56:14,724] [basehttp.py:157] [basehttp:log_message] [INFO]- "GET /user/role/?username=admin&application=sys&type=button HTTP/1.1" 200 291
[2020-06-28 22:56:14,724] [basehttp.py:157] [basehttp:log_message] [INFO]- "GET /user/role/?username=admin&application=sys&type=menu HTTP/1.1" 200 1161
[2020-06-28 22:56:29,394] [log.py:222] [log:log_response] [WARNING]- Forbidden: /user/role/
[2020-06-28 22:56:29,398] [log.py:222] [log:log_response] [WARNING]- Forbidden: /user/role/
[2020-06-28 22:56:29,398] [basehttp.py:157] [basehttp:log_message] [WARNING]- "GET /user/role/?username=admin&application=sys&type=menu HTTP/1.1" 403 24
[2020-06-28 22:56:29,400] [basehttp.py:157] [basehttp:log_message] [WARNING]- "GET /user/role/?username=admin&application=sys&type=button HTTP/1.1" 403 24
[2020-06-28 22:57:59,296] [basehttp.py:157] [basehttp:log_message] [INFO]- "POST /auth/ HTTP/1.1" 200 65
[2020-06-28 22:58:03,531] [basehttp.py:157] [basehttp:log_message] [INFO]- "GET /user/role/?username=admin&application=sys&type=button HTTP/1.1" 200 291
[2020-06-28 22:58:03,548] [basehttp.py:157] [basehttp:log_message] [INFO]- "GET /user/role/?username=admin&application=sys&type=menu HTTP/1.1" 200 1161
[2020-06-28 22:58:14,522] [log.py:222] [log:log_response] [WARNING]- Forbidden: /user/role/
[2020-06-28 22:58:14,522] [basehttp.py:157] [basehttp:log_message] [WARNING]- "GET /user/role/?username=admin&application=sys&type=button HTTP/1.1" 403 24
[2020-06-28 22:58:14,525] [log.py:222] [log:log_response] [WARNING]- Forbidden: /user/role/
[2020-06-28 22:58:14,526] [basehttp.py:157] [basehttp:log_message] [WARNING]- "GET /user/role/?username=admin&application=sys&type=menu HTTP/1.1" 403 24
[2020-06-28 22:59:30,140] [basehttp.py:157] [basehttp:log_message] [INFO]- "POST /auth/ HTTP/1.1" 200 65
[2020-06-28 22:59:35,253] [basehttp.py:157] [basehttp:log_message] [INFO]- "GET /user/role/?username=admin&application=sys&type=menu HTTP/1.1" 200 1161
[2020-06-28 22:59:35,260] [basehttp.py:157] [basehttp:log_message] [INFO]- "GET /user/role/?username=admin&application=sys&type=button HTTP/1.1" 200 291
[2020-06-28 22:59:38,173] [basehttp.py:157] [basehttp:log_message] [INFO]- "GET /user/?current_page=1&pre_page=10 HTTP/1.1" 200 73634
[2020-06-28 22:59:52,647] [log.py:222] [log:log_response] [WARNING]- Forbidden: /user/
[2020-06-28 22:59:52,647] [basehttp.py:157] [basehttp:log_message] [WARNING]- "GET /user/?current_page=1&pre_page=10 HTTP/1.1" 403 24
[2020-06-28 22:59:52,651] [log.py:222] [log:log_response] [WARNING]- Forbidden: /user/role/
[2020-06-28 22:59:52,653] [basehttp.py:157] [basehttp:log_message] [WARNING]- "GET /user/role/?username=admin&application=sys&type=button HTTP/1.1" 403 24
[2020-06-28 22:59:52,682] [log.py:222] [log:log_response] [WARNING]- Forbidden: /user/role/
[2020-06-28 22:59:52,682] [basehttp.py:157] [basehttp:log_message] [WARNING]- "GET /user/role/?username=admin&application=sys&type=menu HTTP/1.1" 403 24
[2020-06-28 23:01:18,007] [basehttp.py:157] [basehttp:log_message] [INFO]- "OPTIONS /auth/ HTTP/1.1" 200 0
[2020-06-28 23:01:18,201] [basehttp.py:157] [basehttp:log_message] [INFO]- "POST /auth/ HTTP/1.1" 200 65
[2020-06-28 23:01:20,086] [basehttp.py:157] [basehttp:log_message] [INFO]- "GET /user/role/?username=admin&application=sys&type=menu HTTP/1.1" 200 1161
[2020-06-28 23:01:20,107] [basehttp.py:157] [basehttp:log_message] [INFO]- "GET /user/role/?username=admin&application=sys&type=button HTTP/1.1" 200 291
[2020-06-28 23:01:22,828] [basehttp.py:157] [basehttp:log_message] [INFO]- "GET /role/?current_page=1&pre_page=10 HTTP/1.1" 200 30181
[2020-06-28 23:01:34,568] [log.py:222] [log:log_response] [WARNING]- Forbidden: /user/
[2020-06-28 23:01:34,570] [basehttp.py:157] [basehttp:log_message] [WARNING]- "GET /user/?current_page=1&pre_page=10 HTTP/1.1" 403 24
[2020-06-28 23:02:50,280] [basehttp.py:157] [basehttp:log_message] [INFO]- "POST /auth/ HTTP/1.1" 200 65
[2020-06-28 23:02:51,981] [basehttp.py:157] [basehttp:log_message] [INFO]- "GET /user/role/?username=admin&application=sys&type=button HTTP/1.1" 200 291
[2020-06-28 23:02:52,016] [basehttp.py:157] [basehttp:log_message] [INFO]- "GET /user/role/?username=admin&application=sys&type=menu HTTP/1.1" 200 1161
[2020-06-28 23:02:53,832] [basehttp.py:157] [basehttp:log_message] [INFO]- "GET /user/?current_page=1&pre_page=10 HTTP/1.1" 200 73634
[2020-06-28 23:03:16,816] [log.py:222] [log:log_response] [WARNING]- Forbidden: /role/
[2020-06-28 23:03:16,819] [basehttp.py:157] [basehttp:log_message] [WARNING]- "GET /role/ HTTP/1.1" 403 24
[2020-06-28 23:06:14,172] [basehttp.py:157] [basehttp:log_message] [INFO]- "POST /auth/ HTTP/1.1" 200 65
[2020-06-28 23:06:16,507] [basehttp.py:157] [basehttp:log_message] [INFO]- "GET /user/role/?username=admin&application=sys&type=button HTTP/1.1" 200 291
[2020-06-28 23:06:16,511] [basehttp.py:157] [basehttp:log_message] [INFO]- "GET /user/role/?username=admin&application=sys&type=menu HTTP/1.1" 200 1161
[2020-06-28 23:06:17,861] [basehttp.py:157] [basehttp:log_message] [INFO]- "GET /role/?current_page=1&pre_page=10 HTTP/1.1" 200 30181
[2020-06-28 23:06:19,044] [basehttp.py:157] [basehttp:log_message] [INFO]- "GET /user/?current_page=1&pre_page=10 HTTP/1.1" 200 73634
[2020-06-28 23:06:35,117] [log.py:222] [log:log_response] [WARNING]- Forbidden: /role/
[2020-06-28 23:06:35,118] [basehttp.py:157] [basehttp:log_message] [WARNING]- "GET /role/ HTTP/1.1" 403 24
[2020-06-28 23:09:05,679] [basehttp.py:157] [basehttp:log_message] [INFO]- "POST /auth/ HTTP/1.1" 200 65
[2020-06-28 23:09:07,804] [basehttp.py:157] [basehttp:log_message] [INFO]- "GET /user/role/?username=admin&application=sys&type=button HTTP/1.1" 200 291
[2020-06-28 23:09:07,808] [basehttp.py:157] [basehttp:log_message] [INFO]- "GET /user/role/?username=admin&application=sys&type=menu HTTP/1.1" 200 1161
[2020-06-28 23:09:10,122] [basehttp.py:157] [basehttp:log_message] [INFO]- "GET /user/?current_page=1&pre_page=10 HTTP/1.1" 200 73634
[2020-06-28 23:09:22,402] [log.py:222] [log:log_response] [WARNING]- Forbidden: /role/
[2020-06-28 23:09:22,404] [basehttp.py:157] [basehttp:log_message] [WARNING]- "GET /role/ HTTP/1.1" 403 24
[2020-06-28 23:09:55,725] [basehttp.py:157] [basehttp:log_message] [INFO]- "POST /auth/ HTTP/1.1" 200 65
[2020-06-28 23:09:57,926] [basehttp.py:157] [basehttp:log_message] [INFO]- "GET /user/role/?username=admin&application=sys&type=button HTTP/1.1" 200 291
[2020-06-28 23:09:57,926] [basehttp.py:157] [basehttp:log_message] [INFO]- "GET /user/role/?username=admin&application=sys&type=menu HTTP/1.1" 200 1161
[2020-06-28 23:09:59,573] [basehttp.py:157] [basehttp:log_message] [INFO]- "GET /user/?current_page=1&pre_page=10 HTTP/1.1" 200 73634
[2020-06-28 23:10:22,425] [log.py:222] [log:log_response] [WARNING]- Forbidden: /role/
[2020-06-28 23:10:22,426] [basehttp.py:157] [basehttp:log_message] [WARNING]- "GET /role/ HTTP/1.1" 403 24
[2020-06-28 23:10:45,947] [log.py:222] [log:log_response] [ERROR]- Internal Server Error: /auth/
Traceback (most recent call last):
  File "/home/rock/quality_inspection/python-workspace/project-sys/sys_auth/views.py", line 95, in post
    raise exceptions.AuthenticationFailed('未查询到用户信息！')
rest_framework.exceptions.AuthenticationFailed: 未查询到用户信息！

During handling of the above exception, another exception occurred:

Traceback (most recent call last):
  File "/home/rock/anaconda3/envs/venv/lib/python3.8/site-packages/django/core/handlers/exception.py", line 34, in inner
    response = get_response(request)
  File "/home/rock/anaconda3/envs/venv/lib/python3.8/site-packages/django/core/handlers/base.py", line 115, in _get_response
    response = self.process_exception_by_middleware(e, request)
  File "/home/rock/anaconda3/envs/venv/lib/python3.8/site-packages/django/core/handlers/base.py", line 113, in _get_response
    response = wrapped_callback(request, *callback_args, **callback_kwargs)
  File "/home/rock/anaconda3/envs/venv/lib/python3.8/site-packages/django/views/decorators/csrf.py", line 54, in wrapped_view
    return view_func(*args, **kwargs)
  File "/home/rock/anaconda3/envs/venv/lib/python3.8/site-packages/django/views/generic/base.py", line 71, in view
    return self.dispatch(request, *args, **kwargs)
  File "/home/rock/anaconda3/envs/venv/lib/python3.8/site-packages/rest_framework/views.py", line 505, in dispatch
    response = self.handle_exception(exc)
  File "/home/rock/anaconda3/envs/venv/lib/python3.8/site-packages/rest_framework/views.py", line 465, in handle_exception
    self.raise_uncaught_exception(exc)
  File "/home/rock/anaconda3/envs/venv/lib/python3.8/site-packages/rest_framework/views.py", line 476, in raise_uncaught_exception
    raise exc
  File "/home/rock/anaconda3/envs/venv/lib/python3.8/site-packages/rest_framework/views.py", line 502, in dispatch
    response = handler(request, *args, **kwargs)
  File "/home/rock/quality_inspection/python-workspace/project-sys/sys_auth/views.py", line 105, in post
    except exceptions as e:
TypeError: catching classes that do not inherit from BaseException is not allowed
[2020-06-28 23:10:45,948] [basehttp.py:157] [basehttp:log_message] [ERROR]- "POST /auth/ HTTP/1.1" 500 19112
[2020-06-28 23:10:58,381] [basehttp.py:157] [basehttp:log_message] [INFO]- "POST /auth/ HTTP/1.1" 200 65
[2020-06-28 23:11:17,605] [basehttp.py:157] [basehttp:log_message] [INFO]- "GET /user/role/?username=admin&application=sys&type=menu HTTP/1.1" 200 1161
[2020-06-28 23:11:17,614] [basehttp.py:157] [basehttp:log_message] [INFO]- "GET /user/role/?username=admin&application=sys&type=button HTTP/1.1" 200 291
[2020-06-28 23:11:19,917] [basehttp.py:157] [basehttp:log_message] [INFO]- "GET /user/?current_page=1&pre_page=10 HTTP/1.1" 200 73634
[2020-06-28 23:11:57,987] [log.py:222] [log:log_response] [WARNING]- Forbidden: /user/delete/
[2020-06-28 23:11:57,989] [basehttp.py:157] [basehttp:log_message] [WARNING]- "PUT /user/delete/ HTTP/1.1" 403 24
[2020-06-28 23:13:11,515] [basehttp.py:157] [basehttp:log_message] [INFO]- "OPTIONS /auth/ HTTP/1.1" 200 0
[2020-06-28 23:13:11,717] [basehttp.py:157] [basehttp:log_message] [INFO]- "POST /auth/ HTTP/1.1" 200 65
[2020-06-28 23:13:15,051] [basehttp.py:157] [basehttp:log_message] [INFO]- "GET /user/role/?username=admin&application=sys&type=menu HTTP/1.1" 200 1161
[2020-06-28 23:13:15,079] [basehttp.py:157] [basehttp:log_message] [INFO]- "GET /user/role/?username=admin&application=sys&type=button HTTP/1.1" 200 291
[2020-06-28 23:13:17,398] [basehttp.py:157] [basehttp:log_message] [INFO]- "GET /user/?current_page=1&pre_page=10 HTTP/1.1" 200 73634
[2020-06-28 23:14:56,253] [log.py:222] [log:log_response] [WARNING]- Forbidden: /user/
[2020-06-28 23:14:56,254] [basehttp.py:157] [basehttp:log_message] [WARNING]- "GET /user/?current_page=1&pre_page=10 HTTP/1.1" 403 24
[2020-06-28 23:14:56,257] [log.py:222] [log:log_response] [WARNING]- Forbidden: /user/role/
[2020-06-28 23:14:56,259] [log.py:222] [log:log_response] [WARNING]- Forbidden: /user/role/
[2020-06-28 23:14:56,261] [basehttp.py:157] [basehttp:log_message] [WARNING]- "GET /user/role/?username=admin&application=sys&type=button HTTP/1.1" 403 24
[2020-06-28 23:14:56,262] [basehttp.py:157] [basehttp:log_message] [WARNING]- "GET /user/role/?username=admin&application=sys&type=menu HTTP/1.1" 403 24
[2020-06-29 09:33:17,414] [basehttp.py:157] [basehttp:log_message] [INFO]- "OPTIONS /auth/ HTTP/1.1" 200 0
[2020-06-29 09:33:18,139] [log.py:222] [log:log_response] [ERROR]- Internal Server Error: /auth/
Traceback (most recent call last):
  File "/home/rock/quality_inspection/python-workspace/project-sys/sys_auth/views.py", line 95, in post
    raise exceptions.AuthenticationFailed('未查询到用户信息！')
rest_framework.exceptions.AuthenticationFailed: 未查询到用户信息！

During handling of the above exception, another exception occurred:

Traceback (most recent call last):
  File "/home/rock/anaconda3/envs/venv/lib/python3.8/site-packages/django/core/handlers/exception.py", line 34, in inner
    response = get_response(request)
  File "/home/rock/anaconda3/envs/venv/lib/python3.8/site-packages/django/core/handlers/base.py", line 115, in _get_response
    response = self.process_exception_by_middleware(e, request)
  File "/home/rock/anaconda3/envs/venv/lib/python3.8/site-packages/django/core/handlers/base.py", line 113, in _get_response
    response = wrapped_callback(request, *callback_args, **callback_kwargs)
  File "/home/rock/anaconda3/envs/venv/lib/python3.8/site-packages/django/views/decorators/csrf.py", line 54, in wrapped_view
    return view_func(*args, **kwargs)
  File "/home/rock/anaconda3/envs/venv/lib/python3.8/site-packages/django/views/generic/base.py", line 71, in view
    return self.dispatch(request, *args, **kwargs)
  File "/home/rock/anaconda3/envs/venv/lib/python3.8/site-packages/rest_framework/views.py", line 505, in dispatch
    response = self.handle_exception(exc)
  File "/home/rock/anaconda3/envs/venv/lib/python3.8/site-packages/rest_framework/views.py", line 465, in handle_exception
    self.raise_uncaught_exception(exc)
  File "/home/rock/anaconda3/envs/venv/lib/python3.8/site-packages/rest_framework/views.py", line 476, in raise_uncaught_exception
    raise exc
  File "/home/rock/anaconda3/envs/venv/lib/python3.8/site-packages/rest_framework/views.py", line 502, in dispatch
    response = handler(request, *args, **kwargs)
  File "/home/rock/quality_inspection/python-workspace/project-sys/sys_auth/views.py", line 105, in post
    except exceptions as e:
TypeError: catching classes that do not inherit from BaseException is not allowed
[2020-06-29 09:33:18,141] [basehttp.py:157] [basehttp:log_message] [ERROR]- "POST /auth/ HTTP/1.1" 500 19112
[2020-06-29 09:33:25,374] [basehttp.py:157] [basehttp:log_message] [INFO]- "POST /auth/ HTTP/1.1" 200 65
[2020-06-29 10:07:10,594] [basehttp.py:157] [basehttp:log_message] [INFO]- "OPTIONS /auth/ HTTP/1.1" 200 0
[2020-06-29 10:07:10,874] [log.py:222] [log:log_response] [ERROR]- Internal Server Error: /auth/
Traceback (most recent call last):
  File "/home/rock/quality_inspection/python-workspace/project-sys/sys_auth/views.py", line 95, in post
    raise exceptions.AuthenticationFailed('未查询到用户信息！')
rest_framework.exceptions.AuthenticationFailed: 未查询到用户信息！

During handling of the above exception, another exception occurred:

Traceback (most recent call last):
  File "/home/rock/anaconda3/envs/venv/lib/python3.8/site-packages/django/core/handlers/exception.py", line 34, in inner
    response = get_response(request)
  File "/home/rock/anaconda3/envs/venv/lib/python3.8/site-packages/django/core/handlers/base.py", line 115, in _get_response
    response = self.process_exception_by_middleware(e, request)
  File "/home/rock/anaconda3/envs/venv/lib/python3.8/site-packages/django/core/handlers/base.py", line 113, in _get_response
    response = wrapped_callback(request, *callback_args, **callback_kwargs)
  File "/home/rock/anaconda3/envs/venv/lib/python3.8/site-packages/django/views/decorators/csrf.py", line 54, in wrapped_view
    return view_func(*args, **kwargs)
  File "/home/rock/anaconda3/envs/venv/lib/python3.8/site-packages/django/views/generic/base.py", line 71, in view
    return self.dispatch(request, *args, **kwargs)
  File "/home/rock/anaconda3/envs/venv/lib/python3.8/site-packages/rest_framework/views.py", line 505, in dispatch
    response = self.handle_exception(exc)
  File "/home/rock/anaconda3/envs/venv/lib/python3.8/site-packages/rest_framework/views.py", line 465, in handle_exception
    self.raise_uncaught_exception(exc)
  File "/home/rock/anaconda3/envs/venv/lib/python3.8/site-packages/rest_framework/views.py", line 476, in raise_uncaught_exception
    raise exc
  File "/home/rock/anaconda3/envs/venv/lib/python3.8/site-packages/rest_framework/views.py", line 502, in dispatch
    response = handler(request, *args, **kwargs)
  File "/home/rock/quality_inspection/python-workspace/project-sys/sys_auth/views.py", line 105, in post
    except exceptions as e:
TypeError: catching classes that do not inherit from BaseException is not allowed
[2020-06-29 10:07:10,875] [basehttp.py:157] [basehttp:log_message] [ERROR]- "POST /auth/ HTTP/1.1" 500 19108
[2020-06-29 10:07:46,004] [log.py:222] [log:log_response] [ERROR]- Internal Server Error: /auth/
Traceback (most recent call last):
  File "/home/rock/quality_inspection/python-workspace/project-sys/sys_auth/views.py", line 95, in post
    raise exceptions.AuthenticationFailed('未查询到用户信息！')
rest_framework.exceptions.AuthenticationFailed: 未查询到用户信息！

During handling of the above exception, another exception occurred:

Traceback (most recent call last):
  File "/home/rock/anaconda3/envs/venv/lib/python3.8/site-packages/django/core/handlers/exception.py", line 34, in inner
    response = get_response(request)
  File "/home/rock/anaconda3/envs/venv/lib/python3.8/site-packages/django/core/handlers/base.py", line 115, in _get_response
    response = self.process_exception_by_middleware(e, request)
  File "/home/rock/anaconda3/envs/venv/lib/python3.8/site-packages/django/core/handlers/base.py", line 113, in _get_response
    response = wrapped_callback(request, *callback_args, **callback_kwargs)
  File "/home/rock/anaconda3/envs/venv/lib/python3.8/site-packages/django/views/decorators/csrf.py", line 54, in wrapped_view
    return view_func(*args, **kwargs)
  File "/home/rock/anaconda3/envs/venv/lib/python3.8/site-packages/django/views/generic/base.py", line 71, in view
    return self.dispatch(request, *args, **kwargs)
  File "/home/rock/anaconda3/envs/venv/lib/python3.8/site-packages/rest_framework/views.py", line 505, in dispatch
    response = self.handle_exception(exc)
  File "/home/rock/anaconda3/envs/venv/lib/python3.8/site-packages/rest_framework/views.py", line 465, in handle_exception
    self.raise_uncaught_exception(exc)
  File "/home/rock/anaconda3/envs/venv/lib/python3.8/site-packages/rest_framework/views.py", line 476, in raise_uncaught_exception
    raise exc
  File "/home/rock/anaconda3/envs/venv/lib/python3.8/site-packages/rest_framework/views.py", line 502, in dispatch
    response = handler(request, *args, **kwargs)
  File "/home/rock/quality_inspection/python-workspace/project-sys/sys_auth/views.py", line 105, in post
    except exceptions as e:
TypeError: catching classes that do not inherit from BaseException is not allowed
[2020-06-29 10:07:46,005] [basehttp.py:157] [basehttp:log_message] [ERROR]- "POST /auth/ HTTP/1.1" 500 19105
