[2020-06-30 10:29:37,220] [autoreload.py:598] [autoreload:run_with_reloader] [INFO]- Watching for file changes with StatReloader
[2020-06-30 10:29:56,314] [autoreload.py:222] [autoreload:trigger_reload] [INFO]- /home/rock/quality_inspection/python-workspace/project-sys/sys_auth/views.py changed, reloading.
[2020-06-30 10:29:57,066] [autoreload.py:598] [autoreload:run_with_reloader] [INFO]- Watching for file changes with StatReloader
[2020-06-30 10:30:06,439] [log.py:222] [log:log_response] [ERROR]- Internal Server Error: /user/role/
Traceback (most recent call last):
  File "/home/rock/anaconda3/envs/venv/lib/python3.8/site-packages/django/core/handlers/exception.py", line 34, in inner
    response = get_response(request)
  File "/home/rock/anaconda3/envs/venv/lib/python3.8/site-packages/django/core/handlers/base.py", line 115, in _get_response
    response = self.process_exception_by_middleware(e, request)
  File "/home/rock/anaconda3/envs/venv/lib/python3.8/site-packages/django/core/handlers/base.py", line 113, in _get_response
    response = wrapped_callback(request, *callback_args, **callback_kwargs)
  File "/home/rock/anaconda3/envs/venv/lib/python3.8/site-packages/django/views/decorators/csrf.py", line 54, in wrapped_view
    return view_func(*args, **kwargs)
  File "/home/rock/anaconda3/envs/venv/lib/python3.8/site-packages/rest_framework/viewsets.py", line 114, in view
    return self.dispatch(request, *args, **kwargs)
  File "/home/rock/anaconda3/envs/venv/lib/python3.8/site-packages/rest_framework/views.py", line 505, in dispatch
    response = self.handle_exception(exc)
  File "/home/rock/anaconda3/envs/venv/lib/python3.8/site-packages/rest_framework/views.py", line 465, in handle_exception
    self.raise_uncaught_exception(exc)
  File "/home/rock/anaconda3/envs/venv/lib/python3.8/site-packages/rest_framework/views.py", line 476, in raise_uncaught_exception
    raise exc
  File "/home/rock/anaconda3/envs/venv/lib/python3.8/site-packages/rest_framework/views.py", line 493, in dispatch
    self.initial(request, *args, **kwargs)
  File "/home/rock/anaconda3/envs/venv/lib/python3.8/site-packages/rest_framework/views.py", line 410, in initial
    self.perform_authentication(request)
  File "/home/rock/anaconda3/envs/venv/lib/python3.8/site-packages/rest_framework/views.py", line 324, in perform_authentication
    request.user
  File "/home/rock/anaconda3/envs/venv/lib/python3.8/site-packages/rest_framework/request.py", line 220, in user
    self._authenticate()
  File "/home/rock/anaconda3/envs/venv/lib/python3.8/site-packages/rest_framework/request.py", line 380, in _authenticate
    self.user, self.auth = user_auth_tuple
  File "/home/rock/anaconda3/envs/venv/lib/python3.8/site-packages/django/template/response.py", line 118, in __iter__
    raise ContentNotRenderedError(
django.template.response.ContentNotRenderedError: The response content must be rendered before it can be iterated over.
[2020-06-30 10:30:06,441] [log.py:222] [log:log_response] [ERROR]- Internal Server Error: /user/role/
Traceback (most recent call last):
  File "/home/rock/anaconda3/envs/venv/lib/python3.8/site-packages/django/core/handlers/exception.py", line 34, in inner
    response = get_response(request)
  File "/home/rock/anaconda3/envs/venv/lib/python3.8/site-packages/django/core/handlers/base.py", line 115, in _get_response
    response = self.process_exception_by_middleware(e, request)
  File "/home/rock/anaconda3/envs/venv/lib/python3.8/site-packages/django/core/handlers/base.py", line 113, in _get_response
    response = wrapped_callback(request, *callback_args, **callback_kwargs)
  File "/home/rock/anaconda3/envs/venv/lib/python3.8/site-packages/django/views/decorators/csrf.py", line 54, in wrapped_view
    return view_func(*args, **kwargs)
  File "/home/rock/anaconda3/envs/venv/lib/python3.8/site-packages/rest_framework/viewsets.py", line 114, in view
    return self.dispatch(request, *args, **kwargs)
  File "/home/rock/anaconda3/envs/venv/lib/python3.8/site-packages/rest_framework/views.py", line 505, in dispatch
    response = self.handle_exception(exc)
  File "/home/rock/anaconda3/envs/venv/lib/python3.8/site-packages/rest_framework/views.py", line 465, in handle_exception
    self.raise_uncaught_exception(exc)
  File "/home/rock/anaconda3/envs/venv/lib/python3.8/site-packages/rest_framework/views.py", line 476, in raise_uncaught_exception
    raise exc
  File "/home/rock/anaconda3/envs/venv/lib/python3.8/site-packages/rest_framework/views.py", line 493, in dispatch
    self.initial(request, *args, **kwargs)
  File "/home/rock/anaconda3/envs/venv/lib/python3.8/site-packages/rest_framework/views.py", line 410, in initial
    self.perform_authentication(request)
  File "/home/rock/anaconda3/envs/venv/lib/python3.8/site-packages/rest_framework/views.py", line 324, in perform_authentication
    request.user
  File "/home/rock/anaconda3/envs/venv/lib/python3.8/site-packages/rest_framework/request.py", line 220, in user
    self._authenticate()
  File "/home/rock/anaconda3/envs/venv/lib/python3.8/site-packages/rest_framework/request.py", line 380, in _authenticate
    self.user, self.auth = user_auth_tuple
  File "/home/rock/anaconda3/envs/venv/lib/python3.8/site-packages/django/template/response.py", line 118, in __iter__
    raise ContentNotRenderedError(
django.template.response.ContentNotRenderedError: The response content must be rendered before it can be iterated over.
[2020-06-30 10:30:06,443] [basehttp.py:157] [basehttp:log_message] [ERROR]- "GET /user/role/?username=admin&application=sys&type=button HTTP/1.1" 500 20165
[2020-06-30 10:30:06,446] [basehttp.py:157] [basehttp:log_message] [ERROR]- "GET /user/role/?username=admin&application=sys&type=menu HTTP/1.1" 500 20159
[2020-06-30 10:30:20,591] [log.py:222] [log:log_response] [ERROR]- Internal Server Error: /user/role/
Traceback (most recent call last):
  File "/home/rock/anaconda3/envs/venv/lib/python3.8/site-packages/django/core/handlers/exception.py", line 34, in inner
    response = get_response(request)
  File "/home/rock/anaconda3/envs/venv/lib/python3.8/site-packages/django/core/handlers/base.py", line 115, in _get_response
    response = self.process_exception_by_middleware(e, request)
  File "/home/rock/anaconda3/envs/venv/lib/python3.8/site-packages/django/core/handlers/base.py", line 113, in _get_response
    response = wrapped_callback(request, *callback_args, **callback_kwargs)
  File "/home/rock/anaconda3/envs/venv/lib/python3.8/site-packages/django/views/decorators/csrf.py", line 54, in wrapped_view
    return view_func(*args, **kwargs)
  File "/home/rock/anaconda3/envs/venv/lib/python3.8/site-packages/rest_framework/viewsets.py", line 114, in view
    return self.dispatch(request, *args, **kwargs)
  File "/home/rock/anaconda3/envs/venv/lib/python3.8/site-packages/rest_framework/views.py", line 505, in dispatch
    response = self.handle_exception(exc)
  File "/home/rock/anaconda3/envs/venv/lib/python3.8/site-packages/rest_framework/views.py", line 465, in handle_exception
    self.raise_uncaught_exception(exc)
  File "/home/rock/anaconda3/envs/venv/lib/python3.8/site-packages/rest_framework/views.py", line 476, in raise_uncaught_exception
    raise exc
  File "/home/rock/anaconda3/envs/venv/lib/python3.8/site-packages/rest_framework/views.py", line 493, in dispatch
    self.initial(request, *args, **kwargs)
  File "/home/rock/anaconda3/envs/venv/lib/python3.8/site-packages/rest_framework/views.py", line 410, in initial
    self.perform_authentication(request)
  File "/home/rock/anaconda3/envs/venv/lib/python3.8/site-packages/rest_framework/views.py", line 324, in perform_authentication
    request.user
  File "/home/rock/anaconda3/envs/venv/lib/python3.8/site-packages/rest_framework/request.py", line 220, in user
    self._authenticate()
  File "/home/rock/anaconda3/envs/venv/lib/python3.8/site-packages/rest_framework/request.py", line 380, in _authenticate
    self.user, self.auth = user_auth_tuple
  File "/home/rock/anaconda3/envs/venv/lib/python3.8/site-packages/django/template/response.py", line 118, in __iter__
    raise ContentNotRenderedError(
django.template.response.ContentNotRenderedError: The response content must be rendered before it can be iterated over.
[2020-06-30 10:30:20,592] [basehttp.py:157] [basehttp:log_message] [ERROR]- "GET /user/role/?username=admin&application=sys&type=menu HTTP/1.1" 500 20159
[2020-06-30 10:30:20,636] [log.py:222] [log:log_response] [ERROR]- Internal Server Error: /user/role/
Traceback (most recent call last):
  File "/home/rock/anaconda3/envs/venv/lib/python3.8/site-packages/django/core/handlers/exception.py", line 34, in inner
    response = get_response(request)
  File "/home/rock/anaconda3/envs/venv/lib/python3.8/site-packages/django/core/handlers/base.py", line 115, in _get_response
    response = self.process_exception_by_middleware(e, request)
  File "/home/rock/anaconda3/envs/venv/lib/python3.8/site-packages/django/core/handlers/base.py", line 113, in _get_response
    response = wrapped_callback(request, *callback_args, **callback_kwargs)
  File "/home/rock/anaconda3/envs/venv/lib/python3.8/site-packages/django/views/decorators/csrf.py", line 54, in wrapped_view
    return view_func(*args, **kwargs)
  File "/home/rock/anaconda3/envs/venv/lib/python3.8/site-packages/rest_framework/viewsets.py", line 114, in view
    return self.dispatch(request, *args, **kwargs)
  File "/home/rock/anaconda3/envs/venv/lib/python3.8/site-packages/rest_framework/views.py", line 505, in dispatch
    response = self.handle_exception(exc)
  File "/home/rock/anaconda3/envs/venv/lib/python3.8/site-packages/rest_framework/views.py", line 465, in handle_exception
    self.raise_uncaught_exception(exc)
  File "/home/rock/anaconda3/envs/venv/lib/python3.8/site-packages/rest_framework/views.py", line 476, in raise_uncaught_exception
    raise exc
  File "/home/rock/anaconda3/envs/venv/lib/python3.8/site-packages/rest_framework/views.py", line 493, in dispatch
    self.initial(request, *args, **kwargs)
  File "/home/rock/anaconda3/envs/venv/lib/python3.8/site-packages/rest_framework/views.py", line 410, in initial
    self.perform_authentication(request)
  File "/home/rock/anaconda3/envs/venv/lib/python3.8/site-packages/rest_framework/views.py", line 324, in perform_authentication
    request.user
  File "/home/rock/anaconda3/envs/venv/lib/python3.8/site-packages/rest_framework/request.py", line 220, in user
    self._authenticate()
  File "/home/rock/anaconda3/envs/venv/lib/python3.8/site-packages/rest_framework/request.py", line 380, in _authenticate
    self.user, self.auth = user_auth_tuple
  File "/home/rock/anaconda3/envs/venv/lib/python3.8/site-packages/django/template/response.py", line 118, in __iter__
    raise ContentNotRenderedError(
django.template.response.ContentNotRenderedError: The response content must be rendered before it can be iterated over.
[2020-06-30 10:30:20,638] [basehttp.py:157] [basehttp:log_message] [ERROR]- "GET /user/role/?username=admin&application=sys&type=button HTTP/1.1" 500 20165
[2020-06-30 10:30:41,354] [autoreload.py:598] [autoreload:run_with_reloader] [INFO]- Watching for file changes with StatReloader
[2020-06-30 10:30:45,708] [log.py:222] [log:log_response] [ERROR]- Internal Server Error: /user/role/
Traceback (most recent call last):
  File "/home/rock/anaconda3/envs/venv/lib/python3.8/site-packages/django/core/handlers/exception.py", line 34, in inner
    response = get_response(request)
  File "/home/rock/anaconda3/envs/venv/lib/python3.8/site-packages/django/core/handlers/base.py", line 115, in _get_response
    response = self.process_exception_by_middleware(e, request)
  File "/home/rock/anaconda3/envs/venv/lib/python3.8/site-packages/django/core/handlers/base.py", line 113, in _get_response
    response = wrapped_callback(request, *callback_args, **callback_kwargs)
  File "/home/rock/anaconda3/envs/venv/lib/python3.8/site-packages/django/views/decorators/csrf.py", line 54, in wrapped_view
    return view_func(*args, **kwargs)
  File "/home/rock/anaconda3/envs/venv/lib/python3.8/site-packages/rest_framework/viewsets.py", line 114, in view
    return self.dispatch(request, *args, **kwargs)
  File "/home/rock/anaconda3/envs/venv/lib/python3.8/site-packages/rest_framework/views.py", line 505, in dispatch
    response = self.handle_exception(exc)
  File "/home/rock/anaconda3/envs/venv/lib/python3.8/site-packages/rest_framework/views.py", line 465, in handle_exception
    self.raise_uncaught_exception(exc)
  File "/home/rock/anaconda3/envs/venv/lib/python3.8/site-packages/rest_framework/views.py", line 476, in raise_uncaught_exception
    raise exc
  File "/home/rock/anaconda3/envs/venv/lib/python3.8/site-packages/rest_framework/views.py", line 493, in dispatch
    self.initial(request, *args, **kwargs)
  File "/home/rock/anaconda3/envs/venv/lib/python3.8/site-packages/rest_framework/views.py", line 410, in initial
    self.perform_authentication(request)
  File "/home/rock/anaconda3/envs/venv/lib/python3.8/site-packages/rest_framework/views.py", line 324, in perform_authentication
    request.user
  File "/home/rock/anaconda3/envs/venv/lib/python3.8/site-packages/rest_framework/request.py", line 220, in user
    self._authenticate()
  File "/home/rock/anaconda3/envs/venv/lib/python3.8/site-packages/rest_framework/request.py", line 380, in _authenticate
    self.user, self.auth = user_auth_tuple
  File "/home/rock/anaconda3/envs/venv/lib/python3.8/site-packages/django/template/response.py", line 118, in __iter__
    raise ContentNotRenderedError(
django.template.response.ContentNotRenderedError: The response content must be rendered before it can be iterated over.
[2020-06-30 10:30:45,709] [log.py:222] [log:log_response] [ERROR]- Internal Server Error: /user/role/
Traceback (most recent call last):
  File "/home/rock/anaconda3/envs/venv/lib/python3.8/site-packages/django/core/handlers/exception.py", line 34, in inner
    response = get_response(request)
  File "/home/rock/anaconda3/envs/venv/lib/python3.8/site-packages/django/core/handlers/base.py", line 115, in _get_response
    response = self.process_exception_by_middleware(e, request)
  File "/home/rock/anaconda3/envs/venv/lib/python3.8/site-packages/django/core/handlers/base.py", line 113, in _get_response
    response = wrapped_callback(request, *callback_args, **callback_kwargs)
  File "/home/rock/anaconda3/envs/venv/lib/python3.8/site-packages/django/views/decorators/csrf.py", line 54, in wrapped_view
    return view_func(*args, **kwargs)
  File "/home/rock/anaconda3/envs/venv/lib/python3.8/site-packages/rest_framework/viewsets.py", line 114, in view
    return self.dispatch(request, *args, **kwargs)
  File "/home/rock/anaconda3/envs/venv/lib/python3.8/site-packages/rest_framework/views.py", line 505, in dispatch
    response = self.handle_exception(exc)
  File "/home/rock/anaconda3/envs/venv/lib/python3.8/site-packages/rest_framework/views.py", line 465, in handle_exception
    self.raise_uncaught_exception(exc)
  File "/home/rock/anaconda3/envs/venv/lib/python3.8/site-packages/rest_framework/views.py", line 476, in raise_uncaught_exception
    raise exc
  File "/home/rock/anaconda3/envs/venv/lib/python3.8/site-packages/rest_framework/views.py", line 493, in dispatch
    self.initial(request, *args, **kwargs)
  File "/home/rock/anaconda3/envs/venv/lib/python3.8/site-packages/rest_framework/views.py", line 410, in initial
    self.perform_authentication(request)
  File "/home/rock/anaconda3/envs/venv/lib/python3.8/site-packages/rest_framework/views.py", line 324, in perform_authentication
    request.user
  File "/home/rock/anaconda3/envs/venv/lib/python3.8/site-packages/rest_framework/request.py", line 220, in user
    self._authenticate()
  File "/home/rock/anaconda3/envs/venv/lib/python3.8/site-packages/rest_framework/request.py", line 380, in _authenticate
    self.user, self.auth = user_auth_tuple
  File "/home/rock/anaconda3/envs/venv/lib/python3.8/site-packages/django/template/response.py", line 118, in __iter__
    raise ContentNotRenderedError(
django.template.response.ContentNotRenderedError: The response content must be rendered before it can be iterated over.
[2020-06-30 10:30:45,711] [basehttp.py:157] [basehttp:log_message] [ERROR]- "GET /user/role/?username=admin&application=sys&type=menu HTTP/1.1" 500 20159
[2020-06-30 10:30:45,713] [basehttp.py:157] [basehttp:log_message] [ERROR]- "GET /user/role/?username=admin&application=sys&type=button HTTP/1.1" 500 20165
[2020-06-30 10:30:58,468] [basehttp.py:157] [basehttp:log_message] [INFO]- "OPTIONS /auth/ HTTP/1.1" 200 0
[2020-06-30 10:30:58,794] [basehttp.py:157] [basehttp:log_message] [INFO]- "POST /auth/ HTTP/1.1" 200 65
[2020-06-30 10:31:00,992] [basehttp.py:157] [basehttp:log_message] [INFO]- "GET /user/role/?username=admin&application=sys&type=menu HTTP/1.1" 200 1161
[2020-06-30 10:31:00,994] [basehttp.py:157] [basehttp:log_message] [INFO]- "GET /user/role/?username=admin&application=sys&type=button HTTP/1.1" 200 291
[2020-06-30 10:31:04,396] [log.py:222] [log:log_response] [ERROR]- Internal Server Error: /user/
Traceback (most recent call last):
  File "/home/rock/anaconda3/envs/venv/lib/python3.8/site-packages/django/core/handlers/exception.py", line 34, in inner
    response = get_response(request)
  File "/home/rock/anaconda3/envs/venv/lib/python3.8/site-packages/django/core/handlers/base.py", line 115, in _get_response
    response = self.process_exception_by_middleware(e, request)
  File "/home/rock/anaconda3/envs/venv/lib/python3.8/site-packages/django/core/handlers/base.py", line 113, in _get_response
    response = wrapped_callback(request, *callback_args, **callback_kwargs)
  File "/home/rock/anaconda3/envs/venv/lib/python3.8/site-packages/django/views/decorators/csrf.py", line 54, in wrapped_view
    return view_func(*args, **kwargs)
  File "/home/rock/anaconda3/envs/venv/lib/python3.8/site-packages/rest_framework/viewsets.py", line 114, in view
    return self.dispatch(request, *args, **kwargs)
  File "/home/rock/anaconda3/envs/venv/lib/python3.8/site-packages/rest_framework/views.py", line 505, in dispatch
    response = self.handle_exception(exc)
  File "/home/rock/anaconda3/envs/venv/lib/python3.8/site-packages/rest_framework/views.py", line 465, in handle_exception
    self.raise_uncaught_exception(exc)
  File "/home/rock/anaconda3/envs/venv/lib/python3.8/site-packages/rest_framework/views.py", line 476, in raise_uncaught_exception
    raise exc
  File "/home/rock/anaconda3/envs/venv/lib/python3.8/site-packages/rest_framework/views.py", line 502, in dispatch
    response = handler(request, *args, **kwargs)
  File "/home/rock/anaconda3/envs/venv/lib/python3.8/site-packages/django/utils/decorators.py", line 122, in _wrapped_view
    result = middleware.process_request(request)
  File "/home/rock/anaconda3/envs/venv/lib/python3.8/site-packages/dwebsocket/middleware.py", line 28, in process_request
    request.websocket = factory_cls(request).create_websocket()
  File "/home/rock/anaconda3/envs/venv/lib/python3.8/site-packages/dwebsocket/backends/default/factory.py", line 37, in create_websocket
    if not self.is_websocket():
  File "/home/rock/anaconda3/envs/venv/lib/python3.8/site-packages/dwebsocket/factory.py", line 14, in is_websocket
    if self.request.META.get(
AttributeError: 'UserViewSet' object has no attribute 'META'
[2020-06-30 10:31:04,408] [basehttp.py:157] [basehttp:log_message] [ERROR]- "GET /user/?current_page=1&pre_page=10 HTTP/1.1" 500 19946
[2020-06-30 10:31:27,692] [autoreload.py:222] [autoreload:trigger_reload] [INFO]- /home/rock/quality_inspection/python-workspace/project-sys/sys_auth/views.py changed, reloading.
[2020-06-30 10:31:28,609] [autoreload.py:598] [autoreload:run_with_reloader] [INFO]- Watching for file changes with StatReloader
[2020-06-30 10:31:33,968] [basehttp.py:157] [basehttp:log_message] [INFO]- "GET /user/role/?username=admin&application=sys&type=menu HTTP/1.1" 200 1161
[2020-06-30 10:31:33,970] [basehttp.py:157] [basehttp:log_message] [INFO]- "GET /user/role/?username=admin&application=sys&type=button HTTP/1.1" 200 291
[2020-06-30 10:31:34,253] [basehttp.py:157] [basehttp:log_message] [INFO]- "GET /user/?current_page=1&pre_page=10 HTTP/1.1" 200 79673
[2020-06-30 13:51:57,176] [autoreload.py:222] [autoreload:trigger_reload] [INFO]- /home/rock/quality_inspection/python-workspace/project-sys/project-sys/settings.py changed, reloading.
[2020-06-30 14:01:47,815] [autoreload.py:598] [autoreload:run_with_reloader] [INFO]- Watching for file changes with StatReloader
[2020-06-30 14:11:08,879] [autoreload.py:598] [autoreload:run_with_reloader] [INFO]- Watching for file changes with StatReloader
[2020-06-30 14:13:46,384] [basehttp.py:157] [basehttp:log_message] [INFO]- "POST /sys/api/auth/ HTTP/1.1" 200 65
[2020-06-30 14:13:53,437] [basehttp.py:157] [basehttp:log_message] [INFO]- "OPTIONS /sys/api/user/role?username=admin&application=sys&type=menu HTTP/1.1" 200 0
[2020-06-30 14:13:53,439] [basehttp.py:157] [basehttp:log_message] [INFO]- "OPTIONS /sys/api/user/role?username=admin&application=sys&type=button HTTP/1.1" 200 0
[2020-06-30 14:13:53,476] [basehttp.py:157] [basehttp:log_message] [INFO]- "GET /sys/api/user/role?username=admin&application=sys&type=button HTTP/1.1" 301 0
[2020-06-30 14:13:53,477] [basehttp.py:157] [basehttp:log_message] [INFO]- "GET /sys/api/user/role?username=admin&application=sys&type=menu HTTP/1.1" 301 0
[2020-06-30 14:13:53,539] [basehttp.py:157] [basehttp:log_message] [INFO]- "OPTIONS /sys/api/user/role/?username=admin&application=sys&type=menu HTTP/1.1" 200 0
[2020-06-30 14:13:53,540] [basehttp.py:157] [basehttp:log_message] [INFO]- "OPTIONS /sys/api/user/role/?username=admin&application=sys&type=button HTTP/1.1" 200 0
[2020-06-30 14:13:53,885] [basehttp.py:157] [basehttp:log_message] [INFO]- "GET /sys/api/user/role/?username=admin&application=sys&type=menu HTTP/1.1" 200 1161
[2020-06-30 14:13:53,887] [basehttp.py:157] [basehttp:log_message] [INFO]- "GET /sys/api/user/role/?username=admin&application=sys&type=button HTTP/1.1" 200 291
[2020-06-30 14:14:01,103] [basehttp.py:157] [basehttp:log_message] [INFO]- "GET /sys/api/user/role?username=admin&application=monitor&type=menu HTTP/1.1" 301 0
[2020-06-30 14:14:01,109] [basehttp.py:157] [basehttp:log_message] [INFO]- "GET /sys/api/user/role?username=admin&application=monitor&type=button HTTP/1.1" 301 0
[2020-06-30 14:14:01,397] [basehttp.py:157] [basehttp:log_message] [INFO]- "GET /sys/api/user/role/?username=admin&application=monitor&type=menu HTTP/1.1" 200 2593
[2020-06-30 14:14:01,417] [basehttp.py:157] [basehttp:log_message] [INFO]- "GET /sys/api/user/role/?username=admin&application=monitor&type=button HTTP/1.1" 200 2
[2020-06-30 14:14:33,300] [basehttp.py:157] [basehttp:log_message] [INFO]- "GET /sys/api/user/role/?username=admin&application=monitor&type=button HTTP/1.1" 200 2
[2020-06-30 14:14:33,314] [basehttp.py:157] [basehttp:log_message] [INFO]- "GET /sys/api/user/role/?username=admin&application=monitor&type=menu HTTP/1.1" 200 2593
[2020-06-30 14:14:49,400] [basehttp.py:157] [basehttp:log_message] [INFO]- "GET /sys/api/user/role/?username=admin&application=sys&type=button HTTP/1.1" 200 291
[2020-06-30 14:14:49,402] [basehttp.py:157] [basehttp:log_message] [INFO]- "GET /sys/api/user/role/?username=admin&application=sys&type=menu HTTP/1.1" 200 1161
[2020-06-30 14:14:58,191] [basehttp.py:157] [basehttp:log_message] [INFO]- "GET /sys/api/menu/ HTTP/1.1" 200 15945
[2020-06-30 14:17:28,124] [basehttp.py:157] [basehttp:log_message] [INFO]- "GET /sys/api/user/role?username=admin&application=asset&type=menu HTTP/1.1" 301 0
[2020-06-30 14:17:28,125] [basehttp.py:157] [basehttp:log_message] [INFO]- "GET /sys/api/user/role?username=admin&application=asset&type=button HTTP/1.1" 301 0
[2020-06-30 14:17:28,905] [log.py:222] [log:log_response] [ERROR]- Internal Server Error: /sys/api/user/role/
Traceback (most recent call last):
  File "/home/rock/anaconda3/envs/venv/lib/python3.8/site-packages/django/core/handlers/exception.py", line 34, in inner
    response = get_response(request)
  File "/home/rock/anaconda3/envs/venv/lib/python3.8/site-packages/django/core/handlers/base.py", line 115, in _get_response
    response = self.process_exception_by_middleware(e, request)
  File "/home/rock/anaconda3/envs/venv/lib/python3.8/site-packages/django/core/handlers/base.py", line 113, in _get_response
    response = wrapped_callback(request, *callback_args, **callback_kwargs)
  File "/home/rock/anaconda3/envs/venv/lib/python3.8/site-packages/django/views/decorators/csrf.py", line 54, in wrapped_view
    return view_func(*args, **kwargs)
  File "/home/rock/anaconda3/envs/venv/lib/python3.8/site-packages/rest_framework/viewsets.py", line 114, in view
    return self.dispatch(request, *args, **kwargs)
  File "/home/rock/anaconda3/envs/venv/lib/python3.8/site-packages/rest_framework/views.py", line 505, in dispatch
    response = self.handle_exception(exc)
  File "/home/rock/anaconda3/envs/venv/lib/python3.8/site-packages/rest_framework/views.py", line 465, in handle_exception
    self.raise_uncaught_exception(exc)
  File "/home/rock/anaconda3/envs/venv/lib/python3.8/site-packages/rest_framework/views.py", line 476, in raise_uncaught_exception
    raise exc
  File "/home/rock/anaconda3/envs/venv/lib/python3.8/site-packages/rest_framework/views.py", line 493, in dispatch
    self.initial(request, *args, **kwargs)
  File "/home/rock/anaconda3/envs/venv/lib/python3.8/site-packages/rest_framework/views.py", line 410, in initial
    self.perform_authentication(request)
  File "/home/rock/anaconda3/envs/venv/lib/python3.8/site-packages/rest_framework/views.py", line 324, in perform_authentication
    request.user
  File "/home/rock/anaconda3/envs/venv/lib/python3.8/site-packages/rest_framework/request.py", line 220, in user
    self._authenticate()
  File "/home/rock/anaconda3/envs/venv/lib/python3.8/site-packages/rest_framework/request.py", line 380, in _authenticate
    self.user, self.auth = user_auth_tuple
  File "/home/rock/anaconda3/envs/venv/lib/python3.8/site-packages/django/template/response.py", line 118, in __iter__
    raise ContentNotRenderedError(
django.template.response.ContentNotRenderedError: The response content must be rendered before it can be iterated over.
[2020-06-30 14:17:28,914] [log.py:222] [log:log_response] [ERROR]- Internal Server Error: /sys/api/user/role/
Traceback (most recent call last):
  File "/home/rock/anaconda3/envs/venv/lib/python3.8/site-packages/django/core/handlers/exception.py", line 34, in inner
    response = get_response(request)
  File "/home/rock/anaconda3/envs/venv/lib/python3.8/site-packages/django/core/handlers/base.py", line 115, in _get_response
    response = self.process_exception_by_middleware(e, request)
  File "/home/rock/anaconda3/envs/venv/lib/python3.8/site-packages/django/core/handlers/base.py", line 113, in _get_response
    response = wrapped_callback(request, *callback_args, **callback_kwargs)
  File "/home/rock/anaconda3/envs/venv/lib/python3.8/site-packages/django/views/decorators/csrf.py", line 54, in wrapped_view
    return view_func(*args, **kwargs)
  File "/home/rock/anaconda3/envs/venv/lib/python3.8/site-packages/rest_framework/viewsets.py", line 114, in view
    return self.dispatch(request, *args, **kwargs)
  File "/home/rock/anaconda3/envs/venv/lib/python3.8/site-packages/rest_framework/views.py", line 505, in dispatch
    response = self.handle_exception(exc)
  File "/home/rock/anaconda3/envs/venv/lib/python3.8/site-packages/rest_framework/views.py", line 465, in handle_exception
    self.raise_uncaught_exception(exc)
  File "/home/rock/anaconda3/envs/venv/lib/python3.8/site-packages/rest_framework/views.py", line 476, in raise_uncaught_exception
    raise exc
  File "/home/rock/anaconda3/envs/venv/lib/python3.8/site-packages/rest_framework/views.py", line 493, in dispatch
    self.initial(request, *args, **kwargs)
  File "/home/rock/anaconda3/envs/venv/lib/python3.8/site-packages/rest_framework/views.py", line 410, in initial
    self.perform_authentication(request)
  File "/home/rock/anaconda3/envs/venv/lib/python3.8/site-packages/rest_framework/views.py", line 324, in perform_authentication
    request.user
  File "/home/rock/anaconda3/envs/venv/lib/python3.8/site-packages/rest_framework/request.py", line 220, in user
    self._authenticate()
  File "/home/rock/anaconda3/envs/venv/lib/python3.8/site-packages/rest_framework/request.py", line 380, in _authenticate
    self.user, self.auth = user_auth_tuple
  File "/home/rock/anaconda3/envs/venv/lib/python3.8/site-packages/django/template/response.py", line 118, in __iter__
    raise ContentNotRenderedError(
django.template.response.ContentNotRenderedError: The response content must be rendered before it can be iterated over.
[2020-06-30 14:17:28,916] [basehttp.py:157] [basehttp:log_message] [ERROR]- "GET /sys/api/user/role/?username=admin&application=asset&type=button HTTP/1.1" 500 20212
[2020-06-30 14:17:28,919] [basehttp.py:157] [basehttp:log_message] [ERROR]- "GET /sys/api/user/role/?username=admin&application=asset&type=menu HTTP/1.1" 500 20206
[2020-06-30 14:17:52,767] [log.py:222] [log:log_response] [ERROR]- Internal Server Error: /sys/api/user/role/
Traceback (most recent call last):
  File "/home/rock/anaconda3/envs/venv/lib/python3.8/site-packages/django/core/handlers/exception.py", line 34, in inner
    response = get_response(request)
  File "/home/rock/anaconda3/envs/venv/lib/python3.8/site-packages/django/core/handlers/base.py", line 115, in _get_response
    response = self.process_exception_by_middleware(e, request)
  File "/home/rock/anaconda3/envs/venv/lib/python3.8/site-packages/django/core/handlers/base.py", line 113, in _get_response
    response = wrapped_callback(request, *callback_args, **callback_kwargs)
  File "/home/rock/anaconda3/envs/venv/lib/python3.8/site-packages/django/views/decorators/csrf.py", line 54, in wrapped_view
    return view_func(*args, **kwargs)
  File "/home/rock/anaconda3/envs/venv/lib/python3.8/site-packages/rest_framework/viewsets.py", line 114, in view
    return self.dispatch(request, *args, **kwargs)
  File "/home/rock/anaconda3/envs/venv/lib/python3.8/site-packages/rest_framework/views.py", line 505, in dispatch
    response = self.handle_exception(exc)
  File "/home/rock/anaconda3/envs/venv/lib/python3.8/site-packages/rest_framework/views.py", line 465, in handle_exception
    self.raise_uncaught_exception(exc)
  File "/home/rock/anaconda3/envs/venv/lib/python3.8/site-packages/rest_framework/views.py", line 476, in raise_uncaught_exception
    raise exc
  File "/home/rock/anaconda3/envs/venv/lib/python3.8/site-packages/rest_framework/views.py", line 493, in dispatch
    self.initial(request, *args, **kwargs)
  File "/home/rock/anaconda3/envs/venv/lib/python3.8/site-packages/rest_framework/views.py", line 410, in initial
    self.perform_authentication(request)
  File "/home/rock/anaconda3/envs/venv/lib/python3.8/site-packages/rest_framework/views.py", line 324, in perform_authentication
    request.user
  File "/home/rock/anaconda3/envs/venv/lib/python3.8/site-packages/rest_framework/request.py", line 220, in user
    self._authenticate()
  File "/home/rock/anaconda3/envs/venv/lib/python3.8/site-packages/rest_framework/request.py", line 380, in _authenticate
    self.user, self.auth = user_auth_tuple
  File "/home/rock/anaconda3/envs/venv/lib/python3.8/site-packages/django/template/response.py", line 118, in __iter__
    raise ContentNotRenderedError(
django.template.response.ContentNotRenderedError: The response content must be rendered before it can be iterated over.
[2020-06-30 14:17:52,775] [basehttp.py:157] [basehttp:log_message] [ERROR]- "GET /sys/api/user/role/?username=admin&application=asset&type=button HTTP/1.1" 500 20212
[2020-06-30 14:17:52,819] [log.py:222] [log:log_response] [ERROR]- Internal Server Error: /sys/api/user/role/
Traceback (most recent call last):
  File "/home/rock/anaconda3/envs/venv/lib/python3.8/site-packages/django/core/handlers/exception.py", line 34, in inner
    response = get_response(request)
  File "/home/rock/anaconda3/envs/venv/lib/python3.8/site-packages/django/core/handlers/base.py", line 115, in _get_response
    response = self.process_exception_by_middleware(e, request)
  File "/home/rock/anaconda3/envs/venv/lib/python3.8/site-packages/django/core/handlers/base.py", line 113, in _get_response
    response = wrapped_callback(request, *callback_args, **callback_kwargs)
  File "/home/rock/anaconda3/envs/venv/lib/python3.8/site-packages/django/views/decorators/csrf.py", line 54, in wrapped_view
    return view_func(*args, **kwargs)
  File "/home/rock/anaconda3/envs/venv/lib/python3.8/site-packages/rest_framework/viewsets.py", line 114, in view
    return self.dispatch(request, *args, **kwargs)
  File "/home/rock/anaconda3/envs/venv/lib/python3.8/site-packages/rest_framework/views.py", line 505, in dispatch
    response = self.handle_exception(exc)
  File "/home/rock/anaconda3/envs/venv/lib/python3.8/site-packages/rest_framework/views.py", line 465, in handle_exception
    self.raise_uncaught_exception(exc)
  File "/home/rock/anaconda3/envs/venv/lib/python3.8/site-packages/rest_framework/views.py", line 476, in raise_uncaught_exception
    raise exc
  File "/home/rock/anaconda3/envs/venv/lib/python3.8/site-packages/rest_framework/views.py", line 493, in dispatch
    self.initial(request, *args, **kwargs)
  File "/home/rock/anaconda3/envs/venv/lib/python3.8/site-packages/rest_framework/views.py", line 410, in initial
    self.perform_authentication(request)
  File "/home/rock/anaconda3/envs/venv/lib/python3.8/site-packages/rest_framework/views.py", line 324, in perform_authentication
    request.user
  File "/home/rock/anaconda3/envs/venv/lib/python3.8/site-packages/rest_framework/request.py", line 220, in user
    self._authenticate()
  File "/home/rock/anaconda3/envs/venv/lib/python3.8/site-packages/rest_framework/request.py", line 380, in _authenticate
    self.user, self.auth = user_auth_tuple
  File "/home/rock/anaconda3/envs/venv/lib/python3.8/site-packages/django/template/response.py", line 118, in __iter__
    raise ContentNotRenderedError(
django.template.response.ContentNotRenderedError: The response content must be rendered before it can be iterated over.
[2020-06-30 14:17:52,820] [basehttp.py:157] [basehttp:log_message] [ERROR]- "GET /sys/api/user/role/?username=admin&application=asset&type=menu HTTP/1.1" 500 20206
[2020-06-30 14:18:06,374] [log.py:222] [log:log_response] [ERROR]- Internal Server Error: /sys/api/user/role/
Traceback (most recent call last):
  File "/home/rock/anaconda3/envs/venv/lib/python3.8/site-packages/django/core/handlers/exception.py", line 34, in inner
    response = get_response(request)
  File "/home/rock/anaconda3/envs/venv/lib/python3.8/site-packages/django/core/handlers/base.py", line 115, in _get_response
    response = self.process_exception_by_middleware(e, request)
  File "/home/rock/anaconda3/envs/venv/lib/python3.8/site-packages/django/core/handlers/base.py", line 113, in _get_response
    response = wrapped_callback(request, *callback_args, **callback_kwargs)
  File "/home/rock/anaconda3/envs/venv/lib/python3.8/site-packages/django/views/decorators/csrf.py", line 54, in wrapped_view
    return view_func(*args, **kwargs)
  File "/home/rock/anaconda3/envs/venv/lib/python3.8/site-packages/rest_framework/viewsets.py", line 114, in view
    return self.dispatch(request, *args, **kwargs)
  File "/home/rock/anaconda3/envs/venv/lib/python3.8/site-packages/rest_framework/views.py", line 505, in dispatch
    response = self.handle_exception(exc)
  File "/home/rock/anaconda3/envs/venv/lib/python3.8/site-packages/rest_framework/views.py", line 465, in handle_exception
    self.raise_uncaught_exception(exc)
  File "/home/rock/anaconda3/envs/venv/lib/python3.8/site-packages/rest_framework/views.py", line 476, in raise_uncaught_exception
    raise exc
  File "/home/rock/anaconda3/envs/venv/lib/python3.8/site-packages/rest_framework/views.py", line 493, in dispatch
    self.initial(request, *args, **kwargs)
  File "/home/rock/anaconda3/envs/venv/lib/python3.8/site-packages/rest_framework/views.py", line 410, in initial
    self.perform_authentication(request)
  File "/home/rock/anaconda3/envs/venv/lib/python3.8/site-packages/rest_framework/views.py", line 324, in perform_authentication
    request.user
  File "/home/rock/anaconda3/envs/venv/lib/python3.8/site-packages/rest_framework/request.py", line 220, in user
    self._authenticate()
  File "/home/rock/anaconda3/envs/venv/lib/python3.8/site-packages/rest_framework/request.py", line 380, in _authenticate
    self.user, self.auth = user_auth_tuple
  File "/home/rock/anaconda3/envs/venv/lib/python3.8/site-packages/django/template/response.py", line 118, in __iter__
    raise ContentNotRenderedError(
django.template.response.ContentNotRenderedError: The response content must be rendered before it can be iterated over.
[2020-06-30 14:18:06,383] [log.py:222] [log:log_response] [ERROR]- Internal Server Error: /sys/api/user/role/
Traceback (most recent call last):
  File "/home/rock/anaconda3/envs/venv/lib/python3.8/site-packages/django/core/handlers/exception.py", line 34, in inner
    response = get_response(request)
  File "/home/rock/anaconda3/envs/venv/lib/python3.8/site-packages/django/core/handlers/base.py", line 115, in _get_response
    response = self.process_exception_by_middleware(e, request)
  File "/home/rock/anaconda3/envs/venv/lib/python3.8/site-packages/django/core/handlers/base.py", line 113, in _get_response
    response = wrapped_callback(request, *callback_args, **callback_kwargs)
  File "/home/rock/anaconda3/envs/venv/lib/python3.8/site-packages/django/views/decorators/csrf.py", line 54, in wrapped_view
    return view_func(*args, **kwargs)
  File "/home/rock/anaconda3/envs/venv/lib/python3.8/site-packages/rest_framework/viewsets.py", line 114, in view
    return self.dispatch(request, *args, **kwargs)
  File "/home/rock/anaconda3/envs/venv/lib/python3.8/site-packages/rest_framework/views.py", line 505, in dispatch
    response = self.handle_exception(exc)
  File "/home/rock/anaconda3/envs/venv/lib/python3.8/site-packages/rest_framework/views.py", line 465, in handle_exception
    self.raise_uncaught_exception(exc)
  File "/home/rock/anaconda3/envs/venv/lib/python3.8/site-packages/rest_framework/views.py", line 476, in raise_uncaught_exception
    raise exc
  File "/home/rock/anaconda3/envs/venv/lib/python3.8/site-packages/rest_framework/views.py", line 493, in dispatch
    self.initial(request, *args, **kwargs)
  File "/home/rock/anaconda3/envs/venv/lib/python3.8/site-packages/rest_framework/views.py", line 410, in initial
    self.perform_authentication(request)
  File "/home/rock/anaconda3/envs/venv/lib/python3.8/site-packages/rest_framework/views.py", line 324, in perform_authentication
    request.user
  File "/home/rock/anaconda3/envs/venv/lib/python3.8/site-packages/rest_framework/request.py", line 220, in user
    self._authenticate()
  File "/home/rock/anaconda3/envs/venv/lib/python3.8/site-packages/rest_framework/request.py", line 380, in _authenticate
    self.user, self.auth = user_auth_tuple
  File "/home/rock/anaconda3/envs/venv/lib/python3.8/site-packages/django/template/response.py", line 118, in __iter__
    raise ContentNotRenderedError(
django.template.response.ContentNotRenderedError: The response content must be rendered before it can be iterated over.
[2020-06-30 14:18:06,388] [basehttp.py:157] [basehttp:log_message] [ERROR]- "GET /sys/api/user/role/?username=admin&application=asset&type=menu HTTP/1.1" 500 20206
[2020-06-30 14:18:06,392] [basehttp.py:157] [basehttp:log_message] [ERROR]- "GET /sys/api/user/role/?username=admin&application=asset&type=button HTTP/1.1" 500 20212
[2020-06-30 14:18:48,600] [basehttp.py:157] [basehttp:log_message] [INFO]- "POST /sys/api/auth/ HTTP/1.1" 200 65
[2020-06-30 14:18:50,868] [basehttp.py:157] [basehttp:log_message] [INFO]- "GET /sys/api/user/role/?username=admin&application=sys&type=menu HTTP/1.1" 200 1161
[2020-06-30 14:18:50,869] [basehttp.py:157] [basehttp:log_message] [INFO]- "GET /sys/api/user/role/?username=admin&application=sys&type=button HTTP/1.1" 200 291
[2020-06-30 14:18:54,116] [basehttp.py:157] [basehttp:log_message] [INFO]- "GET /sys/api/user/role/?username=admin&application=asset&type=button HTTP/1.1" 200 60
[2020-06-30 14:18:54,118] [basehttp.py:157] [basehttp:log_message] [INFO]- "GET /sys/api/user/role/?username=admin&application=asset&type=menu HTTP/1.1" 200 6014
[2020-06-30 14:19:16,660] [basehttp.py:157] [basehttp:log_message] [INFO]- "GET /sys/api/user/role/?username=admin&application=monitor&type=menu HTTP/1.1" 200 2593
[2020-06-30 14:19:16,721] [basehttp.py:157] [basehttp:log_message] [INFO]- "GET /sys/api/user/role/?username=admin&application=monitor&type=button HTTP/1.1" 200 2
[2020-06-30 14:20:07,385] [basehttp.py:157] [basehttp:log_message] [INFO]- "GET /sys/api/user/role/?username=admin&application=asset&type=menu HTTP/1.1" 200 6014
[2020-06-30 14:20:07,416] [basehttp.py:157] [basehttp:log_message] [INFO]- "GET /sys/api/user/role/?username=admin&application=asset&type=button HTTP/1.1" 200 60
[2020-06-30 14:20:10,518] [basehttp.py:157] [basehttp:log_message] [INFO]- "GET /sys/api/user/role/?username=admin&application=sys&type=button HTTP/1.1" 200 291
[2020-06-30 14:20:10,520] [basehttp.py:157] [basehttp:log_message] [INFO]- "GET /sys/api/user/role/?username=admin&application=sys&type=menu HTTP/1.1" 200 1161
[2020-06-30 15:20:19,754] [autoreload.py:598] [autoreload:run_with_reloader] [INFO]- Watching for file changes with StatReloader
[2020-06-30 19:02:14,827] [autoreload.py:598] [autoreload:run_with_reloader] [INFO]- Watching for file changes with StatReloader
[2020-06-30 19:02:19,946] [basehttp.py:157] [basehttp:log_message] [INFO]- "POST /sys/api/auth/ HTTP/1.1" 200 65
[2020-06-30 19:02:22,090] [basehttp.py:157] [basehttp:log_message] [INFO]- "GET /sys/api/user/role/?username=admin&application=asset&type=menu HTTP/1.1" 200 6014
[2020-06-30 19:02:22,091] [basehttp.py:157] [basehttp:log_message] [INFO]- "GET /sys/api/user/role/?username=admin&application=asset&type=button HTTP/1.1" 200 60
[2020-06-30 19:02:46,603] [basehttp.py:157] [basehttp:log_message] [INFO]- "GET /sys/api/user/role/?username=admin&application=monitor&type=menu HTTP/1.1" 200 2593
[2020-06-30 19:02:46,636] [basehttp.py:157] [basehttp:log_message] [INFO]- "GET /sys/api/user/role/?username=admin&application=monitor&type=button HTTP/1.1" 200 2
[2020-06-30 19:04:13,075] [autoreload.py:222] [autoreload:trigger_reload] [INFO]- /home/rock/quality_inspection/python-workspace/project-sys/sys_auth/views.py changed, reloading.
[2020-06-30 19:04:13,860] [autoreload.py:598] [autoreload:run_with_reloader] [INFO]- Watching for file changes with StatReloader
[2020-07-01 09:18:45,119] [log.py:222] [log:log_response] [ERROR]- Internal Server Error: /sys/api/user/role/
Traceback (most recent call last):
  File "/home/rock/anaconda3/envs/venv/lib/python3.8/site-packages/django/core/handlers/exception.py", line 34, in inner
    response = get_response(request)
  File "/home/rock/anaconda3/envs/venv/lib/python3.8/site-packages/django/core/handlers/base.py", line 115, in _get_response
    response = self.process_exception_by_middleware(e, request)
  File "/home/rock/anaconda3/envs/venv/lib/python3.8/site-packages/django/core/handlers/base.py", line 113, in _get_response
    response = wrapped_callback(request, *callback_args, **callback_kwargs)
  File "/home/rock/anaconda3/envs/venv/lib/python3.8/site-packages/django/views/decorators/csrf.py", line 54, in wrapped_view
    return view_func(*args, **kwargs)
  File "/home/rock/anaconda3/envs/venv/lib/python3.8/site-packages/rest_framework/viewsets.py", line 114, in view
    return self.dispatch(request, *args, **kwargs)
  File "/home/rock/anaconda3/envs/venv/lib/python3.8/site-packages/rest_framework/views.py", line 505, in dispatch
    response = self.handle_exception(exc)
  File "/home/rock/anaconda3/envs/venv/lib/python3.8/site-packages/rest_framework/views.py", line 465, in handle_exception
    self.raise_uncaught_exception(exc)
  File "/home/rock/anaconda3/envs/venv/lib/python3.8/site-packages/rest_framework/views.py", line 476, in raise_uncaught_exception
    raise exc
  File "/home/rock/anaconda3/envs/venv/lib/python3.8/site-packages/rest_framework/views.py", line 493, in dispatch
    self.initial(request, *args, **kwargs)
  File "/home/rock/anaconda3/envs/venv/lib/python3.8/site-packages/rest_framework/views.py", line 410, in initial
    self.perform_authentication(request)
  File "/home/rock/anaconda3/envs/venv/lib/python3.8/site-packages/rest_framework/views.py", line 324, in perform_authentication
    request.user
  File "/home/rock/anaconda3/envs/venv/lib/python3.8/site-packages/rest_framework/request.py", line 220, in user
    self._authenticate()
  File "/home/rock/anaconda3/envs/venv/lib/python3.8/site-packages/rest_framework/request.py", line 380, in _authenticate
    self.user, self.auth = user_auth_tuple
  File "/home/rock/anaconda3/envs/venv/lib/python3.8/site-packages/django/template/response.py", line 118, in __iter__
    raise ContentNotRenderedError(
django.template.response.ContentNotRenderedError: The response content must be rendered before it can be iterated over.
[2020-07-01 09:18:45,128] [log.py:222] [log:log_response] [ERROR]- Internal Server Error: /sys/api/user/role/
Traceback (most recent call last):
  File "/home/rock/anaconda3/envs/venv/lib/python3.8/site-packages/django/core/handlers/exception.py", line 34, in inner
    response = get_response(request)
  File "/home/rock/anaconda3/envs/venv/lib/python3.8/site-packages/django/core/handlers/base.py", line 115, in _get_response
    response = self.process_exception_by_middleware(e, request)
  File "/home/rock/anaconda3/envs/venv/lib/python3.8/site-packages/django/core/handlers/base.py", line 113, in _get_response
    response = wrapped_callback(request, *callback_args, **callback_kwargs)
  File "/home/rock/anaconda3/envs/venv/lib/python3.8/site-packages/django/views/decorators/csrf.py", line 54, in wrapped_view
    return view_func(*args, **kwargs)
  File "/home/rock/anaconda3/envs/venv/lib/python3.8/site-packages/rest_framework/viewsets.py", line 114, in view
    return self.dispatch(request, *args, **kwargs)
  File "/home/rock/anaconda3/envs/venv/lib/python3.8/site-packages/rest_framework/views.py", line 505, in dispatch
    response = self.handle_exception(exc)
  File "/home/rock/anaconda3/envs/venv/lib/python3.8/site-packages/rest_framework/views.py", line 465, in handle_exception
    self.raise_uncaught_exception(exc)
  File "/home/rock/anaconda3/envs/venv/lib/python3.8/site-packages/rest_framework/views.py", line 476, in raise_uncaught_exception
    raise exc
  File "/home/rock/anaconda3/envs/venv/lib/python3.8/site-packages/rest_framework/views.py", line 493, in dispatch
    self.initial(request, *args, **kwargs)
  File "/home/rock/anaconda3/envs/venv/lib/python3.8/site-packages/rest_framework/views.py", line 410, in initial
    self.perform_authentication(request)
  File "/home/rock/anaconda3/envs/venv/lib/python3.8/site-packages/rest_framework/views.py", line 324, in perform_authentication
    request.user
  File "/home/rock/anaconda3/envs/venv/lib/python3.8/site-packages/rest_framework/request.py", line 220, in user
    self._authenticate()
  File "/home/rock/anaconda3/envs/venv/lib/python3.8/site-packages/rest_framework/request.py", line 380, in _authenticate
    self.user, self.auth = user_auth_tuple
  File "/home/rock/anaconda3/envs/venv/lib/python3.8/site-packages/django/template/response.py", line 118, in __iter__
    raise ContentNotRenderedError(
django.template.response.ContentNotRenderedError: The response content must be rendered before it can be iterated over.
[2020-07-01 09:18:45,368] [basehttp.py:157] [basehttp:log_message] [ERROR]- "GET /sys/api/user/role/?username=admin&application=monitor&type=menu HTTP/1.1" 500 20211
[2020-07-01 09:18:45,371] [basehttp.py:157] [basehttp:log_message] [ERROR]- "GET /sys/api/user/role/?username=admin&application=monitor&type=button HTTP/1.1" 500 20217
[2020-07-01 09:20:42,927] [basehttp.py:157] [basehttp:log_message] [INFO]- "POST /sys/api/auth/ HTTP/1.1" 200 65
[2020-07-01 09:20:44,552] [basehttp.py:157] [basehttp:log_message] [INFO]- "OPTIONS /sys/api/user/role?username=admin&application=sys&type=menu HTTP/1.1" 200 0
[2020-07-01 09:20:44,555] [basehttp.py:157] [basehttp:log_message] [INFO]- "OPTIONS /sys/api/user/role?username=admin&application=sys&type=button HTTP/1.1" 200 0
[2020-07-01 09:20:44,587] [basehttp.py:157] [basehttp:log_message] [INFO]- "OPTIONS /sys/api/user/role/?username=admin&application=sys&type=menu HTTP/1.1" 200 0
[2020-07-01 09:20:44,587] [basehttp.py:157] [basehttp:log_message] [INFO]- "OPTIONS /sys/api/user/role/?username=admin&application=sys&type=button HTTP/1.1" 200 0
[2020-07-01 09:20:44,982] [basehttp.py:157] [basehttp:log_message] [INFO]- "GET /sys/api/user/role/?username=admin&application=sys&type=menu HTTP/1.1" 200 1161
[2020-07-01 09:20:44,983] [basehttp.py:157] [basehttp:log_message] [INFO]- "GET /sys/api/user/role/?username=admin&application=sys&type=button HTTP/1.1" 200 291
[2020-07-01 09:21:09,321] [basehttp.py:157] [basehttp:log_message] [INFO]- "GET /sys/api/user/role/?username=admin&application=sys&type=button HTTP/1.1" 200 291
[2020-07-01 09:21:09,338] [basehttp.py:157] [basehttp:log_message] [INFO]- "GET /sys/api/user/role/?username=admin&application=sys&type=menu HTTP/1.1" 200 1161
[2020-07-01 09:36:28,129] [basehttp.py:157] [basehttp:log_message] [INFO]- "GET /sys/api/menu/ HTTP/1.1" 200 15945
[2020-07-01 09:36:33,839] [basehttp.py:157] [basehttp:log_message] [INFO]- "GET /sys/api/role/?current_page=1&pre_page=10 HTTP/1.1" 200 33048
[2020-07-01 09:36:35,175] [basehttp.py:157] [basehttp:log_message] [INFO]- "GET /sys/api/user/?current_page=1&pre_page=10 HTTP/1.1" 200 79673
[2020-07-01 09:36:36,631] [basehttp.py:157] [basehttp:log_message] [INFO]- "GET /sys/api/menu/ HTTP/1.1" 200 15945
[2020-07-01 09:37:23,225] [basehttp.py:157] [basehttp:log_message] [INFO]- "GET /sys/api/user/role/?username=admin&application=asset&type=menu HTTP/1.1" 200 6014
[2020-07-01 09:37:23,240] [basehttp.py:157] [basehttp:log_message] [INFO]- "GET /sys/api/user/role/?username=admin&application=asset&type=button HTTP/1.1" 200 60
[2020-07-01 09:37:26,020] [basehttp.py:157] [basehttp:log_message] [INFO]- "OPTIONS /sys/api/user/role?username=admin&application=sys&type=menu HTTP/1.1" 200 0
[2020-07-01 09:37:26,021] [basehttp.py:157] [basehttp:log_message] [INFO]- "OPTIONS /sys/api/user/role?username=admin&application=sys&type=button HTTP/1.1" 200 0
[2020-07-01 09:37:26,048] [basehttp.py:157] [basehttp:log_message] [INFO]- "OPTIONS /sys/api/user/role/?username=admin&application=sys&type=menu HTTP/1.1" 200 0
[2020-07-01 09:37:26,053] [basehttp.py:157] [basehttp:log_message] [INFO]- "OPTIONS /sys/api/user/role/?username=admin&application=sys&type=button HTTP/1.1" 200 0
[2020-07-01 09:37:26,417] [basehttp.py:157] [basehttp:log_message] [INFO]- "GET /sys/api/user/role/?username=admin&application=sys&type=menu HTTP/1.1" 200 1161
[2020-07-01 09:37:26,434] [basehttp.py:157] [basehttp:log_message] [INFO]- "GET /sys/api/user/role/?username=admin&application=sys&type=button HTTP/1.1" 200 291
[2020-07-01 09:37:50,483] [basehttp.py:157] [basehttp:log_message] [INFO]- "GET /sys/api/user/role/?username=admin&application=sys&type=button HTTP/1.1" 200 291
[2020-07-01 09:37:50,484] [basehttp.py:157] [basehttp:log_message] [INFO]- "GET /sys/api/user/role/?username=admin&application=sys&type=menu HTTP/1.1" 200 1161
[2020-07-01 09:37:52,007] [basehttp.py:157] [basehttp:log_message] [INFO]- "GET /sys/api/menu/ HTTP/1.1" 200 15945
[2020-07-01 09:37:57,093] [basehttp.py:157] [basehttp:log_message] [INFO]- "GET /sys/api/menu/app_list/ HTTP/1.1" 200 25
[2020-07-01 09:38:18,679] [basehttp.py:157] [basehttp:log_message] [INFO]- "POST /sys/api/menu/ HTTP/1.1" 201 265
[2020-07-01 09:38:18,928] [basehttp.py:157] [basehttp:log_message] [INFO]- "GET /sys/api/menu/ HTTP/1.1" 200 16211
[2020-07-01 09:38:31,069] [basehttp.py:157] [basehttp:log_message] [INFO]- "GET /sys/api/menu/app_list/ HTTP/1.1" 200 38
[2020-07-01 09:39:24,663] [basehttp.py:157] [basehttp:log_message] [INFO]- "POST /sys/api/menu/ HTTP/1.1" 201 296
[2020-07-01 09:39:24,890] [basehttp.py:157] [basehttp:log_message] [INFO]- "GET /sys/api/menu/ HTTP/1.1" 200 16508
[2020-07-01 09:40:36,038] [basehttp.py:157] [basehttp:log_message] [INFO]- "GET /sys/api/menu/app_list/ HTTP/1.1" 200 38
[2020-07-01 09:40:52,774] [basehttp.py:157] [basehttp:log_message] [INFO]- "POST /sys/api/menu/ HTTP/1.1" 201 271
[2020-07-01 09:40:53,018] [basehttp.py:157] [basehttp:log_message] [INFO]- "GET /sys/api/menu/ HTTP/1.1" 200 16780
[2020-07-01 09:40:54,782] [basehttp.py:157] [basehttp:log_message] [INFO]- "GET /sys/api/menu/app_list/ HTTP/1.1" 200 38
[2020-07-01 09:41:54,119] [basehttp.py:157] [basehttp:log_message] [INFO]- "POST /sys/api/menu/ HTTP/1.1" 201 284
[2020-07-01 09:41:54,313] [basehttp.py:157] [basehttp:log_message] [INFO]- "GET /sys/api/menu/ HTTP/1.1" 200 17065
[2020-07-01 09:41:55,985] [basehttp.py:157] [basehttp:log_message] [INFO]- "GET /sys/api/menu/app_list/ HTTP/1.1" 200 38
[2020-07-01 09:44:16,126] [basehttp.py:157] [basehttp:log_message] [INFO]- "POST /sys/api/menu/ HTTP/1.1" 201 294
[2020-07-01 09:44:16,344] [basehttp.py:157] [basehttp:log_message] [INFO]- "GET /sys/api/menu/ HTTP/1.1" 200 17360
[2020-07-01 09:44:17,479] [basehttp.py:157] [basehttp:log_message] [INFO]- "GET /sys/api/menu/app_list/ HTTP/1.1" 200 38
[2020-07-01 09:45:04,106] [basehttp.py:157] [basehttp:log_message] [INFO]- "POST /sys/api/menu/ HTTP/1.1" 201 294
[2020-07-01 09:45:04,312] [basehttp.py:157] [basehttp:log_message] [INFO]- "GET /sys/api/menu/ HTTP/1.1" 200 17655
[2020-07-01 10:28:42,934] [log.py:222] [log:log_response] [ERROR]- Internal Server Error: /sys/api/user/role/
Traceback (most recent call last):
  File "/home/rock/anaconda3/envs/venv/lib/python3.8/site-packages/django/core/handlers/exception.py", line 34, in inner
    response = get_response(request)
  File "/home/rock/anaconda3/envs/venv/lib/python3.8/site-packages/django/core/handlers/base.py", line 115, in _get_response
    response = self.process_exception_by_middleware(e, request)
  File "/home/rock/anaconda3/envs/venv/lib/python3.8/site-packages/django/core/handlers/base.py", line 113, in _get_response
    response = wrapped_callback(request, *callback_args, **callback_kwargs)
  File "/home/rock/anaconda3/envs/venv/lib/python3.8/site-packages/django/views/decorators/csrf.py", line 54, in wrapped_view
    return view_func(*args, **kwargs)
  File "/home/rock/anaconda3/envs/venv/lib/python3.8/site-packages/rest_framework/viewsets.py", line 114, in view
    return self.dispatch(request, *args, **kwargs)
  File "/home/rock/anaconda3/envs/venv/lib/python3.8/site-packages/rest_framework/views.py", line 505, in dispatch
    response = self.handle_exception(exc)
  File "/home/rock/anaconda3/envs/venv/lib/python3.8/site-packages/rest_framework/views.py", line 465, in handle_exception
    self.raise_uncaught_exception(exc)
  File "/home/rock/anaconda3/envs/venv/lib/python3.8/site-packages/rest_framework/views.py", line 476, in raise_uncaught_exception
    raise exc
  File "/home/rock/anaconda3/envs/venv/lib/python3.8/site-packages/rest_framework/views.py", line 493, in dispatch
    self.initial(request, *args, **kwargs)
  File "/home/rock/anaconda3/envs/venv/lib/python3.8/site-packages/rest_framework/views.py", line 410, in initial
    self.perform_authentication(request)
  File "/home/rock/anaconda3/envs/venv/lib/python3.8/site-packages/rest_framework/views.py", line 324, in perform_authentication
    request.user
  File "/home/rock/anaconda3/envs/venv/lib/python3.8/site-packages/rest_framework/request.py", line 220, in user
    self._authenticate()
  File "/home/rock/anaconda3/envs/venv/lib/python3.8/site-packages/rest_framework/request.py", line 380, in _authenticate
    self.user, self.auth = user_auth_tuple
  File "/home/rock/anaconda3/envs/venv/lib/python3.8/site-packages/django/template/response.py", line 118, in __iter__
    raise ContentNotRenderedError(
django.template.response.ContentNotRenderedError: The response content must be rendered before it can be iterated over.
[2020-07-01 10:28:42,948] [basehttp.py:157] [basehttp:log_message] [ERROR]- "GET /sys/api/user/role/?username=admin&application=asset&type=button HTTP/1.1" 500 20211
[2020-07-01 10:28:42,961] [log.py:222] [log:log_response] [ERROR]- Internal Server Error: /sys/api/user/role/
Traceback (most recent call last):
  File "/home/rock/anaconda3/envs/venv/lib/python3.8/site-packages/django/core/handlers/exception.py", line 34, in inner
    response = get_response(request)
  File "/home/rock/anaconda3/envs/venv/lib/python3.8/site-packages/django/core/handlers/base.py", line 115, in _get_response
    response = self.process_exception_by_middleware(e, request)
  File "/home/rock/anaconda3/envs/venv/lib/python3.8/site-packages/django/core/handlers/base.py", line 113, in _get_response
    response = wrapped_callback(request, *callback_args, **callback_kwargs)
  File "/home/rock/anaconda3/envs/venv/lib/python3.8/site-packages/django/views/decorators/csrf.py", line 54, in wrapped_view
    return view_func(*args, **kwargs)
  File "/home/rock/anaconda3/envs/venv/lib/python3.8/site-packages/rest_framework/viewsets.py", line 114, in view
    return self.dispatch(request, *args, **kwargs)
  File "/home/rock/anaconda3/envs/venv/lib/python3.8/site-packages/rest_framework/views.py", line 505, in dispatch
    response = self.handle_exception(exc)
  File "/home/rock/anaconda3/envs/venv/lib/python3.8/site-packages/rest_framework/views.py", line 465, in handle_exception
    self.raise_uncaught_exception(exc)
  File "/home/rock/anaconda3/envs/venv/lib/python3.8/site-packages/rest_framework/views.py", line 476, in raise_uncaught_exception
    raise exc
  File "/home/rock/anaconda3/envs/venv/lib/python3.8/site-packages/rest_framework/views.py", line 493, in dispatch
    self.initial(request, *args, **kwargs)
  File "/home/rock/anaconda3/envs/venv/lib/python3.8/site-packages/rest_framework/views.py", line 410, in initial
    self.perform_authentication(request)
  File "/home/rock/anaconda3/envs/venv/lib/python3.8/site-packages/rest_framework/views.py", line 324, in perform_authentication
    request.user
  File "/home/rock/anaconda3/envs/venv/lib/python3.8/site-packages/rest_framework/request.py", line 220, in user
    self._authenticate()
  File "/home/rock/anaconda3/envs/venv/lib/python3.8/site-packages/rest_framework/request.py", line 380, in _authenticate
    self.user, self.auth = user_auth_tuple
  File "/home/rock/anaconda3/envs/venv/lib/python3.8/site-packages/django/template/response.py", line 118, in __iter__
    raise ContentNotRenderedError(
django.template.response.ContentNotRenderedError: The response content must be rendered before it can be iterated over.
[2020-07-01 10:28:42,964] [basehttp.py:157] [basehttp:log_message] [ERROR]- "GET /sys/api/user/role/?username=admin&application=asset&type=menu HTTP/1.1" 500 20205
[2020-07-01 10:28:57,560] [basehttp.py:157] [basehttp:log_message] [INFO]- "OPTIONS /sys/api/user/role?username=admin&application=sys&type=button HTTP/1.1" 200 0
[2020-07-01 10:28:57,561] [basehttp.py:157] [basehttp:log_message] [INFO]- "OPTIONS /sys/api/user/role?username=admin&application=sys&type=menu HTTP/1.1" 200 0
[2020-07-01 10:28:57,575] [basehttp.py:157] [basehttp:log_message] [INFO]- "OPTIONS /sys/api/user/role/?username=admin&application=sys&type=button HTTP/1.1" 200 0
[2020-07-01 10:28:57,575] [basehttp.py:157] [basehttp:log_message] [INFO]- "OPTIONS /sys/api/user/role/?username=admin&application=sys&type=menu HTTP/1.1" 200 0
[2020-07-01 10:28:57,868] [log.py:222] [log:log_response] [ERROR]- Internal Server Error: /sys/api/user/role/
Traceback (most recent call last):
  File "/home/rock/anaconda3/envs/venv/lib/python3.8/site-packages/django/core/handlers/exception.py", line 34, in inner
    response = get_response(request)
  File "/home/rock/anaconda3/envs/venv/lib/python3.8/site-packages/django/core/handlers/base.py", line 115, in _get_response
    response = self.process_exception_by_middleware(e, request)
  File "/home/rock/anaconda3/envs/venv/lib/python3.8/site-packages/django/core/handlers/base.py", line 113, in _get_response
    response = wrapped_callback(request, *callback_args, **callback_kwargs)
  File "/home/rock/anaconda3/envs/venv/lib/python3.8/site-packages/django/views/decorators/csrf.py", line 54, in wrapped_view
    return view_func(*args, **kwargs)
  File "/home/rock/anaconda3/envs/venv/lib/python3.8/site-packages/rest_framework/viewsets.py", line 114, in view
    return self.dispatch(request, *args, **kwargs)
  File "/home/rock/anaconda3/envs/venv/lib/python3.8/site-packages/rest_framework/views.py", line 505, in dispatch
    response = self.handle_exception(exc)
  File "/home/rock/anaconda3/envs/venv/lib/python3.8/site-packages/rest_framework/views.py", line 465, in handle_exception
    self.raise_uncaught_exception(exc)
  File "/home/rock/anaconda3/envs/venv/lib/python3.8/site-packages/rest_framework/views.py", line 476, in raise_uncaught_exception
    raise exc
  File "/home/rock/anaconda3/envs/venv/lib/python3.8/site-packages/rest_framework/views.py", line 493, in dispatch
    self.initial(request, *args, **kwargs)
  File "/home/rock/anaconda3/envs/venv/lib/python3.8/site-packages/rest_framework/views.py", line 410, in initial
    self.perform_authentication(request)
  File "/home/rock/anaconda3/envs/venv/lib/python3.8/site-packages/rest_framework/views.py", line 324, in perform_authentication
    request.user
  File "/home/rock/anaconda3/envs/venv/lib/python3.8/site-packages/rest_framework/request.py", line 220, in user
    self._authenticate()
  File "/home/rock/anaconda3/envs/venv/lib/python3.8/site-packages/rest_framework/request.py", line 380, in _authenticate
    self.user, self.auth = user_auth_tuple
  File "/home/rock/anaconda3/envs/venv/lib/python3.8/site-packages/django/template/response.py", line 118, in __iter__
    raise ContentNotRenderedError(
django.template.response.ContentNotRenderedError: The response content must be rendered before it can be iterated over.
[2020-07-01 10:28:57,871] [basehttp.py:157] [basehttp:log_message] [ERROR]- "GET /sys/api/user/role/?username=admin&application=sys&type=button HTTP/1.1" 500 19645
[2020-07-01 10:28:57,912] [log.py:222] [log:log_response] [ERROR]- Internal Server Error: /sys/api/user/role/
Traceback (most recent call last):
  File "/home/rock/anaconda3/envs/venv/lib/python3.8/site-packages/django/core/handlers/exception.py", line 34, in inner
    response = get_response(request)
  File "/home/rock/anaconda3/envs/venv/lib/python3.8/site-packages/django/core/handlers/base.py", line 115, in _get_response
    response = self.process_exception_by_middleware(e, request)
  File "/home/rock/anaconda3/envs/venv/lib/python3.8/site-packages/django/core/handlers/base.py", line 113, in _get_response
    response = wrapped_callback(request, *callback_args, **callback_kwargs)
  File "/home/rock/anaconda3/envs/venv/lib/python3.8/site-packages/django/views/decorators/csrf.py", line 54, in wrapped_view
    return view_func(*args, **kwargs)
  File "/home/rock/anaconda3/envs/venv/lib/python3.8/site-packages/rest_framework/viewsets.py", line 114, in view
    return self.dispatch(request, *args, **kwargs)
  File "/home/rock/anaconda3/envs/venv/lib/python3.8/site-packages/rest_framework/views.py", line 505, in dispatch
    response = self.handle_exception(exc)
  File "/home/rock/anaconda3/envs/venv/lib/python3.8/site-packages/rest_framework/views.py", line 465, in handle_exception
    self.raise_uncaught_exception(exc)
  File "/home/rock/anaconda3/envs/venv/lib/python3.8/site-packages/rest_framework/views.py", line 476, in raise_uncaught_exception
    raise exc
  File "/home/rock/anaconda3/envs/venv/lib/python3.8/site-packages/rest_framework/views.py", line 493, in dispatch
    self.initial(request, *args, **kwargs)
  File "/home/rock/anaconda3/envs/venv/lib/python3.8/site-packages/rest_framework/views.py", line 410, in initial
    self.perform_authentication(request)
  File "/home/rock/anaconda3/envs/venv/lib/python3.8/site-packages/rest_framework/views.py", line 324, in perform_authentication
    request.user
  File "/home/rock/anaconda3/envs/venv/lib/python3.8/site-packages/rest_framework/request.py", line 220, in user
    self._authenticate()
  File "/home/rock/anaconda3/envs/venv/lib/python3.8/site-packages/rest_framework/request.py", line 380, in _authenticate
    self.user, self.auth = user_auth_tuple
  File "/home/rock/anaconda3/envs/venv/lib/python3.8/site-packages/django/template/response.py", line 118, in __iter__
    raise ContentNotRenderedError(
django.template.response.ContentNotRenderedError: The response content must be rendered before it can be iterated over.
[2020-07-01 10:28:57,915] [basehttp.py:157] [basehttp:log_message] [ERROR]- "GET /sys/api/user/role/?username=admin&application=sys&type=menu HTTP/1.1" 500 19639
[2020-07-01 10:35:19,472] [log.py:222] [log:log_response] [WARNING]- Unauthorized: /sys/api/auth/
[2020-07-01 10:35:19,472] [basehttp.py:157] [basehttp:log_message] [WARNING]- "POST /sys/api/auth/ HTTP/1.1" 401 25
[2020-07-01 10:35:24,503] [basehttp.py:157] [basehttp:log_message] [INFO]- "POST /sys/api/auth/ HTTP/1.1" 200 65
[2020-07-01 10:35:26,847] [basehttp.py:157] [basehttp:log_message] [INFO]- "GET /sys/api/user/role/?username=admin&application=asset&type=menu HTTP/1.1" 200 6014
[2020-07-01 10:35:26,847] [basehttp.py:157] [basehttp:log_message] [INFO]- "GET /sys/api/user/role/?username=admin&application=asset&type=button HTTP/1.1" 200 60
[2020-07-01 10:38:45,435] [basehttp.py:157] [basehttp:log_message] [INFO]- "GET /sys/api/user/role?username=admin&application=automation&type=menu HTTP/1.1" 301 0
[2020-07-01 10:38:45,436] [basehttp.py:157] [basehttp:log_message] [INFO]- "GET /sys/api/user/role?username=admin&application=automation&type=button HTTP/1.1" 301 0
[2020-07-01 10:38:45,774] [log.py:222] [log:log_response] [ERROR]- Internal Server Error: /sys/api/user/role/
Traceback (most recent call last):
  File "/home/rock/anaconda3/envs/venv/lib/python3.8/site-packages/django/core/handlers/exception.py", line 34, in inner
    response = get_response(request)
  File "/home/rock/anaconda3/envs/venv/lib/python3.8/site-packages/django/core/handlers/base.py", line 115, in _get_response
    response = self.process_exception_by_middleware(e, request)
  File "/home/rock/anaconda3/envs/venv/lib/python3.8/site-packages/django/core/handlers/base.py", line 113, in _get_response
    response = wrapped_callback(request, *callback_args, **callback_kwargs)
  File "/home/rock/anaconda3/envs/venv/lib/python3.8/site-packages/django/views/decorators/csrf.py", line 54, in wrapped_view
    return view_func(*args, **kwargs)
  File "/home/rock/anaconda3/envs/venv/lib/python3.8/site-packages/rest_framework/viewsets.py", line 114, in view
    return self.dispatch(request, *args, **kwargs)
  File "/home/rock/anaconda3/envs/venv/lib/python3.8/site-packages/rest_framework/views.py", line 505, in dispatch
    response = self.handle_exception(exc)
  File "/home/rock/anaconda3/envs/venv/lib/python3.8/site-packages/rest_framework/views.py", line 465, in handle_exception
    self.raise_uncaught_exception(exc)
  File "/home/rock/anaconda3/envs/venv/lib/python3.8/site-packages/rest_framework/views.py", line 476, in raise_uncaught_exception
    raise exc
  File "/home/rock/anaconda3/envs/venv/lib/python3.8/site-packages/rest_framework/views.py", line 493, in dispatch
    self.initial(request, *args, **kwargs)
  File "/home/rock/anaconda3/envs/venv/lib/python3.8/site-packages/rest_framework/views.py", line 410, in initial
    self.perform_authentication(request)
  File "/home/rock/anaconda3/envs/venv/lib/python3.8/site-packages/rest_framework/views.py", line 324, in perform_authentication
    request.user
  File "/home/rock/anaconda3/envs/venv/lib/python3.8/site-packages/rest_framework/request.py", line 220, in user
    self._authenticate()
  File "/home/rock/anaconda3/envs/venv/lib/python3.8/site-packages/rest_framework/request.py", line 380, in _authenticate
    self.user, self.auth = user_auth_tuple
  File "/home/rock/anaconda3/envs/venv/lib/python3.8/site-packages/django/template/response.py", line 118, in __iter__
    raise ContentNotRenderedError(
django.template.response.ContentNotRenderedError: The response content must be rendered before it can be iterated over.
[2020-07-01 10:38:45,776] [basehttp.py:157] [basehttp:log_message] [ERROR]- "GET /sys/api/user/role/?username=admin&application=automation&type=button HTTP/1.1" 500 20226
[2020-07-01 10:38:45,822] [log.py:222] [log:log_response] [ERROR]- Internal Server Error: /sys/api/user/role/
Traceback (most recent call last):
  File "/home/rock/anaconda3/envs/venv/lib/python3.8/site-packages/django/core/handlers/exception.py", line 34, in inner
    response = get_response(request)
  File "/home/rock/anaconda3/envs/venv/lib/python3.8/site-packages/django/core/handlers/base.py", line 115, in _get_response
    response = self.process_exception_by_middleware(e, request)
  File "/home/rock/anaconda3/envs/venv/lib/python3.8/site-packages/django/core/handlers/base.py", line 113, in _get_response
    response = wrapped_callback(request, *callback_args, **callback_kwargs)
  File "/home/rock/anaconda3/envs/venv/lib/python3.8/site-packages/django/views/decorators/csrf.py", line 54, in wrapped_view
    return view_func(*args, **kwargs)
  File "/home/rock/anaconda3/envs/venv/lib/python3.8/site-packages/rest_framework/viewsets.py", line 114, in view
    return self.dispatch(request, *args, **kwargs)
  File "/home/rock/anaconda3/envs/venv/lib/python3.8/site-packages/rest_framework/views.py", line 505, in dispatch
    response = self.handle_exception(exc)
  File "/home/rock/anaconda3/envs/venv/lib/python3.8/site-packages/rest_framework/views.py", line 465, in handle_exception
    self.raise_uncaught_exception(exc)
  File "/home/rock/anaconda3/envs/venv/lib/python3.8/site-packages/rest_framework/views.py", line 476, in raise_uncaught_exception
    raise exc
  File "/home/rock/anaconda3/envs/venv/lib/python3.8/site-packages/rest_framework/views.py", line 493, in dispatch
    self.initial(request, *args, **kwargs)
  File "/home/rock/anaconda3/envs/venv/lib/python3.8/site-packages/rest_framework/views.py", line 410, in initial
    self.perform_authentication(request)
  File "/home/rock/anaconda3/envs/venv/lib/python3.8/site-packages/rest_framework/views.py", line 324, in perform_authentication
    request.user
  File "/home/rock/anaconda3/envs/venv/lib/python3.8/site-packages/rest_framework/request.py", line 220, in user
    self._authenticate()
  File "/home/rock/anaconda3/envs/venv/lib/python3.8/site-packages/rest_framework/request.py", line 380, in _authenticate
    self.user, self.auth = user_auth_tuple
  File "/home/rock/anaconda3/envs/venv/lib/python3.8/site-packages/django/template/response.py", line 118, in __iter__
    raise ContentNotRenderedError(
django.template.response.ContentNotRenderedError: The response content must be rendered before it can be iterated over.
[2020-07-01 10:38:45,825] [basehttp.py:157] [basehttp:log_message] [ERROR]- "GET /sys/api/user/role/?username=admin&application=automation&type=menu HTTP/1.1" 500 20220
[2020-07-01 10:38:55,158] [log.py:222] [log:log_response] [ERROR]- Internal Server Error: /sys/api/user/role/
Traceback (most recent call last):
  File "/home/rock/anaconda3/envs/venv/lib/python3.8/site-packages/django/core/handlers/exception.py", line 34, in inner
    response = get_response(request)
  File "/home/rock/anaconda3/envs/venv/lib/python3.8/site-packages/django/core/handlers/base.py", line 115, in _get_response
    response = self.process_exception_by_middleware(e, request)
  File "/home/rock/anaconda3/envs/venv/lib/python3.8/site-packages/django/core/handlers/base.py", line 113, in _get_response
    response = wrapped_callback(request, *callback_args, **callback_kwargs)
  File "/home/rock/anaconda3/envs/venv/lib/python3.8/site-packages/django/views/decorators/csrf.py", line 54, in wrapped_view
    return view_func(*args, **kwargs)
  File "/home/rock/anaconda3/envs/venv/lib/python3.8/site-packages/rest_framework/viewsets.py", line 114, in view
    return self.dispatch(request, *args, **kwargs)
  File "/home/rock/anaconda3/envs/venv/lib/python3.8/site-packages/rest_framework/views.py", line 505, in dispatch
    response = self.handle_exception(exc)
  File "/home/rock/anaconda3/envs/venv/lib/python3.8/site-packages/rest_framework/views.py", line 465, in handle_exception
    self.raise_uncaught_exception(exc)
  File "/home/rock/anaconda3/envs/venv/lib/python3.8/site-packages/rest_framework/views.py", line 476, in raise_uncaught_exception
    raise exc
  File "/home/rock/anaconda3/envs/venv/lib/python3.8/site-packages/rest_framework/views.py", line 493, in dispatch
    self.initial(request, *args, **kwargs)
  File "/home/rock/anaconda3/envs/venv/lib/python3.8/site-packages/rest_framework/views.py", line 410, in initial
    self.perform_authentication(request)
  File "/home/rock/anaconda3/envs/venv/lib/python3.8/site-packages/rest_framework/views.py", line 324, in perform_authentication
    request.user
  File "/home/rock/anaconda3/envs/venv/lib/python3.8/site-packages/rest_framework/request.py", line 220, in user
    self._authenticate()
  File "/home/rock/anaconda3/envs/venv/lib/python3.8/site-packages/rest_framework/request.py", line 380, in _authenticate
    self.user, self.auth = user_auth_tuple
  File "/home/rock/anaconda3/envs/venv/lib/python3.8/site-packages/django/template/response.py", line 118, in __iter__
    raise ContentNotRenderedError(
django.template.response.ContentNotRenderedError: The response content must be rendered before it can be iterated over.
[2020-07-01 10:38:55,161] [basehttp.py:157] [basehttp:log_message] [ERROR]- "GET /sys/api/user/role/?username=admin&application=sys&type=button HTTP/1.1" 500 19645
[2020-07-01 10:38:55,211] [log.py:222] [log:log_response] [ERROR]- Internal Server Error: /sys/api/user/role/
Traceback (most recent call last):
  File "/home/rock/anaconda3/envs/venv/lib/python3.8/site-packages/django/core/handlers/exception.py", line 34, in inner
    response = get_response(request)
  File "/home/rock/anaconda3/envs/venv/lib/python3.8/site-packages/django/core/handlers/base.py", line 115, in _get_response
    response = self.process_exception_by_middleware(e, request)
  File "/home/rock/anaconda3/envs/venv/lib/python3.8/site-packages/django/core/handlers/base.py", line 113, in _get_response
    response = wrapped_callback(request, *callback_args, **callback_kwargs)
  File "/home/rock/anaconda3/envs/venv/lib/python3.8/site-packages/django/views/decorators/csrf.py", line 54, in wrapped_view
    return view_func(*args, **kwargs)
  File "/home/rock/anaconda3/envs/venv/lib/python3.8/site-packages/rest_framework/viewsets.py", line 114, in view
    return self.dispatch(request, *args, **kwargs)
  File "/home/rock/anaconda3/envs/venv/lib/python3.8/site-packages/rest_framework/views.py", line 505, in dispatch
    response = self.handle_exception(exc)
  File "/home/rock/anaconda3/envs/venv/lib/python3.8/site-packages/rest_framework/views.py", line 465, in handle_exception
    self.raise_uncaught_exception(exc)
  File "/home/rock/anaconda3/envs/venv/lib/python3.8/site-packages/rest_framework/views.py", line 476, in raise_uncaught_exception
    raise exc
  File "/home/rock/anaconda3/envs/venv/lib/python3.8/site-packages/rest_framework/views.py", line 493, in dispatch
    self.initial(request, *args, **kwargs)
  File "/home/rock/anaconda3/envs/venv/lib/python3.8/site-packages/rest_framework/views.py", line 410, in initial
    self.perform_authentication(request)
  File "/home/rock/anaconda3/envs/venv/lib/python3.8/site-packages/rest_framework/views.py", line 324, in perform_authentication
    request.user
  File "/home/rock/anaconda3/envs/venv/lib/python3.8/site-packages/rest_framework/request.py", line 220, in user
    self._authenticate()
  File "/home/rock/anaconda3/envs/venv/lib/python3.8/site-packages/rest_framework/request.py", line 380, in _authenticate
    self.user, self.auth = user_auth_tuple
  File "/home/rock/anaconda3/envs/venv/lib/python3.8/site-packages/django/template/response.py", line 118, in __iter__
    raise ContentNotRenderedError(
django.template.response.ContentNotRenderedError: The response content must be rendered before it can be iterated over.
[2020-07-01 10:38:55,213] [basehttp.py:157] [basehttp:log_message] [ERROR]- "GET /sys/api/user/role/?username=admin&application=sys&type=menu HTTP/1.1" 500 19639
[2020-07-01 10:39:00,295] [basehttp.py:157] [basehttp:log_message] [INFO]- "OPTIONS /sys/api/user/role?username=admin&application=sys&type=menu HTTP/1.1" 200 0
[2020-07-01 10:39:00,297] [basehttp.py:157] [basehttp:log_message] [INFO]- "OPTIONS /sys/api/user/role?username=admin&application=sys&type=button HTTP/1.1" 200 0
[2020-07-01 10:39:00,355] [basehttp.py:157] [basehttp:log_message] [INFO]- "OPTIONS /sys/api/user/role/?username=admin&application=sys&type=button HTTP/1.1" 200 0
[2020-07-01 10:39:00,356] [basehttp.py:157] [basehttp:log_message] [INFO]- "OPTIONS /sys/api/user/role/?username=admin&application=sys&type=menu HTTP/1.1" 200 0
[2020-07-01 10:39:00,591] [log.py:222] [log:log_response] [ERROR]- Internal Server Error: /sys/api/user/role/
Traceback (most recent call last):
  File "/home/rock/anaconda3/envs/venv/lib/python3.8/site-packages/django/core/handlers/exception.py", line 34, in inner
    response = get_response(request)
  File "/home/rock/anaconda3/envs/venv/lib/python3.8/site-packages/django/core/handlers/base.py", line 115, in _get_response
    response = self.process_exception_by_middleware(e, request)
  File "/home/rock/anaconda3/envs/venv/lib/python3.8/site-packages/django/core/handlers/base.py", line 113, in _get_response
    response = wrapped_callback(request, *callback_args, **callback_kwargs)
  File "/home/rock/anaconda3/envs/venv/lib/python3.8/site-packages/django/views/decorators/csrf.py", line 54, in wrapped_view
    return view_func(*args, **kwargs)
  File "/home/rock/anaconda3/envs/venv/lib/python3.8/site-packages/rest_framework/viewsets.py", line 114, in view
    return self.dispatch(request, *args, **kwargs)
  File "/home/rock/anaconda3/envs/venv/lib/python3.8/site-packages/rest_framework/views.py", line 505, in dispatch
    response = self.handle_exception(exc)
  File "/home/rock/anaconda3/envs/venv/lib/python3.8/site-packages/rest_framework/views.py", line 465, in handle_exception
    self.raise_uncaught_exception(exc)
  File "/home/rock/anaconda3/envs/venv/lib/python3.8/site-packages/rest_framework/views.py", line 476, in raise_uncaught_exception
    raise exc
  File "/home/rock/anaconda3/envs/venv/lib/python3.8/site-packages/rest_framework/views.py", line 493, in dispatch
    self.initial(request, *args, **kwargs)
  File "/home/rock/anaconda3/envs/venv/lib/python3.8/site-packages/rest_framework/views.py", line 410, in initial
    self.perform_authentication(request)
  File "/home/rock/anaconda3/envs/venv/lib/python3.8/site-packages/rest_framework/views.py", line 324, in perform_authentication
    request.user
  File "/home/rock/anaconda3/envs/venv/lib/python3.8/site-packages/rest_framework/request.py", line 220, in user
    self._authenticate()
  File "/home/rock/anaconda3/envs/venv/lib/python3.8/site-packages/rest_framework/request.py", line 380, in _authenticate
    self.user, self.auth = user_auth_tuple
  File "/home/rock/anaconda3/envs/venv/lib/python3.8/site-packages/django/template/response.py", line 118, in __iter__
    raise ContentNotRenderedError(
django.template.response.ContentNotRenderedError: The response content must be rendered before it can be iterated over.
[2020-07-01 10:39:00,598] [basehttp.py:157] [basehttp:log_message] [ERROR]- "GET /sys/api/user/role/?username=admin&application=sys&type=button HTTP/1.1" 500 19645
[2020-07-01 10:39:00,624] [log.py:222] [log:log_response] [ERROR]- Internal Server Error: /sys/api/user/role/
Traceback (most recent call last):
  File "/home/rock/anaconda3/envs/venv/lib/python3.8/site-packages/django/core/handlers/exception.py", line 34, in inner
    response = get_response(request)
  File "/home/rock/anaconda3/envs/venv/lib/python3.8/site-packages/django/core/handlers/base.py", line 115, in _get_response
    response = self.process_exception_by_middleware(e, request)
  File "/home/rock/anaconda3/envs/venv/lib/python3.8/site-packages/django/core/handlers/base.py", line 113, in _get_response
    response = wrapped_callback(request, *callback_args, **callback_kwargs)
  File "/home/rock/anaconda3/envs/venv/lib/python3.8/site-packages/django/views/decorators/csrf.py", line 54, in wrapped_view
    return view_func(*args, **kwargs)
  File "/home/rock/anaconda3/envs/venv/lib/python3.8/site-packages/rest_framework/viewsets.py", line 114, in view
    return self.dispatch(request, *args, **kwargs)
  File "/home/rock/anaconda3/envs/venv/lib/python3.8/site-packages/rest_framework/views.py", line 505, in dispatch
    response = self.handle_exception(exc)
  File "/home/rock/anaconda3/envs/venv/lib/python3.8/site-packages/rest_framework/views.py", line 465, in handle_exception
    self.raise_uncaught_exception(exc)
  File "/home/rock/anaconda3/envs/venv/lib/python3.8/site-packages/rest_framework/views.py", line 476, in raise_uncaught_exception
    raise exc
  File "/home/rock/anaconda3/envs/venv/lib/python3.8/site-packages/rest_framework/views.py", line 493, in dispatch
    self.initial(request, *args, **kwargs)
  File "/home/rock/anaconda3/envs/venv/lib/python3.8/site-packages/rest_framework/views.py", line 410, in initial
    self.perform_authentication(request)
  File "/home/rock/anaconda3/envs/venv/lib/python3.8/site-packages/rest_framework/views.py", line 324, in perform_authentication
    request.user
  File "/home/rock/anaconda3/envs/venv/lib/python3.8/site-packages/rest_framework/request.py", line 220, in user
    self._authenticate()
  File "/home/rock/anaconda3/envs/venv/lib/python3.8/site-packages/rest_framework/request.py", line 380, in _authenticate
    self.user, self.auth = user_auth_tuple
  File "/home/rock/anaconda3/envs/venv/lib/python3.8/site-packages/django/template/response.py", line 118, in __iter__
    raise ContentNotRenderedError(
django.template.response.ContentNotRenderedError: The response content must be rendered before it can be iterated over.
[2020-07-01 10:39:00,625] [basehttp.py:157] [basehttp:log_message] [ERROR]- "GET /sys/api/user/role/?username=admin&application=sys&type=menu HTTP/1.1" 500 19639
[2020-07-01 10:42:01,044] [log.py:222] [log:log_response] [ERROR]- Internal Server Error: /sys/api/user/role/
Traceback (most recent call last):
  File "/home/rock/anaconda3/envs/venv/lib/python3.8/site-packages/django/core/handlers/exception.py", line 34, in inner
    response = get_response(request)
  File "/home/rock/anaconda3/envs/venv/lib/python3.8/site-packages/django/core/handlers/base.py", line 115, in _get_response
    response = self.process_exception_by_middleware(e, request)
  File "/home/rock/anaconda3/envs/venv/lib/python3.8/site-packages/django/core/handlers/base.py", line 113, in _get_response
    response = wrapped_callback(request, *callback_args, **callback_kwargs)
  File "/home/rock/anaconda3/envs/venv/lib/python3.8/site-packages/django/views/decorators/csrf.py", line 54, in wrapped_view
    return view_func(*args, **kwargs)
  File "/home/rock/anaconda3/envs/venv/lib/python3.8/site-packages/rest_framework/viewsets.py", line 114, in view
    return self.dispatch(request, *args, **kwargs)
  File "/home/rock/anaconda3/envs/venv/lib/python3.8/site-packages/rest_framework/views.py", line 505, in dispatch
    response = self.handle_exception(exc)
  File "/home/rock/anaconda3/envs/venv/lib/python3.8/site-packages/rest_framework/views.py", line 465, in handle_exception
    self.raise_uncaught_exception(exc)
  File "/home/rock/anaconda3/envs/venv/lib/python3.8/site-packages/rest_framework/views.py", line 476, in raise_uncaught_exception
    raise exc
  File "/home/rock/anaconda3/envs/venv/lib/python3.8/site-packages/rest_framework/views.py", line 493, in dispatch
    self.initial(request, *args, **kwargs)
  File "/home/rock/anaconda3/envs/venv/lib/python3.8/site-packages/rest_framework/views.py", line 410, in initial
    self.perform_authentication(request)
  File "/home/rock/anaconda3/envs/venv/lib/python3.8/site-packages/rest_framework/views.py", line 324, in perform_authentication
    request.user
  File "/home/rock/anaconda3/envs/venv/lib/python3.8/site-packages/rest_framework/request.py", line 220, in user
    self._authenticate()
  File "/home/rock/anaconda3/envs/venv/lib/python3.8/site-packages/rest_framework/request.py", line 380, in _authenticate
    self.user, self.auth = user_auth_tuple
  File "/home/rock/anaconda3/envs/venv/lib/python3.8/site-packages/django/template/response.py", line 118, in __iter__
    raise ContentNotRenderedError(
django.template.response.ContentNotRenderedError: The response content must be rendered before it can be iterated over.
[2020-07-01 10:42:01,073] [basehttp.py:157] [basehttp:log_message] [ERROR]- "GET /sys/api/user/role/?username=admin&application=automation&type=button HTTP/1.1" 500 20226
[2020-07-01 10:42:01,102] [log.py:222] [log:log_response] [ERROR]- Internal Server Error: /sys/api/user/role/
Traceback (most recent call last):
  File "/home/rock/anaconda3/envs/venv/lib/python3.8/site-packages/django/core/handlers/exception.py", line 34, in inner
    response = get_response(request)
  File "/home/rock/anaconda3/envs/venv/lib/python3.8/site-packages/django/core/handlers/base.py", line 115, in _get_response
    response = self.process_exception_by_middleware(e, request)
  File "/home/rock/anaconda3/envs/venv/lib/python3.8/site-packages/django/core/handlers/base.py", line 113, in _get_response
    response = wrapped_callback(request, *callback_args, **callback_kwargs)
  File "/home/rock/anaconda3/envs/venv/lib/python3.8/site-packages/django/views/decorators/csrf.py", line 54, in wrapped_view
    return view_func(*args, **kwargs)
  File "/home/rock/anaconda3/envs/venv/lib/python3.8/site-packages/rest_framework/viewsets.py", line 114, in view
    return self.dispatch(request, *args, **kwargs)
  File "/home/rock/anaconda3/envs/venv/lib/python3.8/site-packages/rest_framework/views.py", line 505, in dispatch
    response = self.handle_exception(exc)
  File "/home/rock/anaconda3/envs/venv/lib/python3.8/site-packages/rest_framework/views.py", line 465, in handle_exception
    self.raise_uncaught_exception(exc)
  File "/home/rock/anaconda3/envs/venv/lib/python3.8/site-packages/rest_framework/views.py", line 476, in raise_uncaught_exception
    raise exc
  File "/home/rock/anaconda3/envs/venv/lib/python3.8/site-packages/rest_framework/views.py", line 493, in dispatch
    self.initial(request, *args, **kwargs)
  File "/home/rock/anaconda3/envs/venv/lib/python3.8/site-packages/rest_framework/views.py", line 410, in initial
    self.perform_authentication(request)
  File "/home/rock/anaconda3/envs/venv/lib/python3.8/site-packages/rest_framework/views.py", line 324, in perform_authentication
    request.user
  File "/home/rock/anaconda3/envs/venv/lib/python3.8/site-packages/rest_framework/request.py", line 220, in user
    self._authenticate()
  File "/home/rock/anaconda3/envs/venv/lib/python3.8/site-packages/rest_framework/request.py", line 380, in _authenticate
    self.user, self.auth = user_auth_tuple
  File "/home/rock/anaconda3/envs/venv/lib/python3.8/site-packages/django/template/response.py", line 118, in __iter__
    raise ContentNotRenderedError(
django.template.response.ContentNotRenderedError: The response content must be rendered before it can be iterated over.
[2020-07-01 10:42:01,104] [basehttp.py:157] [basehttp:log_message] [ERROR]- "GET /sys/api/user/role/?username=admin&application=automation&type=menu HTTP/1.1" 500 20220
[2020-07-01 10:42:14,565] [log.py:222] [log:log_response] [ERROR]- Internal Server Error: /sys/api/user/role/
Traceback (most recent call last):
  File "/home/rock/anaconda3/envs/venv/lib/python3.8/site-packages/django/core/handlers/exception.py", line 34, in inner
    response = get_response(request)
  File "/home/rock/anaconda3/envs/venv/lib/python3.8/site-packages/django/core/handlers/base.py", line 115, in _get_response
    response = self.process_exception_by_middleware(e, request)
  File "/home/rock/anaconda3/envs/venv/lib/python3.8/site-packages/django/core/handlers/base.py", line 113, in _get_response
    response = wrapped_callback(request, *callback_args, **callback_kwargs)
  File "/home/rock/anaconda3/envs/venv/lib/python3.8/site-packages/django/views/decorators/csrf.py", line 54, in wrapped_view
    return view_func(*args, **kwargs)
  File "/home/rock/anaconda3/envs/venv/lib/python3.8/site-packages/rest_framework/viewsets.py", line 114, in view
    return self.dispatch(request, *args, **kwargs)
  File "/home/rock/anaconda3/envs/venv/lib/python3.8/site-packages/rest_framework/views.py", line 505, in dispatch
    response = self.handle_exception(exc)
  File "/home/rock/anaconda3/envs/venv/lib/python3.8/site-packages/rest_framework/views.py", line 465, in handle_exception
    self.raise_uncaught_exception(exc)
  File "/home/rock/anaconda3/envs/venv/lib/python3.8/site-packages/rest_framework/views.py", line 476, in raise_uncaught_exception
    raise exc
  File "/home/rock/anaconda3/envs/venv/lib/python3.8/site-packages/rest_framework/views.py", line 493, in dispatch
    self.initial(request, *args, **kwargs)
  File "/home/rock/anaconda3/envs/venv/lib/python3.8/site-packages/rest_framework/views.py", line 410, in initial
    self.perform_authentication(request)
  File "/home/rock/anaconda3/envs/venv/lib/python3.8/site-packages/rest_framework/views.py", line 324, in perform_authentication
    request.user
  File "/home/rock/anaconda3/envs/venv/lib/python3.8/site-packages/rest_framework/request.py", line 220, in user
    self._authenticate()
  File "/home/rock/anaconda3/envs/venv/lib/python3.8/site-packages/rest_framework/request.py", line 380, in _authenticate
    self.user, self.auth = user_auth_tuple
  File "/home/rock/anaconda3/envs/venv/lib/python3.8/site-packages/django/template/response.py", line 118, in __iter__
    raise ContentNotRenderedError(
django.template.response.ContentNotRenderedError: The response content must be rendered before it can be iterated over.
[2020-07-01 10:42:14,586] [log.py:222] [log:log_response] [ERROR]- Internal Server Error: /sys/api/user/role/
Traceback (most recent call last):
  File "/home/rock/anaconda3/envs/venv/lib/python3.8/site-packages/django/core/handlers/exception.py", line 34, in inner
    response = get_response(request)
  File "/home/rock/anaconda3/envs/venv/lib/python3.8/site-packages/django/core/handlers/base.py", line 115, in _get_response
    response = self.process_exception_by_middleware(e, request)
  File "/home/rock/anaconda3/envs/venv/lib/python3.8/site-packages/django/core/handlers/base.py", line 113, in _get_response
    response = wrapped_callback(request, *callback_args, **callback_kwargs)
  File "/home/rock/anaconda3/envs/venv/lib/python3.8/site-packages/django/views/decorators/csrf.py", line 54, in wrapped_view
    return view_func(*args, **kwargs)
  File "/home/rock/anaconda3/envs/venv/lib/python3.8/site-packages/rest_framework/viewsets.py", line 114, in view
    return self.dispatch(request, *args, **kwargs)
  File "/home/rock/anaconda3/envs/venv/lib/python3.8/site-packages/rest_framework/views.py", line 505, in dispatch
    response = self.handle_exception(exc)
  File "/home/rock/anaconda3/envs/venv/lib/python3.8/site-packages/rest_framework/views.py", line 465, in handle_exception
    self.raise_uncaught_exception(exc)
  File "/home/rock/anaconda3/envs/venv/lib/python3.8/site-packages/rest_framework/views.py", line 476, in raise_uncaught_exception
    raise exc
  File "/home/rock/anaconda3/envs/venv/lib/python3.8/site-packages/rest_framework/views.py", line 493, in dispatch
    self.initial(request, *args, **kwargs)
  File "/home/rock/anaconda3/envs/venv/lib/python3.8/site-packages/rest_framework/views.py", line 410, in initial
    self.perform_authentication(request)
  File "/home/rock/anaconda3/envs/venv/lib/python3.8/site-packages/rest_framework/views.py", line 324, in perform_authentication
    request.user
  File "/home/rock/anaconda3/envs/venv/lib/python3.8/site-packages/rest_framework/request.py", line 220, in user
    self._authenticate()
  File "/home/rock/anaconda3/envs/venv/lib/python3.8/site-packages/rest_framework/request.py", line 380, in _authenticate
    self.user, self.auth = user_auth_tuple
  File "/home/rock/anaconda3/envs/venv/lib/python3.8/site-packages/django/template/response.py", line 118, in __iter__
    raise ContentNotRenderedError(
django.template.response.ContentNotRenderedError: The response content must be rendered before it can be iterated over.
[2020-07-01 10:42:14,588] [basehttp.py:157] [basehttp:log_message] [ERROR]- "GET /sys/api/user/role/?username=admin&application=automation&type=button HTTP/1.1" 500 20226
[2020-07-01 10:42:14,591] [basehttp.py:157] [basehttp:log_message] [ERROR]- "GET /sys/api/user/role/?username=admin&application=automation&type=menu HTTP/1.1" 500 20220
[2020-07-01 10:56:32,994] [autoreload.py:222] [autoreload:trigger_reload] [INFO]- /home/rock/quality_inspection/python-workspace/project-sys/sys_auth/views.py changed, reloading.
