[2020-10-19 09:16:18,348] [autoreload.py:598] [autoreload:run_with_reloader] [INFO]- Watching for file changes with StatReloader
[2020-10-19 09:19:07,656] [basehttp.py:157] [basehttp:log_message] [INFO]- "POST /sys/api/auth/ HTTP/1.1" 200 65
[2020-10-19 09:19:12,751] [basehttp.py:157] [basehttp:log_message] [INFO]- "GET /sys/api/user/role/?username=wl&application=automation&type=button HTTP/1.1" 200 2
[2020-10-19 09:19:12,752] [basehttp.py:157] [basehttp:log_message] [INFO]- "GET /sys/api/user/role/?username=wl&application=automation&type=menu HTTP/1.1" 200 7733
[2020-10-19 09:19:19,399] [basehttp.py:157] [basehttp:log_message] [INFO]- "POST /sys/api/auth/ HTTP/1.1" 200 65
[2020-10-19 09:19:23,509] [basehttp.py:157] [basehttp:log_message] [INFO]- "POST /sys/api/auth/ HTTP/1.1" 200 65
[2020-10-19 09:19:23,660] [basehttp.py:157] [basehttp:log_message] [INFO]- "POST /sys/api/auth/ HTTP/1.1" 200 65
[2020-10-19 09:20:25,972] [basehttp.py:157] [basehttp:log_message] [INFO]- "POST /sys/api/auth/ HTTP/1.1" 200 65
[2020-10-19 09:20:25,973] [basehttp.py:157] [basehttp:log_message] [INFO]- "POST /sys/api/auth/ HTTP/1.1" 200 65
[2020-10-19 09:20:25,988] [basehttp.py:157] [basehttp:log_message] [INFO]- "POST /sys/api/auth/ HTTP/1.1" 200 65
[2020-10-19 09:20:25,989] [basehttp.py:157] [basehttp:log_message] [INFO]- "POST /sys/api/auth/ HTTP/1.1" 200 65
[2020-10-19 09:20:29,060] [basehttp.py:157] [basehttp:log_message] [INFO]- "POST /sys/api/auth/ HTTP/1.1" 200 65
[2020-10-19 10:24:45,380] [basehttp.py:157] [basehttp:log_message] [INFO]- "GET /sys/api/user/role/?username=wl&application=sys&type=menu HTTP/1.1" 200 1161
[2020-10-19 10:24:45,380] [basehttp.py:157] [basehttp:log_message] [INFO]- "GET /sys/api/user/role/?username=wl&application=sys&type=button HTTP/1.1" 200 291
[2020-10-19 10:24:48,062] [basehttp.py:157] [basehttp:log_message] [INFO]- "GET /sys/api/user/?current_page=1&pre_page=10 HTTP/1.1" 200 222158
[2020-10-19 10:24:49,229] [basehttp.py:157] [basehttp:log_message] [INFO]- "GET /sys/api/role/?current_page=1&pre_page=10 HTTP/1.1" 200 57972
[2020-10-19 10:24:53,480] [basehttp.py:157] [basehttp:log_message] [INFO]- "GET /sys/api/user/?current_page=1&pre_page=10 HTTP/1.1" 200 222158
[2020-10-19 10:24:54,744] [basehttp.py:157] [basehttp:log_message] [INFO]- "GET /sys/api/menu/ HTTP/1.1" 200 31720
[2020-10-19 10:24:58,734] [basehttp.py:157] [basehttp:log_message] [INFO]- "GET /sys/api/user/?current_page=1&pre_page=10 HTTP/1.1" 200 222158
[2020-10-19 10:26:01,874] [basehttp.py:157] [basehttp:log_message] [INFO]- "GET /sys/api/user/?current_page=1&pre_page=10 HTTP/1.1" 200 222158
[2020-10-19 10:34:34,596] [basehttp.py:157] [basehttp:log_message] [INFO]- "GET /sys/api/user/role/?username=wl&application=sys&type=button HTTP/1.1" 200 291
[2020-10-19 10:34:34,605] [basehttp.py:157] [basehttp:log_message] [INFO]- "GET /sys/api/user/role/?username=wl&application=sys&type=menu HTTP/1.1" 200 1161
[2020-10-19 10:34:34,773] [basehttp.py:157] [basehttp:log_message] [INFO]- "GET /sys/api/user/?current_page=1&pre_page=10 HTTP/1.1" 200 222158
[2020-10-19 10:36:10,911] [basehttp.py:157] [basehttp:log_message] [INFO]- "GET /sys/api/user/role/?username=wl&application=sys&type=button HTTP/1.1" 200 291
[2020-10-19 10:36:10,912] [basehttp.py:157] [basehttp:log_message] [INFO]- "GET /sys/api/user/role/?username=wl&application=sys&type=menu HTTP/1.1" 200 1161
[2020-10-19 10:36:11,243] [basehttp.py:157] [basehttp:log_message] [INFO]- "GET /sys/api/user/?current_page=1&pre_page=10 HTTP/1.1" 200 222158
[2020-10-19 10:39:11,508] [basehttp.py:157] [basehttp:log_message] [INFO]- "GET /sys/api/user/role/?username=wl&application=sys&type=button HTTP/1.1" 200 291
[2020-10-19 10:39:11,692] [basehttp.py:157] [basehttp:log_message] [INFO]- "GET /sys/api/user/role/?username=wl&application=sys&type=menu HTTP/1.1" 200 1161
[2020-10-19 10:39:12,079] [basehttp.py:157] [basehttp:log_message] [INFO]- "GET /sys/api/user/?current_page=1&pre_page=10 HTTP/1.1" 200 222158
[2020-10-19 11:07:07,896] [basehttp.py:157] [basehttp:log_message] [INFO]- "GET /sys/api/user/role/?username=wl&application=sys&type=button HTTP/1.1" 200 291
[2020-10-19 11:07:07,897] [basehttp.py:157] [basehttp:log_message] [INFO]- "GET /sys/api/user/role/?username=wl&application=sys&type=menu HTTP/1.1" 200 1161
[2020-10-19 11:07:08,120] [basehttp.py:157] [basehttp:log_message] [INFO]- "GET /sys/api/user/?current_page=1&pre_page=10 HTTP/1.1" 200 222158
[2020-10-19 11:07:19,999] [basehttp.py:157] [basehttp:log_message] [INFO]- "GET /sys/api/user/role/?username=wl&application=sys&type=menu HTTP/1.1" 200 1161
[2020-10-19 11:07:19,999] [basehttp.py:157] [basehttp:log_message] [INFO]- "GET /sys/api/user/role/?username=wl&application=sys&type=button HTTP/1.1" 200 291
[2020-10-19 11:07:20,227] [basehttp.py:157] [basehttp:log_message] [INFO]- "GET /sys/api/user/?current_page=1&pre_page=10 HTTP/1.1" 200 222158
[2020-10-19 11:08:11,366] [log.py:222] [log:log_response] [ERROR]- Internal Server Error: /sys/api/user/role/
Traceback (most recent call last):
  File "/home/rock/anaconda3/envs/venv/lib/python3.8/site-packages/django/db/backends/base/base.py", line 220, in ensure_connection
    self.connect()
  File "/home/rock/anaconda3/envs/venv/lib/python3.8/site-packages/django/utils/asyncio.py", line 26, in inner
    return func(*args, **kwargs)
  File "/home/rock/anaconda3/envs/venv/lib/python3.8/site-packages/django/db/backends/base/base.py", line 197, in connect
    self.connection = self.get_new_connection(conn_params)
  File "/home/rock/anaconda3/envs/venv/lib/python3.8/site-packages/django/utils/asyncio.py", line 26, in inner
    return func(*args, **kwargs)
  File "/home/rock/anaconda3/envs/venv/lib/python3.8/site-packages/django/db/backends/mysql/base.py", line 233, in get_new_connection
    return Database.connect(**conn_params)
  File "/home/rock/anaconda3/envs/venv/lib/python3.8/site-packages/MySQLdb/__init__.py", line 84, in Connect
    return Connection(*args, **kwargs)
  File "/home/rock/anaconda3/envs/venv/lib/python3.8/site-packages/MySQLdb/connections.py", line 179, in __init__
    super(Connection, self).__init__(*args, **kwargs2)
MySQLdb._exceptions.OperationalError: (1040, 'Too many connections')

The above exception was the direct cause of the following exception:

Traceback (most recent call last):
  File "/home/rock/anaconda3/envs/venv/lib/python3.8/site-packages/django/core/handlers/exception.py", line 34, in inner
    response = get_response(request)
  File "/home/rock/anaconda3/envs/venv/lib/python3.8/site-packages/django/core/handlers/base.py", line 115, in _get_response
    response = self.process_exception_by_middleware(e, request)
  File "/home/rock/anaconda3/envs/venv/lib/python3.8/site-packages/django/core/handlers/base.py", line 113, in _get_response
    response = wrapped_callback(request, *callback_args, **callback_kwargs)
  File "/home/rock/anaconda3/envs/venv/lib/python3.8/site-packages/django/views/decorators/csrf.py", line 54, in wrapped_view
    return view_func(*args, **kwargs)
  File "/home/rock/anaconda3/envs/venv/lib/python3.8/site-packages/rest_framework/viewsets.py", line 114, in view
    return self.dispatch(request, *args, **kwargs)
  File "/home/rock/anaconda3/envs/venv/lib/python3.8/site-packages/rest_framework/views.py", line 505, in dispatch
    response = self.handle_exception(exc)
  File "/home/rock/anaconda3/envs/venv/lib/python3.8/site-packages/rest_framework/views.py", line 465, in handle_exception
    self.raise_uncaught_exception(exc)
  File "/home/rock/anaconda3/envs/venv/lib/python3.8/site-packages/rest_framework/views.py", line 476, in raise_uncaught_exception
    raise exc
  File "/home/rock/anaconda3/envs/venv/lib/python3.8/site-packages/rest_framework/views.py", line 493, in dispatch
    self.initial(request, *args, **kwargs)
  File "/home/rock/anaconda3/envs/venv/lib/python3.8/site-packages/rest_framework/views.py", line 410, in initial
    self.perform_authentication(request)
  File "/home/rock/anaconda3/envs/venv/lib/python3.8/site-packages/rest_framework/views.py", line 324, in perform_authentication
    request.user
  File "/home/rock/anaconda3/envs/venv/lib/python3.8/site-packages/rest_framework/request.py", line 220, in user
    self._authenticate()
  File "/home/rock/anaconda3/envs/venv/lib/python3.8/site-packages/rest_framework/request.py", line 373, in _authenticate
    user_auth_tuple = authenticator.authenticate(self)
  File "/home/rock/quality_inspection/python-workspace/project-sys/sys_auth/views.py", line 39, in authenticate
    token_obj = Token.objects.filter(token=token).first()
  File "/home/rock/anaconda3/envs/venv/lib/python3.8/site-packages/django/db/models/query.py", line 664, in first
    for obj in (self if self.ordered else self.order_by('pk'))[:1]:
  File "/home/rock/anaconda3/envs/venv/lib/python3.8/site-packages/django/db/models/query.py", line 276, in __iter__
    self._fetch_all()
  File "/home/rock/anaconda3/envs/venv/lib/python3.8/site-packages/django/db/models/query.py", line 1261, in _fetch_all
    self._result_cache = list(self._iterable_class(self))
  File "/home/rock/anaconda3/envs/venv/lib/python3.8/site-packages/django/db/models/query.py", line 57, in __iter__
    results = compiler.execute_sql(chunked_fetch=self.chunked_fetch, chunk_size=self.chunk_size)
  File "/home/rock/anaconda3/envs/venv/lib/python3.8/site-packages/django/db/models/sql/compiler.py", line 1149, in execute_sql
    cursor = self.connection.cursor()
  File "/home/rock/anaconda3/envs/venv/lib/python3.8/site-packages/django/utils/asyncio.py", line 26, in inner
    return func(*args, **kwargs)
  File "/home/rock/anaconda3/envs/venv/lib/python3.8/site-packages/django/db/backends/base/base.py", line 260, in cursor
    return self._cursor()
  File "/home/rock/anaconda3/envs/venv/lib/python3.8/site-packages/django/db/backends/base/base.py", line 236, in _cursor
    self.ensure_connection()
  File "/home/rock/anaconda3/envs/venv/lib/python3.8/site-packages/django/utils/asyncio.py", line 26, in inner
    return func(*args, **kwargs)
  File "/home/rock/anaconda3/envs/venv/lib/python3.8/site-packages/django/db/backends/base/base.py", line 220, in ensure_connection
    self.connect()
  File "/home/rock/anaconda3/envs/venv/lib/python3.8/site-packages/django/db/utils.py", line 90, in __exit__
    raise dj_exc_value.with_traceback(traceback) from exc_value
  File "/home/rock/anaconda3/envs/venv/lib/python3.8/site-packages/django/db/backends/base/base.py", line 220, in ensure_connection
    self.connect()
  File "/home/rock/anaconda3/envs/venv/lib/python3.8/site-packages/django/utils/asyncio.py", line 26, in inner
    return func(*args, **kwargs)
  File "/home/rock/anaconda3/envs/venv/lib/python3.8/site-packages/django/db/backends/base/base.py", line 197, in connect
    self.connection = self.get_new_connection(conn_params)
  File "/home/rock/anaconda3/envs/venv/lib/python3.8/site-packages/django/utils/asyncio.py", line 26, in inner
    return func(*args, **kwargs)
  File "/home/rock/anaconda3/envs/venv/lib/python3.8/site-packages/django/db/backends/mysql/base.py", line 233, in get_new_connection
    return Database.connect(**conn_params)
  File "/home/rock/anaconda3/envs/venv/lib/python3.8/site-packages/MySQLdb/__init__.py", line 84, in Connect
    return Connection(*args, **kwargs)
  File "/home/rock/anaconda3/envs/venv/lib/python3.8/site-packages/MySQLdb/connections.py", line 179, in __init__
    super(Connection, self).__init__(*args, **kwargs2)
django.db.utils.OperationalError: (1040, 'Too many connections')
[2020-10-19 11:08:11,372] [log.py:222] [log:log_response] [ERROR]- Internal Server Error: /sys/api/user/role/
Traceback (most recent call last):
  File "/home/rock/anaconda3/envs/venv/lib/python3.8/site-packages/django/db/backends/base/base.py", line 220, in ensure_connection
    self.connect()
  File "/home/rock/anaconda3/envs/venv/lib/python3.8/site-packages/django/utils/asyncio.py", line 26, in inner
    return func(*args, **kwargs)
  File "/home/rock/anaconda3/envs/venv/lib/python3.8/site-packages/django/db/backends/base/base.py", line 197, in connect
    self.connection = self.get_new_connection(conn_params)
  File "/home/rock/anaconda3/envs/venv/lib/python3.8/site-packages/django/utils/asyncio.py", line 26, in inner
    return func(*args, **kwargs)
  File "/home/rock/anaconda3/envs/venv/lib/python3.8/site-packages/django/db/backends/mysql/base.py", line 233, in get_new_connection
    return Database.connect(**conn_params)
  File "/home/rock/anaconda3/envs/venv/lib/python3.8/site-packages/MySQLdb/__init__.py", line 84, in Connect
    return Connection(*args, **kwargs)
  File "/home/rock/anaconda3/envs/venv/lib/python3.8/site-packages/MySQLdb/connections.py", line 179, in __init__
    super(Connection, self).__init__(*args, **kwargs2)
MySQLdb._exceptions.OperationalError: (1040, 'Too many connections')

The above exception was the direct cause of the following exception:

Traceback (most recent call last):
  File "/home/rock/anaconda3/envs/venv/lib/python3.8/site-packages/django/core/handlers/exception.py", line 34, in inner
    response = get_response(request)
  File "/home/rock/anaconda3/envs/venv/lib/python3.8/site-packages/django/core/handlers/base.py", line 115, in _get_response
    response = self.process_exception_by_middleware(e, request)
  File "/home/rock/anaconda3/envs/venv/lib/python3.8/site-packages/django/core/handlers/base.py", line 113, in _get_response
    response = wrapped_callback(request, *callback_args, **callback_kwargs)
  File "/home/rock/anaconda3/envs/venv/lib/python3.8/site-packages/django/views/decorators/csrf.py", line 54, in wrapped_view
    return view_func(*args, **kwargs)
  File "/home/rock/anaconda3/envs/venv/lib/python3.8/site-packages/rest_framework/viewsets.py", line 114, in view
    return self.dispatch(request, *args, **kwargs)
  File "/home/rock/anaconda3/envs/venv/lib/python3.8/site-packages/rest_framework/views.py", line 505, in dispatch
    response = self.handle_exception(exc)
  File "/home/rock/anaconda3/envs/venv/lib/python3.8/site-packages/rest_framework/views.py", line 465, in handle_exception
    self.raise_uncaught_exception(exc)
  File "/home/rock/anaconda3/envs/venv/lib/python3.8/site-packages/rest_framework/views.py", line 476, in raise_uncaught_exception
    raise exc
  File "/home/rock/anaconda3/envs/venv/lib/python3.8/site-packages/rest_framework/views.py", line 493, in dispatch
    self.initial(request, *args, **kwargs)
  File "/home/rock/anaconda3/envs/venv/lib/python3.8/site-packages/rest_framework/views.py", line 410, in initial
    self.perform_authentication(request)
  File "/home/rock/anaconda3/envs/venv/lib/python3.8/site-packages/rest_framework/views.py", line 324, in perform_authentication
    request.user
  File "/home/rock/anaconda3/envs/venv/lib/python3.8/site-packages/rest_framework/request.py", line 220, in user
    self._authenticate()
  File "/home/rock/anaconda3/envs/venv/lib/python3.8/site-packages/rest_framework/request.py", line 373, in _authenticate
    user_auth_tuple = authenticator.authenticate(self)
  File "/home/rock/quality_inspection/python-workspace/project-sys/sys_auth/views.py", line 39, in authenticate
    token_obj = Token.objects.filter(token=token).first()
  File "/home/rock/anaconda3/envs/venv/lib/python3.8/site-packages/django/db/models/query.py", line 664, in first
    for obj in (self if self.ordered else self.order_by('pk'))[:1]:
  File "/home/rock/anaconda3/envs/venv/lib/python3.8/site-packages/django/db/models/query.py", line 276, in __iter__
    self._fetch_all()
  File "/home/rock/anaconda3/envs/venv/lib/python3.8/site-packages/django/db/models/query.py", line 1261, in _fetch_all
    self._result_cache = list(self._iterable_class(self))
  File "/home/rock/anaconda3/envs/venv/lib/python3.8/site-packages/django/db/models/query.py", line 57, in __iter__
    results = compiler.execute_sql(chunked_fetch=self.chunked_fetch, chunk_size=self.chunk_size)
  File "/home/rock/anaconda3/envs/venv/lib/python3.8/site-packages/django/db/models/sql/compiler.py", line 1149, in execute_sql
    cursor = self.connection.cursor()
  File "/home/rock/anaconda3/envs/venv/lib/python3.8/site-packages/django/utils/asyncio.py", line 26, in inner
    return func(*args, **kwargs)
  File "/home/rock/anaconda3/envs/venv/lib/python3.8/site-packages/django/db/backends/base/base.py", line 260, in cursor
    return self._cursor()
  File "/home/rock/anaconda3/envs/venv/lib/python3.8/site-packages/django/db/backends/base/base.py", line 236, in _cursor
    self.ensure_connection()
  File "/home/rock/anaconda3/envs/venv/lib/python3.8/site-packages/django/utils/asyncio.py", line 26, in inner
    return func(*args, **kwargs)
  File "/home/rock/anaconda3/envs/venv/lib/python3.8/site-packages/django/db/backends/base/base.py", line 220, in ensure_connection
    self.connect()
  File "/home/rock/anaconda3/envs/venv/lib/python3.8/site-packages/django/db/utils.py", line 90, in __exit__
    raise dj_exc_value.with_traceback(traceback) from exc_value
  File "/home/rock/anaconda3/envs/venv/lib/python3.8/site-packages/django/db/backends/base/base.py", line 220, in ensure_connection
    self.connect()
  File "/home/rock/anaconda3/envs/venv/lib/python3.8/site-packages/django/utils/asyncio.py", line 26, in inner
    return func(*args, **kwargs)
  File "/home/rock/anaconda3/envs/venv/lib/python3.8/site-packages/django/db/backends/base/base.py", line 197, in connect
    self.connection = self.get_new_connection(conn_params)
  File "/home/rock/anaconda3/envs/venv/lib/python3.8/site-packages/django/utils/asyncio.py", line 26, in inner
    return func(*args, **kwargs)
  File "/home/rock/anaconda3/envs/venv/lib/python3.8/site-packages/django/db/backends/mysql/base.py", line 233, in get_new_connection
    return Database.connect(**conn_params)
  File "/home/rock/anaconda3/envs/venv/lib/python3.8/site-packages/MySQLdb/__init__.py", line 84, in Connect
    return Connection(*args, **kwargs)
  File "/home/rock/anaconda3/envs/venv/lib/python3.8/site-packages/MySQLdb/connections.py", line 179, in __init__
    super(Connection, self).__init__(*args, **kwargs2)
django.db.utils.OperationalError: (1040, 'Too many connections')
[2020-10-19 11:08:11,378] [log.py:222] [log:log_response] [ERROR]- Internal Server Error: /sys/api/user/
Traceback (most recent call last):
  File "/home/rock/anaconda3/envs/venv/lib/python3.8/site-packages/django/db/backends/base/base.py", line 220, in ensure_connection
    self.connect()
  File "/home/rock/anaconda3/envs/venv/lib/python3.8/site-packages/django/utils/asyncio.py", line 26, in inner
    return func(*args, **kwargs)
  File "/home/rock/anaconda3/envs/venv/lib/python3.8/site-packages/django/db/backends/base/base.py", line 197, in connect
    self.connection = self.get_new_connection(conn_params)
  File "/home/rock/anaconda3/envs/venv/lib/python3.8/site-packages/django/utils/asyncio.py", line 26, in inner
    return func(*args, **kwargs)
  File "/home/rock/anaconda3/envs/venv/lib/python3.8/site-packages/django/db/backends/mysql/base.py", line 233, in get_new_connection
    return Database.connect(**conn_params)
  File "/home/rock/anaconda3/envs/venv/lib/python3.8/site-packages/MySQLdb/__init__.py", line 84, in Connect
    return Connection(*args, **kwargs)
  File "/home/rock/anaconda3/envs/venv/lib/python3.8/site-packages/MySQLdb/connections.py", line 179, in __init__
    super(Connection, self).__init__(*args, **kwargs2)
MySQLdb._exceptions.OperationalError: (1040, 'Too many connections')

The above exception was the direct cause of the following exception:

Traceback (most recent call last):
  File "/home/rock/anaconda3/envs/venv/lib/python3.8/site-packages/django/core/handlers/exception.py", line 34, in inner
    response = get_response(request)
  File "/home/rock/anaconda3/envs/venv/lib/python3.8/site-packages/django/core/handlers/base.py", line 115, in _get_response
    response = self.process_exception_by_middleware(e, request)
  File "/home/rock/anaconda3/envs/venv/lib/python3.8/site-packages/django/core/handlers/base.py", line 113, in _get_response
    response = wrapped_callback(request, *callback_args, **callback_kwargs)
  File "/home/rock/anaconda3/envs/venv/lib/python3.8/site-packages/django/views/decorators/csrf.py", line 54, in wrapped_view
    return view_func(*args, **kwargs)
  File "/home/rock/anaconda3/envs/venv/lib/python3.8/site-packages/rest_framework/viewsets.py", line 114, in view
    return self.dispatch(request, *args, **kwargs)
  File "/home/rock/anaconda3/envs/venv/lib/python3.8/site-packages/rest_framework/views.py", line 505, in dispatch
    response = self.handle_exception(exc)
  File "/home/rock/anaconda3/envs/venv/lib/python3.8/site-packages/rest_framework/views.py", line 465, in handle_exception
    self.raise_uncaught_exception(exc)
  File "/home/rock/anaconda3/envs/venv/lib/python3.8/site-packages/rest_framework/views.py", line 476, in raise_uncaught_exception
    raise exc
  File "/home/rock/anaconda3/envs/venv/lib/python3.8/site-packages/rest_framework/views.py", line 493, in dispatch
    self.initial(request, *args, **kwargs)
  File "/home/rock/anaconda3/envs/venv/lib/python3.8/site-packages/rest_framework/views.py", line 410, in initial
    self.perform_authentication(request)
  File "/home/rock/anaconda3/envs/venv/lib/python3.8/site-packages/rest_framework/views.py", line 324, in perform_authentication
    request.user
  File "/home/rock/anaconda3/envs/venv/lib/python3.8/site-packages/rest_framework/request.py", line 220, in user
    self._authenticate()
  File "/home/rock/anaconda3/envs/venv/lib/python3.8/site-packages/rest_framework/request.py", line 373, in _authenticate
    user_auth_tuple = authenticator.authenticate(self)
  File "/home/rock/quality_inspection/python-workspace/project-sys/sys_auth/views.py", line 39, in authenticate
    token_obj = Token.objects.filter(token=token).first()
  File "/home/rock/anaconda3/envs/venv/lib/python3.8/site-packages/django/db/models/query.py", line 664, in first
    for obj in (self if self.ordered else self.order_by('pk'))[:1]:
  File "/home/rock/anaconda3/envs/venv/lib/python3.8/site-packages/django/db/models/query.py", line 276, in __iter__
    self._fetch_all()
  File "/home/rock/anaconda3/envs/venv/lib/python3.8/site-packages/django/db/models/query.py", line 1261, in _fetch_all
    self._result_cache = list(self._iterable_class(self))
  File "/home/rock/anaconda3/envs/venv/lib/python3.8/site-packages/django/db/models/query.py", line 57, in __iter__
    results = compiler.execute_sql(chunked_fetch=self.chunked_fetch, chunk_size=self.chunk_size)
  File "/home/rock/anaconda3/envs/venv/lib/python3.8/site-packages/django/db/models/sql/compiler.py", line 1149, in execute_sql
    cursor = self.connection.cursor()
  File "/home/rock/anaconda3/envs/venv/lib/python3.8/site-packages/django/utils/asyncio.py", line 26, in inner
    return func(*args, **kwargs)
  File "/home/rock/anaconda3/envs/venv/lib/python3.8/site-packages/django/db/backends/base/base.py", line 260, in cursor
    return self._cursor()
  File "/home/rock/anaconda3/envs/venv/lib/python3.8/site-packages/django/db/backends/base/base.py", line 236, in _cursor
    self.ensure_connection()
  File "/home/rock/anaconda3/envs/venv/lib/python3.8/site-packages/django/utils/asyncio.py", line 26, in inner
    return func(*args, **kwargs)
  File "/home/rock/anaconda3/envs/venv/lib/python3.8/site-packages/django/db/backends/base/base.py", line 220, in ensure_connection
    self.connect()
  File "/home/rock/anaconda3/envs/venv/lib/python3.8/site-packages/django/db/utils.py", line 90, in __exit__
    raise dj_exc_value.with_traceback(traceback) from exc_value
  File "/home/rock/anaconda3/envs/venv/lib/python3.8/site-packages/django/db/backends/base/base.py", line 220, in ensure_connection
    self.connect()
  File "/home/rock/anaconda3/envs/venv/lib/python3.8/site-packages/django/utils/asyncio.py", line 26, in inner
    return func(*args, **kwargs)
  File "/home/rock/anaconda3/envs/venv/lib/python3.8/site-packages/django/db/backends/base/base.py", line 197, in connect
    self.connection = self.get_new_connection(conn_params)
  File "/home/rock/anaconda3/envs/venv/lib/python3.8/site-packages/django/utils/asyncio.py", line 26, in inner
    return func(*args, **kwargs)
  File "/home/rock/anaconda3/envs/venv/lib/python3.8/site-packages/django/db/backends/mysql/base.py", line 233, in get_new_connection
    return Database.connect(**conn_params)
  File "/home/rock/anaconda3/envs/venv/lib/python3.8/site-packages/MySQLdb/__init__.py", line 84, in Connect
    return Connection(*args, **kwargs)
  File "/home/rock/anaconda3/envs/venv/lib/python3.8/site-packages/MySQLdb/connections.py", line 179, in __init__
    super(Connection, self).__init__(*args, **kwargs2)
django.db.utils.OperationalError: (1040, 'Too many connections')
[2020-10-19 11:08:11,380] [basehttp.py:157] [basehttp:log_message] [ERROR]- "GET /sys/api/user/role/?username=wl&application=sys&type=menu HTTP/1.1" 500 24737
[2020-10-19 11:08:11,381] [basehttp.py:157] [basehttp:log_message] [ERROR]- "GET /sys/api/user/role/?username=wl&application=sys&type=button HTTP/1.1" 500 24743
[2020-10-19 11:08:11,383] [basehttp.py:157] [basehttp:log_message] [ERROR]- "GET /sys/api/user/?current_page=1&pre_page=10 HTTP/1.1" 500 24680
[2020-10-19 11:09:15,249] [basehttp.py:157] [basehttp:log_message] [INFO]- "GET /sys/api/user/?current_page=1&pre_page=10 HTTP/1.1" 200 222158
[2020-10-19 11:12:47,416] [log.py:222] [log:log_response] [ERROR]- Internal Server Error: /sys/api/user/
Traceback (most recent call last):
  File "/home/rock/anaconda3/envs/venv/lib/python3.8/site-packages/django/db/backends/base/base.py", line 220, in ensure_connection
    self.connect()
  File "/home/rock/anaconda3/envs/venv/lib/python3.8/site-packages/django/utils/asyncio.py", line 26, in inner
    return func(*args, **kwargs)
  File "/home/rock/anaconda3/envs/venv/lib/python3.8/site-packages/django/db/backends/base/base.py", line 197, in connect
    self.connection = self.get_new_connection(conn_params)
  File "/home/rock/anaconda3/envs/venv/lib/python3.8/site-packages/django/utils/asyncio.py", line 26, in inner
    return func(*args, **kwargs)
  File "/home/rock/anaconda3/envs/venv/lib/python3.8/site-packages/django/db/backends/mysql/base.py", line 233, in get_new_connection
    return Database.connect(**conn_params)
  File "/home/rock/anaconda3/envs/venv/lib/python3.8/site-packages/MySQLdb/__init__.py", line 84, in Connect
    return Connection(*args, **kwargs)
  File "/home/rock/anaconda3/envs/venv/lib/python3.8/site-packages/MySQLdb/connections.py", line 179, in __init__
    super(Connection, self).__init__(*args, **kwargs2)
MySQLdb._exceptions.OperationalError: (1040, 'Too many connections')

The above exception was the direct cause of the following exception:

Traceback (most recent call last):
  File "/home/rock/anaconda3/envs/venv/lib/python3.8/site-packages/django/core/handlers/exception.py", line 34, in inner
    response = get_response(request)
  File "/home/rock/anaconda3/envs/venv/lib/python3.8/site-packages/django/core/handlers/base.py", line 115, in _get_response
    response = self.process_exception_by_middleware(e, request)
  File "/home/rock/anaconda3/envs/venv/lib/python3.8/site-packages/django/core/handlers/base.py", line 113, in _get_response
    response = wrapped_callback(request, *callback_args, **callback_kwargs)
  File "/home/rock/anaconda3/envs/venv/lib/python3.8/site-packages/django/views/decorators/csrf.py", line 54, in wrapped_view
    return view_func(*args, **kwargs)
  File "/home/rock/anaconda3/envs/venv/lib/python3.8/site-packages/rest_framework/viewsets.py", line 114, in view
    return self.dispatch(request, *args, **kwargs)
  File "/home/rock/anaconda3/envs/venv/lib/python3.8/site-packages/rest_framework/views.py", line 505, in dispatch
    response = self.handle_exception(exc)
  File "/home/rock/anaconda3/envs/venv/lib/python3.8/site-packages/rest_framework/views.py", line 465, in handle_exception
    self.raise_uncaught_exception(exc)
  File "/home/rock/anaconda3/envs/venv/lib/python3.8/site-packages/rest_framework/views.py", line 476, in raise_uncaught_exception
    raise exc
  File "/home/rock/anaconda3/envs/venv/lib/python3.8/site-packages/rest_framework/views.py", line 493, in dispatch
    self.initial(request, *args, **kwargs)
  File "/home/rock/anaconda3/envs/venv/lib/python3.8/site-packages/rest_framework/views.py", line 410, in initial
    self.perform_authentication(request)
  File "/home/rock/anaconda3/envs/venv/lib/python3.8/site-packages/rest_framework/views.py", line 324, in perform_authentication
    request.user
  File "/home/rock/anaconda3/envs/venv/lib/python3.8/site-packages/rest_framework/request.py", line 220, in user
    self._authenticate()
  File "/home/rock/anaconda3/envs/venv/lib/python3.8/site-packages/rest_framework/request.py", line 373, in _authenticate
    user_auth_tuple = authenticator.authenticate(self)
  File "/home/rock/quality_inspection/python-workspace/project-sys/sys_auth/views.py", line 39, in authenticate
    token_obj = Token.objects.filter(token=token).first()
  File "/home/rock/anaconda3/envs/venv/lib/python3.8/site-packages/django/db/models/query.py", line 664, in first
    for obj in (self if self.ordered else self.order_by('pk'))[:1]:
  File "/home/rock/anaconda3/envs/venv/lib/python3.8/site-packages/django/db/models/query.py", line 276, in __iter__
    self._fetch_all()
  File "/home/rock/anaconda3/envs/venv/lib/python3.8/site-packages/django/db/models/query.py", line 1261, in _fetch_all
    self._result_cache = list(self._iterable_class(self))
  File "/home/rock/anaconda3/envs/venv/lib/python3.8/site-packages/django/db/models/query.py", line 57, in __iter__
    results = compiler.execute_sql(chunked_fetch=self.chunked_fetch, chunk_size=self.chunk_size)
  File "/home/rock/anaconda3/envs/venv/lib/python3.8/site-packages/django/db/models/sql/compiler.py", line 1149, in execute_sql
    cursor = self.connection.cursor()
  File "/home/rock/anaconda3/envs/venv/lib/python3.8/site-packages/django/utils/asyncio.py", line 26, in inner
    return func(*args, **kwargs)
  File "/home/rock/anaconda3/envs/venv/lib/python3.8/site-packages/django/db/backends/base/base.py", line 260, in cursor
    return self._cursor()
  File "/home/rock/anaconda3/envs/venv/lib/python3.8/site-packages/django/db/backends/base/base.py", line 236, in _cursor
    self.ensure_connection()
  File "/home/rock/anaconda3/envs/venv/lib/python3.8/site-packages/django/utils/asyncio.py", line 26, in inner
    return func(*args, **kwargs)
  File "/home/rock/anaconda3/envs/venv/lib/python3.8/site-packages/django/db/backends/base/base.py", line 220, in ensure_connection
    self.connect()
  File "/home/rock/anaconda3/envs/venv/lib/python3.8/site-packages/django/db/utils.py", line 90, in __exit__
    raise dj_exc_value.with_traceback(traceback) from exc_value
  File "/home/rock/anaconda3/envs/venv/lib/python3.8/site-packages/django/db/backends/base/base.py", line 220, in ensure_connection
    self.connect()
  File "/home/rock/anaconda3/envs/venv/lib/python3.8/site-packages/django/utils/asyncio.py", line 26, in inner
    return func(*args, **kwargs)
  File "/home/rock/anaconda3/envs/venv/lib/python3.8/site-packages/django/db/backends/base/base.py", line 197, in connect
    self.connection = self.get_new_connection(conn_params)
  File "/home/rock/anaconda3/envs/venv/lib/python3.8/site-packages/django/utils/asyncio.py", line 26, in inner
    return func(*args, **kwargs)
  File "/home/rock/anaconda3/envs/venv/lib/python3.8/site-packages/django/db/backends/mysql/base.py", line 233, in get_new_connection
    return Database.connect(**conn_params)
  File "/home/rock/anaconda3/envs/venv/lib/python3.8/site-packages/MySQLdb/__init__.py", line 84, in Connect
    return Connection(*args, **kwargs)
  File "/home/rock/anaconda3/envs/venv/lib/python3.8/site-packages/MySQLdb/connections.py", line 179, in __init__
    super(Connection, self).__init__(*args, **kwargs2)
django.db.utils.OperationalError: (1040, 'Too many connections')
[2020-10-19 11:12:47,417] [basehttp.py:157] [basehttp:log_message] [ERROR]- "GET /sys/api/user/?current_page=1&pre_page=10 HTTP/1.1" 500 24680
[2020-10-19 11:12:56,870] [basehttp.py:157] [basehttp:log_message] [INFO]- "GET /sys/api/user/role/?username=wl&application=sys&type=button HTTP/1.1" 200 291
[2020-10-19 11:12:56,870] [basehttp.py:157] [basehttp:log_message] [INFO]- "GET /sys/api/user/role/?username=wl&application=sys&type=menu HTTP/1.1" 200 1161
[2020-10-19 11:12:57,104] [basehttp.py:157] [basehttp:log_message] [INFO]- "GET /sys/api/user/?current_page=1&pre_page=10 HTTP/1.1" 200 222158
[2020-10-19 11:13:10,467] [basehttp.py:157] [basehttp:log_message] [INFO]- "GET /sys/api/user/role/?username=wl&application=sys&type=button HTTP/1.1" 200 291
[2020-10-19 11:13:10,486] [basehttp.py:157] [basehttp:log_message] [INFO]- "GET /sys/api/user/role/?username=wl&application=sys&type=menu HTTP/1.1" 200 1161
[2020-10-19 11:13:11,463] [basehttp.py:157] [basehttp:log_message] [INFO]- "GET /sys/api/user/?current_page=1&pre_page=10 HTTP/1.1" 200 222158
[2020-10-19 11:23:28,368] [basehttp.py:157] [basehttp:log_message] [INFO]- "GET /sys/api/user/role/?username=wl&application=sys&type=button HTTP/1.1" 200 291
[2020-10-19 11:23:28,369] [basehttp.py:157] [basehttp:log_message] [INFO]- "GET /sys/api/user/role/?username=wl&application=sys&type=menu HTTP/1.1" 200 1161
[2020-10-19 11:23:28,638] [basehttp.py:157] [basehttp:log_message] [INFO]- "GET /sys/api/user/?current_page=1&pre_page=10 HTTP/1.1" 200 222158
[2020-10-19 11:23:50,272] [basehttp.py:157] [basehttp:log_message] [INFO]- "GET /sys/api/user/role/?username=wl&application=sys&type=button HTTP/1.1" 200 291
[2020-10-19 11:23:50,274] [basehttp.py:157] [basehttp:log_message] [INFO]- "GET /sys/api/user/role/?username=wl&application=sys&type=menu HTTP/1.1" 200 1161
[2020-10-19 11:23:50,470] [basehttp.py:157] [basehttp:log_message] [INFO]- "GET /sys/api/user/?current_page=1&pre_page=10 HTTP/1.1" 200 222158
[2020-10-19 17:18:12,247] [log.py:222] [log:log_response] [WARNING]- Forbidden: /sys/api/menu/
[2020-10-19 17:18:12,305] [basehttp.py:157] [basehttp:log_message] [WARNING]- "GET /sys/api/menu/ HTTP/1.1" 403 24
[2020-10-19 17:26:26,484] [basehttp.py:157] [basehttp:log_message] [INFO]- "POST /sys/api/auth/ HTTP/1.1" 200 65
[2020-10-19 17:26:30,512] [basehttp.py:157] [basehttp:log_message] [INFO]- "POST /sys/api/auth/ HTTP/1.1" 200 65
[2020-10-19 17:26:34,184] [basehttp.py:157] [basehttp:log_message] [INFO]- "GET /sys/api/user/role/?username=wl&application=automation&type=button HTTP/1.1" 200 2
[2020-10-19 17:26:34,186] [basehttp.py:157] [basehttp:log_message] [INFO]- "GET /sys/api/user/role/?username=wl&application=automation&type=menu HTTP/1.1" 200 7733
