[2020-06-11 09:19:11,404] [autoreload.py:598] [autoreload:run_with_reloader] [INFO]- Watching for file changes with StatReloader
[2020-06-11 09:25:51,471] [basehttp.py:157] [basehttp:log_message] [INFO]- "OPTIONS /role/user?username=et&pid=1 HTTP/1.1" 200 0
[2020-06-11 09:25:51,610] [basehttp.py:157] [basehttp:log_message] [INFO]- "OPTIONS /role/user/?username=et&pid=1 HTTP/1.1" 200 0
[2020-06-11 09:25:51,778] [basehttp.py:157] [basehttp:log_message] [INFO]- "GET /role/user/?username=et&pid=1 HTTP/1.1" 200 1521
[2020-06-11 09:26:00,923] [basehttp.py:157] [basehttp:log_message] [INFO]- "OPTIONS /user/?current_page=1&pre_page=10 HTTP/1.1" 200 0
[2020-06-11 09:26:00,959] [basehttp.py:157] [basehttp:log_message] [INFO]- "GET /user/?current_page=1&pre_page=10 HTTP/1.1" 200 1819
[2020-06-11 09:27:05,757] [basehttp.py:157] [basehttp:log_message] [INFO]- "OPTIONS /role/?current_page=1&pre_page=10 HTTP/1.1" 200 0
[2020-06-11 09:27:05,788] [basehttp.py:157] [basehttp:log_message] [INFO]- "GET /role/?current_page=1&pre_page=10 HTTP/1.1" 200 4738
[2020-06-11 09:27:06,439] [basehttp.py:157] [basehttp:log_message] [INFO]- "GET /user/?current_page=1&pre_page=10 HTTP/1.1" 200 1819
[2020-06-11 09:28:50,175] [basehttp.py:157] [basehttp:log_message] [INFO]- "GET /user/?current_page=1&pre_page=10 HTTP/1.1" 200 1819
[2020-06-11 09:34:45,447] [basehttp.py:157] [basehttp:log_message] [INFO]- "GET /user/?current_page=1&pre_page=10 HTTP/1.1" 200 1819
[2020-06-11 09:35:00,010] [basehttp.py:157] [basehttp:log_message] [INFO]- "GET /user/?current_page=1&pre_page=10 HTTP/1.1" 200 1819
[2020-06-11 09:35:00,040] [basehttp.py:157] [basehttp:log_message] [INFO]- "GET /role/user/?username=et&pid=1 HTTP/1.1" 200 1526
[2020-06-11 09:43:42,011] [basehttp.py:157] [basehttp:log_message] [INFO]- "OPTIONS /user/?current_page=1&pre_page=10 HTTP/1.1" 200 0
[2020-06-11 09:43:42,022] [basehttp.py:157] [basehttp:log_message] [INFO]- "GET /user/?current_page=1&pre_page=10 HTTP/1.1" 200 1819
[2020-06-11 09:43:43,542] [basehttp.py:157] [basehttp:log_message] [INFO]- "OPTIONS /role/user?username=et&pid=1 HTTP/1.1" 200 0
[2020-06-11 09:43:43,548] [basehttp.py:157] [basehttp:log_message] [INFO]- "GET /user/?current_page=1&pre_page=10 HTTP/1.1" 200 1819
[2020-06-11 09:43:43,650] [basehttp.py:157] [basehttp:log_message] [INFO]- "OPTIONS /role/user/?username=et&pid=1 HTTP/1.1" 200 0
[2020-06-11 09:43:43,707] [basehttp.py:157] [basehttp:log_message] [INFO]- "GET /role/user/?username=et&pid=1 HTTP/1.1" 200 1526
[2020-06-11 09:44:34,437] [basehttp.py:157] [basehttp:log_message] [INFO]- "GET /user/?current_page=1&pre_page=10 HTTP/1.1" 200 1819
[2020-06-11 09:46:15,792] [basehttp.py:157] [basehttp:log_message] [INFO]- "GET /user/?current_page=1&pre_page=10 HTTP/1.1" 200 1819
[2020-06-11 09:47:19,269] [basehttp.py:157] [basehttp:log_message] [INFO]- "GET /user/?current_page=1&pre_page=10 HTTP/1.1" 200 1819
[2020-06-11 09:47:57,748] [basehttp.py:157] [basehttp:log_message] [INFO]- "GET /user/?current_page=1&pre_page=10 HTTP/1.1" 200 1819
[2020-06-11 09:47:57,774] [basehttp.py:157] [basehttp:log_message] [INFO]- "GET /role/user/?username=et&pid=1 HTTP/1.1" 200 1526
[2020-06-11 09:48:09,640] [basehttp.py:157] [basehttp:log_message] [INFO]- "OPTIONS /role/2/assign_user/ HTTP/1.1" 200 0
[2020-06-11 09:48:10,021] [log.py:222] [log:log_response] [ERROR]- Internal Server Error: /role/2/assign_user/
Traceback (most recent call last):
  File "/home/rock/anaconda3/envs/venv/lib/python3.8/site-packages/django/core/handlers/exception.py", line 34, in inner
    response = get_response(request)
  File "/home/rock/anaconda3/envs/venv/lib/python3.8/site-packages/django/core/handlers/base.py", line 115, in _get_response
    response = self.process_exception_by_middleware(e, request)
  File "/home/rock/anaconda3/envs/venv/lib/python3.8/site-packages/django/core/handlers/base.py", line 113, in _get_response
    response = wrapped_callback(request, *callback_args, **callback_kwargs)
  File "/home/rock/anaconda3/envs/venv/lib/python3.8/site-packages/django/views/decorators/csrf.py", line 54, in wrapped_view
    return view_func(*args, **kwargs)
  File "/home/rock/anaconda3/envs/venv/lib/python3.8/site-packages/rest_framework/viewsets.py", line 114, in view
    return self.dispatch(request, *args, **kwargs)
  File "/home/rock/anaconda3/envs/venv/lib/python3.8/site-packages/rest_framework/views.py", line 505, in dispatch
    response = self.handle_exception(exc)
  File "/home/rock/anaconda3/envs/venv/lib/python3.8/site-packages/rest_framework/views.py", line 465, in handle_exception
    self.raise_uncaught_exception(exc)
  File "/home/rock/anaconda3/envs/venv/lib/python3.8/site-packages/rest_framework/views.py", line 476, in raise_uncaught_exception
    raise exc
  File "/home/rock/anaconda3/envs/venv/lib/python3.8/site-packages/rest_framework/views.py", line 502, in dispatch
    response = handler(request, *args, **kwargs)
  File "/home/rock/quality_inspection/python-workspace/project-sys/sys_auth/views.py", line 220, in assign_user
    users = User.objects.filter(id__in=user_ids).all()
  File "/home/rock/anaconda3/envs/venv/lib/python3.8/site-packages/django/db/models/manager.py", line 82, in manager_method
    return getattr(self.get_queryset(), name)(*args, **kwargs)
  File "/home/rock/anaconda3/envs/venv/lib/python3.8/site-packages/django/db/models/query.py", line 904, in filter
    return self._filter_or_exclude(False, *args, **kwargs)
  File "/home/rock/anaconda3/envs/venv/lib/python3.8/site-packages/django/db/models/query.py", line 923, in _filter_or_exclude
    clone.query.add_q(Q(*args, **kwargs))
  File "/home/rock/anaconda3/envs/venv/lib/python3.8/site-packages/django/db/models/sql/query.py", line 1351, in add_q
    clause, _ = self._add_q(q_object, self.used_aliases)
  File "/home/rock/anaconda3/envs/venv/lib/python3.8/site-packages/django/db/models/sql/query.py", line 1378, in _add_q
    child_clause, needed_inner = self.build_filter(
  File "/home/rock/anaconda3/envs/venv/lib/python3.8/site-packages/django/db/models/sql/query.py", line 1312, in build_filter
    condition = self.build_lookup(lookups, col, value)
  File "/home/rock/anaconda3/envs/venv/lib/python3.8/site-packages/django/db/models/sql/query.py", line 1166, in build_lookup
    lookup = lookup_class(lhs, rhs)
  File "/home/rock/anaconda3/envs/venv/lib/python3.8/site-packages/django/db/models/lookups.py", line 22, in __init__
    self.rhs = self.get_prep_lookup()
  File "/home/rock/anaconda3/envs/venv/lib/python3.8/site-packages/django/db/models/lookups.py", line 217, in get_prep_lookup
    for rhs_value in self.rhs:
TypeError: 'NoneType' object is not iterable
[2020-06-11 09:48:10,023] [basehttp.py:157] [basehttp:log_message] [ERROR]- "PUT /role/2/assign_user/ HTTP/1.1" 500 20911
[2020-06-11 09:50:38,214] [basehttp.py:157] [basehttp:log_message] [INFO]- "GET /user/?current_page=1&pre_page=10 HTTP/1.1" 200 1819
[2020-06-11 09:50:38,236] [basehttp.py:157] [basehttp:log_message] [INFO]- "GET /role/user/?username=et&pid=1 HTTP/1.1" 200 1526
[2020-06-11 09:52:20,596] [basehttp.py:157] [basehttp:log_message] [INFO]- "GET /user/?current_page=1&pre_page=10 HTTP/1.1" 200 1819
[2020-06-11 09:52:23,184] [basehttp.py:157] [basehttp:log_message] [INFO]- "GET /user/?current_page=1&pre_page=10 HTTP/1.1" 200 1819
[2020-06-11 09:52:23,213] [basehttp.py:157] [basehttp:log_message] [INFO]- "GET /role/user/?username=et&pid=1 HTTP/1.1" 200 1526
[2020-06-11 09:52:30,143] [basehttp.py:157] [basehttp:log_message] [INFO]- "GET /user/?current_page=1&pre_page=10 HTTP/1.1" 200 1819
[2020-06-11 09:52:30,185] [basehttp.py:157] [basehttp:log_message] [INFO]- "GET /role/user/?username=et&pid=1 HTTP/1.1" 200 1526
[2020-06-11 09:53:02,791] [basehttp.py:157] [basehttp:log_message] [INFO]- "GET /user/?current_page=1&pre_page=10 HTTP/1.1" 200 1819
[2020-06-11 09:54:11,037] [basehttp.py:157] [basehttp:log_message] [INFO]- "OPTIONS /user/?current_page=1&pre_page=10 HTTP/1.1" 200 0
[2020-06-11 09:54:11,051] [basehttp.py:157] [basehttp:log_message] [INFO]- "GET /user/?current_page=1&pre_page=10 HTTP/1.1" 200 1819
[2020-06-11 09:54:13,482] [basehttp.py:157] [basehttp:log_message] [INFO]- "OPTIONS /role/user?username=et&pid=1 HTTP/1.1" 200 0
[2020-06-11 09:54:13,493] [basehttp.py:157] [basehttp:log_message] [INFO]- "GET /user/?current_page=1&pre_page=10 HTTP/1.1" 200 1819
[2020-06-11 09:54:13,690] [basehttp.py:157] [basehttp:log_message] [INFO]- "OPTIONS /role/user/?username=et&pid=1 HTTP/1.1" 200 0
[2020-06-11 09:54:13,716] [basehttp.py:157] [basehttp:log_message] [INFO]- "GET /role/user/?username=et&pid=1 HTTP/1.1" 200 1526
[2020-06-11 09:54:20,201] [basehttp.py:157] [basehttp:log_message] [INFO]- "GET /user/?current_page=1&pre_page=10 HTTP/1.1" 200 1819
[2020-06-11 09:54:21,837] [basehttp.py:157] [basehttp:log_message] [INFO]- "GET /user/?current_page=1&pre_page=10 HTTP/1.1" 200 1819
[2020-06-11 09:54:21,872] [basehttp.py:157] [basehttp:log_message] [INFO]- "GET /role/user/?username=et&pid=1 HTTP/1.1" 200 1526
[2020-06-11 09:54:58,261] [basehttp.py:157] [basehttp:log_message] [INFO]- "GET /user/?current_page=1&pre_page=10 HTTP/1.1" 200 1819
[2020-06-11 09:59:10,900] [basehttp.py:157] [basehttp:log_message] [INFO]- "GET /user/?current_page=1&pre_page=10 HTTP/1.1" 200 1819
[2020-06-11 10:01:13,494] [autoreload.py:222] [autoreload:trigger_reload] [INFO]- /home/rock/quality_inspection/python-workspace/project-sys/sys_auth/views.py changed, reloading.
[2020-06-11 10:01:13,869] [autoreload.py:598] [autoreload:run_with_reloader] [INFO]- Watching for file changes with StatReloader
[2020-06-11 10:12:36,786] [autoreload.py:222] [autoreload:trigger_reload] [INFO]- /home/rock/quality_inspection/python-workspace/project-sys/sys_auth/views.py changed, reloading.
[2020-06-11 10:12:37,221] [autoreload.py:598] [autoreload:run_with_reloader] [INFO]- Watching for file changes with StatReloader
[2020-06-11 10:18:25,587] [autoreload.py:222] [autoreload:trigger_reload] [INFO]- /home/rock/quality_inspection/python-workspace/project-sys/sys_auth/views.py changed, reloading.
[2020-06-11 10:18:26,377] [autoreload.py:598] [autoreload:run_with_reloader] [INFO]- Watching for file changes with StatReloader
[2020-06-11 10:22:26,257] [autoreload.py:222] [autoreload:trigger_reload] [INFO]- /home/rock/quality_inspection/python-workspace/project-sys/sys_auth/views.py changed, reloading.
[2020-06-11 10:22:26,733] [autoreload.py:598] [autoreload:run_with_reloader] [INFO]- Watching for file changes with StatReloader
[2020-06-11 10:28:02,289] [autoreload.py:222] [autoreload:trigger_reload] [INFO]- /home/rock/quality_inspection/python-workspace/project-sys/sys_auth/views.py changed, reloading.
[2020-06-11 10:28:02,617] [autoreload.py:598] [autoreload:run_with_reloader] [INFO]- Watching for file changes with StatReloader
[2020-06-11 10:28:09,171] [autoreload.py:222] [autoreload:trigger_reload] [INFO]- /home/rock/quality_inspection/python-workspace/project-sys/sys_auth/views.py changed, reloading.
[2020-06-11 10:28:09,491] [autoreload.py:598] [autoreload:run_with_reloader] [INFO]- Watching for file changes with StatReloader
[2020-06-11 10:28:14,914] [autoreload.py:222] [autoreload:trigger_reload] [INFO]- /home/rock/quality_inspection/python-workspace/project-sys/sys_auth/views.py changed, reloading.
[2020-06-11 10:28:15,270] [autoreload.py:598] [autoreload:run_with_reloader] [INFO]- Watching for file changes with StatReloader
[2020-06-11 10:28:27,994] [autoreload.py:222] [autoreload:trigger_reload] [INFO]- /home/rock/quality_inspection/python-workspace/project-sys/sys_auth/views.py changed, reloading.
[2020-06-11 10:28:28,377] [autoreload.py:598] [autoreload:run_with_reloader] [INFO]- Watching for file changes with StatReloader
[2020-06-11 10:28:37,021] [autoreload.py:222] [autoreload:trigger_reload] [INFO]- /home/rock/quality_inspection/python-workspace/project-sys/sys_auth/views.py changed, reloading.
[2020-06-11 10:28:37,397] [autoreload.py:598] [autoreload:run_with_reloader] [INFO]- Watching for file changes with StatReloader
[2020-06-11 10:28:43,941] [autoreload.py:222] [autoreload:trigger_reload] [INFO]- /home/rock/quality_inspection/python-workspace/project-sys/sys_auth/views.py changed, reloading.
[2020-06-11 10:28:44,332] [autoreload.py:598] [autoreload:run_with_reloader] [INFO]- Watching for file changes with StatReloader
[2020-06-11 10:29:10,618] [autoreload.py:222] [autoreload:trigger_reload] [INFO]- /home/rock/quality_inspection/python-workspace/project-sys/sys_auth/views.py changed, reloading.
[2020-06-11 10:29:10,941] [autoreload.py:598] [autoreload:run_with_reloader] [INFO]- Watching for file changes with StatReloader
[2020-06-11 10:29:44,661] [autoreload.py:222] [autoreload:trigger_reload] [INFO]- /home/rock/quality_inspection/python-workspace/project-sys/sys_auth/views.py changed, reloading.
[2020-06-11 10:29:44,990] [autoreload.py:598] [autoreload:run_with_reloader] [INFO]- Watching for file changes with StatReloader
[2020-06-11 10:48:32,260] [autoreload.py:222] [autoreload:trigger_reload] [INFO]- /home/rock/quality_inspection/python-workspace/project-sys/sys_auth/views.py changed, reloading.
[2020-06-11 10:48:32,623] [autoreload.py:598] [autoreload:run_with_reloader] [INFO]- Watching for file changes with StatReloader
[2020-06-11 10:48:34,837] [basehttp.py:157] [basehttp:log_message] [INFO]- "OPTIONS /role/user?username=et&pid=1 HTTP/1.1" 200 0
[2020-06-11 10:48:34,838] [basehttp.py:157] [basehttp:log_message] [INFO]- "OPTIONS /user/?current_page=1&pre_page=10 HTTP/1.1" 200 0
[2020-06-11 10:48:34,885] [basehttp.py:157] [basehttp:log_message] [INFO]- "GET /user/?current_page=1&pre_page=10 HTTP/1.1" 200 1819
[2020-06-11 10:48:34,889] [basehttp.py:157] [basehttp:log_message] [INFO]- "OPTIONS /role/user/?username=et&pid=1 HTTP/1.1" 200 0
[2020-06-11 10:48:34,919] [basehttp.py:157] [basehttp:log_message] [INFO]- "GET /role/user/?username=et&pid=1 HTTP/1.1" 200 1526
[2020-06-11 10:48:38,884] [basehttp.py:157] [basehttp:log_message] [INFO]- "OPTIONS /user/?username=a&current_page=1&pre_page=10 HTTP/1.1" 200 0
[2020-06-11 10:48:38,901] [basehttp.py:157] [basehttp:log_message] [INFO]- "GET /user/?username=a&current_page=1&pre_page=10 HTTP/1.1" 200 783
[2020-06-11 10:48:43,029] [basehttp.py:157] [basehttp:log_message] [INFO]- "OPTIONS /user/?username=fd&current_page=1&pre_page=10 HTTP/1.1" 200 0
[2020-06-11 10:48:43,051] [basehttp.py:157] [basehttp:log_message] [INFO]- "GET /user/?username=fd&current_page=1&pre_page=10 HTTP/1.1" 200 73
[2020-06-11 10:48:45,883] [basehttp.py:157] [basehttp:log_message] [INFO]- "OPTIONS /user/?username=we&current_page=1&pre_page=10 HTTP/1.1" 200 0
[2020-06-11 10:48:45,907] [basehttp.py:157] [basehttp:log_message] [INFO]- "GET /user/?username=we&current_page=1&pre_page=10 HTTP/1.1" 200 954
[2020-06-11 10:50:50,917] [basehttp.py:157] [basehttp:log_message] [INFO]- "GET /user/?current_page=1&pre_page=10 HTTP/1.1" 200 1819
[2020-06-11 10:50:55,894] [basehttp.py:157] [basehttp:log_message] [INFO]- "GET /user/?current_page=1&pre_page=10 HTTP/1.1" 200 1819
[2020-06-11 10:50:55,933] [basehttp.py:157] [basehttp:log_message] [INFO]- "GET /role/user/?username=et&pid=1 HTTP/1.1" 200 1526
[2020-06-11 10:55:58,759] [basehttp.py:157] [basehttp:log_message] [INFO]- "GET /user/?current_page=1&pre_page=10 HTTP/1.1" 200 1819
[2020-06-11 11:00:09,756] [autoreload.py:222] [autoreload:trigger_reload] [INFO]- /home/rock/quality_inspection/python-workspace/project-sys/sys_auth/views.py changed, reloading.
[2020-06-11 11:00:10,137] [autoreload.py:598] [autoreload:run_with_reloader] [INFO]- Watching for file changes with StatReloader
[2020-06-11 11:00:34,314] [autoreload.py:222] [autoreload:trigger_reload] [INFO]- /home/rock/quality_inspection/python-workspace/project-sys/sys_auth/views.py changed, reloading.
[2020-06-11 11:00:34,687] [autoreload.py:598] [autoreload:run_with_reloader] [INFO]- Watching for file changes with StatReloader
[2020-06-11 11:00:48,443] [autoreload.py:222] [autoreload:trigger_reload] [INFO]- /home/rock/quality_inspection/python-workspace/project-sys/sys_auth/views.py changed, reloading.
[2020-06-11 11:00:48,805] [autoreload.py:598] [autoreload:run_with_reloader] [INFO]- Watching for file changes with StatReloader
[2020-06-11 11:01:04,691] [autoreload.py:222] [autoreload:trigger_reload] [INFO]- /home/rock/quality_inspection/python-workspace/project-sys/sys_auth/views.py changed, reloading.
[2020-06-11 11:01:05,075] [autoreload.py:598] [autoreload:run_with_reloader] [INFO]- Watching for file changes with StatReloader
[2020-06-11 11:01:42,928] [autoreload.py:222] [autoreload:trigger_reload] [INFO]- /home/rock/quality_inspection/python-workspace/project-sys/sys_auth/views.py changed, reloading.
[2020-06-11 11:01:43,267] [autoreload.py:598] [autoreload:run_with_reloader] [INFO]- Watching for file changes with StatReloader
[2020-06-11 11:02:22,184] [log.py:222] [log:log_response] [ERROR]- Internal Server Error: /user/
Traceback (most recent call last):
  File "/home/rock/anaconda3/envs/venv/lib/python3.8/site-packages/rest_framework/fields.py", line 454, in get_attribute
    return get_attribute(instance, self.source_attrs)
  File "/home/rock/anaconda3/envs/venv/lib/python3.8/site-packages/rest_framework/fields.py", line 94, in get_attribute
    instance = getattr(instance, attr)
AttributeError: 'tuple' object has no attribute 'username'

During handling of the above exception, another exception occurred:

Traceback (most recent call last):
  File "/home/rock/anaconda3/envs/venv/lib/python3.8/site-packages/django/core/handlers/exception.py", line 34, in inner
    response = get_response(request)
  File "/home/rock/anaconda3/envs/venv/lib/python3.8/site-packages/django/core/handlers/base.py", line 115, in _get_response
    response = self.process_exception_by_middleware(e, request)
  File "/home/rock/anaconda3/envs/venv/lib/python3.8/site-packages/django/core/handlers/base.py", line 113, in _get_response
    response = wrapped_callback(request, *callback_args, **callback_kwargs)
  File "/home/rock/anaconda3/envs/venv/lib/python3.8/site-packages/django/views/decorators/csrf.py", line 54, in wrapped_view
    return view_func(*args, **kwargs)
  File "/home/rock/anaconda3/envs/venv/lib/python3.8/site-packages/rest_framework/viewsets.py", line 114, in view
    return self.dispatch(request, *args, **kwargs)
  File "/home/rock/anaconda3/envs/venv/lib/python3.8/site-packages/rest_framework/views.py", line 505, in dispatch
    response = self.handle_exception(exc)
  File "/home/rock/anaconda3/envs/venv/lib/python3.8/site-packages/rest_framework/views.py", line 465, in handle_exception
    self.raise_uncaught_exception(exc)
  File "/home/rock/anaconda3/envs/venv/lib/python3.8/site-packages/rest_framework/views.py", line 476, in raise_uncaught_exception
    raise exc
  File "/home/rock/anaconda3/envs/venv/lib/python3.8/site-packages/rest_framework/views.py", line 502, in dispatch
    response = handler(request, *args, **kwargs)
  File "/home/rock/quality_inspection/python-workspace/project-sys/sys_auth/views.py", line 149, in list
    return Response(self.get_serializer(user_list, many=True).data)
  File "/home/rock/anaconda3/envs/venv/lib/python3.8/site-packages/rest_framework/serializers.py", line 760, in data
    ret = super().data
  File "/home/rock/anaconda3/envs/venv/lib/python3.8/site-packages/rest_framework/serializers.py", line 260, in data
    self._data = self.to_representation(self.instance)
  File "/home/rock/anaconda3/envs/venv/lib/python3.8/site-packages/rest_framework/serializers.py", line 677, in to_representation
    return [
  File "/home/rock/anaconda3/envs/venv/lib/python3.8/site-packages/rest_framework/serializers.py", line 678, in <listcomp>
    self.child.to_representation(item) for item in iterable
  File "/home/rock/anaconda3/envs/venv/lib/python3.8/site-packages/rest_framework/serializers.py", line 516, in to_representation
    attribute = field.get_attribute(instance)
  File "/home/rock/anaconda3/envs/venv/lib/python3.8/site-packages/rest_framework/fields.py", line 487, in get_attribute
    raise type(exc)(msg)
AttributeError: Got AttributeError when attempting to get a value for field `username` on serializer `UserSerializer`.
The serializer field might be named incorrectly and not match any attribute or key on the `tuple` instance.
Original exception text was: 'tuple' object has no attribute 'username'.
[2020-06-11 11:02:22,185] [basehttp.py:157] [basehttp:log_message] [ERROR]- "GET /user/ HTTP/1.1" 500 21077
[2020-06-11 11:04:22,390] [autoreload.py:222] [autoreload:trigger_reload] [INFO]- /home/rock/quality_inspection/python-workspace/project-sys/sys_auth/views.py changed, reloading.
[2020-06-11 11:04:22,759] [autoreload.py:598] [autoreload:run_with_reloader] [INFO]- Watching for file changes with StatReloader
[2020-06-11 11:04:24,131] [log.py:222] [log:log_response] [ERROR]- Internal Server Error: /user/
Traceback (most recent call last):
  File "/home/rock/anaconda3/envs/venv/lib/python3.8/site-packages/django/core/handlers/exception.py", line 34, in inner
    response = get_response(request)
  File "/home/rock/anaconda3/envs/venv/lib/python3.8/site-packages/django/core/handlers/base.py", line 115, in _get_response
    response = self.process_exception_by_middleware(e, request)
  File "/home/rock/anaconda3/envs/venv/lib/python3.8/site-packages/django/core/handlers/base.py", line 113, in _get_response
    response = wrapped_callback(request, *callback_args, **callback_kwargs)
  File "/home/rock/anaconda3/envs/venv/lib/python3.8/site-packages/django/views/decorators/csrf.py", line 54, in wrapped_view
    return view_func(*args, **kwargs)
  File "/home/rock/anaconda3/envs/venv/lib/python3.8/site-packages/rest_framework/viewsets.py", line 114, in view
    return self.dispatch(request, *args, **kwargs)
  File "/home/rock/anaconda3/envs/venv/lib/python3.8/site-packages/rest_framework/views.py", line 505, in dispatch
    response = self.handle_exception(exc)
  File "/home/rock/anaconda3/envs/venv/lib/python3.8/site-packages/rest_framework/views.py", line 465, in handle_exception
    self.raise_uncaught_exception(exc)
  File "/home/rock/anaconda3/envs/venv/lib/python3.8/site-packages/rest_framework/views.py", line 476, in raise_uncaught_exception
    raise exc
  File "/home/rock/anaconda3/envs/venv/lib/python3.8/site-packages/rest_framework/views.py", line 502, in dispatch
    response = handler(request, *args, **kwargs)
  File "/home/rock/quality_inspection/python-workspace/project-sys/sys_auth/views.py", line 130, in list
    user_list = User.objects.get_queryset().order_by('id').values_list("role__name","user__username")
  File "/home/rock/anaconda3/envs/venv/lib/python3.8/site-packages/django/db/models/query.py", line 836, in values_list
    clone = self._values(*_fields, **expressions)
  File "/home/rock/anaconda3/envs/venv/lib/python3.8/site-packages/django/db/models/query.py", line 804, in _values
    clone.query.set_values(fields)
  File "/home/rock/anaconda3/envs/venv/lib/python3.8/site-packages/django/db/models/sql/query.py", line 2146, in set_values
    self.add_fields(field_names, True)
  File "/home/rock/anaconda3/envs/venv/lib/python3.8/site-packages/django/db/models/sql/query.py", line 1866, in add_fields
    join_info = self.setup_joins(name.split(LOOKUP_SEP), opts, alias, allow_many=allow_m2m)
  File "/home/rock/anaconda3/envs/venv/lib/python3.8/site-packages/django/db/models/sql/query.py", line 1567, in setup_joins
    path, final_field, targets, rest = self.names_to_path(
  File "/home/rock/anaconda3/envs/venv/lib/python3.8/site-packages/django/db/models/sql/query.py", line 1483, in names_to_path
    raise FieldError("Cannot resolve keyword '%s' into field. "
django.core.exceptions.FieldError: Cannot resolve keyword 'user' into field. Choices are: create_time, email, id, is_delete, password, phone, remove_time, role, roleuser, token, username
[2020-06-11 11:04:24,133] [basehttp.py:157] [basehttp:log_message] [ERROR]- "GET /user/ HTTP/1.1" 500 20506
[2020-06-11 11:04:45,123] [autoreload.py:598] [autoreload:run_with_reloader] [INFO]- Watching for file changes with StatReloader
[2020-06-11 11:04:48,447] [log.py:222] [log:log_response] [ERROR]- Internal Server Error: /user/
Traceback (most recent call last):
  File "/home/rock/anaconda3/envs/venv/lib/python3.8/site-packages/django/core/handlers/exception.py", line 34, in inner
    response = get_response(request)
  File "/home/rock/anaconda3/envs/venv/lib/python3.8/site-packages/django/core/handlers/base.py", line 115, in _get_response
    response = self.process_exception_by_middleware(e, request)
  File "/home/rock/anaconda3/envs/venv/lib/python3.8/site-packages/django/core/handlers/base.py", line 113, in _get_response
    response = wrapped_callback(request, *callback_args, **callback_kwargs)
  File "/home/rock/anaconda3/envs/venv/lib/python3.8/site-packages/django/views/decorators/csrf.py", line 54, in wrapped_view
    return view_func(*args, **kwargs)
  File "/home/rock/anaconda3/envs/venv/lib/python3.8/site-packages/rest_framework/viewsets.py", line 114, in view
    return self.dispatch(request, *args, **kwargs)
  File "/home/rock/anaconda3/envs/venv/lib/python3.8/site-packages/rest_framework/views.py", line 505, in dispatch
    response = self.handle_exception(exc)
  File "/home/rock/anaconda3/envs/venv/lib/python3.8/site-packages/rest_framework/views.py", line 465, in handle_exception
    self.raise_uncaught_exception(exc)
  File "/home/rock/anaconda3/envs/venv/lib/python3.8/site-packages/rest_framework/views.py", line 476, in raise_uncaught_exception
    raise exc
  File "/home/rock/anaconda3/envs/venv/lib/python3.8/site-packages/rest_framework/views.py", line 502, in dispatch
    response = handler(request, *args, **kwargs)
  File "/home/rock/quality_inspection/python-workspace/project-sys/sys_auth/views.py", line 130, in list
    user_list = User.objects.get_queryset().order_by('id').values_list("role__name","user__username")
  File "/home/rock/anaconda3/envs/venv/lib/python3.8/site-packages/django/db/models/query.py", line 836, in values_list
    clone = self._values(*_fields, **expressions)
  File "/home/rock/anaconda3/envs/venv/lib/python3.8/site-packages/django/db/models/query.py", line 804, in _values
    clone.query.set_values(fields)
  File "/home/rock/anaconda3/envs/venv/lib/python3.8/site-packages/django/db/models/sql/query.py", line 2146, in set_values
    self.add_fields(field_names, True)
  File "/home/rock/anaconda3/envs/venv/lib/python3.8/site-packages/django/db/models/sql/query.py", line 1866, in add_fields
    join_info = self.setup_joins(name.split(LOOKUP_SEP), opts, alias, allow_many=allow_m2m)
  File "/home/rock/anaconda3/envs/venv/lib/python3.8/site-packages/django/db/models/sql/query.py", line 1567, in setup_joins
    path, final_field, targets, rest = self.names_to_path(
  File "/home/rock/anaconda3/envs/venv/lib/python3.8/site-packages/django/db/models/sql/query.py", line 1483, in names_to_path
    raise FieldError("Cannot resolve keyword '%s' into field. "
django.core.exceptions.FieldError: Cannot resolve keyword 'user' into field. Choices are: create_time, email, id, is_delete, password, phone, remove_time, role, roleuser, token, username
[2020-06-11 11:04:48,449] [basehttp.py:157] [basehttp:log_message] [ERROR]- "GET /user/ HTTP/1.1" 500 20506
[2020-06-11 11:06:53,782] [autoreload.py:222] [autoreload:trigger_reload] [INFO]- /home/rock/quality_inspection/python-workspace/project-sys/sys_auth/views.py changed, reloading.
[2020-06-11 11:06:54,148] [autoreload.py:598] [autoreload:run_with_reloader] [INFO]- Watching for file changes with StatReloader
[2020-06-11 11:07:00,491] [log.py:222] [log:log_response] [ERROR]- Internal Server Error: /user/
Traceback (most recent call last):
  File "/home/rock/anaconda3/envs/venv/lib/python3.8/site-packages/rest_framework/fields.py", line 454, in get_attribute
    return get_attribute(instance, self.source_attrs)
  File "/home/rock/anaconda3/envs/venv/lib/python3.8/site-packages/rest_framework/fields.py", line 94, in get_attribute
    instance = getattr(instance, attr)
AttributeError: 'tuple' object has no attribute 'username'

During handling of the above exception, another exception occurred:

Traceback (most recent call last):
  File "/home/rock/anaconda3/envs/venv/lib/python3.8/site-packages/django/core/handlers/exception.py", line 34, in inner
    response = get_response(request)
  File "/home/rock/anaconda3/envs/venv/lib/python3.8/site-packages/django/core/handlers/base.py", line 115, in _get_response
    response = self.process_exception_by_middleware(e, request)
  File "/home/rock/anaconda3/envs/venv/lib/python3.8/site-packages/django/core/handlers/base.py", line 113, in _get_response
    response = wrapped_callback(request, *callback_args, **callback_kwargs)
  File "/home/rock/anaconda3/envs/venv/lib/python3.8/site-packages/django/views/decorators/csrf.py", line 54, in wrapped_view
    return view_func(*args, **kwargs)
  File "/home/rock/anaconda3/envs/venv/lib/python3.8/site-packages/rest_framework/viewsets.py", line 114, in view
    return self.dispatch(request, *args, **kwargs)
  File "/home/rock/anaconda3/envs/venv/lib/python3.8/site-packages/rest_framework/views.py", line 505, in dispatch
    response = self.handle_exception(exc)
  File "/home/rock/anaconda3/envs/venv/lib/python3.8/site-packages/rest_framework/views.py", line 465, in handle_exception
    self.raise_uncaught_exception(exc)
  File "/home/rock/anaconda3/envs/venv/lib/python3.8/site-packages/rest_framework/views.py", line 476, in raise_uncaught_exception
    raise exc
  File "/home/rock/anaconda3/envs/venv/lib/python3.8/site-packages/rest_framework/views.py", line 502, in dispatch
    response = handler(request, *args, **kwargs)
  File "/home/rock/quality_inspection/python-workspace/project-sys/sys_auth/views.py", line 149, in list
    return Response(self.get_serializer(user_list, many=True).data)
  File "/home/rock/anaconda3/envs/venv/lib/python3.8/site-packages/rest_framework/serializers.py", line 760, in data
    ret = super().data
  File "/home/rock/anaconda3/envs/venv/lib/python3.8/site-packages/rest_framework/serializers.py", line 260, in data
    self._data = self.to_representation(self.instance)
  File "/home/rock/anaconda3/envs/venv/lib/python3.8/site-packages/rest_framework/serializers.py", line 677, in to_representation
    return [
  File "/home/rock/anaconda3/envs/venv/lib/python3.8/site-packages/rest_framework/serializers.py", line 678, in <listcomp>
    self.child.to_representation(item) for item in iterable
  File "/home/rock/anaconda3/envs/venv/lib/python3.8/site-packages/rest_framework/serializers.py", line 516, in to_representation
    attribute = field.get_attribute(instance)
  File "/home/rock/anaconda3/envs/venv/lib/python3.8/site-packages/rest_framework/fields.py", line 487, in get_attribute
    raise type(exc)(msg)
AttributeError: Got AttributeError when attempting to get a value for field `username` on serializer `UserSerializer`.
The serializer field might be named incorrectly and not match any attribute or key on the `tuple` instance.
Original exception text was: 'tuple' object has no attribute 'username'.
[2020-06-11 11:07:00,493] [basehttp.py:157] [basehttp:log_message] [ERROR]- "GET /user/ HTTP/1.1" 500 21077
[2020-06-11 11:12:43,192] [autoreload.py:222] [autoreload:trigger_reload] [INFO]- /home/rock/quality_inspection/python-workspace/project-sys/sys_auth/views.py changed, reloading.
[2020-06-11 11:12:43,616] [autoreload.py:598] [autoreload:run_with_reloader] [INFO]- Watching for file changes with StatReloader
[2020-06-11 11:12:44,316] [basehttp.py:157] [basehttp:log_message] [INFO]- "GET /user/ HTTP/1.1" 200 6840
[2020-06-11 11:13:50,450] [autoreload.py:222] [autoreload:trigger_reload] [INFO]- /home/rock/quality_inspection/python-workspace/project-sys/sys_auth/views.py changed, reloading.
[2020-06-11 11:13:50,768] [autoreload.py:598] [autoreload:run_with_reloader] [INFO]- Watching for file changes with StatReloader
[2020-06-11 11:15:28,129] [basehttp.py:157] [basehttp:log_message] [INFO]- "OPTIONS /user/?current_page=1&pre_page=10 HTTP/1.1" 200 0
[2020-06-11 11:15:28,157] [basehttp.py:157] [basehttp:log_message] [INFO]- "GET /user/?current_page=1&pre_page=10 HTTP/1.1" 200 1819
[2020-06-11 11:18:52,987] [basehttp.py:157] [basehttp:log_message] [INFO]- "GET /user/?current_page=1&pre_page=10 HTTP/1.1" 200 1819
[2020-06-11 11:19:33,792] [log.py:222] [log:log_response] [WARNING]- Forbidden: /role/
[2020-06-11 11:19:33,793] [basehttp.py:157] [basehttp:log_message] [WARNING]- "GET /role/ HTTP/1.1" 403 40
[2020-06-11 11:19:59,580] [basehttp.py:157] [basehttp:log_message] [INFO]- "GET /role/ HTTP/1.1" 200 4667
[2020-06-11 11:21:50,815] [basehttp.py:157] [basehttp:log_message] [INFO]- "GET /role/user?mlq=&pid=1 HTTP/1.1" 301 0
[2020-06-11 11:21:50,856] [log.py:222] [log:log_response] [ERROR]- Internal Server Error: /role/user/
Traceback (most recent call last):
  File "/home/rock/anaconda3/envs/venv/lib/python3.8/site-packages/django/core/handlers/exception.py", line 34, in inner
    response = get_response(request)
  File "/home/rock/anaconda3/envs/venv/lib/python3.8/site-packages/django/core/handlers/base.py", line 115, in _get_response
    response = self.process_exception_by_middleware(e, request)
  File "/home/rock/anaconda3/envs/venv/lib/python3.8/site-packages/django/core/handlers/base.py", line 113, in _get_response
    response = wrapped_callback(request, *callback_args, **callback_kwargs)
  File "/home/rock/anaconda3/envs/venv/lib/python3.8/site-packages/django/views/decorators/csrf.py", line 54, in wrapped_view
    return view_func(*args, **kwargs)
  File "/home/rock/anaconda3/envs/venv/lib/python3.8/site-packages/rest_framework/viewsets.py", line 114, in view
    return self.dispatch(request, *args, **kwargs)
  File "/home/rock/anaconda3/envs/venv/lib/python3.8/site-packages/rest_framework/views.py", line 505, in dispatch
    response = self.handle_exception(exc)
  File "/home/rock/anaconda3/envs/venv/lib/python3.8/site-packages/rest_framework/views.py", line 465, in handle_exception
    self.raise_uncaught_exception(exc)
  File "/home/rock/anaconda3/envs/venv/lib/python3.8/site-packages/rest_framework/views.py", line 476, in raise_uncaught_exception
    raise exc
  File "/home/rock/anaconda3/envs/venv/lib/python3.8/site-packages/rest_framework/views.py", line 502, in dispatch
    response = handler(request, *args, **kwargs)
  File "/home/rock/quality_inspection/python-workspace/project-sys/sys_auth/views.py", line 198, in user
    role_info = RoleUser.objects.filter(user_id=user_info.id).first()
AttributeError: 'NoneType' object has no attribute 'id'
[2020-06-11 11:21:50,856] [basehttp.py:157] [basehttp:log_message] [ERROR]- "GET /role/user/?mlq=&pid=1 HTTP/1.1" 500 19291
[2020-06-11 11:22:16,237] [basehttp.py:157] [basehttp:log_message] [INFO]- "GET /role/user?mlq=&pid=1 HTTP/1.1" 301 0
[2020-06-11 11:22:16,257] [log.py:222] [log:log_response] [ERROR]- Internal Server Error: /role/user/
Traceback (most recent call last):
  File "/home/rock/anaconda3/envs/venv/lib/python3.8/site-packages/django/core/handlers/exception.py", line 34, in inner
    response = get_response(request)
  File "/home/rock/anaconda3/envs/venv/lib/python3.8/site-packages/django/core/handlers/base.py", line 115, in _get_response
    response = self.process_exception_by_middleware(e, request)
  File "/home/rock/anaconda3/envs/venv/lib/python3.8/site-packages/django/core/handlers/base.py", line 113, in _get_response
    response = wrapped_callback(request, *callback_args, **callback_kwargs)
  File "/home/rock/anaconda3/envs/venv/lib/python3.8/site-packages/django/views/decorators/csrf.py", line 54, in wrapped_view
    return view_func(*args, **kwargs)
  File "/home/rock/anaconda3/envs/venv/lib/python3.8/site-packages/rest_framework/viewsets.py", line 114, in view
    return self.dispatch(request, *args, **kwargs)
  File "/home/rock/anaconda3/envs/venv/lib/python3.8/site-packages/rest_framework/views.py", line 505, in dispatch
    response = self.handle_exception(exc)
  File "/home/rock/anaconda3/envs/venv/lib/python3.8/site-packages/rest_framework/views.py", line 465, in handle_exception
    self.raise_uncaught_exception(exc)
  File "/home/rock/anaconda3/envs/venv/lib/python3.8/site-packages/rest_framework/views.py", line 476, in raise_uncaught_exception
    raise exc
  File "/home/rock/anaconda3/envs/venv/lib/python3.8/site-packages/rest_framework/views.py", line 502, in dispatch
    response = handler(request, *args, **kwargs)
  File "/home/rock/quality_inspection/python-workspace/project-sys/sys_auth/views.py", line 198, in user
    role_info = RoleUser.objects.filter(user_id=user_info.id).first()
AttributeError: 'NoneType' object has no attribute 'id'
[2020-06-11 11:22:16,257] [basehttp.py:157] [basehttp:log_message] [ERROR]- "GET /role/user/?mlq=&pid=1 HTTP/1.1" 500 19291
[2020-06-11 11:22:41,772] [basehttp.py:157] [basehttp:log_message] [INFO]- "GET /role/user?username=mlq&pid=1 HTTP/1.1" 301 0
[2020-06-11 11:22:41,788] [basehttp.py:157] [basehttp:log_message] [INFO]- "GET /role/user/?username=mlq&pid=1 HTTP/1.1" 200 846
[2020-06-11 11:23:24,749] [basehttp.py:157] [basehttp:log_message] [INFO]- "GET /role/user?username=admin&pid=1 HTTP/1.1" 301 0
[2020-06-11 11:23:24,768] [basehttp.py:157] [basehttp:log_message] [INFO]- "GET /role/user/?username=admin&pid=1 HTTP/1.1" 200 1591
[2020-06-11 11:24:50,195] [basehttp.py:157] [basehttp:log_message] [INFO]- "GET /role/user?username=%E9%A9%AC%E5%88%A9%E5%BC%BA&pid=1 HTTP/1.1" 301 0
[2020-06-11 11:24:52,819] [basehttp.py:157] [basehttp:log_message] [INFO]- "GET /role/user?username=%E9%A9%AC%E5%88%A9%E5%BC%BA&pid=1 HTTP/1.1" 301 0
[2020-06-11 11:24:54,200] [basehttp.py:157] [basehttp:log_message] [INFO]- "GET /role/user?username=%E9%A9%AC%E5%88%A9%E5%BC%BA&pid=1 HTTP/1.1" 301 0
[2020-06-11 11:24:54,913] [basehttp.py:157] [basehttp:log_message] [INFO]- "GET /role/user?username=%E9%A9%AC%E5%88%A9%E5%BC%BA&pid=1 HTTP/1.1" 301 0
[2020-06-11 12:05:13,133] [autoreload.py:222] [autoreload:trigger_reload] [INFO]- /home/rock/quality_inspection/python-workspace/project-sys/sys_auth/views.py changed, reloading.
[2020-06-11 12:05:13,875] [autoreload.py:598] [autoreload:run_with_reloader] [INFO]- Watching for file changes with StatReloader
[2020-06-11 12:13:35,288] [autoreload.py:222] [autoreload:trigger_reload] [INFO]- /home/rock/quality_inspection/python-workspace/project-sys/sys_auth/views.py changed, reloading.
[2020-06-11 12:13:35,681] [autoreload.py:598] [autoreload:run_with_reloader] [INFO]- Watching for file changes with StatReloader
[2020-06-11 12:13:41,518] [basehttp.py:157] [basehttp:log_message] [INFO]- "GET /user/ HTTP/1.1" 200 6840
[2020-06-11 12:14:03,150] [autoreload.py:222] [autoreload:trigger_reload] [INFO]- /home/rock/quality_inspection/python-workspace/project-sys/sys_auth/views.py changed, reloading.
[2020-06-11 12:14:03,529] [autoreload.py:598] [autoreload:run_with_reloader] [INFO]- Watching for file changes with StatReloader
[2020-06-11 12:14:04,090] [basehttp.py:157] [basehttp:log_message] [INFO]- "GET /user/ HTTP/1.1" 200 6840
[2020-06-11 12:15:00,005] [autoreload.py:222] [autoreload:trigger_reload] [INFO]- /home/rock/quality_inspection/python-workspace/project-sys/sys_auth/views.py changed, reloading.
[2020-06-11 12:15:00,394] [autoreload.py:598] [autoreload:run_with_reloader] [INFO]- Watching for file changes with StatReloader
[2020-06-11 12:15:00,914] [basehttp.py:157] [basehttp:log_message] [INFO]- "GET /user/ HTTP/1.1" 200 6840
[2020-06-11 12:17:17,005] [autoreload.py:222] [autoreload:trigger_reload] [INFO]- /home/rock/quality_inspection/python-workspace/project-sys/sys_auth/views.py changed, reloading.
[2020-06-11 12:17:17,394] [autoreload.py:598] [autoreload:run_with_reloader] [INFO]- Watching for file changes with StatReloader
[2020-06-11 12:17:28,050] [autoreload.py:222] [autoreload:trigger_reload] [INFO]- /home/rock/quality_inspection/python-workspace/project-sys/sys_auth/views.py changed, reloading.
[2020-06-11 12:17:28,475] [autoreload.py:598] [autoreload:run_with_reloader] [INFO]- Watching for file changes with StatReloader
[2020-06-11 12:17:29,415] [basehttp.py:157] [basehttp:log_message] [INFO]- "GET /user/ HTTP/1.1" 200 6840
[2020-06-11 12:21:56,220] [autoreload.py:222] [autoreload:trigger_reload] [INFO]- /home/rock/quality_inspection/python-workspace/project-sys/sys_auth/views.py changed, reloading.
[2020-06-11 12:21:56,697] [autoreload.py:598] [autoreload:run_with_reloader] [INFO]- Watching for file changes with StatReloader
[2020-06-11 12:24:45,045] [autoreload.py:222] [autoreload:trigger_reload] [INFO]- /home/rock/quality_inspection/python-workspace/project-sys/sys_auth/views.py changed, reloading.
[2020-06-11 12:24:45,357] [autoreload.py:598] [autoreload:run_with_reloader] [INFO]- Watching for file changes with StatReloader
[2020-06-11 12:25:07,634] [autoreload.py:222] [autoreload:trigger_reload] [INFO]- /home/rock/quality_inspection/python-workspace/project-sys/sys_auth/views.py changed, reloading.
[2020-06-11 12:25:07,964] [autoreload.py:598] [autoreload:run_with_reloader] [INFO]- Watching for file changes with StatReloader
[2020-06-11 12:31:08,175] [autoreload.py:222] [autoreload:trigger_reload] [INFO]- /home/rock/quality_inspection/python-workspace/project-sys/sys_auth/views.py changed, reloading.
[2020-06-11 12:31:08,773] [autoreload.py:598] [autoreload:run_with_reloader] [INFO]- Watching for file changes with StatReloader
[2020-06-11 12:32:18,101] [autoreload.py:222] [autoreload:trigger_reload] [INFO]- /home/rock/quality_inspection/python-workspace/project-sys/sys_auth/views.py changed, reloading.
[2020-06-11 12:32:18,513] [autoreload.py:598] [autoreload:run_with_reloader] [INFO]- Watching for file changes with StatReloader
[2020-06-11 12:33:42,218] [basehttp.py:157] [basehttp:log_message] [INFO]- "GET /role/role_by_user?username=mlq HTTP/1.1" 301 0
[2020-06-11 12:33:42,229] [log.py:222] [log:log_response] [WARNING]- Forbidden: /role/role_by_user/
[2020-06-11 12:33:42,229] [basehttp.py:157] [basehttp:log_message] [WARNING]- "GET /role/role_by_user/?username=mlq HTTP/1.1" 403 40
[2020-06-11 12:34:11,192] [basehttp.py:157] [basehttp:log_message] [INFO]- "GET /role/role_by_user?username=mlq HTTP/1.1" 301 0
[2020-06-11 12:34:11,236] [log.py:222] [log:log_response] [ERROR]- Internal Server Error: /role/role_by_user/
Traceback (most recent call last):
  File "/home/rock/anaconda3/envs/venv/lib/python3.8/site-packages/django/core/handlers/exception.py", line 34, in inner
    response = get_response(request)
  File "/home/rock/anaconda3/envs/venv/lib/python3.8/site-packages/django/core/handlers/base.py", line 115, in _get_response
    response = self.process_exception_by_middleware(e, request)
  File "/home/rock/anaconda3/envs/venv/lib/python3.8/site-packages/django/core/handlers/base.py", line 113, in _get_response
    response = wrapped_callback(request, *callback_args, **callback_kwargs)
  File "/home/rock/anaconda3/envs/venv/lib/python3.8/site-packages/django/views/decorators/csrf.py", line 54, in wrapped_view
    return view_func(*args, **kwargs)
  File "/home/rock/anaconda3/envs/venv/lib/python3.8/site-packages/rest_framework/viewsets.py", line 114, in view
    return self.dispatch(request, *args, **kwargs)
  File "/home/rock/anaconda3/envs/venv/lib/python3.8/site-packages/rest_framework/views.py", line 505, in dispatch
    response = self.handle_exception(exc)
  File "/home/rock/anaconda3/envs/venv/lib/python3.8/site-packages/rest_framework/views.py", line 465, in handle_exception
    self.raise_uncaught_exception(exc)
  File "/home/rock/anaconda3/envs/venv/lib/python3.8/site-packages/rest_framework/views.py", line 476, in raise_uncaught_exception
    raise exc
  File "/home/rock/anaconda3/envs/venv/lib/python3.8/site-packages/rest_framework/views.py", line 502, in dispatch
    response = handler(request, *args, **kwargs)
  File "/home/rock/quality_inspection/python-workspace/project-sys/sys_auth/views.py", line 266, in role_by_user
    role = Role.objects.filter(user_username=user_name).all()
  File "/home/rock/anaconda3/envs/venv/lib/python3.8/site-packages/django/db/models/manager.py", line 82, in manager_method
    return getattr(self.get_queryset(), name)(*args, **kwargs)
  File "/home/rock/anaconda3/envs/venv/lib/python3.8/site-packages/django/db/models/query.py", line 904, in filter
    return self._filter_or_exclude(False, *args, **kwargs)
  File "/home/rock/anaconda3/envs/venv/lib/python3.8/site-packages/django/db/models/query.py", line 923, in _filter_or_exclude
    clone.query.add_q(Q(*args, **kwargs))
  File "/home/rock/anaconda3/envs/venv/lib/python3.8/site-packages/django/db/models/sql/query.py", line 1351, in add_q
    clause, _ = self._add_q(q_object, self.used_aliases)
  File "/home/rock/anaconda3/envs/venv/lib/python3.8/site-packages/django/db/models/sql/query.py", line 1378, in _add_q
    child_clause, needed_inner = self.build_filter(
  File "/home/rock/anaconda3/envs/venv/lib/python3.8/site-packages/django/db/models/sql/query.py", line 1251, in build_filter
    lookups, parts, reffed_expression = self.solve_lookup_type(arg)
  File "/home/rock/anaconda3/envs/venv/lib/python3.8/site-packages/django/db/models/sql/query.py", line 1088, in solve_lookup_type
    _, field, _, lookup_parts = self.names_to_path(lookup_splitted, self.get_meta())
  File "/home/rock/anaconda3/envs/venv/lib/python3.8/site-packages/django/db/models/sql/query.py", line 1483, in names_to_path
    raise FieldError("Cannot resolve keyword '%s' into field. "
django.core.exceptions.FieldError: Cannot resolve keyword 'user_username' into field. Choices are: create_time, id, is_delete, mark, menus, name, remove_time, rolemenu, roleuser, users
[2020-06-11 12:34:11,238] [basehttp.py:157] [basehttp:log_message] [ERROR]- "GET /role/role_by_user/?username=mlq HTTP/1.1" 500 21026
[2020-06-11 12:34:48,370] [autoreload.py:222] [autoreload:trigger_reload] [INFO]- /home/rock/quality_inspection/python-workspace/project-sys/sys_auth/views.py changed, reloading.
[2020-06-11 12:34:48,748] [autoreload.py:598] [autoreload:run_with_reloader] [INFO]- Watching for file changes with StatReloader
[2020-06-11 12:34:50,770] [basehttp.py:157] [basehttp:log_message] [INFO]- "GET /role/role_by_user?username=mlq HTTP/1.1" 301 0
[2020-06-11 12:34:50,816] [log.py:222] [log:log_response] [ERROR]- Internal Server Error: /role/role_by_user/
Traceback (most recent call last):
  File "/home/rock/anaconda3/envs/venv/lib/python3.8/site-packages/rest_framework/fields.py", line 454, in get_attribute
    return get_attribute(instance, self.source_attrs)
  File "/home/rock/anaconda3/envs/venv/lib/python3.8/site-packages/rest_framework/fields.py", line 94, in get_attribute
    instance = getattr(instance, attr)
AttributeError: 'QuerySet' object has no attribute 'name'

During handling of the above exception, another exception occurred:

Traceback (most recent call last):
  File "/home/rock/anaconda3/envs/venv/lib/python3.8/site-packages/django/core/handlers/exception.py", line 34, in inner
    response = get_response(request)
  File "/home/rock/anaconda3/envs/venv/lib/python3.8/site-packages/django/core/handlers/base.py", line 115, in _get_response
    response = self.process_exception_by_middleware(e, request)
  File "/home/rock/anaconda3/envs/venv/lib/python3.8/site-packages/django/core/handlers/base.py", line 113, in _get_response
    response = wrapped_callback(request, *callback_args, **callback_kwargs)
  File "/home/rock/anaconda3/envs/venv/lib/python3.8/site-packages/django/views/decorators/csrf.py", line 54, in wrapped_view
    return view_func(*args, **kwargs)
  File "/home/rock/anaconda3/envs/venv/lib/python3.8/site-packages/rest_framework/viewsets.py", line 114, in view
    return self.dispatch(request, *args, **kwargs)
  File "/home/rock/anaconda3/envs/venv/lib/python3.8/site-packages/rest_framework/views.py", line 505, in dispatch
    response = self.handle_exception(exc)
  File "/home/rock/anaconda3/envs/venv/lib/python3.8/site-packages/rest_framework/views.py", line 465, in handle_exception
    self.raise_uncaught_exception(exc)
  File "/home/rock/anaconda3/envs/venv/lib/python3.8/site-packages/rest_framework/views.py", line 476, in raise_uncaught_exception
    raise exc
  File "/home/rock/anaconda3/envs/venv/lib/python3.8/site-packages/rest_framework/views.py", line 502, in dispatch
    response = handler(request, *args, **kwargs)
  File "/home/rock/quality_inspection/python-workspace/project-sys/sys_auth/views.py", line 268, in role_by_user
    return Response(serializer.data)
  File "/home/rock/anaconda3/envs/venv/lib/python3.8/site-packages/rest_framework/serializers.py", line 562, in data
    ret = super().data
  File "/home/rock/anaconda3/envs/venv/lib/python3.8/site-packages/rest_framework/serializers.py", line 260, in data
    self._data = self.to_representation(self.instance)
  File "/home/rock/anaconda3/envs/venv/lib/python3.8/site-packages/rest_framework/serializers.py", line 516, in to_representation
    attribute = field.get_attribute(instance)
  File "/home/rock/anaconda3/envs/venv/lib/python3.8/site-packages/rest_framework/fields.py", line 487, in get_attribute
    raise type(exc)(msg)
AttributeError: Got AttributeError when attempting to get a value for field `name` on serializer `RoleSerializer`.
The serializer field might be named incorrectly and not match any attribute or key on the `QuerySet` instance.
Original exception text was: 'QuerySet' object has no attribute 'name'.
[2020-06-11 12:34:50,817] [basehttp.py:157] [basehttp:log_message] [ERROR]- "GET /role/role_by_user/?username=mlq HTTP/1.1" 500 20875
[2020-06-11 12:34:57,835] [basehttp.py:157] [basehttp:log_message] [INFO]- "GET /role/role_by_user?username=mlq HTTP/1.1" 301 0
[2020-06-11 12:34:57,871] [log.py:222] [log:log_response] [ERROR]- Internal Server Error: /role/role_by_user/
Traceback (most recent call last):
  File "/home/rock/anaconda3/envs/venv/lib/python3.8/site-packages/rest_framework/fields.py", line 454, in get_attribute
    return get_attribute(instance, self.source_attrs)
  File "/home/rock/anaconda3/envs/venv/lib/python3.8/site-packages/rest_framework/fields.py", line 94, in get_attribute
    instance = getattr(instance, attr)
AttributeError: 'QuerySet' object has no attribute 'name'

During handling of the above exception, another exception occurred:

Traceback (most recent call last):
  File "/home/rock/anaconda3/envs/venv/lib/python3.8/site-packages/django/core/handlers/exception.py", line 34, in inner
    response = get_response(request)
  File "/home/rock/anaconda3/envs/venv/lib/python3.8/site-packages/django/core/handlers/base.py", line 115, in _get_response
    response = self.process_exception_by_middleware(e, request)
  File "/home/rock/anaconda3/envs/venv/lib/python3.8/site-packages/django/core/handlers/base.py", line 113, in _get_response
    response = wrapped_callback(request, *callback_args, **callback_kwargs)
  File "/home/rock/anaconda3/envs/venv/lib/python3.8/site-packages/django/views/decorators/csrf.py", line 54, in wrapped_view
    return view_func(*args, **kwargs)
  File "/home/rock/anaconda3/envs/venv/lib/python3.8/site-packages/rest_framework/viewsets.py", line 114, in view
    return self.dispatch(request, *args, **kwargs)
  File "/home/rock/anaconda3/envs/venv/lib/python3.8/site-packages/rest_framework/views.py", line 505, in dispatch
    response = self.handle_exception(exc)
  File "/home/rock/anaconda3/envs/venv/lib/python3.8/site-packages/rest_framework/views.py", line 465, in handle_exception
    self.raise_uncaught_exception(exc)
  File "/home/rock/anaconda3/envs/venv/lib/python3.8/site-packages/rest_framework/views.py", line 476, in raise_uncaught_exception
    raise exc
  File "/home/rock/anaconda3/envs/venv/lib/python3.8/site-packages/rest_framework/views.py", line 502, in dispatch
    response = handler(request, *args, **kwargs)
  File "/home/rock/quality_inspection/python-workspace/project-sys/sys_auth/views.py", line 268, in role_by_user
    return Response(serializer.data)
  File "/home/rock/anaconda3/envs/venv/lib/python3.8/site-packages/rest_framework/serializers.py", line 562, in data
    ret = super().data
  File "/home/rock/anaconda3/envs/venv/lib/python3.8/site-packages/rest_framework/serializers.py", line 260, in data
    self._data = self.to_representation(self.instance)
  File "/home/rock/anaconda3/envs/venv/lib/python3.8/site-packages/rest_framework/serializers.py", line 516, in to_representation
    attribute = field.get_attribute(instance)
  File "/home/rock/anaconda3/envs/venv/lib/python3.8/site-packages/rest_framework/fields.py", line 487, in get_attribute
    raise type(exc)(msg)
AttributeError: Got AttributeError when attempting to get a value for field `name` on serializer `RoleSerializer`.
The serializer field might be named incorrectly and not match any attribute or key on the `QuerySet` instance.
Original exception text was: 'QuerySet' object has no attribute 'name'.
[2020-06-11 12:34:57,872] [basehttp.py:157] [basehttp:log_message] [ERROR]- "GET /role/role_by_user/?username=mlq HTTP/1.1" 500 20875
[2020-06-11 12:35:07,777] [autoreload.py:222] [autoreload:trigger_reload] [INFO]- /home/rock/quality_inspection/python-workspace/project-sys/sys_auth/views.py changed, reloading.
[2020-06-11 12:35:08,130] [autoreload.py:598] [autoreload:run_with_reloader] [INFO]- Watching for file changes with StatReloader
[2020-06-11 12:35:09,048] [basehttp.py:157] [basehttp:log_message] [INFO]- "GET /role/role_by_user?username=mlq HTTP/1.1" 301 0
[2020-06-11 12:35:09,095] [log.py:222] [log:log_response] [ERROR]- Internal Server Error: /role/role_by_user/
Traceback (most recent call last):
  File "/home/rock/anaconda3/envs/venv/lib/python3.8/site-packages/django/core/handlers/exception.py", line 34, in inner
    response = get_response(request)
  File "/home/rock/anaconda3/envs/venv/lib/python3.8/site-packages/django/core/handlers/base.py", line 115, in _get_response
    response = self.process_exception_by_middleware(e, request)
  File "/home/rock/anaconda3/envs/venv/lib/python3.8/site-packages/django/core/handlers/base.py", line 113, in _get_response
    response = wrapped_callback(request, *callback_args, **callback_kwargs)
  File "/home/rock/anaconda3/envs/venv/lib/python3.8/site-packages/django/views/decorators/csrf.py", line 54, in wrapped_view
    return view_func(*args, **kwargs)
  File "/home/rock/anaconda3/envs/venv/lib/python3.8/site-packages/rest_framework/viewsets.py", line 114, in view
    return self.dispatch(request, *args, **kwargs)
  File "/home/rock/anaconda3/envs/venv/lib/python3.8/site-packages/rest_framework/views.py", line 505, in dispatch
    response = self.handle_exception(exc)
  File "/home/rock/anaconda3/envs/venv/lib/python3.8/site-packages/rest_framework/views.py", line 465, in handle_exception
    self.raise_uncaught_exception(exc)
  File "/home/rock/anaconda3/envs/venv/lib/python3.8/site-packages/rest_framework/views.py", line 476, in raise_uncaught_exception
    raise exc
  File "/home/rock/anaconda3/envs/venv/lib/python3.8/site-packages/rest_framework/views.py", line 502, in dispatch
    response = handler(request, *args, **kwargs)
  File "/home/rock/quality_inspection/python-workspace/project-sys/sys_auth/views.py", line 266, in role_by_user
    role = Role.objects.filter(user__username=user_name).all()
  File "/home/rock/anaconda3/envs/venv/lib/python3.8/site-packages/django/db/models/manager.py", line 82, in manager_method
    return getattr(self.get_queryset(), name)(*args, **kwargs)
  File "/home/rock/anaconda3/envs/venv/lib/python3.8/site-packages/django/db/models/query.py", line 904, in filter
    return self._filter_or_exclude(False, *args, **kwargs)
  File "/home/rock/anaconda3/envs/venv/lib/python3.8/site-packages/django/db/models/query.py", line 923, in _filter_or_exclude
    clone.query.add_q(Q(*args, **kwargs))
  File "/home/rock/anaconda3/envs/venv/lib/python3.8/site-packages/django/db/models/sql/query.py", line 1351, in add_q
    clause, _ = self._add_q(q_object, self.used_aliases)
  File "/home/rock/anaconda3/envs/venv/lib/python3.8/site-packages/django/db/models/sql/query.py", line 1378, in _add_q
    child_clause, needed_inner = self.build_filter(
  File "/home/rock/anaconda3/envs/venv/lib/python3.8/site-packages/django/db/models/sql/query.py", line 1251, in build_filter
    lookups, parts, reffed_expression = self.solve_lookup_type(arg)
  File "/home/rock/anaconda3/envs/venv/lib/python3.8/site-packages/django/db/models/sql/query.py", line 1088, in solve_lookup_type
    _, field, _, lookup_parts = self.names_to_path(lookup_splitted, self.get_meta())
  File "/home/rock/anaconda3/envs/venv/lib/python3.8/site-packages/django/db/models/sql/query.py", line 1483, in names_to_path
    raise FieldError("Cannot resolve keyword '%s' into field. "
django.core.exceptions.FieldError: Cannot resolve keyword 'user' into field. Choices are: create_time, id, is_delete, mark, menus, name, remove_time, rolemenu, roleuser, users
[2020-06-11 12:35:09,097] [basehttp.py:157] [basehttp:log_message] [ERROR]- "GET /role/role_by_user/?username=mlq HTTP/1.1" 500 21009
[2020-06-11 12:36:54,811] [autoreload.py:222] [autoreload:trigger_reload] [INFO]- /home/rock/quality_inspection/python-workspace/project-sys/sys_auth/views.py changed, reloading.
[2020-06-11 12:36:55,194] [autoreload.py:598] [autoreload:run_with_reloader] [INFO]- Watching for file changes with StatReloader
[2020-06-11 12:36:55,446] [basehttp.py:157] [basehttp:log_message] [INFO]- "GET /role/role_by_user?username=mlq HTTP/1.1" 301 0
[2020-06-11 12:36:55,486] [log.py:222] [log:log_response] [ERROR]- Internal Server Error: /role/role_by_user/
Traceback (most recent call last):
  File "/home/rock/anaconda3/envs/venv/lib/python3.8/site-packages/django/core/handlers/exception.py", line 34, in inner
    response = get_response(request)
  File "/home/rock/anaconda3/envs/venv/lib/python3.8/site-packages/django/core/handlers/base.py", line 115, in _get_response
    response = self.process_exception_by_middleware(e, request)
  File "/home/rock/anaconda3/envs/venv/lib/python3.8/site-packages/django/core/handlers/base.py", line 113, in _get_response
    response = wrapped_callback(request, *callback_args, **callback_kwargs)
  File "/home/rock/anaconda3/envs/venv/lib/python3.8/site-packages/django/views/decorators/csrf.py", line 54, in wrapped_view
    return view_func(*args, **kwargs)
  File "/home/rock/anaconda3/envs/venv/lib/python3.8/site-packages/rest_framework/viewsets.py", line 114, in view
    return self.dispatch(request, *args, **kwargs)
  File "/home/rock/anaconda3/envs/venv/lib/python3.8/site-packages/rest_framework/views.py", line 505, in dispatch
    response = self.handle_exception(exc)
  File "/home/rock/anaconda3/envs/venv/lib/python3.8/site-packages/rest_framework/views.py", line 465, in handle_exception
    self.raise_uncaught_exception(exc)
  File "/home/rock/anaconda3/envs/venv/lib/python3.8/site-packages/rest_framework/views.py", line 476, in raise_uncaught_exception
    raise exc
  File "/home/rock/anaconda3/envs/venv/lib/python3.8/site-packages/rest_framework/views.py", line 502, in dispatch
    response = handler(request, *args, **kwargs)
  File "/home/rock/quality_inspection/python-workspace/project-sys/sys_auth/views.py", line 266, in role_by_user
    role = Role.objects.filter(user__username=user_name).all()
  File "/home/rock/anaconda3/envs/venv/lib/python3.8/site-packages/django/db/models/manager.py", line 82, in manager_method
    return getattr(self.get_queryset(), name)(*args, **kwargs)
  File "/home/rock/anaconda3/envs/venv/lib/python3.8/site-packages/django/db/models/query.py", line 904, in filter
    return self._filter_or_exclude(False, *args, **kwargs)
  File "/home/rock/anaconda3/envs/venv/lib/python3.8/site-packages/django/db/models/query.py", line 923, in _filter_or_exclude
    clone.query.add_q(Q(*args, **kwargs))
  File "/home/rock/anaconda3/envs/venv/lib/python3.8/site-packages/django/db/models/sql/query.py", line 1351, in add_q
    clause, _ = self._add_q(q_object, self.used_aliases)
  File "/home/rock/anaconda3/envs/venv/lib/python3.8/site-packages/django/db/models/sql/query.py", line 1378, in _add_q
    child_clause, needed_inner = self.build_filter(
  File "/home/rock/anaconda3/envs/venv/lib/python3.8/site-packages/django/db/models/sql/query.py", line 1251, in build_filter
    lookups, parts, reffed_expression = self.solve_lookup_type(arg)
  File "/home/rock/anaconda3/envs/venv/lib/python3.8/site-packages/django/db/models/sql/query.py", line 1088, in solve_lookup_type
    _, field, _, lookup_parts = self.names_to_path(lookup_splitted, self.get_meta())
  File "/home/rock/anaconda3/envs/venv/lib/python3.8/site-packages/django/db/models/sql/query.py", line 1483, in names_to_path
    raise FieldError("Cannot resolve keyword '%s' into field. "
django.core.exceptions.FieldError: Cannot resolve keyword 'user' into field. Choices are: create_time, id, is_delete, mark, menus, name, remove_time, rolemenu, roleuser, users
[2020-06-11 12:36:55,487] [basehttp.py:157] [basehttp:log_message] [ERROR]- "GET /role/role_by_user/?username=mlq HTTP/1.1" 500 21009
[2020-06-11 12:37:17,343] [autoreload.py:222] [autoreload:trigger_reload] [INFO]- /home/rock/quality_inspection/python-workspace/project-sys/sys_auth/views.py changed, reloading.
[2020-06-11 12:37:17,746] [autoreload.py:598] [autoreload:run_with_reloader] [INFO]- Watching for file changes with StatReloader
[2020-06-11 12:37:18,125] [basehttp.py:157] [basehttp:log_message] [INFO]- "GET /role/role_by_user?username=mlq HTTP/1.1" 301 0
[2020-06-11 12:37:18,180] [log.py:222] [log:log_response] [ERROR]- Internal Server Error: /role/role_by_user/
Traceback (most recent call last):
  File "/home/rock/anaconda3/envs/venv/lib/python3.8/site-packages/rest_framework/fields.py", line 454, in get_attribute
    return get_attribute(instance, self.source_attrs)
  File "/home/rock/anaconda3/envs/venv/lib/python3.8/site-packages/rest_framework/fields.py", line 94, in get_attribute
    instance = getattr(instance, attr)
AttributeError: 'QuerySet' object has no attribute 'name'

During handling of the above exception, another exception occurred:

Traceback (most recent call last):
  File "/home/rock/anaconda3/envs/venv/lib/python3.8/site-packages/django/core/handlers/exception.py", line 34, in inner
    response = get_response(request)
  File "/home/rock/anaconda3/envs/venv/lib/python3.8/site-packages/django/core/handlers/base.py", line 115, in _get_response
    response = self.process_exception_by_middleware(e, request)
  File "/home/rock/anaconda3/envs/venv/lib/python3.8/site-packages/django/core/handlers/base.py", line 113, in _get_response
    response = wrapped_callback(request, *callback_args, **callback_kwargs)
  File "/home/rock/anaconda3/envs/venv/lib/python3.8/site-packages/django/views/decorators/csrf.py", line 54, in wrapped_view
    return view_func(*args, **kwargs)
  File "/home/rock/anaconda3/envs/venv/lib/python3.8/site-packages/rest_framework/viewsets.py", line 114, in view
    return self.dispatch(request, *args, **kwargs)
  File "/home/rock/anaconda3/envs/venv/lib/python3.8/site-packages/rest_framework/views.py", line 505, in dispatch
    response = self.handle_exception(exc)
  File "/home/rock/anaconda3/envs/venv/lib/python3.8/site-packages/rest_framework/views.py", line 465, in handle_exception
    self.raise_uncaught_exception(exc)
  File "/home/rock/anaconda3/envs/venv/lib/python3.8/site-packages/rest_framework/views.py", line 476, in raise_uncaught_exception
    raise exc
  File "/home/rock/anaconda3/envs/venv/lib/python3.8/site-packages/rest_framework/views.py", line 502, in dispatch
    response = handler(request, *args, **kwargs)
  File "/home/rock/quality_inspection/python-workspace/project-sys/sys_auth/views.py", line 270, in role_by_user
    return Response(serializer.data)
  File "/home/rock/anaconda3/envs/venv/lib/python3.8/site-packages/rest_framework/serializers.py", line 562, in data
    ret = super().data
  File "/home/rock/anaconda3/envs/venv/lib/python3.8/site-packages/rest_framework/serializers.py", line 260, in data
    self._data = self.to_representation(self.instance)
  File "/home/rock/anaconda3/envs/venv/lib/python3.8/site-packages/rest_framework/serializers.py", line 516, in to_representation
    attribute = field.get_attribute(instance)
  File "/home/rock/anaconda3/envs/venv/lib/python3.8/site-packages/rest_framework/fields.py", line 487, in get_attribute
    raise type(exc)(msg)
AttributeError: Got AttributeError when attempting to get a value for field `name` on serializer `RoleSerializer`.
The serializer field might be named incorrectly and not match any attribute or key on the `QuerySet` instance.
Original exception text was: 'QuerySet' object has no attribute 'name'.
[2020-06-11 12:37:18,181] [basehttp.py:157] [basehttp:log_message] [ERROR]- "GET /role/role_by_user/?username=mlq HTTP/1.1" 500 20875
[2020-06-11 12:37:45,427] [autoreload.py:222] [autoreload:trigger_reload] [INFO]- /home/rock/quality_inspection/python-workspace/project-sys/sys_auth/views.py changed, reloading.
[2020-06-11 12:37:45,847] [autoreload.py:598] [autoreload:run_with_reloader] [INFO]- Watching for file changes with StatReloader
[2020-06-11 12:37:46,218] [basehttp.py:157] [basehttp:log_message] [INFO]- "GET /role/role_by_user?username=mlq HTTP/1.1" 301 0
[2020-06-11 12:37:46,266] [log.py:222] [log:log_response] [ERROR]- Internal Server Error: /role/role_by_user/
Traceback (most recent call last):
  File "/home/rock/anaconda3/envs/venv/lib/python3.8/site-packages/rest_framework/fields.py", line 454, in get_attribute
    return get_attribute(instance, self.source_attrs)
  File "/home/rock/anaconda3/envs/venv/lib/python3.8/site-packages/rest_framework/fields.py", line 94, in get_attribute
    instance = getattr(instance, attr)
AttributeError: 'QuerySet' object has no attribute 'name'

During handling of the above exception, another exception occurred:

Traceback (most recent call last):
  File "/home/rock/anaconda3/envs/venv/lib/python3.8/site-packages/django/core/handlers/exception.py", line 34, in inner
    response = get_response(request)
  File "/home/rock/anaconda3/envs/venv/lib/python3.8/site-packages/django/core/handlers/base.py", line 115, in _get_response
    response = self.process_exception_by_middleware(e, request)
  File "/home/rock/anaconda3/envs/venv/lib/python3.8/site-packages/django/core/handlers/base.py", line 113, in _get_response
    response = wrapped_callback(request, *callback_args, **callback_kwargs)
  File "/home/rock/anaconda3/envs/venv/lib/python3.8/site-packages/django/views/decorators/csrf.py", line 54, in wrapped_view
    return view_func(*args, **kwargs)
  File "/home/rock/anaconda3/envs/venv/lib/python3.8/site-packages/rest_framework/viewsets.py", line 114, in view
    return self.dispatch(request, *args, **kwargs)
  File "/home/rock/anaconda3/envs/venv/lib/python3.8/site-packages/rest_framework/views.py", line 505, in dispatch
    response = self.handle_exception(exc)
  File "/home/rock/anaconda3/envs/venv/lib/python3.8/site-packages/rest_framework/views.py", line 465, in handle_exception
    self.raise_uncaught_exception(exc)
  File "/home/rock/anaconda3/envs/venv/lib/python3.8/site-packages/rest_framework/views.py", line 476, in raise_uncaught_exception
    raise exc
  File "/home/rock/anaconda3/envs/venv/lib/python3.8/site-packages/rest_framework/views.py", line 502, in dispatch
    response = handler(request, *args, **kwargs)
  File "/home/rock/quality_inspection/python-workspace/project-sys/sys_auth/views.py", line 272, in role_by_user
    return Response(serializer.data)
  File "/home/rock/anaconda3/envs/venv/lib/python3.8/site-packages/rest_framework/serializers.py", line 562, in data
    ret = super().data
  File "/home/rock/anaconda3/envs/venv/lib/python3.8/site-packages/rest_framework/serializers.py", line 260, in data
    self._data = self.to_representation(self.instance)
  File "/home/rock/anaconda3/envs/venv/lib/python3.8/site-packages/rest_framework/serializers.py", line 516, in to_representation
    attribute = field.get_attribute(instance)
  File "/home/rock/anaconda3/envs/venv/lib/python3.8/site-packages/rest_framework/fields.py", line 487, in get_attribute
    raise type(exc)(msg)
AttributeError: Got AttributeError when attempting to get a value for field `name` on serializer `RoleSerializer`.
The serializer field might be named incorrectly and not match any attribute or key on the `QuerySet` instance.
Original exception text was: 'QuerySet' object has no attribute 'name'.
[2020-06-11 12:37:46,268] [basehttp.py:157] [basehttp:log_message] [ERROR]- "GET /role/role_by_user/?username=mlq HTTP/1.1" 500 20875
[2020-06-11 12:39:26,751] [autoreload.py:222] [autoreload:trigger_reload] [INFO]- /home/rock/quality_inspection/python-workspace/project-sys/sys_auth/views.py changed, reloading.
[2020-06-11 12:39:27,139] [autoreload.py:598] [autoreload:run_with_reloader] [INFO]- Watching for file changes with StatReloader
[2020-06-11 12:39:28,096] [basehttp.py:157] [basehttp:log_message] [INFO]- "GET /role/role_by_user?username=mlq HTTP/1.1" 301 0
[2020-06-11 12:39:28,137] [log.py:222] [log:log_response] [ERROR]- Internal Server Error: /role/role_by_user/
Traceback (most recent call last):
  File "/home/rock/anaconda3/envs/venv/lib/python3.8/site-packages/rest_framework/fields.py", line 454, in get_attribute
    return get_attribute(instance, self.source_attrs)
  File "/home/rock/anaconda3/envs/venv/lib/python3.8/site-packages/rest_framework/fields.py", line 94, in get_attribute
    instance = getattr(instance, attr)
AttributeError: 'QuerySet' object has no attribute 'name'

During handling of the above exception, another exception occurred:

Traceback (most recent call last):
  File "/home/rock/anaconda3/envs/venv/lib/python3.8/site-packages/django/core/handlers/exception.py", line 34, in inner
    response = get_response(request)
  File "/home/rock/anaconda3/envs/venv/lib/python3.8/site-packages/django/core/handlers/base.py", line 115, in _get_response
    response = self.process_exception_by_middleware(e, request)
  File "/home/rock/anaconda3/envs/venv/lib/python3.8/site-packages/django/core/handlers/base.py", line 113, in _get_response
    response = wrapped_callback(request, *callback_args, **callback_kwargs)
  File "/home/rock/anaconda3/envs/venv/lib/python3.8/site-packages/django/views/decorators/csrf.py", line 54, in wrapped_view
    return view_func(*args, **kwargs)
  File "/home/rock/anaconda3/envs/venv/lib/python3.8/site-packages/rest_framework/viewsets.py", line 114, in view
    return self.dispatch(request, *args, **kwargs)
  File "/home/rock/anaconda3/envs/venv/lib/python3.8/site-packages/rest_framework/views.py", line 505, in dispatch
    response = self.handle_exception(exc)
  File "/home/rock/anaconda3/envs/venv/lib/python3.8/site-packages/rest_framework/views.py", line 465, in handle_exception
    self.raise_uncaught_exception(exc)
  File "/home/rock/anaconda3/envs/venv/lib/python3.8/site-packages/rest_framework/views.py", line 476, in raise_uncaught_exception
    raise exc
  File "/home/rock/anaconda3/envs/venv/lib/python3.8/site-packages/rest_framework/views.py", line 502, in dispatch
    response = handler(request, *args, **kwargs)
  File "/home/rock/quality_inspection/python-workspace/project-sys/sys_auth/views.py", line 273, in role_by_user
    return Response(serializer.data)
  File "/home/rock/anaconda3/envs/venv/lib/python3.8/site-packages/rest_framework/serializers.py", line 562, in data
    ret = super().data
  File "/home/rock/anaconda3/envs/venv/lib/python3.8/site-packages/rest_framework/serializers.py", line 260, in data
    self._data = self.to_representation(self.instance)
  File "/home/rock/anaconda3/envs/venv/lib/python3.8/site-packages/rest_framework/serializers.py", line 516, in to_representation
    attribute = field.get_attribute(instance)
  File "/home/rock/anaconda3/envs/venv/lib/python3.8/site-packages/rest_framework/fields.py", line 487, in get_attribute
    raise type(exc)(msg)
AttributeError: Got AttributeError when attempting to get a value for field `name` on serializer `RoleSerializer`.
The serializer field might be named incorrectly and not match any attribute or key on the `QuerySet` instance.
Original exception text was: 'QuerySet' object has no attribute 'name'.
[2020-06-11 12:39:28,139] [basehttp.py:157] [basehttp:log_message] [ERROR]- "GET /role/role_by_user/?username=mlq HTTP/1.1" 500 20875
[2020-06-11 12:42:03,822] [autoreload.py:222] [autoreload:trigger_reload] [INFO]- /home/rock/quality_inspection/python-workspace/project-sys/sys_auth/views.py changed, reloading.
[2020-06-11 12:42:04,296] [autoreload.py:598] [autoreload:run_with_reloader] [INFO]- Watching for file changes with StatReloader
[2020-06-11 12:44:49,930] [autoreload.py:222] [autoreload:trigger_reload] [INFO]- /home/rock/quality_inspection/python-workspace/project-sys/sys_auth/views.py changed, reloading.
[2020-06-11 12:44:50,262] [autoreload.py:598] [autoreload:run_with_reloader] [INFO]- Watching for file changes with StatReloader
[2020-06-11 12:44:50,927] [basehttp.py:157] [basehttp:log_message] [INFO]- "GET /role/role_by_user?username=mlq HTTP/1.1" 301 0
[2020-06-11 12:44:50,986] [log.py:222] [log:log_response] [ERROR]- Internal Server Error: /role/role_by_user/
Traceback (most recent call last):
  File "/home/rock/anaconda3/envs/venv/lib/python3.8/site-packages/rest_framework/fields.py", line 454, in get_attribute
    return get_attribute(instance, self.source_attrs)
  File "/home/rock/anaconda3/envs/venv/lib/python3.8/site-packages/rest_framework/fields.py", line 94, in get_attribute
    instance = getattr(instance, attr)
AttributeError: 'QuerySet' object has no attribute 'name'

During handling of the above exception, another exception occurred:

Traceback (most recent call last):
  File "/home/rock/anaconda3/envs/venv/lib/python3.8/site-packages/django/core/handlers/exception.py", line 34, in inner
    response = get_response(request)
  File "/home/rock/anaconda3/envs/venv/lib/python3.8/site-packages/django/core/handlers/base.py", line 115, in _get_response
    response = self.process_exception_by_middleware(e, request)
  File "/home/rock/anaconda3/envs/venv/lib/python3.8/site-packages/django/core/handlers/base.py", line 113, in _get_response
    response = wrapped_callback(request, *callback_args, **callback_kwargs)
  File "/home/rock/anaconda3/envs/venv/lib/python3.8/site-packages/django/views/decorators/csrf.py", line 54, in wrapped_view
    return view_func(*args, **kwargs)
  File "/home/rock/anaconda3/envs/venv/lib/python3.8/site-packages/rest_framework/viewsets.py", line 114, in view
    return self.dispatch(request, *args, **kwargs)
  File "/home/rock/anaconda3/envs/venv/lib/python3.8/site-packages/rest_framework/views.py", line 505, in dispatch
    response = self.handle_exception(exc)
  File "/home/rock/anaconda3/envs/venv/lib/python3.8/site-packages/rest_framework/views.py", line 465, in handle_exception
    self.raise_uncaught_exception(exc)
  File "/home/rock/anaconda3/envs/venv/lib/python3.8/site-packages/rest_framework/views.py", line 476, in raise_uncaught_exception
    raise exc
  File "/home/rock/anaconda3/envs/venv/lib/python3.8/site-packages/rest_framework/views.py", line 502, in dispatch
    response = handler(request, *args, **kwargs)
  File "/home/rock/quality_inspection/python-workspace/project-sys/sys_auth/views.py", line 273, in role_by_user
    return Response(serializer.data)
  File "/home/rock/anaconda3/envs/venv/lib/python3.8/site-packages/rest_framework/serializers.py", line 562, in data
    ret = super().data
  File "/home/rock/anaconda3/envs/venv/lib/python3.8/site-packages/rest_framework/serializers.py", line 260, in data
    self._data = self.to_representation(self.instance)
  File "/home/rock/anaconda3/envs/venv/lib/python3.8/site-packages/rest_framework/serializers.py", line 516, in to_representation
    attribute = field.get_attribute(instance)
  File "/home/rock/anaconda3/envs/venv/lib/python3.8/site-packages/rest_framework/fields.py", line 487, in get_attribute
    raise type(exc)(msg)
AttributeError: Got AttributeError when attempting to get a value for field `name` on serializer `RoleSerializer`.
The serializer field might be named incorrectly and not match any attribute or key on the `QuerySet` instance.
Original exception text was: 'QuerySet' object has no attribute 'name'.
[2020-06-11 12:44:50,988] [basehttp.py:157] [basehttp:log_message] [ERROR]- "GET /role/role_by_user/?username=mlq HTTP/1.1" 500 20875
[2020-06-11 12:46:59,341] [autoreload.py:222] [autoreload:trigger_reload] [INFO]- /home/rock/quality_inspection/python-workspace/project-sys/sys_auth/serializers.py changed, reloading.
[2020-06-11 12:46:59,715] [autoreload.py:598] [autoreload:run_with_reloader] [INFO]- Watching for file changes with StatReloader
[2020-06-11 12:47:03,022] [basehttp.py:157] [basehttp:log_message] [INFO]- "GET /role/role_by_user?username=mlq HTTP/1.1" 301 0
[2020-06-11 12:47:03,068] [log.py:222] [log:log_response] [ERROR]- Internal Server Error: /role/role_by_user/
Traceback (most recent call last):
  File "/home/rock/anaconda3/envs/venv/lib/python3.8/site-packages/rest_framework/fields.py", line 454, in get_attribute
    return get_attribute(instance, self.source_attrs)
  File "/home/rock/anaconda3/envs/venv/lib/python3.8/site-packages/rest_framework/fields.py", line 94, in get_attribute
    instance = getattr(instance, attr)
AttributeError: 'QuerySet' object has no attribute 'name'

During handling of the above exception, another exception occurred:

Traceback (most recent call last):
  File "/home/rock/anaconda3/envs/venv/lib/python3.8/site-packages/django/core/handlers/exception.py", line 34, in inner
    response = get_response(request)
  File "/home/rock/anaconda3/envs/venv/lib/python3.8/site-packages/django/core/handlers/base.py", line 115, in _get_response
    response = self.process_exception_by_middleware(e, request)
  File "/home/rock/anaconda3/envs/venv/lib/python3.8/site-packages/django/core/handlers/base.py", line 113, in _get_response
    response = wrapped_callback(request, *callback_args, **callback_kwargs)
  File "/home/rock/anaconda3/envs/venv/lib/python3.8/site-packages/django/views/decorators/csrf.py", line 54, in wrapped_view
    return view_func(*args, **kwargs)
  File "/home/rock/anaconda3/envs/venv/lib/python3.8/site-packages/rest_framework/viewsets.py", line 114, in view
    return self.dispatch(request, *args, **kwargs)
  File "/home/rock/anaconda3/envs/venv/lib/python3.8/site-packages/rest_framework/views.py", line 505, in dispatch
    response = self.handle_exception(exc)
  File "/home/rock/anaconda3/envs/venv/lib/python3.8/site-packages/rest_framework/views.py", line 465, in handle_exception
    self.raise_uncaught_exception(exc)
  File "/home/rock/anaconda3/envs/venv/lib/python3.8/site-packages/rest_framework/views.py", line 476, in raise_uncaught_exception
    raise exc
  File "/home/rock/anaconda3/envs/venv/lib/python3.8/site-packages/rest_framework/views.py", line 502, in dispatch
    response = handler(request, *args, **kwargs)
  File "/home/rock/quality_inspection/python-workspace/project-sys/sys_auth/views.py", line 273, in role_by_user
    return Response(serializer.data)
  File "/home/rock/anaconda3/envs/venv/lib/python3.8/site-packages/rest_framework/serializers.py", line 562, in data
    ret = super().data
  File "/home/rock/anaconda3/envs/venv/lib/python3.8/site-packages/rest_framework/serializers.py", line 260, in data
    self._data = self.to_representation(self.instance)
  File "/home/rock/anaconda3/envs/venv/lib/python3.8/site-packages/rest_framework/serializers.py", line 516, in to_representation
    attribute = field.get_attribute(instance)
  File "/home/rock/anaconda3/envs/venv/lib/python3.8/site-packages/rest_framework/fields.py", line 487, in get_attribute
    raise type(exc)(msg)
AttributeError: Got AttributeError when attempting to get a value for field `name` on serializer `RoleSerializer`.
The serializer field might be named incorrectly and not match any attribute or key on the `QuerySet` instance.
Original exception text was: 'QuerySet' object has no attribute 'name'.
[2020-06-11 12:47:03,070] [basehttp.py:157] [basehttp:log_message] [ERROR]- "GET /role/role_by_user/?username=mlq HTTP/1.1" 500 20875
[2020-06-11 12:47:14,777] [autoreload.py:222] [autoreload:trigger_reload] [INFO]- /home/rock/quality_inspection/python-workspace/project-sys/sys_auth/serializers.py changed, reloading.
[2020-06-11 12:47:15,137] [autoreload.py:598] [autoreload:run_with_reloader] [INFO]- Watching for file changes with StatReloader
[2020-06-11 12:47:24,567] [basehttp.py:157] [basehttp:log_message] [INFO]- "GET /role/user?username=mlq&pid=1 HTTP/1.1" 301 0
[2020-06-11 12:47:24,582] [basehttp.py:157] [basehttp:log_message] [INFO]- "GET /role/user/?username=mlq&pid=1 HTTP/1.1" 200 846
[2020-06-11 12:48:27,012] [autoreload.py:222] [autoreload:trigger_reload] [INFO]- /home/rock/quality_inspection/python-workspace/project-sys/sys_auth/views.py changed, reloading.
[2020-06-11 12:48:27,372] [autoreload.py:598] [autoreload:run_with_reloader] [INFO]- Watching for file changes with StatReloader
[2020-06-11 12:49:34,696] [autoreload.py:222] [autoreload:trigger_reload] [INFO]- /home/rock/quality_inspection/python-workspace/project-sys/sys_auth/views.py changed, reloading.
[2020-06-11 12:49:35,062] [autoreload.py:598] [autoreload:run_with_reloader] [INFO]- Watching for file changes with StatReloader
[2020-06-11 12:49:37,670] [basehttp.py:157] [basehttp:log_message] [INFO]- "GET /role/role_by_user?username=mlq HTTP/1.1" 301 0
[2020-06-11 12:49:37,709] [log.py:222] [log:log_response] [ERROR]- Internal Server Error: /role/role_by_user/
Traceback (most recent call last):
  File "/home/rock/anaconda3/envs/venv/lib/python3.8/site-packages/django/core/handlers/exception.py", line 34, in inner
    response = get_response(request)
  File "/home/rock/anaconda3/envs/venv/lib/python3.8/site-packages/django/core/handlers/base.py", line 115, in _get_response
    response = self.process_exception_by_middleware(e, request)
  File "/home/rock/anaconda3/envs/venv/lib/python3.8/site-packages/django/core/handlers/base.py", line 113, in _get_response
    response = wrapped_callback(request, *callback_args, **callback_kwargs)
  File "/home/rock/anaconda3/envs/venv/lib/python3.8/site-packages/django/views/decorators/csrf.py", line 54, in wrapped_view
    return view_func(*args, **kwargs)
  File "/home/rock/anaconda3/envs/venv/lib/python3.8/site-packages/rest_framework/viewsets.py", line 114, in view
    return self.dispatch(request, *args, **kwargs)
  File "/home/rock/anaconda3/envs/venv/lib/python3.8/site-packages/rest_framework/views.py", line 505, in dispatch
    response = self.handle_exception(exc)
  File "/home/rock/anaconda3/envs/venv/lib/python3.8/site-packages/rest_framework/views.py", line 465, in handle_exception
    self.raise_uncaught_exception(exc)
  File "/home/rock/anaconda3/envs/venv/lib/python3.8/site-packages/rest_framework/views.py", line 476, in raise_uncaught_exception
    raise exc
  File "/home/rock/anaconda3/envs/venv/lib/python3.8/site-packages/rest_framework/views.py", line 502, in dispatch
    response = handler(request, *args, **kwargs)
  File "/home/rock/quality_inspection/python-workspace/project-sys/sys_auth/views.py", line 268, in role_by_user
    print(role.name)
AttributeError: 'QuerySet' object has no attribute 'name'
[2020-06-11 12:49:37,710] [basehttp.py:157] [basehttp:log_message] [ERROR]- "GET /role/role_by_user/?username=mlq HTTP/1.1" 500 19298
[2020-06-11 12:49:58,442] [autoreload.py:222] [autoreload:trigger_reload] [INFO]- /home/rock/quality_inspection/python-workspace/project-sys/sys_auth/views.py changed, reloading.
[2020-06-11 12:49:58,805] [autoreload.py:598] [autoreload:run_with_reloader] [INFO]- Watching for file changes with StatReloader
[2020-06-11 12:49:59,008] [basehttp.py:157] [basehttp:log_message] [INFO]- "GET /role/role_by_user?username=mlq HTTP/1.1" 301 0
[2020-06-11 12:49:59,085] [log.py:222] [log:log_response] [ERROR]- Internal Server Error: /role/role_by_user/
Traceback (most recent call last):
  File "/home/rock/anaconda3/envs/venv/lib/python3.8/site-packages/django/core/handlers/exception.py", line 34, in inner
    response = get_response(request)
  File "/home/rock/anaconda3/envs/venv/lib/python3.8/site-packages/django/core/handlers/base.py", line 115, in _get_response
    response = self.process_exception_by_middleware(e, request)
  File "/home/rock/anaconda3/envs/venv/lib/python3.8/site-packages/django/core/handlers/base.py", line 113, in _get_response
    response = wrapped_callback(request, *callback_args, **callback_kwargs)
  File "/home/rock/anaconda3/envs/venv/lib/python3.8/site-packages/django/views/decorators/csrf.py", line 54, in wrapped_view
    return view_func(*args, **kwargs)
  File "/home/rock/anaconda3/envs/venv/lib/python3.8/site-packages/rest_framework/viewsets.py", line 114, in view
    return self.dispatch(request, *args, **kwargs)
  File "/home/rock/anaconda3/envs/venv/lib/python3.8/site-packages/rest_framework/views.py", line 505, in dispatch
    response = self.handle_exception(exc)
  File "/home/rock/anaconda3/envs/venv/lib/python3.8/site-packages/rest_framework/views.py", line 465, in handle_exception
    self.raise_uncaught_exception(exc)
  File "/home/rock/anaconda3/envs/venv/lib/python3.8/site-packages/rest_framework/views.py", line 476, in raise_uncaught_exception
    raise exc
  File "/home/rock/anaconda3/envs/venv/lib/python3.8/site-packages/rest_framework/views.py", line 502, in dispatch
    response = handler(request, *args, **kwargs)
  File "/home/rock/quality_inspection/python-workspace/project-sys/sys_auth/views.py", line 268, in role_by_user
    print(role.name)
AttributeError: 'QuerySet' object has no attribute 'name'
[2020-06-11 12:49:59,087] [basehttp.py:157] [basehttp:log_message] [ERROR]- "GET /role/role_by_user/?username=mlq HTTP/1.1" 500 19298
[2020-06-11 12:50:24,199] [autoreload.py:222] [autoreload:trigger_reload] [INFO]- /home/rock/quality_inspection/python-workspace/project-sys/sys_auth/views.py changed, reloading.
[2020-06-11 12:50:24,663] [autoreload.py:598] [autoreload:run_with_reloader] [INFO]- Watching for file changes with StatReloader
[2020-06-11 12:51:32,028] [autoreload.py:222] [autoreload:trigger_reload] [INFO]- /home/rock/quality_inspection/python-workspace/project-sys/sys_auth/views.py changed, reloading.
[2020-06-11 12:51:32,618] [autoreload.py:598] [autoreload:run_with_reloader] [INFO]- Watching for file changes with StatReloader
[2020-06-11 12:51:35,247] [basehttp.py:157] [basehttp:log_message] [INFO]- "GET /role/role_by_user?username=mlq HTTP/1.1" 301 0
[2020-06-11 12:51:35,307] [log.py:222] [log:log_response] [ERROR]- Internal Server Error: /role/role_by_user/
Traceback (most recent call last):
  File "/home/rock/anaconda3/envs/venv/lib/python3.8/site-packages/django/core/handlers/exception.py", line 34, in inner
    response = get_response(request)
  File "/home/rock/anaconda3/envs/venv/lib/python3.8/site-packages/django/core/handlers/base.py", line 115, in _get_response
    response = self.process_exception_by_middleware(e, request)
  File "/home/rock/anaconda3/envs/venv/lib/python3.8/site-packages/django/core/handlers/base.py", line 113, in _get_response
    response = wrapped_callback(request, *callback_args, **callback_kwargs)
  File "/home/rock/anaconda3/envs/venv/lib/python3.8/site-packages/django/views/decorators/csrf.py", line 54, in wrapped_view
    return view_func(*args, **kwargs)
  File "/home/rock/anaconda3/envs/venv/lib/python3.8/site-packages/rest_framework/viewsets.py", line 114, in view
    return self.dispatch(request, *args, **kwargs)
  File "/home/rock/anaconda3/envs/venv/lib/python3.8/site-packages/rest_framework/views.py", line 505, in dispatch
    response = self.handle_exception(exc)
  File "/home/rock/anaconda3/envs/venv/lib/python3.8/site-packages/rest_framework/views.py", line 465, in handle_exception
    self.raise_uncaught_exception(exc)
  File "/home/rock/anaconda3/envs/venv/lib/python3.8/site-packages/rest_framework/views.py", line 476, in raise_uncaught_exception
    raise exc
  File "/home/rock/anaconda3/envs/venv/lib/python3.8/site-packages/rest_framework/views.py", line 502, in dispatch
    response = handler(request, *args, **kwargs)
  File "/home/rock/quality_inspection/python-workspace/project-sys/sys_auth/views.py", line 268, in role_by_user
    print(role[1])
  File "/home/rock/anaconda3/envs/venv/lib/python3.8/site-packages/django/db/models/query.py", line 314, in __getitem__
    return qs._result_cache[0]
IndexError: list index out of range
[2020-06-11 12:51:35,308] [basehttp.py:157] [basehttp:log_message] [ERROR]- "GET /role/role_by_user/?username=mlq HTTP/1.1" 500 19403
[2020-06-11 12:51:51,967] [autoreload.py:222] [autoreload:trigger_reload] [INFO]- /home/rock/quality_inspection/python-workspace/project-sys/sys_auth/views.py changed, reloading.
[2020-06-11 12:51:52,713] [autoreload.py:598] [autoreload:run_with_reloader] [INFO]- Watching for file changes with StatReloader
[2020-06-11 12:51:53,462] [basehttp.py:157] [basehttp:log_message] [INFO]- "GET /role/role_by_user?username=mlq HTTP/1.1" 301 0
[2020-06-11 12:51:53,536] [log.py:222] [log:log_response] [ERROR]- Internal Server Error: /role/role_by_user/
Traceback (most recent call last):
  File "/home/rock/anaconda3/envs/venv/lib/python3.8/site-packages/rest_framework/fields.py", line 454, in get_attribute
    return get_attribute(instance, self.source_attrs)
  File "/home/rock/anaconda3/envs/venv/lib/python3.8/site-packages/rest_framework/fields.py", line 94, in get_attribute
    instance = getattr(instance, attr)
AttributeError: 'QuerySet' object has no attribute 'name'

During handling of the above exception, another exception occurred:

Traceback (most recent call last):
  File "/home/rock/anaconda3/envs/venv/lib/python3.8/site-packages/django/core/handlers/exception.py", line 34, in inner
    response = get_response(request)
  File "/home/rock/anaconda3/envs/venv/lib/python3.8/site-packages/django/core/handlers/base.py", line 115, in _get_response
    response = self.process_exception_by_middleware(e, request)
  File "/home/rock/anaconda3/envs/venv/lib/python3.8/site-packages/django/core/handlers/base.py", line 113, in _get_response
    response = wrapped_callback(request, *callback_args, **callback_kwargs)
  File "/home/rock/anaconda3/envs/venv/lib/python3.8/site-packages/django/views/decorators/csrf.py", line 54, in wrapped_view
    return view_func(*args, **kwargs)
  File "/home/rock/anaconda3/envs/venv/lib/python3.8/site-packages/rest_framework/viewsets.py", line 114, in view
    return self.dispatch(request, *args, **kwargs)
  File "/home/rock/anaconda3/envs/venv/lib/python3.8/site-packages/rest_framework/views.py", line 505, in dispatch
    response = self.handle_exception(exc)
  File "/home/rock/anaconda3/envs/venv/lib/python3.8/site-packages/rest_framework/views.py", line 465, in handle_exception
    self.raise_uncaught_exception(exc)
  File "/home/rock/anaconda3/envs/venv/lib/python3.8/site-packages/rest_framework/views.py", line 476, in raise_uncaught_exception
    raise exc
  File "/home/rock/anaconda3/envs/venv/lib/python3.8/site-packages/rest_framework/views.py", line 502, in dispatch
    response = handler(request, *args, **kwargs)
  File "/home/rock/quality_inspection/python-workspace/project-sys/sys_auth/views.py", line 273, in role_by_user
    return Response(serializer.data)
  File "/home/rock/anaconda3/envs/venv/lib/python3.8/site-packages/rest_framework/serializers.py", line 562, in data
    ret = super().data
  File "/home/rock/anaconda3/envs/venv/lib/python3.8/site-packages/rest_framework/serializers.py", line 260, in data
    self._data = self.to_representation(self.instance)
  File "/home/rock/anaconda3/envs/venv/lib/python3.8/site-packages/rest_framework/serializers.py", line 516, in to_representation
    attribute = field.get_attribute(instance)
  File "/home/rock/anaconda3/envs/venv/lib/python3.8/site-packages/rest_framework/fields.py", line 487, in get_attribute
    raise type(exc)(msg)
AttributeError: Got AttributeError when attempting to get a value for field `name` on serializer `RoleSerializer`.
The serializer field might be named incorrectly and not match any attribute or key on the `QuerySet` instance.
Original exception text was: 'QuerySet' object has no attribute 'name'.
[2020-06-11 12:51:53,538] [basehttp.py:157] [basehttp:log_message] [ERROR]- "GET /role/role_by_user/?username=mlq HTTP/1.1" 500 20875
[2020-06-11 12:52:51,552] [autoreload.py:222] [autoreload:trigger_reload] [INFO]- /home/rock/quality_inspection/python-workspace/project-sys/sys_auth/views.py changed, reloading.
[2020-06-11 12:52:52,156] [autoreload.py:598] [autoreload:run_with_reloader] [INFO]- Watching for file changes with StatReloader
[2020-06-11 12:52:52,703] [basehttp.py:157] [basehttp:log_message] [INFO]- "GET /role/role_by_user?username=mlq HTTP/1.1" 301 0
[2020-06-11 12:52:52,771] [log.py:222] [log:log_response] [ERROR]- Internal Server Error: /role/role_by_user/
Traceback (most recent call last):
  File "/home/rock/anaconda3/envs/venv/lib/python3.8/site-packages/rest_framework/fields.py", line 454, in get_attribute
    return get_attribute(instance, self.source_attrs)
  File "/home/rock/anaconda3/envs/venv/lib/python3.8/site-packages/rest_framework/fields.py", line 94, in get_attribute
    instance = getattr(instance, attr)
AttributeError: 'QuerySet' object has no attribute 'name'

During handling of the above exception, another exception occurred:

Traceback (most recent call last):
  File "/home/rock/anaconda3/envs/venv/lib/python3.8/site-packages/django/core/handlers/exception.py", line 34, in inner
    response = get_response(request)
  File "/home/rock/anaconda3/envs/venv/lib/python3.8/site-packages/django/core/handlers/base.py", line 115, in _get_response
    response = self.process_exception_by_middleware(e, request)
  File "/home/rock/anaconda3/envs/venv/lib/python3.8/site-packages/django/core/handlers/base.py", line 113, in _get_response
    response = wrapped_callback(request, *callback_args, **callback_kwargs)
  File "/home/rock/anaconda3/envs/venv/lib/python3.8/site-packages/django/views/decorators/csrf.py", line 54, in wrapped_view
    return view_func(*args, **kwargs)
  File "/home/rock/anaconda3/envs/venv/lib/python3.8/site-packages/rest_framework/viewsets.py", line 114, in view
    return self.dispatch(request, *args, **kwargs)
  File "/home/rock/anaconda3/envs/venv/lib/python3.8/site-packages/rest_framework/views.py", line 505, in dispatch
    response = self.handle_exception(exc)
  File "/home/rock/anaconda3/envs/venv/lib/python3.8/site-packages/rest_framework/views.py", line 465, in handle_exception
    self.raise_uncaught_exception(exc)
  File "/home/rock/anaconda3/envs/venv/lib/python3.8/site-packages/rest_framework/views.py", line 476, in raise_uncaught_exception
    raise exc
  File "/home/rock/anaconda3/envs/venv/lib/python3.8/site-packages/rest_framework/views.py", line 502, in dispatch
    response = handler(request, *args, **kwargs)
  File "/home/rock/quality_inspection/python-workspace/project-sys/sys_auth/views.py", line 273, in role_by_user
    return Response(serializer.data)
  File "/home/rock/anaconda3/envs/venv/lib/python3.8/site-packages/rest_framework/serializers.py", line 562, in data
    ret = super().data
  File "/home/rock/anaconda3/envs/venv/lib/python3.8/site-packages/rest_framework/serializers.py", line 260, in data
    self._data = self.to_representation(self.instance)
  File "/home/rock/anaconda3/envs/venv/lib/python3.8/site-packages/rest_framework/serializers.py", line 516, in to_representation
    attribute = field.get_attribute(instance)
  File "/home/rock/anaconda3/envs/venv/lib/python3.8/site-packages/rest_framework/fields.py", line 487, in get_attribute
    raise type(exc)(msg)
AttributeError: Got AttributeError when attempting to get a value for field `name` on serializer `RoleSerializer`.
The serializer field might be named incorrectly and not match any attribute or key on the `QuerySet` instance.
Original exception text was: 'QuerySet' object has no attribute 'name'.
[2020-06-11 12:52:52,773] [basehttp.py:157] [basehttp:log_message] [ERROR]- "GET /role/role_by_user/?username=mlq HTTP/1.1" 500 20875
[2020-06-11 12:54:45,954] [basehttp.py:157] [basehttp:log_message] [INFO]- "GET /role/role_by_user?username=mlq HTTP/1.1" 301 0
[2020-06-11 12:54:45,997] [log.py:222] [log:log_response] [ERROR]- Internal Server Error: /role/role_by_user/
Traceback (most recent call last):
  File "/home/rock/anaconda3/envs/venv/lib/python3.8/site-packages/rest_framework/fields.py", line 454, in get_attribute
    return get_attribute(instance, self.source_attrs)
  File "/home/rock/anaconda3/envs/venv/lib/python3.8/site-packages/rest_framework/fields.py", line 94, in get_attribute
    instance = getattr(instance, attr)
AttributeError: 'QuerySet' object has no attribute 'name'

During handling of the above exception, another exception occurred:

Traceback (most recent call last):
  File "/home/rock/anaconda3/envs/venv/lib/python3.8/site-packages/django/core/handlers/exception.py", line 34, in inner
    response = get_response(request)
  File "/home/rock/anaconda3/envs/venv/lib/python3.8/site-packages/django/core/handlers/base.py", line 115, in _get_response
    response = self.process_exception_by_middleware(e, request)
  File "/home/rock/anaconda3/envs/venv/lib/python3.8/site-packages/django/core/handlers/base.py", line 113, in _get_response
    response = wrapped_callback(request, *callback_args, **callback_kwargs)
  File "/home/rock/anaconda3/envs/venv/lib/python3.8/site-packages/django/views/decorators/csrf.py", line 54, in wrapped_view
    return view_func(*args, **kwargs)
  File "/home/rock/anaconda3/envs/venv/lib/python3.8/site-packages/rest_framework/viewsets.py", line 114, in view
    return self.dispatch(request, *args, **kwargs)
  File "/home/rock/anaconda3/envs/venv/lib/python3.8/site-packages/rest_framework/views.py", line 505, in dispatch
    response = self.handle_exception(exc)
  File "/home/rock/anaconda3/envs/venv/lib/python3.8/site-packages/rest_framework/views.py", line 465, in handle_exception
    self.raise_uncaught_exception(exc)
  File "/home/rock/anaconda3/envs/venv/lib/python3.8/site-packages/rest_framework/views.py", line 476, in raise_uncaught_exception
    raise exc
  File "/home/rock/anaconda3/envs/venv/lib/python3.8/site-packages/rest_framework/views.py", line 502, in dispatch
    response = handler(request, *args, **kwargs)
  File "/home/rock/quality_inspection/python-workspace/project-sys/sys_auth/views.py", line 273, in role_by_user
    return Response(serializer.data)
  File "/home/rock/anaconda3/envs/venv/lib/python3.8/site-packages/rest_framework/serializers.py", line 562, in data
    ret = super().data
  File "/home/rock/anaconda3/envs/venv/lib/python3.8/site-packages/rest_framework/serializers.py", line 260, in data
    self._data = self.to_representation(self.instance)
  File "/home/rock/anaconda3/envs/venv/lib/python3.8/site-packages/rest_framework/serializers.py", line 516, in to_representation
    attribute = field.get_attribute(instance)
  File "/home/rock/anaconda3/envs/venv/lib/python3.8/site-packages/rest_framework/fields.py", line 487, in get_attribute
    raise type(exc)(msg)
AttributeError: Got AttributeError when attempting to get a value for field `name` on serializer `RoleSerializer`.
The serializer field might be named incorrectly and not match any attribute or key on the `QuerySet` instance.
Original exception text was: 'QuerySet' object has no attribute 'name'.
[2020-06-11 12:54:45,998] [basehttp.py:157] [basehttp:log_message] [ERROR]- "GET /role/role_by_user/?username=mlq HTTP/1.1" 500 20875
[2020-06-11 12:55:48,214] [autoreload.py:222] [autoreload:trigger_reload] [INFO]- /home/rock/quality_inspection/python-workspace/project-sys/sys_auth/serializers.py changed, reloading.
[2020-06-11 12:55:48,791] [autoreload.py:598] [autoreload:run_with_reloader] [INFO]- Watching for file changes with StatReloader
[2020-06-11 12:55:49,595] [basehttp.py:157] [basehttp:log_message] [INFO]- "GET /role/role_by_user?username=mlq HTTP/1.1" 301 0
[2020-06-11 12:55:49,652] [log.py:222] [log:log_response] [ERROR]- Internal Server Error: /role/role_by_user/
Traceback (most recent call last):
  File "/home/rock/anaconda3/envs/venv/lib/python3.8/site-packages/rest_framework/fields.py", line 454, in get_attribute
    return get_attribute(instance, self.source_attrs)
  File "/home/rock/anaconda3/envs/venv/lib/python3.8/site-packages/rest_framework/fields.py", line 94, in get_attribute
    instance = getattr(instance, attr)
AttributeError: 'QuerySet' object has no attribute 'name'

During handling of the above exception, another exception occurred:

Traceback (most recent call last):
  File "/home/rock/anaconda3/envs/venv/lib/python3.8/site-packages/django/core/handlers/exception.py", line 34, in inner
    response = get_response(request)
  File "/home/rock/anaconda3/envs/venv/lib/python3.8/site-packages/django/core/handlers/base.py", line 115, in _get_response
    response = self.process_exception_by_middleware(e, request)
  File "/home/rock/anaconda3/envs/venv/lib/python3.8/site-packages/django/core/handlers/base.py", line 113, in _get_response
    response = wrapped_callback(request, *callback_args, **callback_kwargs)
  File "/home/rock/anaconda3/envs/venv/lib/python3.8/site-packages/django/views/decorators/csrf.py", line 54, in wrapped_view
    return view_func(*args, **kwargs)
  File "/home/rock/anaconda3/envs/venv/lib/python3.8/site-packages/rest_framework/viewsets.py", line 114, in view
    return self.dispatch(request, *args, **kwargs)
  File "/home/rock/anaconda3/envs/venv/lib/python3.8/site-packages/rest_framework/views.py", line 505, in dispatch
    response = self.handle_exception(exc)
  File "/home/rock/anaconda3/envs/venv/lib/python3.8/site-packages/rest_framework/views.py", line 465, in handle_exception
    self.raise_uncaught_exception(exc)
  File "/home/rock/anaconda3/envs/venv/lib/python3.8/site-packages/rest_framework/views.py", line 476, in raise_uncaught_exception
    raise exc
  File "/home/rock/anaconda3/envs/venv/lib/python3.8/site-packages/rest_framework/views.py", line 502, in dispatch
    response = handler(request, *args, **kwargs)
  File "/home/rock/quality_inspection/python-workspace/project-sys/sys_auth/views.py", line 273, in role_by_user
    return Response(serializer.data)
  File "/home/rock/anaconda3/envs/venv/lib/python3.8/site-packages/rest_framework/serializers.py", line 562, in data
    ret = super().data
  File "/home/rock/anaconda3/envs/venv/lib/python3.8/site-packages/rest_framework/serializers.py", line 260, in data
    self._data = self.to_representation(self.instance)
  File "/home/rock/anaconda3/envs/venv/lib/python3.8/site-packages/rest_framework/serializers.py", line 516, in to_representation
    attribute = field.get_attribute(instance)
  File "/home/rock/anaconda3/envs/venv/lib/python3.8/site-packages/rest_framework/fields.py", line 487, in get_attribute
    raise type(exc)(msg)
AttributeError: Got AttributeError when attempting to get a value for field `name` on serializer `RoleSerializer`.
The serializer field might be named incorrectly and not match any attribute or key on the `QuerySet` instance.
Original exception text was: 'QuerySet' object has no attribute 'name'.
[2020-06-11 12:55:49,654] [basehttp.py:157] [basehttp:log_message] [ERROR]- "GET /role/role_by_user/?username=mlq HTTP/1.1" 500 20875
[2020-06-11 12:56:00,643] [autoreload.py:222] [autoreload:trigger_reload] [INFO]- /home/rock/quality_inspection/python-workspace/project-sys/sys_auth/serializers.py changed, reloading.
[2020-06-11 12:56:01,110] [autoreload.py:598] [autoreload:run_with_reloader] [INFO]- Watching for file changes with StatReloader
[2020-06-11 12:58:44,308] [autoreload.py:222] [autoreload:trigger_reload] [INFO]- /home/rock/quality_inspection/python-workspace/project-sys/sys_auth/views.py changed, reloading.
[2020-06-11 12:58:44,789] [autoreload.py:598] [autoreload:run_with_reloader] [INFO]- Watching for file changes with StatReloader
[2020-06-11 12:58:45,174] [basehttp.py:157] [basehttp:log_message] [INFO]- "GET /role/role_by_user?username=mlq HTTP/1.1" 301 0
[2020-06-11 12:58:45,219] [log.py:222] [log:log_response] [ERROR]- Internal Server Error: /role/role_by_user/
Traceback (most recent call last):
  File "/home/rock/anaconda3/envs/venv/lib/python3.8/site-packages/django/core/handlers/exception.py", line 34, in inner
    response = get_response(request)
  File "/home/rock/anaconda3/envs/venv/lib/python3.8/site-packages/django/core/handlers/base.py", line 115, in _get_response
    response = self.process_exception_by_middleware(e, request)
  File "/home/rock/anaconda3/envs/venv/lib/python3.8/site-packages/django/core/handlers/base.py", line 113, in _get_response
    response = wrapped_callback(request, *callback_args, **callback_kwargs)
  File "/home/rock/anaconda3/envs/venv/lib/python3.8/site-packages/django/views/decorators/csrf.py", line 54, in wrapped_view
    return view_func(*args, **kwargs)
  File "/home/rock/anaconda3/envs/venv/lib/python3.8/site-packages/rest_framework/viewsets.py", line 114, in view
    return self.dispatch(request, *args, **kwargs)
  File "/home/rock/anaconda3/envs/venv/lib/python3.8/site-packages/rest_framework/views.py", line 505, in dispatch
    response = self.handle_exception(exc)
  File "/home/rock/anaconda3/envs/venv/lib/python3.8/site-packages/rest_framework/views.py", line 465, in handle_exception
    self.raise_uncaught_exception(exc)
  File "/home/rock/anaconda3/envs/venv/lib/python3.8/site-packages/rest_framework/views.py", line 476, in raise_uncaught_exception
    raise exc
  File "/home/rock/anaconda3/envs/venv/lib/python3.8/site-packages/rest_framework/views.py", line 502, in dispatch
    response = handler(request, *args, **kwargs)
  File "/home/rock/quality_inspection/python-workspace/project-sys/sys_auth/views.py", line 269, in role_by_user
    for i in role:
TypeError: 'Role' object is not iterable
[2020-06-11 12:58:45,220] [basehttp.py:157] [basehttp:log_message] [ERROR]- "GET /role/role_by_user/?username=mlq HTTP/1.1" 500 19262
[2020-06-11 12:59:08,156] [autoreload.py:222] [autoreload:trigger_reload] [INFO]- /home/rock/quality_inspection/python-workspace/project-sys/sys_auth/views.py changed, reloading.
[2020-06-11 12:59:08,675] [autoreload.py:598] [autoreload:run_with_reloader] [INFO]- Watching for file changes with StatReloader
[2020-06-11 13:00:51,228] [autoreload.py:222] [autoreload:trigger_reload] [INFO]- /home/rock/quality_inspection/python-workspace/project-sys/sys_auth/views.py changed, reloading.
[2020-06-11 13:00:51,581] [autoreload.py:598] [autoreload:run_with_reloader] [INFO]- Watching for file changes with StatReloader
[2020-06-11 13:00:54,762] [basehttp.py:157] [basehttp:log_message] [INFO]- "GET /role/role_by_user?username=mlq HTTP/1.1" 301 0
[2020-06-11 13:00:54,779] [basehttp.py:157] [basehttp:log_message] [INFO]- "GET /role/role_by_user/?username=mlq HTTP/1.1" 200 853
[2020-06-11 13:01:24,156] [autoreload.py:222] [autoreload:trigger_reload] [INFO]- /home/rock/quality_inspection/python-workspace/project-sys/sys_auth/views.py changed, reloading.
[2020-06-11 13:01:24,520] [autoreload.py:598] [autoreload:run_with_reloader] [INFO]- Watching for file changes with StatReloader
[2020-06-11 13:01:24,810] [basehttp.py:157] [basehttp:log_message] [INFO]- "GET /role/role_by_user?username=mlq HTTP/1.1" 301 0
[2020-06-11 13:01:24,902] [log.py:222] [log:log_response] [ERROR]- Internal Server Error: /role/role_by_user/
Traceback (most recent call last):
  File "/home/rock/anaconda3/envs/venv/lib/python3.8/site-packages/rest_framework/fields.py", line 454, in get_attribute
    return get_attribute(instance, self.source_attrs)
  File "/home/rock/anaconda3/envs/venv/lib/python3.8/site-packages/rest_framework/fields.py", line 94, in get_attribute
    instance = getattr(instance, attr)
AttributeError: 'QuerySet' object has no attribute 'name'

During handling of the above exception, another exception occurred:

Traceback (most recent call last):
  File "/home/rock/anaconda3/envs/venv/lib/python3.8/site-packages/django/core/handlers/exception.py", line 34, in inner
    response = get_response(request)
  File "/home/rock/anaconda3/envs/venv/lib/python3.8/site-packages/django/core/handlers/base.py", line 115, in _get_response
    response = self.process_exception_by_middleware(e, request)
  File "/home/rock/anaconda3/envs/venv/lib/python3.8/site-packages/django/core/handlers/base.py", line 113, in _get_response
    response = wrapped_callback(request, *callback_args, **callback_kwargs)
  File "/home/rock/anaconda3/envs/venv/lib/python3.8/site-packages/django/views/decorators/csrf.py", line 54, in wrapped_view
    return view_func(*args, **kwargs)
  File "/home/rock/anaconda3/envs/venv/lib/python3.8/site-packages/rest_framework/viewsets.py", line 114, in view
    return self.dispatch(request, *args, **kwargs)
  File "/home/rock/anaconda3/envs/venv/lib/python3.8/site-packages/rest_framework/views.py", line 505, in dispatch
    response = self.handle_exception(exc)
  File "/home/rock/anaconda3/envs/venv/lib/python3.8/site-packages/rest_framework/views.py", line 465, in handle_exception
    self.raise_uncaught_exception(exc)
  File "/home/rock/anaconda3/envs/venv/lib/python3.8/site-packages/rest_framework/views.py", line 476, in raise_uncaught_exception
    raise exc
  File "/home/rock/anaconda3/envs/venv/lib/python3.8/site-packages/rest_framework/views.py", line 502, in dispatch
    response = handler(request, *args, **kwargs)
  File "/home/rock/quality_inspection/python-workspace/project-sys/sys_auth/views.py", line 273, in role_by_user
    return Response(self.get_serializer(role, many=False).data)
  File "/home/rock/anaconda3/envs/venv/lib/python3.8/site-packages/rest_framework/serializers.py", line 562, in data
    ret = super().data
  File "/home/rock/anaconda3/envs/venv/lib/python3.8/site-packages/rest_framework/serializers.py", line 260, in data
    self._data = self.to_representation(self.instance)
  File "/home/rock/anaconda3/envs/venv/lib/python3.8/site-packages/rest_framework/serializers.py", line 516, in to_representation
    attribute = field.get_attribute(instance)
  File "/home/rock/anaconda3/envs/venv/lib/python3.8/site-packages/rest_framework/fields.py", line 487, in get_attribute
    raise type(exc)(msg)
AttributeError: Got AttributeError when attempting to get a value for field `name` on serializer `RoleSerializer`.
The serializer field might be named incorrectly and not match any attribute or key on the `QuerySet` instance.
Original exception text was: 'QuerySet' object has no attribute 'name'.
[2020-06-11 13:01:24,904] [basehttp.py:157] [basehttp:log_message] [ERROR]- "GET /role/role_by_user/?username=mlq HTTP/1.1" 500 20902
[2020-06-11 13:01:32,212] [autoreload.py:222] [autoreload:trigger_reload] [INFO]- /home/rock/quality_inspection/python-workspace/project-sys/sys_auth/views.py changed, reloading.
[2020-06-11 13:01:32,611] [autoreload.py:598] [autoreload:run_with_reloader] [INFO]- Watching for file changes with StatReloader
[2020-06-11 13:01:32,914] [basehttp.py:157] [basehttp:log_message] [INFO]- "GET /role/role_by_user?username=mlq HTTP/1.1" 301 0
[2020-06-11 13:01:32,931] [basehttp.py:157] [basehttp:log_message] [INFO]- "GET /role/role_by_user/?username=mlq HTTP/1.1" 200 853
[2020-06-11 13:03:21,442] [basehttp.py:157] [basehttp:log_message] [INFO]- "OPTIONS /role/?current_page=1&pre_page=10 HTTP/1.1" 200 0
[2020-06-11 13:03:21,488] [basehttp.py:157] [basehttp:log_message] [INFO]- "GET /role/?current_page=1&pre_page=10 HTTP/1.1" 200 4743
[2020-06-11 13:03:36,958] [basehttp.py:157] [basehttp:log_message] [INFO]- "OPTIONS /user/?current_page=1&pre_page=10 HTTP/1.1" 200 0
[2020-06-11 13:03:36,974] [basehttp.py:157] [basehttp:log_message] [INFO]- "GET /user/?current_page=1&pre_page=10 HTTP/1.1" 200 1819
[2020-06-11 13:03:52,845] [basehttp.py:157] [basehttp:log_message] [INFO]- "OPTIONS /user/ HTTP/1.1" 200 0
[2020-06-11 13:03:52,866] [log.py:222] [log:log_response] [WARNING]- Bad Request: /user/
[2020-06-11 13:03:52,867] [basehttp.py:157] [basehttp:log_message] [WARNING]- "POST /user/ HTTP/1.1" 400 155
[2020-06-11 13:04:40,997] [basehttp.py:157] [basehttp:log_message] [INFO]- "GET /role/?current_page=1&pre_page=10 HTTP/1.1" 200 4743
[2020-06-11 13:06:23,705] [autoreload.py:222] [autoreload:trigger_reload] [INFO]- /home/rock/quality_inspection/python-workspace/project-sys/sys_auth/views.py changed, reloading.
[2020-06-11 13:06:24,035] [autoreload.py:598] [autoreload:run_with_reloader] [INFO]- Watching for file changes with StatReloader
[2020-06-11 13:10:55,609] [basehttp.py:157] [basehttp:log_message] [INFO]- "GET /role/?current_page=1&pre_page=10 HTTP/1.1" 200 4743
[2020-06-11 13:10:59,391] [basehttp.py:157] [basehttp:log_message] [INFO]- "GET /user/?current_page=1&pre_page=10 HTTP/1.1" 200 1819
[2020-06-11 13:15:37,896] [basehttp.py:157] [basehttp:log_message] [INFO]- "OPTIONS /user/?current_page=1&pre_page=10 HTTP/1.1" 200 0
[2020-06-11 13:15:37,912] [basehttp.py:157] [basehttp:log_message] [INFO]- "GET /user/?current_page=1&pre_page=10 HTTP/1.1" 200 1819
[2020-06-11 13:15:39,453] [basehttp.py:157] [basehttp:log_message] [INFO]- "OPTIONS /role/?current_page=1&pre_page=10 HTTP/1.1" 200 0
[2020-06-11 13:15:39,509] [basehttp.py:157] [basehttp:log_message] [INFO]- "GET /role/?current_page=1&pre_page=10 HTTP/1.1" 200 4743
[2020-06-11 13:15:48,695] [basehttp.py:157] [basehttp:log_message] [INFO]- "GET /user/?current_page=1&pre_page=10 HTTP/1.1" 200 1819
[2020-06-11 13:16:05,591] [basehttp.py:157] [basehttp:log_message] [INFO]- "GET /user/?current_page=1&pre_page=10 HTTP/1.1" 200 1819
[2020-06-11 13:16:08,901] [basehttp.py:157] [basehttp:log_message] [INFO]- "OPTIONS /role/user?username=et&pid=1 HTTP/1.1" 200 0
[2020-06-11 13:16:08,909] [basehttp.py:157] [basehttp:log_message] [INFO]- "GET /user/?current_page=1&pre_page=10 HTTP/1.1" 200 1819
[2020-06-11 13:16:09,092] [basehttp.py:157] [basehttp:log_message] [INFO]- "OPTIONS /role/user/?username=et&pid=1 HTTP/1.1" 200 0
[2020-06-11 13:16:09,116] [basehttp.py:157] [basehttp:log_message] [INFO]- "GET /role/user/?username=et&pid=1 HTTP/1.1" 200 1526
[2020-06-11 13:16:14,332] [basehttp.py:157] [basehttp:log_message] [INFO]- "OPTIONS /user/3/ HTTP/1.1" 200 0
[2020-06-11 13:16:14,496] [basehttp.py:157] [basehttp:log_message] [INFO]- "PUT /user/3/ HTTP/1.1" 200 175
[2020-06-11 13:16:14,583] [basehttp.py:157] [basehttp:log_message] [INFO]- "GET /user/?current_page=1&pre_page=10 HTTP/1.1" 200 1819
[2020-06-11 13:16:35,919] [basehttp.py:157] [basehttp:log_message] [INFO]- "OPTIONS /user/ HTTP/1.1" 200 0
[2020-06-11 13:16:36,105] [basehttp.py:157] [basehttp:log_message] [INFO]- "POST /user/ HTTP/1.1" 201 180
[2020-06-11 13:16:36,172] [basehttp.py:157] [basehttp:log_message] [INFO]- "GET /user/?current_page=1&pre_page=10 HTTP/1.1" 200 1819
[2020-06-11 13:16:40,024] [basehttp.py:157] [basehttp:log_message] [INFO]- "OPTIONS /user/?current_page=4&pre_page=10 HTTP/1.1" 200 0
[2020-06-11 13:16:40,036] [basehttp.py:157] [basehttp:log_message] [INFO]- "GET /user/?current_page=4&pre_page=10 HTTP/1.1" 200 1801
[2020-06-11 13:16:42,286] [basehttp.py:157] [basehttp:log_message] [INFO]- "GET /user/?current_page=1&pre_page=10 HTTP/1.1" 200 1819
[2020-06-11 13:16:46,889] [basehttp.py:157] [basehttp:log_message] [INFO]- "GET /user/?current_page=4&pre_page=10 HTTP/1.1" 200 1801
[2020-06-11 13:16:49,525] [basehttp.py:157] [basehttp:log_message] [INFO]- "GET /user/?current_page=1&pre_page=10 HTTP/1.1" 200 1819
[2020-06-11 13:17:13,639] [basehttp.py:157] [basehttp:log_message] [INFO]- "GET /role/?current_page=1&pre_page=10 HTTP/1.1" 200 4743
[2020-06-11 13:22:00,914] [basehttp.py:157] [basehttp:log_message] [INFO]- "GET /role/?current_page=1&pre_page=10 HTTP/1.1" 200 4743
[2020-06-11 13:22:03,495] [basehttp.py:157] [basehttp:log_message] [INFO]- "GET /role/?current_page=1&pre_page=10 HTTP/1.1" 200 4743
[2020-06-11 13:22:03,526] [basehttp.py:157] [basehttp:log_message] [INFO]- "GET /role/user/?username=et&pid=1 HTTP/1.1" 200 1526
[2020-06-11 13:22:04,356] [basehttp.py:157] [basehttp:log_message] [INFO]- "GET /user/?current_page=1&pre_page=10 HTTP/1.1" 200 1819
[2020-06-11 13:22:06,073] [basehttp.py:157] [basehttp:log_message] [INFO]- "GET /role/?current_page=1&pre_page=10 HTTP/1.1" 200 4743
[2020-06-11 13:22:13,613] [basehttp.py:157] [basehttp:log_message] [INFO]- "OPTIONS /role/1/ HTTP/1.1" 200 0
[2020-06-11 13:22:13,772] [basehttp.py:157] [basehttp:log_message] [INFO]- "PUT /role/1/ HTTP/1.1" 200 2293
[2020-06-11 13:22:13,879] [basehttp.py:157] [basehttp:log_message] [INFO]- "GET /role/?current_page=1&pre_page=10 HTTP/1.1" 200 4745
[2020-06-11 13:23:14,428] [basehttp.py:157] [basehttp:log_message] [INFO]- "GET /role/?current_page=1&pre_page=10 HTTP/1.1" 200 4745
[2020-06-11 13:23:37,851] [basehttp.py:157] [basehttp:log_message] [INFO]- "OPTIONS /role/ HTTP/1.1" 200 0
[2020-06-11 13:23:38,009] [basehttp.py:157] [basehttp:log_message] [INFO]- "POST /role/ HTTP/1.1" 201 149
[2020-06-11 13:23:38,085] [basehttp.py:157] [basehttp:log_message] [INFO]- "GET /role/?current_page=1&pre_page=10 HTTP/1.1" 200 4895
[2020-06-11 13:23:57,567] [basehttp.py:157] [basehttp:log_message] [INFO]- "GET /role/?current_page=1&pre_page=10 HTTP/1.1" 200 4895
[2020-06-11 13:25:30,343] [basehttp.py:157] [basehttp:log_message] [INFO]- "GET /role/?current_page=1&pre_page=10 HTTP/1.1" 200 4895
[2020-06-11 13:27:14,010] [basehttp.py:157] [basehttp:log_message] [INFO]- "OPTIONS /role/?current_page=1&pre_page=10 HTTP/1.1" 200 0
[2020-06-11 13:27:14,051] [basehttp.py:157] [basehttp:log_message] [INFO]- "GET /role/?current_page=1&pre_page=10 HTTP/1.1" 200 4895
[2020-06-11 13:28:08,086] [basehttp.py:157] [basehttp:log_message] [INFO]- "GET /role/?current_page=1&pre_page=10 HTTP/1.1" 200 4895
[2020-06-11 13:28:20,281] [basehttp.py:157] [basehttp:log_message] [INFO]- "OPTIONS /role/user?username=et&pid=1 HTTP/1.1" 200 0
[2020-06-11 13:28:20,305] [basehttp.py:157] [basehttp:log_message] [INFO]- "GET /role/?current_page=1&pre_page=10 HTTP/1.1" 200 4895
[2020-06-11 13:28:20,399] [basehttp.py:157] [basehttp:log_message] [INFO]- "OPTIONS /role/user/?username=et&pid=1 HTTP/1.1" 200 0
[2020-06-11 13:28:20,446] [basehttp.py:157] [basehttp:log_message] [INFO]- "GET /role/user/?username=et&pid=1 HTTP/1.1" 200 1526
[2020-06-11 13:31:28,542] [autoreload.py:222] [autoreload:trigger_reload] [INFO]- /home/rock/quality_inspection/python-workspace/project-sys/sys_auth/views.py changed, reloading.
[2020-06-11 13:31:29,052] [autoreload.py:598] [autoreload:run_with_reloader] [INFO]- Watching for file changes with StatReloader
[2020-06-11 13:37:30,462] [basehttp.py:157] [basehttp:log_message] [INFO]- "OPTIONS /role/?current_page=1&pre_page=10 HTTP/1.1" 200 0
[2020-06-11 13:37:30,544] [basehttp.py:157] [basehttp:log_message] [INFO]- "GET /role/user/?username=et&pid=1 HTTP/1.1" 200 1526
[2020-06-11 13:37:30,551] [basehttp.py:157] [basehttp:log_message] [INFO]- "GET /role/?current_page=1&pre_page=10 HTTP/1.1" 200 4895
[2020-06-11 13:39:42,085] [basehttp.py:157] [basehttp:log_message] [INFO]- "GET /role/?current_page=1&pre_page=10 HTTP/1.1" 200 4895
[2020-06-11 13:41:14,528] [basehttp.py:157] [basehttp:log_message] [INFO]- "GET /role/?current_page=1&pre_page=10 HTTP/1.1" 200 4895
[2020-06-11 13:44:40,162] [basehttp.py:157] [basehttp:log_message] [INFO]- "GET /role/?current_page=1&pre_page=10 HTTP/1.1" 200 4895
[2020-06-11 13:44:45,693] [basehttp.py:157] [basehttp:log_message] [INFO]- "GET /user/ HTTP/1.1" 200 7021
[2020-06-11 14:01:19,449] [basehttp.py:157] [basehttp:log_message] [INFO]- "OPTIONS /user/ HTTP/1.1" 200 0
[2020-06-11 14:01:19,449] [basehttp.py:157] [basehttp:log_message] [INFO]- "OPTIONS /role/?current_page=1&pre_page=10 HTTP/1.1" 200 0
[2020-06-11 14:01:19,499] [basehttp.py:157] [basehttp:log_message] [INFO]- "GET /user/ HTTP/1.1" 200 7021
[2020-06-11 14:01:19,499] [basehttp.py:157] [basehttp:log_message] [INFO]- "GET /role/?current_page=1&pre_page=10 HTTP/1.1" 200 4895
[2020-06-11 14:01:22,096] [basehttp.py:157] [basehttp:log_message] [INFO]- "OPTIONS /role/user?username=et&pid=1 HTTP/1.1" 200 0
[2020-06-11 14:01:22,144] [basehttp.py:157] [basehttp:log_message] [INFO]- "GET /user/ HTTP/1.1" 200 7021
[2020-06-11 14:01:22,147] [basehttp.py:157] [basehttp:log_message] [INFO]- "GET /role/?current_page=1&pre_page=10 HTTP/1.1" 200 4895
[2020-06-11 14:01:22,152] [basehttp.py:157] [basehttp:log_message] [INFO]- "OPTIONS /role/user/?username=et&pid=1 HTTP/1.1" 200 0
[2020-06-11 14:01:22,281] [basehttp.py:157] [basehttp:log_message] [INFO]- "GET /role/user/?username=et&pid=1 HTTP/1.1" 200 1526
[2020-06-11 14:02:31,163] [basehttp.py:157] [basehttp:log_message] [INFO]- "GET /role/?current_page=1&pre_page=10 HTTP/1.1" 200 4895
[2020-06-11 14:02:44,620] [basehttp.py:157] [basehttp:log_message] [INFO]- "GET /role/?current_page=1&pre_page=10 HTTP/1.1" 200 4895
[2020-06-11 14:02:44,652] [basehttp.py:157] [basehttp:log_message] [INFO]- "GET /role/user/?username=et&pid=1 HTTP/1.1" 200 1526
[2020-06-11 14:02:46,813] [basehttp.py:157] [basehttp:log_message] [INFO]- "GET /role/?current_page=1&pre_page=10 HTTP/1.1" 200 4895
[2020-06-11 14:02:46,840] [basehttp.py:157] [basehttp:log_message] [INFO]- "GET /role/user/?username=et&pid=1 HTTP/1.1" 200 1526
[2020-06-11 14:02:48,094] [basehttp.py:157] [basehttp:log_message] [INFO]- "GET /user/ HTTP/1.1" 200 7021
[2020-06-11 14:05:46,182] [basehttp.py:157] [basehttp:log_message] [INFO]- "GET /role/?current_page=1&pre_page=10 HTTP/1.1" 200 4895
[2020-06-11 14:07:13,564] [basehttp.py:157] [basehttp:log_message] [INFO]- "GET /role/?current_page=1&pre_page=10 HTTP/1.1" 200 4895
[2020-06-11 14:07:15,450] [basehttp.py:157] [basehttp:log_message] [INFO]- "GET /user/ HTTP/1.1" 200 7021
[2020-06-11 14:08:44,370] [basehttp.py:157] [basehttp:log_message] [INFO]- "GET /role/?current_page=1&pre_page=10 HTTP/1.1" 200 4895
[2020-06-11 14:08:46,229] [basehttp.py:157] [basehttp:log_message] [INFO]- "GET /user/ HTTP/1.1" 200 7021
[2020-06-11 14:09:26,633] [basehttp.py:157] [basehttp:log_message] [INFO]- "GET /role/?current_page=1&pre_page=10 HTTP/1.1" 200 4895
[2020-06-11 14:09:26,659] [basehttp.py:157] [basehttp:log_message] [INFO]- "GET /role/user/?username=et&pid=1 HTTP/1.1" 200 1526
[2020-06-11 14:09:29,444] [basehttp.py:157] [basehttp:log_message] [INFO]- "GET /role/?current_page=1&pre_page=10 HTTP/1.1" 200 4895
[2020-06-11 14:09:29,449] [basehttp.py:157] [basehttp:log_message] [INFO]- "GET /role/user/?username=et&pid=1 HTTP/1.1" 200 1526
[2020-06-11 14:09:31,486] [basehttp.py:157] [basehttp:log_message] [INFO]- "GET /user/ HTTP/1.1" 200 7021
[2020-06-11 14:12:47,310] [basehttp.py:157] [basehttp:log_message] [INFO]- "OPTIONS /role/?current_page=1&pre_page=10 HTTP/1.1" 200 0
[2020-06-11 14:12:47,311] [basehttp.py:157] [basehttp:log_message] [INFO]- "OPTIONS /role/user?username=et&pid=1 HTTP/1.1" 200 0
[2020-06-11 14:12:47,349] [basehttp.py:157] [basehttp:log_message] [INFO]- "OPTIONS /role/user/?username=et&pid=1 HTTP/1.1" 200 0
[2020-06-11 14:12:47,366] [basehttp.py:157] [basehttp:log_message] [INFO]- "GET /role/?current_page=1&pre_page=10 HTTP/1.1" 200 4895
[2020-06-11 14:12:47,400] [basehttp.py:157] [basehttp:log_message] [INFO]- "GET /role/user/?username=et&pid=1 HTTP/1.1" 200 1526
[2020-06-11 14:12:49,407] [basehttp.py:157] [basehttp:log_message] [INFO]- "OPTIONS /user/ HTTP/1.1" 200 0
[2020-06-11 14:12:49,526] [basehttp.py:157] [basehttp:log_message] [INFO]- "GET /user/ HTTP/1.1" 200 7021
[2020-06-11 14:12:55,309] [basehttp.py:157] [basehttp:log_message] [INFO]- "GET /user/ HTTP/1.1" 200 7021
[2020-06-11 14:13:14,172] [basehttp.py:157] [basehttp:log_message] [INFO]- "GET /role/?current_page=1&pre_page=10 HTTP/1.1" 200 4895
[2020-06-11 14:13:14,194] [basehttp.py:157] [basehttp:log_message] [INFO]- "GET /role/user/?username=et&pid=1 HTTP/1.1" 200 1526
[2020-06-11 14:13:17,049] [basehttp.py:157] [basehttp:log_message] [INFO]- "GET /user/ HTTP/1.1" 200 7021
[2020-06-11 14:13:39,950] [basehttp.py:157] [basehttp:log_message] [INFO]- "GET /user/ HTTP/1.1" 200 7021
[2020-06-11 14:16:01,209] [basehttp.py:157] [basehttp:log_message] [INFO]- "GET /role/?current_page=1&pre_page=10 HTTP/1.1" 200 4895
[2020-06-11 14:16:03,100] [basehttp.py:157] [basehttp:log_message] [INFO]- "GET /role/?current_page=1&pre_page=10 HTTP/1.1" 200 4895
[2020-06-11 14:16:03,130] [basehttp.py:157] [basehttp:log_message] [INFO]- "GET /role/user/?username=et&pid=1 HTTP/1.1" 200 1526
[2020-06-11 14:16:06,871] [basehttp.py:157] [basehttp:log_message] [INFO]- "GET /user/ HTTP/1.1" 200 7021
[2020-06-11 14:16:24,429] [basehttp.py:157] [basehttp:log_message] [INFO]- "GET /role/?current_page=1&pre_page=10 HTTP/1.1" 200 4895
[2020-06-11 14:16:29,141] [basehttp.py:157] [basehttp:log_message] [INFO]- "GET /user/ HTTP/1.1" 200 7021
[2020-06-11 14:17:01,315] [basehttp.py:157] [basehttp:log_message] [INFO]- "GET /role/?current_page=1&pre_page=10 HTTP/1.1" 200 4895
[2020-06-11 14:18:13,010] [basehttp.py:157] [basehttp:log_message] [INFO]- "GET /role/?current_page=1&pre_page=10 HTTP/1.1" 200 4895
[2020-06-11 14:18:15,254] [basehttp.py:157] [basehttp:log_message] [INFO]- "GET /user/ HTTP/1.1" 200 7021
[2020-06-11 14:18:43,522] [basehttp.py:157] [basehttp:log_message] [INFO]- "GET /role/?current_page=1&pre_page=10 HTTP/1.1" 200 4895
[2020-06-11 14:18:45,824] [basehttp.py:157] [basehttp:log_message] [INFO]- "GET /user/ HTTP/1.1" 200 7021
[2020-06-11 14:20:14,912] [basehttp.py:157] [basehttp:log_message] [INFO]- "GET /role/?current_page=1&pre_page=10 HTTP/1.1" 200 4895
[2020-06-11 14:20:14,940] [basehttp.py:157] [basehttp:log_message] [INFO]- "GET /role/user/?username=et&pid=1 HTTP/1.1" 200 1526
[2020-06-11 14:20:17,249] [basehttp.py:157] [basehttp:log_message] [INFO]- "GET /user/ HTTP/1.1" 200 7021
[2020-06-11 14:25:15,581] [basehttp.py:157] [basehttp:log_message] [INFO]- "OPTIONS /role/?current_page=1&pre_page=10 HTTP/1.1" 200 0
[2020-06-11 14:25:15,624] [basehttp.py:157] [basehttp:log_message] [INFO]- "GET /role/?current_page=1&pre_page=10 HTTP/1.1" 200 4895
[2020-06-11 14:25:21,165] [basehttp.py:157] [basehttp:log_message] [INFO]- "OPTIONS /role/user?username=et&pid=1 HTTP/1.1" 200 0
[2020-06-11 14:25:21,203] [basehttp.py:157] [basehttp:log_message] [INFO]- "GET /role/?current_page=1&pre_page=10 HTTP/1.1" 200 4895
[2020-06-11 14:25:21,220] [basehttp.py:157] [basehttp:log_message] [INFO]- "OPTIONS /role/user/?username=et&pid=1 HTTP/1.1" 200 0
[2020-06-11 14:25:21,348] [basehttp.py:157] [basehttp:log_message] [INFO]- "GET /role/user/?username=et&pid=1 HTTP/1.1" 200 1526
[2020-06-11 14:25:23,284] [basehttp.py:157] [basehttp:log_message] [INFO]- "OPTIONS /user/ HTTP/1.1" 200 0
[2020-06-11 14:25:23,425] [basehttp.py:157] [basehttp:log_message] [INFO]- "GET /user/ HTTP/1.1" 200 7021
[2020-06-11 14:25:30,789] [basehttp.py:157] [basehttp:log_message] [INFO]- "GET /user/ HTTP/1.1" 200 7021
[2020-06-11 14:25:38,898] [basehttp.py:157] [basehttp:log_message] [INFO]- "GET /role/?current_page=1&pre_page=10 HTTP/1.1" 200 4895
[2020-06-11 14:25:38,920] [basehttp.py:157] [basehttp:log_message] [INFO]- "GET /role/user/?username=et&pid=1 HTTP/1.1" 200 1526
[2020-06-11 14:25:40,568] [basehttp.py:157] [basehttp:log_message] [INFO]- "GET /user/ HTTP/1.1" 200 7021
[2020-06-11 14:27:08,543] [basehttp.py:157] [basehttp:log_message] [INFO]- "GET /role/?current_page=1&pre_page=10 HTTP/1.1" 200 4895
[2020-06-11 14:27:11,624] [basehttp.py:157] [basehttp:log_message] [INFO]- "GET /user/ HTTP/1.1" 200 7021
[2020-06-11 14:29:54,295] [basehttp.py:157] [basehttp:log_message] [INFO]- "GET /role/?current_page=1&pre_page=10 HTTP/1.1" 200 4895
[2020-06-11 14:29:57,540] [basehttp.py:157] [basehttp:log_message] [INFO]- "GET /user/ HTTP/1.1" 200 7021
[2020-06-11 14:30:10,251] [basehttp.py:157] [basehttp:log_message] [INFO]- "GET /role/?current_page=1&pre_page=10 HTTP/1.1" 200 4895
[2020-06-11 14:30:12,651] [basehttp.py:157] [basehttp:log_message] [INFO]- "GET /user/ HTTP/1.1" 200 7021
[2020-06-11 14:30:54,205] [basehttp.py:157] [basehttp:log_message] [INFO]- "GET /role/?current_page=1&pre_page=10 HTTP/1.1" 200 4895
[2020-06-11 14:36:11,048] [basehttp.py:157] [basehttp:log_message] [INFO]- "OPTIONS /role/?current_page=1&pre_page=10 HTTP/1.1" 200 0
[2020-06-11 14:36:11,089] [basehttp.py:157] [basehttp:log_message] [INFO]- "GET /role/?current_page=1&pre_page=10 HTTP/1.1" 200 4895
[2020-06-11 14:36:14,668] [basehttp.py:157] [basehttp:log_message] [INFO]- "OPTIONS /role/user?username=et&pid=1 HTTP/1.1" 200 0
[2020-06-11 14:36:14,699] [basehttp.py:157] [basehttp:log_message] [INFO]- "GET /role/?current_page=1&pre_page=10 HTTP/1.1" 200 4895
[2020-06-11 14:36:14,714] [basehttp.py:157] [basehttp:log_message] [INFO]- "OPTIONS /role/user/?username=et&pid=1 HTTP/1.1" 200 0
[2020-06-11 14:36:14,822] [basehttp.py:157] [basehttp:log_message] [INFO]- "GET /role/user/?username=et&pid=1 HTTP/1.1" 200 1526
[2020-06-11 14:36:16,657] [basehttp.py:157] [basehttp:log_message] [INFO]- "OPTIONS /user/ HTTP/1.1" 200 0
[2020-06-11 14:36:16,804] [basehttp.py:157] [basehttp:log_message] [INFO]- "GET /user/ HTTP/1.1" 200 7021
[2020-06-11 14:38:31,091] [basehttp.py:157] [basehttp:log_message] [INFO]- "GET /role/?current_page=1&pre_page=10 HTTP/1.1" 200 4895
[2020-06-11 14:38:33,580] [basehttp.py:157] [basehttp:log_message] [INFO]- "GET /user/ HTTP/1.1" 200 7021
[2020-06-11 14:40:12,647] [basehttp.py:157] [basehttp:log_message] [INFO]- "GET /role/?current_page=1&pre_page=10 HTTP/1.1" 200 4895
[2020-06-11 14:40:26,507] [basehttp.py:157] [basehttp:log_message] [INFO]- "GET /user/ HTTP/1.1" 200 7021
[2020-06-11 14:41:36,598] [basehttp.py:157] [basehttp:log_message] [INFO]- "GET /role/?current_page=1&pre_page=10 HTTP/1.1" 200 4895
[2020-06-11 14:46:57,930] [basehttp.py:157] [basehttp:log_message] [INFO]- "OPTIONS /role/?current_page=1&pre_page=10 HTTP/1.1" 200 0
[2020-06-11 14:46:57,973] [basehttp.py:157] [basehttp:log_message] [INFO]- "GET /role/?current_page=1&pre_page=10 HTTP/1.1" 200 4895
[2020-06-11 14:47:24,000] [basehttp.py:157] [basehttp:log_message] [INFO]- "GET /role/?current_page=1&pre_page=10 HTTP/1.1" 200 4895
[2020-06-11 14:48:23,316] [basehttp.py:157] [basehttp:log_message] [INFO]- "GET /role/?current_page=1&pre_page=10 HTTP/1.1" 200 4895
[2020-06-11 14:48:26,909] [basehttp.py:157] [basehttp:log_message] [INFO]- "OPTIONS /role/user?username=et&pid=1 HTTP/1.1" 200 0
[2020-06-11 14:48:26,950] [basehttp.py:157] [basehttp:log_message] [INFO]- "GET /role/?current_page=1&pre_page=10 HTTP/1.1" 200 4895
[2020-06-11 14:48:26,950] [basehttp.py:157] [basehttp:log_message] [INFO]- "OPTIONS /role/user/?username=et&pid=1 HTTP/1.1" 200 0
[2020-06-11 14:48:26,983] [basehttp.py:157] [basehttp:log_message] [INFO]- "GET /role/user/?username=et&pid=1 HTTP/1.1" 200 1526
[2020-06-11 14:48:51,365] [basehttp.py:157] [basehttp:log_message] [INFO]- "GET /role/?current_page=1&pre_page=10 HTTP/1.1" 200 4895
[2020-06-11 14:48:53,557] [basehttp.py:157] [basehttp:log_message] [INFO]- "OPTIONS /user/ HTTP/1.1" 200 0
[2020-06-11 14:48:53,683] [basehttp.py:157] [basehttp:log_message] [INFO]- "GET /user/ HTTP/1.1" 200 7021
[2020-06-11 14:51:37,565] [basehttp.py:157] [basehttp:log_message] [INFO]- "GET /role/?current_page=1&pre_page=10 HTTP/1.1" 200 4895
[2020-06-11 14:51:39,552] [basehttp.py:157] [basehttp:log_message] [INFO]- "GET /user/ HTTP/1.1" 200 7021
[2020-06-11 14:52:17,080] [basehttp.py:157] [basehttp:log_message] [INFO]- "GET /role/?current_page=1&pre_page=10 HTTP/1.1" 200 4895
[2020-06-11 14:54:13,452] [basehttp.py:157] [basehttp:log_message] [INFO]- "GET /role/?current_page=1&pre_page=10 HTTP/1.1" 200 4895
[2020-06-11 14:54:17,787] [basehttp.py:157] [basehttp:log_message] [INFO]- "GET /user/ HTTP/1.1" 200 7021
[2020-06-11 14:55:51,491] [basehttp.py:157] [basehttp:log_message] [INFO]- "GET /role/?current_page=1&pre_page=10 HTTP/1.1" 200 4895
[2020-06-11 14:55:55,267] [basehttp.py:157] [basehttp:log_message] [INFO]- "GET /role/?current_page=1&pre_page=10 HTTP/1.1" 200 4895
[2020-06-11 14:55:55,293] [basehttp.py:157] [basehttp:log_message] [INFO]- "GET /role/user/?username=et&pid=1 HTTP/1.1" 200 1526
[2020-06-11 14:55:57,815] [basehttp.py:157] [basehttp:log_message] [INFO]- "GET /user/ HTTP/1.1" 200 7021
[2020-06-11 14:56:44,686] [basehttp.py:157] [basehttp:log_message] [INFO]- "GET /role/?current_page=1&pre_page=10 HTTP/1.1" 200 4895
[2020-06-11 14:56:49,268] [basehttp.py:157] [basehttp:log_message] [INFO]- "GET /role/?current_page=1&pre_page=10 HTTP/1.1" 200 4895
[2020-06-11 14:56:49,295] [basehttp.py:157] [basehttp:log_message] [INFO]- "GET /role/user/?username=et&pid=1 HTTP/1.1" 200 1526
[2020-06-11 14:56:51,170] [basehttp.py:157] [basehttp:log_message] [INFO]- "GET /user/ HTTP/1.1" 200 7021
[2020-06-11 14:57:44,284] [basehttp.py:157] [basehttp:log_message] [INFO]- "OPTIONS /role/?current_page=1&pre_page=10 HTTP/1.1" 200 0
[2020-06-11 14:57:44,320] [basehttp.py:157] [basehttp:log_message] [INFO]- "GET /role/?current_page=1&pre_page=10 HTTP/1.1" 200 4895
[2020-06-11 14:57:46,192] [basehttp.py:157] [basehttp:log_message] [INFO]- "GET /user/ HTTP/1.1" 200 7021
[2020-06-11 14:57:55,641] [basehttp.py:157] [basehttp:log_message] [INFO]- "GET /role/?current_page=1&pre_page=10 HTTP/1.1" 200 4895
[2020-06-11 14:57:55,676] [basehttp.py:157] [basehttp:log_message] [INFO]- "GET /role/user/?username=et&pid=1 HTTP/1.1" 200 1526
[2020-06-11 14:57:59,451] [basehttp.py:157] [basehttp:log_message] [INFO]- "GET /user/ HTTP/1.1" 200 7021
[2020-06-11 14:58:12,658] [basehttp.py:157] [basehttp:log_message] [INFO]- "GET /role/?current_page=1&pre_page=10 HTTP/1.1" 200 4895
[2020-06-11 14:58:13,953] [basehttp.py:157] [basehttp:log_message] [INFO]- "GET /user/ HTTP/1.1" 200 7021
[2020-06-11 14:59:03,568] [basehttp.py:157] [basehttp:log_message] [INFO]- "GET /role/?current_page=1&pre_page=10 HTTP/1.1" 200 4895
[2020-06-11 14:59:05,813] [basehttp.py:157] [basehttp:log_message] [INFO]- "OPTIONS /user/ HTTP/1.1" 200 0
[2020-06-11 14:59:05,910] [basehttp.py:157] [basehttp:log_message] [INFO]- "GET /user/ HTTP/1.1" 200 7021
[2020-06-11 14:59:29,029] [basehttp.py:157] [basehttp:log_message] [INFO]- "GET /role/?current_page=1&pre_page=10 HTTP/1.1" 200 4895
[2020-06-11 14:59:30,736] [basehttp.py:157] [basehttp:log_message] [INFO]- "GET /user/ HTTP/1.1" 200 7021
[2020-06-11 15:02:35,368] [basehttp.py:157] [basehttp:log_message] [INFO]- "GET /role/?current_page=1&pre_page=10 HTTP/1.1" 200 4895
[2020-06-11 15:02:38,265] [basehttp.py:157] [basehttp:log_message] [INFO]- "GET /user/ HTTP/1.1" 200 7021
[2020-06-11 15:03:09,170] [basehttp.py:157] [basehttp:log_message] [INFO]- "OPTIONS /role/user?username=et&pid=1 HTTP/1.1" 200 0
[2020-06-11 15:03:09,202] [basehttp.py:157] [basehttp:log_message] [INFO]- "GET /role/?current_page=1&pre_page=10 HTTP/1.1" 200 4895
[2020-06-11 15:03:09,305] [basehttp.py:157] [basehttp:log_message] [INFO]- "OPTIONS /role/user/?username=et&pid=1 HTTP/1.1" 200 0
[2020-06-11 15:03:09,376] [basehttp.py:157] [basehttp:log_message] [INFO]- "GET /role/user/?username=et&pid=1 HTTP/1.1" 200 1526
[2020-06-11 15:03:12,743] [basehttp.py:157] [basehttp:log_message] [INFO]- "GET /role/?current_page=1&pre_page=10 HTTP/1.1" 200 4895
[2020-06-11 15:03:12,765] [basehttp.py:157] [basehttp:log_message] [INFO]- "GET /role/user/?username=et&pid=1 HTTP/1.1" 200 1526
[2020-06-11 15:03:14,193] [basehttp.py:157] [basehttp:log_message] [INFO]- "GET /user/ HTTP/1.1" 200 7021
[2020-06-11 15:03:59,333] [basehttp.py:157] [basehttp:log_message] [INFO]- "GET /role/?current_page=1&pre_page=10 HTTP/1.1" 200 4895
[2020-06-11 15:04:12,771] [basehttp.py:157] [basehttp:log_message] [INFO]- "GET /role/?current_page=1&pre_page=10 HTTP/1.1" 200 4895
[2020-06-11 15:04:12,803] [basehttp.py:157] [basehttp:log_message] [INFO]- "GET /role/user/?username=et&pid=1 HTTP/1.1" 200 1526
[2020-06-11 15:04:14,401] [basehttp.py:157] [basehttp:log_message] [INFO]- "GET /user/ HTTP/1.1" 200 7021
[2020-06-11 15:04:58,127] [basehttp.py:157] [basehttp:log_message] [INFO]- "GET /role/?current_page=1&pre_page=10 HTTP/1.1" 200 4895
[2020-06-11 15:05:01,236] [basehttp.py:157] [basehttp:log_message] [INFO]- "GET /role/?current_page=1&pre_page=10 HTTP/1.1" 200 4895
[2020-06-11 15:05:01,264] [basehttp.py:157] [basehttp:log_message] [INFO]- "GET /role/user/?username=et&pid=1 HTTP/1.1" 200 1526
[2020-06-11 15:05:02,395] [basehttp.py:157] [basehttp:log_message] [INFO]- "GET /user/ HTTP/1.1" 200 7021
[2020-06-11 15:06:29,639] [basehttp.py:157] [basehttp:log_message] [INFO]- "GET /role/?current_page=1&pre_page=10 HTTP/1.1" 200 4895
[2020-06-11 15:06:29,672] [basehttp.py:157] [basehttp:log_message] [INFO]- "GET /role/user/?username=et&pid=1 HTTP/1.1" 200 1526
[2020-06-11 15:06:30,918] [basehttp.py:157] [basehttp:log_message] [INFO]- "GET /user/ HTTP/1.1" 200 7021
[2020-06-11 15:06:55,567] [basehttp.py:157] [basehttp:log_message] [INFO]- "GET /role/?current_page=1&pre_page=10 HTTP/1.1" 200 4895
[2020-06-11 15:06:55,600] [basehttp.py:157] [basehttp:log_message] [INFO]- "GET /role/user/?username=et&pid=1 HTTP/1.1" 200 1526
[2020-06-11 15:06:56,922] [basehttp.py:157] [basehttp:log_message] [INFO]- "GET /user/ HTTP/1.1" 200 7021
[2020-06-11 15:13:10,440] [basehttp.py:157] [basehttp:log_message] [INFO]- "OPTIONS /role/user?username=et&pid=1 HTTP/1.1" 200 0
[2020-06-11 15:13:10,441] [basehttp.py:157] [basehttp:log_message] [INFO]- "OPTIONS /role/?current_page=1&pre_page=10 HTTP/1.1" 200 0
[2020-06-11 15:13:10,502] [basehttp.py:157] [basehttp:log_message] [INFO]- "OPTIONS /role/user/?username=et&pid=1 HTTP/1.1" 200 0
[2020-06-11 15:13:10,525] [basehttp.py:157] [basehttp:log_message] [INFO]- "GET /role/?current_page=1&pre_page=10 HTTP/1.1" 200 4895
[2020-06-11 15:13:10,534] [basehttp.py:157] [basehttp:log_message] [INFO]- "GET /role/user/?username=et&pid=1 HTTP/1.1" 200 1526
[2020-06-11 15:13:12,130] [basehttp.py:157] [basehttp:log_message] [INFO]- "OPTIONS /user/ HTTP/1.1" 200 0
[2020-06-11 15:13:12,221] [basehttp.py:157] [basehttp:log_message] [INFO]- "GET /user/ HTTP/1.1" 200 7021
[2020-06-11 15:14:24,456] [basehttp.py:157] [basehttp:log_message] [INFO]- "GET /role/?current_page=1&pre_page=10 HTTP/1.1" 200 4895
[2020-06-11 15:14:24,471] [basehttp.py:157] [basehttp:log_message] [INFO]- "GET /role/user/?username=et&pid=1 HTTP/1.1" 200 1526
[2020-06-11 15:14:26,326] [basehttp.py:157] [basehttp:log_message] [INFO]- "GET /user/ HTTP/1.1" 200 7021
[2020-06-11 15:14:59,877] [basehttp.py:157] [basehttp:log_message] [INFO]- "GET /role/?current_page=1&pre_page=10 HTTP/1.1" 200 4895
[2020-06-11 15:14:59,902] [basehttp.py:157] [basehttp:log_message] [INFO]- "GET /role/user/?username=et&pid=1 HTTP/1.1" 200 1526
[2020-06-11 15:15:00,859] [basehttp.py:157] [basehttp:log_message] [INFO]- "GET /user/ HTTP/1.1" 200 7021
[2020-06-11 15:15:17,908] [basehttp.py:157] [basehttp:log_message] [INFO]- "GET /role/?current_page=1&pre_page=10 HTTP/1.1" 200 4895
[2020-06-11 15:15:17,921] [basehttp.py:157] [basehttp:log_message] [INFO]- "GET /role/user/?username=et&pid=1 HTTP/1.1" 200 1526
[2020-06-11 15:15:19,245] [basehttp.py:157] [basehttp:log_message] [INFO]- "GET /user/ HTTP/1.1" 200 7021
[2020-06-11 15:16:08,835] [basehttp.py:157] [basehttp:log_message] [INFO]- "GET /role/?current_page=1&pre_page=10 HTTP/1.1" 200 4895
[2020-06-11 15:16:08,874] [basehttp.py:157] [basehttp:log_message] [INFO]- "GET /role/user/?username=et&pid=1 HTTP/1.1" 200 1526
[2020-06-11 15:16:10,523] [basehttp.py:157] [basehttp:log_message] [INFO]- "GET /user/ HTTP/1.1" 200 7021
[2020-06-11 15:16:47,964] [basehttp.py:157] [basehttp:log_message] [INFO]- "GET /role/?current_page=1&pre_page=10 HTTP/1.1" 200 4895
[2020-06-11 15:16:50,272] [basehttp.py:157] [basehttp:log_message] [INFO]- "GET /user/ HTTP/1.1" 200 7021
[2020-06-11 15:17:11,520] [basehttp.py:157] [basehttp:log_message] [INFO]- "GET /role/?current_page=1&pre_page=10 HTTP/1.1" 200 4895
[2020-06-11 15:17:13,239] [basehttp.py:157] [basehttp:log_message] [INFO]- "GET /user/ HTTP/1.1" 200 7021
[2020-06-11 15:17:21,583] [basehttp.py:157] [basehttp:log_message] [INFO]- "GET /role/user?username=et&pid=1 HTTP/1.1" 301 0
[2020-06-11 15:17:21,610] [basehttp.py:157] [basehttp:log_message] [INFO]- "GET /role/?current_page=1&pre_page=10 HTTP/1.1" 200 4895
[2020-06-11 15:17:21,715] [basehttp.py:157] [basehttp:log_message] [INFO]- "GET /role/user/?username=et&pid=1 HTTP/1.1" 200 1526
[2020-06-11 15:17:23,278] [basehttp.py:157] [basehttp:log_message] [INFO]- "GET /user/ HTTP/1.1" 200 7021
[2020-06-11 15:18:02,537] [basehttp.py:157] [basehttp:log_message] [INFO]- "GET /role/?current_page=1&pre_page=10 HTTP/1.1" 200 4895
[2020-06-11 15:18:05,125] [basehttp.py:157] [basehttp:log_message] [INFO]- "GET /role/?current_page=1&pre_page=10 HTTP/1.1" 200 4895
[2020-06-11 15:18:05,156] [basehttp.py:157] [basehttp:log_message] [INFO]- "GET /role/user/?username=et&pid=1 HTTP/1.1" 200 1526
[2020-06-11 15:18:06,868] [basehttp.py:157] [basehttp:log_message] [INFO]- "GET /user/ HTTP/1.1" 200 7021
[2020-06-11 15:19:01,255] [basehttp.py:157] [basehttp:log_message] [INFO]- "GET /role/?current_page=1&pre_page=10 HTTP/1.1" 200 4895
[2020-06-11 15:20:25,502] [basehttp.py:157] [basehttp:log_message] [INFO]- "GET /role/?current_page=1&pre_page=10 HTTP/1.1" 200 4895
[2020-06-11 15:20:25,536] [basehttp.py:157] [basehttp:log_message] [INFO]- "GET /role/user/?username=et&pid=1 HTTP/1.1" 200 1526
[2020-06-11 15:20:27,350] [basehttp.py:157] [basehttp:log_message] [INFO]- "GET /user/ HTTP/1.1" 200 7021
[2020-06-11 15:20:52,754] [basehttp.py:157] [basehttp:log_message] [INFO]- "OPTIONS /role/1/assign_user/ HTTP/1.1" 200 0
[2020-06-11 15:20:53,230] [log.py:222] [log:log_response] [ERROR]- Internal Server Error: /role/1/assign_user/
Traceback (most recent call last):
  File "/home/rock/anaconda3/envs/venv/lib/python3.8/site-packages/django/core/handlers/exception.py", line 34, in inner
    response = get_response(request)
  File "/home/rock/anaconda3/envs/venv/lib/python3.8/site-packages/django/core/handlers/base.py", line 115, in _get_response
    response = self.process_exception_by_middleware(e, request)
  File "/home/rock/anaconda3/envs/venv/lib/python3.8/site-packages/django/core/handlers/base.py", line 113, in _get_response
    response = wrapped_callback(request, *callback_args, **callback_kwargs)
  File "/home/rock/anaconda3/envs/venv/lib/python3.8/site-packages/django/views/decorators/csrf.py", line 54, in wrapped_view
    return view_func(*args, **kwargs)
  File "/home/rock/anaconda3/envs/venv/lib/python3.8/site-packages/rest_framework/viewsets.py", line 114, in view
    return self.dispatch(request, *args, **kwargs)
  File "/home/rock/anaconda3/envs/venv/lib/python3.8/site-packages/rest_framework/views.py", line 505, in dispatch
    response = self.handle_exception(exc)
  File "/home/rock/anaconda3/envs/venv/lib/python3.8/site-packages/rest_framework/views.py", line 465, in handle_exception
    self.raise_uncaught_exception(exc)
  File "/home/rock/anaconda3/envs/venv/lib/python3.8/site-packages/rest_framework/views.py", line 476, in raise_uncaught_exception
    raise exc
  File "/home/rock/anaconda3/envs/venv/lib/python3.8/site-packages/rest_framework/views.py", line 502, in dispatch
    response = handler(request, *args, **kwargs)
  File "/home/rock/quality_inspection/python-workspace/project-sys/sys_auth/views.py", line 216, in assign_user
    users = User.objects.filter(id__in=user_ids).all()
  File "/home/rock/anaconda3/envs/venv/lib/python3.8/site-packages/django/db/models/manager.py", line 82, in manager_method
    return getattr(self.get_queryset(), name)(*args, **kwargs)
  File "/home/rock/anaconda3/envs/venv/lib/python3.8/site-packages/django/db/models/query.py", line 904, in filter
    return self._filter_or_exclude(False, *args, **kwargs)
  File "/home/rock/anaconda3/envs/venv/lib/python3.8/site-packages/django/db/models/query.py", line 923, in _filter_or_exclude
    clone.query.add_q(Q(*args, **kwargs))
  File "/home/rock/anaconda3/envs/venv/lib/python3.8/site-packages/django/db/models/sql/query.py", line 1351, in add_q
    clause, _ = self._add_q(q_object, self.used_aliases)
  File "/home/rock/anaconda3/envs/venv/lib/python3.8/site-packages/django/db/models/sql/query.py", line 1378, in _add_q
    child_clause, needed_inner = self.build_filter(
  File "/home/rock/anaconda3/envs/venv/lib/python3.8/site-packages/django/db/models/sql/query.py", line 1312, in build_filter
    condition = self.build_lookup(lookups, col, value)
  File "/home/rock/anaconda3/envs/venv/lib/python3.8/site-packages/django/db/models/sql/query.py", line 1166, in build_lookup
    lookup = lookup_class(lhs, rhs)
  File "/home/rock/anaconda3/envs/venv/lib/python3.8/site-packages/django/db/models/lookups.py", line 22, in __init__
    self.rhs = self.get_prep_lookup()
  File "/home/rock/anaconda3/envs/venv/lib/python3.8/site-packages/django/db/models/lookups.py", line 217, in get_prep_lookup
    for rhs_value in self.rhs:
TypeError: 'NoneType' object is not iterable
[2020-06-11 15:20:53,232] [basehttp.py:157] [basehttp:log_message] [ERROR]- "PUT /role/1/assign_user/ HTTP/1.1" 500 20910
[2020-06-11 15:21:46,003] [basehttp.py:157] [basehttp:log_message] [INFO]- "GET /role/?current_page=1&pre_page=10 HTTP/1.1" 200 4895
[2020-06-11 15:21:46,035] [basehttp.py:157] [basehttp:log_message] [INFO]- "GET /role/user/?username=et&pid=1 HTTP/1.1" 200 1526
[2020-06-11 15:21:47,313] [basehttp.py:157] [basehttp:log_message] [INFO]- "GET /user/ HTTP/1.1" 200 7021
[2020-06-11 15:21:51,168] [basehttp.py:157] [basehttp:log_message] [INFO]- "GET /user/ HTTP/1.1" 200 7021
[2020-06-11 15:22:46,139] [basehttp.py:157] [basehttp:log_message] [INFO]- "GET /user/ HTTP/1.1" 200 7021
[2020-06-11 15:25:15,587] [basehttp.py:157] [basehttp:log_message] [INFO]- "OPTIONS /user/ HTTP/1.1" 200 0
[2020-06-11 15:25:15,662] [basehttp.py:157] [basehttp:log_message] [INFO]- "GET /user/ HTTP/1.1" 200 7021
[2020-06-11 15:26:53,900] [log.py:222] [log:log_response] [ERROR]- Internal Server Error: /role/1/assign_user/
Traceback (most recent call last):
  File "/home/rock/anaconda3/envs/venv/lib/python3.8/site-packages/django/core/handlers/exception.py", line 34, in inner
    response = get_response(request)
  File "/home/rock/anaconda3/envs/venv/lib/python3.8/site-packages/django/core/handlers/base.py", line 115, in _get_response
    response = self.process_exception_by_middleware(e, request)
  File "/home/rock/anaconda3/envs/venv/lib/python3.8/site-packages/django/core/handlers/base.py", line 113, in _get_response
    response = wrapped_callback(request, *callback_args, **callback_kwargs)
  File "/home/rock/anaconda3/envs/venv/lib/python3.8/site-packages/django/views/decorators/csrf.py", line 54, in wrapped_view
    return view_func(*args, **kwargs)
  File "/home/rock/anaconda3/envs/venv/lib/python3.8/site-packages/rest_framework/viewsets.py", line 114, in view
    return self.dispatch(request, *args, **kwargs)
  File "/home/rock/anaconda3/envs/venv/lib/python3.8/site-packages/rest_framework/views.py", line 505, in dispatch
    response = self.handle_exception(exc)
  File "/home/rock/anaconda3/envs/venv/lib/python3.8/site-packages/rest_framework/views.py", line 465, in handle_exception
    self.raise_uncaught_exception(exc)
  File "/home/rock/anaconda3/envs/venv/lib/python3.8/site-packages/rest_framework/views.py", line 476, in raise_uncaught_exception
    raise exc
  File "/home/rock/anaconda3/envs/venv/lib/python3.8/site-packages/rest_framework/views.py", line 502, in dispatch
    response = handler(request, *args, **kwargs)
  File "/home/rock/quality_inspection/python-workspace/project-sys/sys_auth/views.py", line 216, in assign_user
    users = User.objects.filter(id__in=user_ids).all()
  File "/home/rock/anaconda3/envs/venv/lib/python3.8/site-packages/django/db/models/manager.py", line 82, in manager_method
    return getattr(self.get_queryset(), name)(*args, **kwargs)
  File "/home/rock/anaconda3/envs/venv/lib/python3.8/site-packages/django/db/models/query.py", line 904, in filter
    return self._filter_or_exclude(False, *args, **kwargs)
  File "/home/rock/anaconda3/envs/venv/lib/python3.8/site-packages/django/db/models/query.py", line 923, in _filter_or_exclude
    clone.query.add_q(Q(*args, **kwargs))
  File "/home/rock/anaconda3/envs/venv/lib/python3.8/site-packages/django/db/models/sql/query.py", line 1351, in add_q
    clause, _ = self._add_q(q_object, self.used_aliases)
  File "/home/rock/anaconda3/envs/venv/lib/python3.8/site-packages/django/db/models/sql/query.py", line 1378, in _add_q
    child_clause, needed_inner = self.build_filter(
  File "/home/rock/anaconda3/envs/venv/lib/python3.8/site-packages/django/db/models/sql/query.py", line 1312, in build_filter
    condition = self.build_lookup(lookups, col, value)
  File "/home/rock/anaconda3/envs/venv/lib/python3.8/site-packages/django/db/models/sql/query.py", line 1166, in build_lookup
    lookup = lookup_class(lhs, rhs)
  File "/home/rock/anaconda3/envs/venv/lib/python3.8/site-packages/django/db/models/lookups.py", line 22, in __init__
    self.rhs = self.get_prep_lookup()
  File "/home/rock/anaconda3/envs/venv/lib/python3.8/site-packages/django/db/models/lookups.py", line 217, in get_prep_lookup
    for rhs_value in self.rhs:
TypeError: 'NoneType' object is not iterable
[2020-06-11 15:26:53,902] [basehttp.py:157] [basehttp:log_message] [ERROR]- "PUT /role/1/assign_user/ HTTP/1.1" 500 20910
[2020-06-11 15:32:17,634] [basehttp.py:157] [basehttp:log_message] [INFO]- "OPTIONS /role/user?username=et&pid=1 HTTP/1.1" 200 0
[2020-06-11 15:32:17,635] [basehttp.py:157] [basehttp:log_message] [INFO]- "OPTIONS /role/?current_page=1&pre_page=10 HTTP/1.1" 200 0
[2020-06-11 15:32:17,698] [basehttp.py:157] [basehttp:log_message] [INFO]- "OPTIONS /role/user/?username=et&pid=1 HTTP/1.1" 200 0
[2020-06-11 15:32:17,714] [basehttp.py:157] [basehttp:log_message] [INFO]- "GET /role/?current_page=1&pre_page=10 HTTP/1.1" 200 4895
[2020-06-11 15:32:17,732] [basehttp.py:157] [basehttp:log_message] [INFO]- "GET /role/user/?username=et&pid=1 HTTP/1.1" 200 1526
[2020-06-11 15:32:25,512] [basehttp.py:157] [basehttp:log_message] [INFO]- "GET /user/ HTTP/1.1" 200 7021
[2020-06-11 15:32:32,790] [basehttp.py:157] [basehttp:log_message] [INFO]- "OPTIONS /role/1/assign_user/ HTTP/1.1" 200 0
[2020-06-11 15:32:32,856] [log.py:222] [log:log_response] [ERROR]- Internal Server Error: /role/1/assign_user/
Traceback (most recent call last):
  File "/home/rock/anaconda3/envs/venv/lib/python3.8/site-packages/django/core/handlers/exception.py", line 34, in inner
    response = get_response(request)
  File "/home/rock/anaconda3/envs/venv/lib/python3.8/site-packages/django/core/handlers/base.py", line 115, in _get_response
    response = self.process_exception_by_middleware(e, request)
  File "/home/rock/anaconda3/envs/venv/lib/python3.8/site-packages/django/core/handlers/base.py", line 113, in _get_response
    response = wrapped_callback(request, *callback_args, **callback_kwargs)
  File "/home/rock/anaconda3/envs/venv/lib/python3.8/site-packages/django/views/decorators/csrf.py", line 54, in wrapped_view
    return view_func(*args, **kwargs)
  File "/home/rock/anaconda3/envs/venv/lib/python3.8/site-packages/rest_framework/viewsets.py", line 114, in view
    return self.dispatch(request, *args, **kwargs)
  File "/home/rock/anaconda3/envs/venv/lib/python3.8/site-packages/rest_framework/views.py", line 505, in dispatch
    response = self.handle_exception(exc)
  File "/home/rock/anaconda3/envs/venv/lib/python3.8/site-packages/rest_framework/views.py", line 465, in handle_exception
    self.raise_uncaught_exception(exc)
  File "/home/rock/anaconda3/envs/venv/lib/python3.8/site-packages/rest_framework/views.py", line 476, in raise_uncaught_exception
    raise exc
  File "/home/rock/anaconda3/envs/venv/lib/python3.8/site-packages/rest_framework/views.py", line 502, in dispatch
    response = handler(request, *args, **kwargs)
  File "/home/rock/quality_inspection/python-workspace/project-sys/sys_auth/views.py", line 216, in assign_user
    users = User.objects.filter(id__in=user_ids).all()
  File "/home/rock/anaconda3/envs/venv/lib/python3.8/site-packages/django/db/models/manager.py", line 82, in manager_method
    return getattr(self.get_queryset(), name)(*args, **kwargs)
  File "/home/rock/anaconda3/envs/venv/lib/python3.8/site-packages/django/db/models/query.py", line 904, in filter
    return self._filter_or_exclude(False, *args, **kwargs)
  File "/home/rock/anaconda3/envs/venv/lib/python3.8/site-packages/django/db/models/query.py", line 923, in _filter_or_exclude
    clone.query.add_q(Q(*args, **kwargs))
  File "/home/rock/anaconda3/envs/venv/lib/python3.8/site-packages/django/db/models/sql/query.py", line 1351, in add_q
    clause, _ = self._add_q(q_object, self.used_aliases)
  File "/home/rock/anaconda3/envs/venv/lib/python3.8/site-packages/django/db/models/sql/query.py", line 1378, in _add_q
    child_clause, needed_inner = self.build_filter(
  File "/home/rock/anaconda3/envs/venv/lib/python3.8/site-packages/django/db/models/sql/query.py", line 1312, in build_filter
    condition = self.build_lookup(lookups, col, value)
  File "/home/rock/anaconda3/envs/venv/lib/python3.8/site-packages/django/db/models/sql/query.py", line 1166, in build_lookup
    lookup = lookup_class(lhs, rhs)
  File "/home/rock/anaconda3/envs/venv/lib/python3.8/site-packages/django/db/models/lookups.py", line 22, in __init__
    self.rhs = self.get_prep_lookup()
  File "/home/rock/anaconda3/envs/venv/lib/python3.8/site-packages/django/db/models/lookups.py", line 217, in get_prep_lookup
    for rhs_value in self.rhs:
TypeError: 'NoneType' object is not iterable
[2020-06-11 15:32:32,859] [basehttp.py:157] [basehttp:log_message] [ERROR]- "PUT /role/1/assign_user/ HTTP/1.1" 500 20910
[2020-06-11 15:33:09,955] [basehttp.py:157] [basehttp:log_message] [INFO]- "GET /role/?current_page=1&pre_page=10 HTTP/1.1" 200 4895
[2020-06-11 15:33:11,212] [basehttp.py:157] [basehttp:log_message] [INFO]- "GET /user/ HTTP/1.1" 200 7021
[2020-06-11 15:33:18,039] [basehttp.py:157] [basehttp:log_message] [INFO]- "PUT /role/1/assign_user/ HTTP/1.1" 200 2293
[2020-06-11 15:33:18,113] [basehttp.py:157] [basehttp:log_message] [INFO]- "GET /role/?current_page=1&pre_page=10 HTTP/1.1" 200 4895
[2020-06-11 15:34:07,956] [basehttp.py:157] [basehttp:log_message] [INFO]- "GET /role/?current_page=1&pre_page=10 HTTP/1.1" 200 4895
[2020-06-11 15:35:52,156] [basehttp.py:157] [basehttp:log_message] [INFO]- "GET /role/?current_page=1&pre_page=10 HTTP/1.1" 200 4895
[2020-06-11 15:35:52,191] [basehttp.py:157] [basehttp:log_message] [INFO]- "GET /role/user/?username=et&pid=1 HTTP/1.1" 200 1526
[2020-06-11 15:35:53,506] [basehttp.py:157] [basehttp:log_message] [INFO]- "OPTIONS /user/ HTTP/1.1" 200 0
[2020-06-11 15:35:53,634] [basehttp.py:157] [basehttp:log_message] [INFO]- "GET /user/ HTTP/1.1" 200 7021
[2020-06-11 15:36:14,753] [basehttp.py:157] [basehttp:log_message] [INFO]- "PUT /role/1/assign_user/ HTTP/1.1" 200 2293
[2020-06-11 15:36:14,834] [basehttp.py:157] [basehttp:log_message] [INFO]- "GET /role/?current_page=1&pre_page=10 HTTP/1.1" 200 4895
[2020-06-11 15:36:20,509] [basehttp.py:157] [basehttp:log_message] [INFO]- "GET /user/ HTTP/1.1" 200 7021
[2020-06-11 15:37:42,935] [basehttp.py:157] [basehttp:log_message] [INFO]- "OPTIONS /auth/ HTTP/1.1" 200 0
[2020-06-11 15:37:43,533] [basehttp.py:157] [basehttp:log_message] [INFO]- "POST /auth/ HTTP/1.1" 200 65
[2020-06-11 15:37:45,212] [basehttp.py:157] [basehttp:log_message] [INFO]- "OPTIONS /role/user?username=wwc&pid=1 HTTP/1.1" 200 0
[2020-06-11 15:37:45,259] [basehttp.py:157] [basehttp:log_message] [INFO]- "GET /role/user?username=wwc&pid=1 HTTP/1.1" 301 0
[2020-06-11 15:37:45,264] [basehttp.py:157] [basehttp:log_message] [INFO]- "OPTIONS /role/user/?username=wwc&pid=1 HTTP/1.1" 200 0
[2020-06-11 15:37:45,391] [log.py:222] [log:log_response] [ERROR]- Internal Server Error: /role/user/
Traceback (most recent call last):
  File "/home/rock/anaconda3/envs/venv/lib/python3.8/site-packages/django/core/handlers/exception.py", line 34, in inner
    response = get_response(request)
  File "/home/rock/anaconda3/envs/venv/lib/python3.8/site-packages/django/core/handlers/base.py", line 115, in _get_response
    response = self.process_exception_by_middleware(e, request)
  File "/home/rock/anaconda3/envs/venv/lib/python3.8/site-packages/django/core/handlers/base.py", line 113, in _get_response
    response = wrapped_callback(request, *callback_args, **callback_kwargs)
  File "/home/rock/anaconda3/envs/venv/lib/python3.8/site-packages/django/views/decorators/csrf.py", line 54, in wrapped_view
    return view_func(*args, **kwargs)
  File "/home/rock/anaconda3/envs/venv/lib/python3.8/site-packages/rest_framework/viewsets.py", line 114, in view
    return self.dispatch(request, *args, **kwargs)
  File "/home/rock/anaconda3/envs/venv/lib/python3.8/site-packages/rest_framework/views.py", line 505, in dispatch
    response = self.handle_exception(exc)
  File "/home/rock/anaconda3/envs/venv/lib/python3.8/site-packages/rest_framework/views.py", line 465, in handle_exception
    self.raise_uncaught_exception(exc)
  File "/home/rock/anaconda3/envs/venv/lib/python3.8/site-packages/rest_framework/views.py", line 476, in raise_uncaught_exception
    raise exc
  File "/home/rock/anaconda3/envs/venv/lib/python3.8/site-packages/rest_framework/views.py", line 502, in dispatch
    response = handler(request, *args, **kwargs)
  File "/home/rock/quality_inspection/python-workspace/project-sys/sys_auth/views.py", line 195, in user
    pk = role_info.role_id
AttributeError: 'NoneType' object has no attribute 'role_id'
[2020-06-11 15:37:45,393] [basehttp.py:157] [basehttp:log_message] [ERROR]- "GET /role/user/?username=wwc&pid=1 HTTP/1.1" 500 19367
[2020-06-11 15:38:46,625] [basehttp.py:157] [basehttp:log_message] [INFO]- "OPTIONS /role/user?username=wwc&pid=1 HTTP/1.1" 200 0
[2020-06-11 15:38:46,690] [basehttp.py:157] [basehttp:log_message] [INFO]- "OPTIONS /role/user/?username=wwc&pid=1 HTTP/1.1" 200 0
[2020-06-11 15:38:46,741] [log.py:222] [log:log_response] [ERROR]- Internal Server Error: /role/user/
Traceback (most recent call last):
  File "/home/rock/anaconda3/envs/venv/lib/python3.8/site-packages/django/core/handlers/exception.py", line 34, in inner
    response = get_response(request)
  File "/home/rock/anaconda3/envs/venv/lib/python3.8/site-packages/django/core/handlers/base.py", line 115, in _get_response
    response = self.process_exception_by_middleware(e, request)
  File "/home/rock/anaconda3/envs/venv/lib/python3.8/site-packages/django/core/handlers/base.py", line 113, in _get_response
    response = wrapped_callback(request, *callback_args, **callback_kwargs)
  File "/home/rock/anaconda3/envs/venv/lib/python3.8/site-packages/django/views/decorators/csrf.py", line 54, in wrapped_view
    return view_func(*args, **kwargs)
  File "/home/rock/anaconda3/envs/venv/lib/python3.8/site-packages/rest_framework/viewsets.py", line 114, in view
    return self.dispatch(request, *args, **kwargs)
  File "/home/rock/anaconda3/envs/venv/lib/python3.8/site-packages/rest_framework/views.py", line 505, in dispatch
    response = self.handle_exception(exc)
  File "/home/rock/anaconda3/envs/venv/lib/python3.8/site-packages/rest_framework/views.py", line 465, in handle_exception
    self.raise_uncaught_exception(exc)
  File "/home/rock/anaconda3/envs/venv/lib/python3.8/site-packages/rest_framework/views.py", line 476, in raise_uncaught_exception
    raise exc
  File "/home/rock/anaconda3/envs/venv/lib/python3.8/site-packages/rest_framework/views.py", line 502, in dispatch
    response = handler(request, *args, **kwargs)
  File "/home/rock/quality_inspection/python-workspace/project-sys/sys_auth/views.py", line 195, in user
    pk = role_info.role_id
AttributeError: 'NoneType' object has no attribute 'role_id'
[2020-06-11 15:38:46,741] [basehttp.py:157] [basehttp:log_message] [ERROR]- "GET /role/user/?username=wwc&pid=1 HTTP/1.1" 500 19367
[2020-06-11 15:38:58,533] [basehttp.py:157] [basehttp:log_message] [INFO]- "OPTIONS /auth/ HTTP/1.1" 200 0
[2020-06-11 15:38:58,686] [basehttp.py:157] [basehttp:log_message] [INFO]- "POST /auth/ HTTP/1.1" 200 65
[2020-06-11 15:39:00,130] [basehttp.py:157] [basehttp:log_message] [INFO]- "OPTIONS /role/user?username=wl&pid=1 HTTP/1.1" 200 0
[2020-06-11 15:39:00,148] [basehttp.py:157] [basehttp:log_message] [INFO]- "GET /role/user?username=wl&pid=1 HTTP/1.1" 301 0
[2020-06-11 15:39:00,192] [basehttp.py:157] [basehttp:log_message] [INFO]- "OPTIONS /role/user/?username=wl&pid=1 HTTP/1.1" 200 0
[2020-06-11 15:39:00,272] [basehttp.py:157] [basehttp:log_message] [INFO]- "GET /role/user/?username=wl&pid=1 HTTP/1.1" 200 1526
[2020-06-11 15:39:02,408] [basehttp.py:157] [basehttp:log_message] [INFO]- "OPTIONS /user/?current_page=1&pre_page=10 HTTP/1.1" 200 0
[2020-06-11 15:39:02,446] [basehttp.py:157] [basehttp:log_message] [INFO]- "GET /user/?current_page=1&pre_page=10 HTTP/1.1" 200 1819
[2020-06-11 15:39:04,559] [basehttp.py:157] [basehttp:log_message] [INFO]- "OPTIONS /role/?current_page=1&pre_page=10 HTTP/1.1" 200 0
[2020-06-11 15:39:04,591] [basehttp.py:157] [basehttp:log_message] [INFO]- "GET /role/?current_page=1&pre_page=10 HTTP/1.1" 200 4895
[2020-06-11 15:39:36,087] [basehttp.py:157] [basehttp:log_message] [INFO]- "OPTIONS /user/ HTTP/1.1" 200 0
[2020-06-11 15:39:36,198] [basehttp.py:157] [basehttp:log_message] [INFO]- "GET /user/ HTTP/1.1" 200 7021
[2020-06-11 15:39:40,020] [basehttp.py:157] [basehttp:log_message] [INFO]- "GET /user/ HTTP/1.1" 200 7021
[2020-06-11 15:40:15,471] [basehttp.py:157] [basehttp:log_message] [INFO]- "OPTIONS /role/1/assign_user/ HTTP/1.1" 200 0
[2020-06-11 15:40:15,683] [basehttp.py:157] [basehttp:log_message] [INFO]- "PUT /role/1/assign_user/ HTTP/1.1" 200 2469
[2020-06-11 15:40:15,829] [basehttp.py:157] [basehttp:log_message] [INFO]- "GET /role/?current_page=1&pre_page=10 HTTP/1.1" 200 5071
[2020-06-11 15:40:39,581] [basehttp.py:157] [basehttp:log_message] [INFO]- "POST /auth/ HTTP/1.1" 200 65
[2020-06-11 15:40:41,988] [basehttp.py:157] [basehttp:log_message] [INFO]- "GET /role/user/?username=wwc&pid=1 HTTP/1.1" 200 1769
[2020-06-11 15:40:54,819] [basehttp.py:157] [basehttp:log_message] [INFO]- "GET /role/?current_page=1&pre_page=10 HTTP/1.1" 200 5071
[2020-06-11 15:40:56,800] [basehttp.py:157] [basehttp:log_message] [INFO]- "GET /user/ HTTP/1.1" 200 7021
[2020-06-11 15:41:39,694] [basehttp.py:157] [basehttp:log_message] [INFO]- "GET /user/ HTTP/1.1" 200 7021
[2020-06-11 15:41:58,325] [basehttp.py:157] [basehttp:log_message] [INFO]- "OPTIONS /role/2/assign_user/ HTTP/1.1" 200 0
[2020-06-11 15:41:58,679] [basehttp.py:157] [basehttp:log_message] [INFO]- "PUT /role/2/assign_user/ HTTP/1.1" 200 1882
[2020-06-11 15:41:58,783] [basehttp.py:157] [basehttp:log_message] [INFO]- "GET /role/?current_page=1&pre_page=10 HTTP/1.1" 200 5427
[2020-06-11 15:42:27,725] [basehttp.py:157] [basehttp:log_message] [INFO]- "POST /auth/ HTTP/1.1" 200 65
[2020-06-11 15:42:29,271] [basehttp.py:157] [basehttp:log_message] [INFO]- "OPTIONS /role/user?username=wll&pid=1 HTTP/1.1" 200 0
[2020-06-11 15:42:29,291] [basehttp.py:157] [basehttp:log_message] [INFO]- "GET /role/user?username=wll&pid=1 HTTP/1.1" 301 0
[2020-06-11 15:42:29,337] [basehttp.py:157] [basehttp:log_message] [INFO]- "OPTIONS /role/user/?username=wll&pid=1 HTTP/1.1" 200 0
[2020-06-11 15:42:29,401] [basehttp.py:157] [basehttp:log_message] [INFO]- "GET /role/user/?username=wll&pid=1 HTTP/1.1" 200 1882
[2020-06-11 15:43:31,184] [basehttp.py:157] [basehttp:log_message] [INFO]- "GET /role/?current_page=1&pre_page=10 HTTP/1.1" 200 5427
[2020-06-11 15:43:33,154] [basehttp.py:157] [basehttp:log_message] [INFO]- "GET /user/ HTTP/1.1" 200 7021
[2020-06-11 15:44:15,476] [basehttp.py:157] [basehttp:log_message] [INFO]- "GET /user/ HTTP/1.1" 200 7021
[2020-06-11 15:45:05,023] [basehttp.py:157] [basehttp:log_message] [INFO]- "GET /role/?current_page=1&pre_page=10 HTTP/1.1" 200 5427
[2020-06-11 15:45:05,046] [basehttp.py:157] [basehttp:log_message] [INFO]- "GET /role/user/?username=wll&pid=1 HTTP/1.1" 200 1882
[2020-06-11 15:45:06,565] [basehttp.py:157] [basehttp:log_message] [INFO]- "GET /user/ HTTP/1.1" 200 7021
[2020-06-11 15:45:31,833] [basehttp.py:157] [basehttp:log_message] [INFO]- "GET /user/ HTTP/1.1" 200 7021
[2020-06-11 15:45:37,581] [basehttp.py:157] [basehttp:log_message] [INFO]- "GET /user/ HTTP/1.1" 200 7021
[2020-06-11 15:45:46,480] [basehttp.py:157] [basehttp:log_message] [INFO]- "GET /user/ HTTP/1.1" 200 7021
[2020-06-11 15:50:28,616] [basehttp.py:157] [basehttp:log_message] [INFO]- "OPTIONS /role/?current_page=1&pre_page=10 HTTP/1.1" 200 0
[2020-06-11 15:50:28,660] [basehttp.py:157] [basehttp:log_message] [INFO]- "GET /role/?current_page=1&pre_page=10 HTTP/1.1" 200 5427
[2020-06-11 15:52:26,291] [basehttp.py:157] [basehttp:log_message] [INFO]- "GET /role/?current_page=1&pre_page=10 HTTP/1.1" 200 5427
[2020-06-11 15:53:44,933] [basehttp.py:157] [basehttp:log_message] [INFO]- "GET /role/?current_page=1&pre_page=10 HTTP/1.1" 200 5427
[2020-06-11 15:54:06,780] [basehttp.py:157] [basehttp:log_message] [INFO]- "OPTIONS /role/user?username=wll&pid=1 HTTP/1.1" 200 0
[2020-06-11 15:54:06,807] [basehttp.py:157] [basehttp:log_message] [INFO]- "GET /role/?current_page=1&pre_page=10 HTTP/1.1" 200 5427
[2020-06-11 15:54:06,942] [basehttp.py:157] [basehttp:log_message] [INFO]- "OPTIONS /role/user/?username=wll&pid=1 HTTP/1.1" 200 0
[2020-06-11 15:54:06,972] [basehttp.py:157] [basehttp:log_message] [INFO]- "GET /role/user/?username=wll&pid=1 HTTP/1.1" 200 1882
[2020-06-11 15:54:07,980] [basehttp.py:157] [basehttp:log_message] [INFO]- "OPTIONS /menu/ HTTP/1.1" 200 0
[2020-06-11 15:54:08,104] [basehttp.py:157] [basehttp:log_message] [INFO]- "GET /menu/ HTTP/1.1" 200 1617
[2020-06-11 15:54:13,613] [basehttp.py:157] [basehttp:log_message] [INFO]- "GET /menu/ HTTP/1.1" 200 1617
[2020-06-11 15:54:20,645] [basehttp.py:157] [basehttp:log_message] [INFO]- "OPTIONS /user/ HTTP/1.1" 200 0
[2020-06-11 15:54:20,715] [basehttp.py:157] [basehttp:log_message] [INFO]- "GET /user/ HTTP/1.1" 200 7021
[2020-06-11 15:54:23,506] [basehttp.py:157] [basehttp:log_message] [INFO]- "GET /user/ HTTP/1.1" 200 7021
[2020-06-11 15:54:25,973] [basehttp.py:157] [basehttp:log_message] [INFO]- "GET /user/ HTTP/1.1" 200 7021
[2020-06-11 15:55:46,586] [basehttp.py:157] [basehttp:log_message] [INFO]- "GET /user/ HTTP/1.1" 200 7021
[2020-06-11 15:55:49,226] [basehttp.py:157] [basehttp:log_message] [INFO]- "GET /user/ HTTP/1.1" 200 7021
[2020-06-11 15:55:52,090] [basehttp.py:157] [basehttp:log_message] [INFO]- "GET /user/ HTTP/1.1" 200 7021
[2020-06-11 15:55:57,156] [basehttp.py:157] [basehttp:log_message] [INFO]- "GET /role/?current_page=1&pre_page=10 HTTP/1.1" 200 5427
[2020-06-11 15:55:57,185] [basehttp.py:157] [basehttp:log_message] [INFO]- "GET /role/user/?username=wll&pid=1 HTTP/1.1" 200 1882
[2020-06-11 15:55:59,049] [basehttp.py:157] [basehttp:log_message] [INFO]- "GET /user/ HTTP/1.1" 200 7021
[2020-06-11 15:57:16,365] [basehttp.py:157] [basehttp:log_message] [INFO]- "GET /user/ HTTP/1.1" 200 7021
[2020-06-11 15:57:18,543] [basehttp.py:157] [basehttp:log_message] [INFO]- "GET /menu/ HTTP/1.1" 200 1617
[2020-06-11 16:00:25,307] [basehttp.py:157] [basehttp:log_message] [INFO]- "GET /role/?current_page=1&pre_page=10 HTTP/1.1" 200 5427
[2020-06-11 16:00:27,630] [basehttp.py:157] [basehttp:log_message] [INFO]- "GET /role/?current_page=1&pre_page=10 HTTP/1.1" 200 5427
[2020-06-11 16:00:27,653] [basehttp.py:157] [basehttp:log_message] [INFO]- "GET /role/user/?username=wll&pid=1 HTTP/1.1" 200 1882
[2020-06-11 16:00:36,927] [basehttp.py:157] [basehttp:log_message] [INFO]- "GET /user/ HTTP/1.1" 200 7021
[2020-06-11 16:00:39,606] [basehttp.py:157] [basehttp:log_message] [INFO]- "GET /menu/ HTTP/1.1" 200 1617
[2020-06-11 16:01:24,855] [basehttp.py:157] [basehttp:log_message] [INFO]- "OPTIONS /role/?current_page=1&pre_page=10 HTTP/1.1" 200 0
[2020-06-11 16:01:24,917] [basehttp.py:157] [basehttp:log_message] [INFO]- "GET /role/?current_page=1&pre_page=10 HTTP/1.1" 200 5427
[2020-06-11 16:01:27,862] [basehttp.py:157] [basehttp:log_message] [INFO]- "GET /role/?current_page=1&pre_page=10 HTTP/1.1" 200 5427
[2020-06-11 16:01:27,886] [basehttp.py:157] [basehttp:log_message] [INFO]- "GET /role/user/?username=wll&pid=1 HTTP/1.1" 200 1882
[2020-06-11 16:01:30,684] [basehttp.py:157] [basehttp:log_message] [INFO]- "GET /user/ HTTP/1.1" 200 7021
[2020-06-11 16:01:32,884] [basehttp.py:157] [basehttp:log_message] [INFO]- "GET /menu/ HTTP/1.1" 200 1617
[2020-06-11 16:01:36,690] [basehttp.py:157] [basehttp:log_message] [INFO]- "GET /user/ HTTP/1.1" 200 7021
[2020-06-11 16:02:22,224] [basehttp.py:157] [basehttp:log_message] [INFO]- "GET /role/?current_page=1&pre_page=10 HTTP/1.1" 200 5427
[2020-06-11 16:02:22,415] [basehttp.py:157] [basehttp:log_message] [INFO]- "GET /menu/ HTTP/1.1" 200 1617
[2020-06-11 16:02:25,073] [basehttp.py:157] [basehttp:log_message] [INFO]- "GET /menu/ HTTP/1.1" 200 1617
[2020-06-11 16:03:26,156] [basehttp.py:157] [basehttp:log_message] [INFO]- "GET /role/?current_page=1&pre_page=10 HTTP/1.1" 200 5427
[2020-06-11 16:03:26,183] [basehttp.py:157] [basehttp:log_message] [INFO]- "GET /role/user/?username=wll&pid=1 HTTP/1.1" 200 1882
[2020-06-11 16:03:36,189] [basehttp.py:157] [basehttp:log_message] [INFO]- "GET /menu/ HTTP/1.1" 200 1617
[2020-06-11 16:05:00,372] [basehttp.py:157] [basehttp:log_message] [INFO]- "GET /role/?current_page=1&pre_page=10 HTTP/1.1" 200 5427
[2020-06-11 16:05:03,485] [basehttp.py:157] [basehttp:log_message] [INFO]- "OPTIONS /role/user?username=wll&pid=1 HTTP/1.1" 200 0
[2020-06-11 16:05:03,512] [basehttp.py:157] [basehttp:log_message] [INFO]- "GET /role/?current_page=1&pre_page=10 HTTP/1.1" 200 5427
[2020-06-11 16:05:03,531] [basehttp.py:157] [basehttp:log_message] [INFO]- "OPTIONS /role/user/?username=wll&pid=1 HTTP/1.1" 200 0
[2020-06-11 16:05:03,645] [basehttp.py:157] [basehttp:log_message] [INFO]- "GET /role/user/?username=wll&pid=1 HTTP/1.1" 200 1882
[2020-06-11 16:05:07,343] [basehttp.py:157] [basehttp:log_message] [INFO]- "OPTIONS /user/ HTTP/1.1" 200 0
[2020-06-11 16:05:07,409] [basehttp.py:157] [basehttp:log_message] [INFO]- "GET /user/ HTTP/1.1" 200 7021
[2020-06-11 16:05:10,915] [basehttp.py:157] [basehttp:log_message] [INFO]- "OPTIONS /menu/ HTTP/1.1" 200 0
[2020-06-11 16:05:11,001] [basehttp.py:157] [basehttp:log_message] [INFO]- "GET /menu/ HTTP/1.1" 200 1617
[2020-06-11 16:06:17,278] [basehttp.py:157] [basehttp:log_message] [INFO]- "GET /role/?current_page=1&pre_page=10 HTTP/1.1" 200 5427
[2020-06-11 16:06:17,288] [basehttp.py:157] [basehttp:log_message] [INFO]- "GET /role/user/?username=wll&pid=1 HTTP/1.1" 200 1882
[2020-06-11 16:06:18,830] [basehttp.py:157] [basehttp:log_message] [INFO]- "GET /menu/ HTTP/1.1" 200 1617
[2020-06-11 16:06:31,832] [basehttp.py:157] [basehttp:log_message] [INFO]- "GET /menu/ HTTP/1.1" 200 1617
[2020-06-11 16:06:45,773] [basehttp.py:157] [basehttp:log_message] [INFO]- "GET /menu/ HTTP/1.1" 200 1617
[2020-06-11 16:08:31,243] [basehttp.py:157] [basehttp:log_message] [INFO]- "GET /menu/ HTTP/1.1" 200 1617
[2020-06-11 16:08:44,864] [basehttp.py:157] [basehttp:log_message] [INFO]- "OPTIONS /role/4/assign_menu/ HTTP/1.1" 200 0
[2020-06-11 16:08:45,107] [log.py:222] [log:log_response] [ERROR]- Internal Server Error: /role/4/assign_menu/
Traceback (most recent call last):
  File "/home/rock/anaconda3/envs/venv/lib/python3.8/site-packages/django/core/handlers/exception.py", line 34, in inner
    response = get_response(request)
  File "/home/rock/anaconda3/envs/venv/lib/python3.8/site-packages/django/core/handlers/base.py", line 115, in _get_response
    response = self.process_exception_by_middleware(e, request)
  File "/home/rock/anaconda3/envs/venv/lib/python3.8/site-packages/django/core/handlers/base.py", line 113, in _get_response
    response = wrapped_callback(request, *callback_args, **callback_kwargs)
  File "/home/rock/anaconda3/envs/venv/lib/python3.8/site-packages/django/views/decorators/csrf.py", line 54, in wrapped_view
    return view_func(*args, **kwargs)
  File "/home/rock/anaconda3/envs/venv/lib/python3.8/site-packages/rest_framework/viewsets.py", line 114, in view
    return self.dispatch(request, *args, **kwargs)
  File "/home/rock/anaconda3/envs/venv/lib/python3.8/site-packages/rest_framework/views.py", line 505, in dispatch
    response = self.handle_exception(exc)
  File "/home/rock/anaconda3/envs/venv/lib/python3.8/site-packages/rest_framework/views.py", line 465, in handle_exception
    self.raise_uncaught_exception(exc)
  File "/home/rock/anaconda3/envs/venv/lib/python3.8/site-packages/rest_framework/views.py", line 476, in raise_uncaught_exception
    raise exc
  File "/home/rock/anaconda3/envs/venv/lib/python3.8/site-packages/rest_framework/views.py", line 502, in dispatch
    response = handler(request, *args, **kwargs)
  File "/home/rock/quality_inspection/python-workspace/project-sys/sys_auth/views.py", line 244, in assign_menu
    menus = Menu.objects.filter(id__in=menu_ids).all()
  File "/home/rock/anaconda3/envs/venv/lib/python3.8/site-packages/django/db/models/manager.py", line 82, in manager_method
    return getattr(self.get_queryset(), name)(*args, **kwargs)
  File "/home/rock/anaconda3/envs/venv/lib/python3.8/site-packages/django/db/models/query.py", line 904, in filter
    return self._filter_or_exclude(False, *args, **kwargs)
  File "/home/rock/anaconda3/envs/venv/lib/python3.8/site-packages/django/db/models/query.py", line 923, in _filter_or_exclude
    clone.query.add_q(Q(*args, **kwargs))
  File "/home/rock/anaconda3/envs/venv/lib/python3.8/site-packages/django/db/models/sql/query.py", line 1351, in add_q
    clause, _ = self._add_q(q_object, self.used_aliases)
  File "/home/rock/anaconda3/envs/venv/lib/python3.8/site-packages/django/db/models/sql/query.py", line 1378, in _add_q
    child_clause, needed_inner = self.build_filter(
  File "/home/rock/anaconda3/envs/venv/lib/python3.8/site-packages/django/db/models/sql/query.py", line 1312, in build_filter
    condition = self.build_lookup(lookups, col, value)
  File "/home/rock/anaconda3/envs/venv/lib/python3.8/site-packages/django/db/models/sql/query.py", line 1166, in build_lookup
    lookup = lookup_class(lhs, rhs)
  File "/home/rock/anaconda3/envs/venv/lib/python3.8/site-packages/django/db/models/lookups.py", line 22, in __init__
    self.rhs = self.get_prep_lookup()
  File "/home/rock/anaconda3/envs/venv/lib/python3.8/site-packages/django/db/models/lookups.py", line 217, in get_prep_lookup
    for rhs_value in self.rhs:
TypeError: 'NoneType' object is not iterable
[2020-06-11 16:08:45,110] [basehttp.py:157] [basehttp:log_message] [ERROR]- "PUT /role/4/assign_menu/ HTTP/1.1" 500 20910
[2020-06-11 16:10:00,135] [basehttp.py:157] [basehttp:log_message] [INFO]- "GET /role/?current_page=1&pre_page=10 HTTP/1.1" 200 5427
[2020-06-11 16:10:00,168] [basehttp.py:157] [basehttp:log_message] [INFO]- "GET /role/user/?username=wll&pid=1 HTTP/1.1" 200 1882
[2020-06-11 16:10:05,029] [basehttp.py:157] [basehttp:log_message] [INFO]- "GET /menu/ HTTP/1.1" 200 1617
[2020-06-11 16:10:12,917] [log.py:222] [log:log_response] [ERROR]- Internal Server Error: /role/4/assign_menu/
Traceback (most recent call last):
  File "/home/rock/anaconda3/envs/venv/lib/python3.8/site-packages/django/core/handlers/exception.py", line 34, in inner
    response = get_response(request)
  File "/home/rock/anaconda3/envs/venv/lib/python3.8/site-packages/django/core/handlers/base.py", line 115, in _get_response
    response = self.process_exception_by_middleware(e, request)
  File "/home/rock/anaconda3/envs/venv/lib/python3.8/site-packages/django/core/handlers/base.py", line 113, in _get_response
    response = wrapped_callback(request, *callback_args, **callback_kwargs)
  File "/home/rock/anaconda3/envs/venv/lib/python3.8/site-packages/django/views/decorators/csrf.py", line 54, in wrapped_view
    return view_func(*args, **kwargs)
  File "/home/rock/anaconda3/envs/venv/lib/python3.8/site-packages/rest_framework/viewsets.py", line 114, in view
    return self.dispatch(request, *args, **kwargs)
  File "/home/rock/anaconda3/envs/venv/lib/python3.8/site-packages/rest_framework/views.py", line 505, in dispatch
    response = self.handle_exception(exc)
  File "/home/rock/anaconda3/envs/venv/lib/python3.8/site-packages/rest_framework/views.py", line 465, in handle_exception
    self.raise_uncaught_exception(exc)
  File "/home/rock/anaconda3/envs/venv/lib/python3.8/site-packages/rest_framework/views.py", line 476, in raise_uncaught_exception
    raise exc
  File "/home/rock/anaconda3/envs/venv/lib/python3.8/site-packages/rest_framework/views.py", line 502, in dispatch
    response = handler(request, *args, **kwargs)
  File "/home/rock/quality_inspection/python-workspace/project-sys/sys_auth/views.py", line 244, in assign_menu
    menus = Menu.objects.filter(id__in=menu_ids).all()
  File "/home/rock/anaconda3/envs/venv/lib/python3.8/site-packages/django/db/models/manager.py", line 82, in manager_method
    return getattr(self.get_queryset(), name)(*args, **kwargs)
  File "/home/rock/anaconda3/envs/venv/lib/python3.8/site-packages/django/db/models/query.py", line 904, in filter
    return self._filter_or_exclude(False, *args, **kwargs)
  File "/home/rock/anaconda3/envs/venv/lib/python3.8/site-packages/django/db/models/query.py", line 923, in _filter_or_exclude
    clone.query.add_q(Q(*args, **kwargs))
  File "/home/rock/anaconda3/envs/venv/lib/python3.8/site-packages/django/db/models/sql/query.py", line 1351, in add_q
    clause, _ = self._add_q(q_object, self.used_aliases)
  File "/home/rock/anaconda3/envs/venv/lib/python3.8/site-packages/django/db/models/sql/query.py", line 1378, in _add_q
    child_clause, needed_inner = self.build_filter(
  File "/home/rock/anaconda3/envs/venv/lib/python3.8/site-packages/django/db/models/sql/query.py", line 1312, in build_filter
    condition = self.build_lookup(lookups, col, value)
  File "/home/rock/anaconda3/envs/venv/lib/python3.8/site-packages/django/db/models/sql/query.py", line 1166, in build_lookup
    lookup = lookup_class(lhs, rhs)
  File "/home/rock/anaconda3/envs/venv/lib/python3.8/site-packages/django/db/models/lookups.py", line 22, in __init__
    self.rhs = self.get_prep_lookup()
  File "/home/rock/anaconda3/envs/venv/lib/python3.8/site-packages/django/db/models/lookups.py", line 217, in get_prep_lookup
    for rhs_value in self.rhs:
TypeError: 'NoneType' object is not iterable
[2020-06-11 16:10:12,918] [basehttp.py:157] [basehttp:log_message] [ERROR]- "PUT /role/4/assign_menu/ HTTP/1.1" 500 20910
[2020-06-11 16:11:15,434] [basehttp.py:157] [basehttp:log_message] [INFO]- "GET /role/?current_page=1&pre_page=10 HTTP/1.1" 200 5427
[2020-06-11 16:11:15,462] [basehttp.py:157] [basehttp:log_message] [INFO]- "GET /role/user/?username=wll&pid=1 HTTP/1.1" 200 1882
[2020-06-11 16:11:18,774] [basehttp.py:157] [basehttp:log_message] [INFO]- "GET /menu/ HTTP/1.1" 200 1617
[2020-06-11 16:11:23,344] [log.py:222] [log:log_response] [ERROR]- Internal Server Error: /role/4/assign_menu/
Traceback (most recent call last):
  File "/home/rock/anaconda3/envs/venv/lib/python3.8/site-packages/django/core/handlers/exception.py", line 34, in inner
    response = get_response(request)
  File "/home/rock/anaconda3/envs/venv/lib/python3.8/site-packages/django/core/handlers/base.py", line 115, in _get_response
    response = self.process_exception_by_middleware(e, request)
  File "/home/rock/anaconda3/envs/venv/lib/python3.8/site-packages/django/core/handlers/base.py", line 113, in _get_response
    response = wrapped_callback(request, *callback_args, **callback_kwargs)
  File "/home/rock/anaconda3/envs/venv/lib/python3.8/site-packages/django/views/decorators/csrf.py", line 54, in wrapped_view
    return view_func(*args, **kwargs)
  File "/home/rock/anaconda3/envs/venv/lib/python3.8/site-packages/rest_framework/viewsets.py", line 114, in view
    return self.dispatch(request, *args, **kwargs)
  File "/home/rock/anaconda3/envs/venv/lib/python3.8/site-packages/rest_framework/views.py", line 505, in dispatch
    response = self.handle_exception(exc)
  File "/home/rock/anaconda3/envs/venv/lib/python3.8/site-packages/rest_framework/views.py", line 465, in handle_exception
    self.raise_uncaught_exception(exc)
  File "/home/rock/anaconda3/envs/venv/lib/python3.8/site-packages/rest_framework/views.py", line 476, in raise_uncaught_exception
    raise exc
  File "/home/rock/anaconda3/envs/venv/lib/python3.8/site-packages/rest_framework/views.py", line 502, in dispatch
    response = handler(request, *args, **kwargs)
  File "/home/rock/quality_inspection/python-workspace/project-sys/sys_auth/views.py", line 244, in assign_menu
    menus = Menu.objects.filter(id__in=menu_ids).all()
  File "/home/rock/anaconda3/envs/venv/lib/python3.8/site-packages/django/db/models/manager.py", line 82, in manager_method
    return getattr(self.get_queryset(), name)(*args, **kwargs)
  File "/home/rock/anaconda3/envs/venv/lib/python3.8/site-packages/django/db/models/query.py", line 904, in filter
    return self._filter_or_exclude(False, *args, **kwargs)
  File "/home/rock/anaconda3/envs/venv/lib/python3.8/site-packages/django/db/models/query.py", line 923, in _filter_or_exclude
    clone.query.add_q(Q(*args, **kwargs))
  File "/home/rock/anaconda3/envs/venv/lib/python3.8/site-packages/django/db/models/sql/query.py", line 1351, in add_q
    clause, _ = self._add_q(q_object, self.used_aliases)
  File "/home/rock/anaconda3/envs/venv/lib/python3.8/site-packages/django/db/models/sql/query.py", line 1378, in _add_q
    child_clause, needed_inner = self.build_filter(
  File "/home/rock/anaconda3/envs/venv/lib/python3.8/site-packages/django/db/models/sql/query.py", line 1312, in build_filter
    condition = self.build_lookup(lookups, col, value)
  File "/home/rock/anaconda3/envs/venv/lib/python3.8/site-packages/django/db/models/sql/query.py", line 1166, in build_lookup
    lookup = lookup_class(lhs, rhs)
  File "/home/rock/anaconda3/envs/venv/lib/python3.8/site-packages/django/db/models/lookups.py", line 22, in __init__
    self.rhs = self.get_prep_lookup()
  File "/home/rock/anaconda3/envs/venv/lib/python3.8/site-packages/django/db/models/lookups.py", line 217, in get_prep_lookup
    for rhs_value in self.rhs:
TypeError: 'NoneType' object is not iterable
[2020-06-11 16:11:23,346] [basehttp.py:157] [basehttp:log_message] [ERROR]- "PUT /role/4/assign_menu/ HTTP/1.1" 500 20910
[2020-06-11 16:14:23,854] [basehttp.py:157] [basehttp:log_message] [INFO]- "OPTIONS /role/?current_page=1&pre_page=10 HTTP/1.1" 200 0
[2020-06-11 16:14:23,893] [basehttp.py:157] [basehttp:log_message] [INFO]- "GET /role/?current_page=1&pre_page=10 HTTP/1.1" 200 5427
[2020-06-11 16:14:26,364] [basehttp.py:157] [basehttp:log_message] [INFO]- "GET /role/?current_page=1&pre_page=10 HTTP/1.1" 200 5427
[2020-06-11 16:14:26,381] [basehttp.py:157] [basehttp:log_message] [INFO]- "GET /role/user/?username=wll&pid=1 HTTP/1.1" 200 1882
[2020-06-11 16:14:29,721] [basehttp.py:157] [basehttp:log_message] [INFO]- "GET /menu/ HTTP/1.1" 200 1617
[2020-06-11 16:14:34,580] [basehttp.py:157] [basehttp:log_message] [INFO]- "PUT /role/4/assign_menu/ HTTP/1.1" 200 384
[2020-06-11 16:14:34,667] [basehttp.py:157] [basehttp:log_message] [INFO]- "GET /role/?current_page=1&pre_page=10 HTTP/1.1" 200 5662
[2020-06-11 16:14:43,263] [basehttp.py:157] [basehttp:log_message] [INFO]- "OPTIONS /user/?current_page=1&pre_page=10 HTTP/1.1" 200 0
[2020-06-11 16:14:43,281] [basehttp.py:157] [basehttp:log_message] [INFO]- "GET /user/?current_page=1&pre_page=10 HTTP/1.1" 200 1819
[2020-06-11 16:15:01,534] [log.py:222] [log:log_response] [WARNING]- Conflict: /user/
[2020-06-11 16:15:01,535] [basehttp.py:157] [basehttp:log_message] [WARNING]- "POST /user/ HTTP/1.1" 409 25
[2020-06-11 16:15:11,756] [basehttp.py:157] [basehttp:log_message] [INFO]- "OPTIONS /user/ HTTP/1.1" 200 0
[2020-06-11 16:15:11,896] [basehttp.py:157] [basehttp:log_message] [INFO]- "POST /user/ HTTP/1.1" 201 177
[2020-06-11 16:15:11,987] [basehttp.py:157] [basehttp:log_message] [INFO]- "GET /user/?current_page=1&pre_page=10 HTTP/1.1" 200 1819
[2020-06-11 16:15:16,528] [basehttp.py:157] [basehttp:log_message] [INFO]- "GET /role/?current_page=1&pre_page=10 HTTP/1.1" 200 5662
[2020-06-11 16:15:19,786] [basehttp.py:157] [basehttp:log_message] [INFO]- "GET /user/ HTTP/1.1" 200 7199
[2020-06-11 16:15:30,369] [basehttp.py:157] [basehttp:log_message] [INFO]- "OPTIONS /role/4/assign_user/ HTTP/1.1" 200 0
[2020-06-11 16:15:30,529] [basehttp.py:157] [basehttp:log_message] [INFO]- "PUT /role/4/assign_user/ HTTP/1.1" 200 561
[2020-06-11 16:15:30,643] [basehttp.py:157] [basehttp:log_message] [INFO]- "GET /role/?current_page=1&pre_page=10 HTTP/1.1" 200 5839
[2020-06-11 16:15:45,375] [basehttp.py:157] [basehttp:log_message] [INFO]- "OPTIONS /auth/ HTTP/1.1" 200 0
[2020-06-11 16:15:45,526] [basehttp.py:157] [basehttp:log_message] [INFO]- "POST /auth/ HTTP/1.1" 200 65
[2020-06-11 16:15:47,377] [basehttp.py:157] [basehttp:log_message] [INFO]- "OPTIONS /role/user?username=test11&pid=1 HTTP/1.1" 200 0
[2020-06-11 16:15:47,414] [basehttp.py:157] [basehttp:log_message] [INFO]- "GET /role/user?username=test11&pid=1 HTTP/1.1" 301 0
[2020-06-11 16:15:47,461] [basehttp.py:157] [basehttp:log_message] [INFO]- "OPTIONS /role/user/?username=test11&pid=1 HTTP/1.1" 200 0
[2020-06-11 16:15:47,520] [basehttp.py:157] [basehttp:log_message] [INFO]- "GET /role/user/?username=test11&pid=1 HTTP/1.1" 200 561
[2020-06-11 16:16:00,075] [basehttp.py:157] [basehttp:log_message] [INFO]- "POST /auth/ HTTP/1.1" 200 65
[2020-06-11 16:16:01,795] [basehttp.py:157] [basehttp:log_message] [INFO]- "OPTIONS /role/user?username=wl&pid=1 HTTP/1.1" 200 0
[2020-06-11 16:16:01,814] [basehttp.py:157] [basehttp:log_message] [INFO]- "OPTIONS /role/user/?username=wl&pid=1 HTTP/1.1" 200 0
[2020-06-11 16:16:01,879] [basehttp.py:157] [basehttp:log_message] [INFO]- "GET /role/user/?username=wl&pid=1 HTTP/1.1" 200 1882
[2020-06-11 16:16:03,399] [basehttp.py:157] [basehttp:log_message] [INFO]- "GET /user/?current_page=1&pre_page=10 HTTP/1.1" 200 1819
[2020-06-11 16:16:04,238] [basehttp.py:157] [basehttp:log_message] [INFO]- "GET /role/?current_page=1&pre_page=10 HTTP/1.1" 200 5839
[2020-06-11 16:16:06,948] [basehttp.py:157] [basehttp:log_message] [INFO]- "GET /user/?current_page=1&pre_page=10 HTTP/1.1" 200 1819
[2020-06-11 16:16:07,845] [basehttp.py:157] [basehttp:log_message] [INFO]- "GET /role/?current_page=1&pre_page=10 HTTP/1.1" 200 5839
[2020-06-11 16:17:46,866] [basehttp.py:157] [basehttp:log_message] [INFO]- "GET /role/?current_page=1&pre_page=10 HTTP/1.1" 200 5839
[2020-06-11 16:17:46,891] [basehttp.py:157] [basehttp:log_message] [INFO]- "GET /role/user/?username=wl&pid=1 HTTP/1.1" 200 1882
[2020-06-11 16:17:54,823] [basehttp.py:157] [basehttp:log_message] [INFO]- "OPTIONS /role/1/ HTTP/1.1" 200 0
[2020-06-11 16:17:54,898] [basehttp.py:157] [basehttp:log_message] [INFO]- "PUT /role/1/ HTTP/1.1" 200 2467
[2020-06-11 16:17:55,017] [basehttp.py:157] [basehttp:log_message] [INFO]- "GET /role/?current_page=1&pre_page=10 HTTP/1.1" 200 5837
[2020-06-11 16:19:00,692] [basehttp.py:157] [basehttp:log_message] [INFO]- "GET /user/ HTTP/1.1" 200 7199
[2020-06-11 16:19:04,059] [basehttp.py:157] [basehttp:log_message] [INFO]- "GET /user/ HTTP/1.1" 200 7199
[2020-06-11 16:19:12,237] [basehttp.py:157] [basehttp:log_message] [INFO]- "GET /user/ HTTP/1.1" 200 7199
[2020-06-11 16:19:21,696] [basehttp.py:157] [basehttp:log_message] [INFO]- "PUT /role/4/assign_user/ HTTP/1.1" 200 561
[2020-06-11 16:19:21,773] [basehttp.py:157] [basehttp:log_message] [INFO]- "GET /role/?current_page=1&pre_page=10 HTTP/1.1" 200 5837
[2020-06-11 16:20:10,207] [basehttp.py:157] [basehttp:log_message] [INFO]- "OPTIONS /menu/ HTTP/1.1" 200 0
[2020-06-11 16:20:10,272] [basehttp.py:157] [basehttp:log_message] [INFO]- "GET /menu/ HTTP/1.1" 200 1617
[2020-06-11 16:20:15,692] [basehttp.py:157] [basehttp:log_message] [INFO]- "GET /user/ HTTP/1.1" 200 7199
[2020-06-11 16:20:26,574] [basehttp.py:157] [basehttp:log_message] [INFO]- "PUT /role/4/assign_user/ HTTP/1.1" 200 561
[2020-06-11 16:20:26,645] [basehttp.py:157] [basehttp:log_message] [INFO]- "GET /role/?current_page=1&pre_page=10 HTTP/1.1" 200 5837
[2020-06-11 16:20:46,199] [basehttp.py:157] [basehttp:log_message] [INFO]- "GET /user/ HTTP/1.1" 200 7199
[2020-06-11 16:24:32,472] [basehttp.py:157] [basehttp:log_message] [INFO]- "OPTIONS /role/?current_page=1&pre_page=10 HTTP/1.1" 200 0
[2020-06-11 16:24:32,507] [basehttp.py:157] [basehttp:log_message] [INFO]- "GET /role/?current_page=1&pre_page=10 HTTP/1.1" 200 5837
[2020-06-11 16:24:34,183] [basehttp.py:157] [basehttp:log_message] [INFO]- "GET /user/ HTTP/1.1" 200 7199
[2020-06-11 16:24:37,827] [basehttp.py:157] [basehttp:log_message] [INFO]- "GET /user/ HTTP/1.1" 200 7199
[2020-06-11 16:24:43,853] [basehttp.py:157] [basehttp:log_message] [INFO]- "PUT /role/4/assign_user/ HTTP/1.1" 200 561
[2020-06-11 16:24:43,906] [basehttp.py:157] [basehttp:log_message] [INFO]- "GET /role/?current_page=1&pre_page=10 HTTP/1.1" 200 5837
[2020-06-11 16:24:45,635] [basehttp.py:157] [basehttp:log_message] [INFO]- "GET /user/ HTTP/1.1" 200 7199
[2020-06-11 16:24:53,146] [basehttp.py:157] [basehttp:log_message] [INFO]- "GET /user/ HTTP/1.1" 200 7199
[2020-06-11 16:42:49,559] [basehttp.py:157] [basehttp:log_message] [INFO]- "OPTIONS /user/?current_page=1&pre_page=10 HTTP/1.1" 200 0
[2020-06-11 16:42:49,576] [basehttp.py:157] [basehttp:log_message] [INFO]- "GET /user/?current_page=1&pre_page=10 HTTP/1.1" 200 1819
[2020-06-11 16:42:52,238] [basehttp.py:157] [basehttp:log_message] [INFO]- "OPTIONS /role/?current_page=1&pre_page=10 HTTP/1.1" 200 0
[2020-06-11 16:42:52,267] [basehttp.py:157] [basehttp:log_message] [INFO]- "GET /role/?current_page=1&pre_page=10 HTTP/1.1" 200 5837
[2020-06-11 16:43:00,016] [basehttp.py:157] [basehttp:log_message] [INFO]- "OPTIONS /user/ HTTP/1.1" 200 0
[2020-06-11 16:43:00,033] [basehttp.py:157] [basehttp:log_message] [INFO]- "GET /user/ HTTP/1.1" 200 7199
[2020-06-11 16:43:09,207] [basehttp.py:157] [basehttp:log_message] [INFO]- "GET /user/ HTTP/1.1" 200 7199
[2020-06-11 16:43:36,166] [basehttp.py:157] [basehttp:log_message] [INFO]- "GET /user/ HTTP/1.1" 200 7199
[2020-06-11 16:44:21,665] [basehttp.py:157] [basehttp:log_message] [INFO]- "OPTIONS /role/user?username=wl&pid=1 HTTP/1.1" 200 0
[2020-06-11 16:44:21,702] [basehttp.py:157] [basehttp:log_message] [INFO]- "OPTIONS /role/user/?username=wl&pid=1 HTTP/1.1" 200 0
[2020-06-11 16:44:21,705] [basehttp.py:157] [basehttp:log_message] [INFO]- "GET /role/?current_page=1&pre_page=10 HTTP/1.1" 200 5837
[2020-06-11 16:44:21,804] [basehttp.py:157] [basehttp:log_message] [INFO]- "GET /role/user/?username=wl&pid=1 HTTP/1.1" 200 1882
[2020-06-11 16:44:27,703] [basehttp.py:157] [basehttp:log_message] [INFO]- "GET /user/?current_page=1&pre_page=10 HTTP/1.1" 200 1819
[2020-06-11 16:44:29,135] [basehttp.py:157] [basehttp:log_message] [INFO]- "GET /role/?current_page=1&pre_page=10 HTTP/1.1" 200 5837
[2020-06-11 16:44:30,510] [basehttp.py:157] [basehttp:log_message] [INFO]- "GET /user/?current_page=1&pre_page=10 HTTP/1.1" 200 1819
[2020-06-11 16:44:33,920] [basehttp.py:157] [basehttp:log_message] [INFO]- "GET /role/?current_page=1&pre_page=10 HTTP/1.1" 200 5837
[2020-06-11 17:54:12,558] [basehttp.py:157] [basehttp:log_message] [INFO]- "OPTIONS /user/?current_page=1&pre_page=10 HTTP/1.1" 200 0
[2020-06-11 17:54:12,573] [basehttp.py:157] [basehttp:log_message] [INFO]- "GET /user/?current_page=1&pre_page=10 HTTP/1.1" 200 1819
[2020-06-11 17:54:14,639] [basehttp.py:157] [basehttp:log_message] [INFO]- "OPTIONS /role/?current_page=1&pre_page=10 HTTP/1.1" 200 0
[2020-06-11 17:54:14,675] [basehttp.py:157] [basehttp:log_message] [INFO]- "GET /role/?current_page=1&pre_page=10 HTTP/1.1" 200 5837
[2020-06-11 17:54:16,990] [basehttp.py:157] [basehttp:log_message] [INFO]- "GET /user/?current_page=1&pre_page=10 HTTP/1.1" 200 1819
