[2020-12-22 09:54:51,272] [autoreload.py:598] [autoreload:run_with_reloader] [INFO]- Watching for file changes with StatReloader
[2020-12-22 09:55:05,467] [autoreload.py:598] [autoreload:run_with_reloader] [INFO]- Watching for file changes with StatReloader
[2020-12-22 09:57:06,962] [autoreload.py:598] [autoreload:run_with_reloader] [INFO]- Watching for file changes with StatReloader
[2020-12-22 09:57:10,275] [autoreload.py:598] [autoreload:run_with_reloader] [INFO]- Watching for file changes with StatReloader
[2020-12-22 16:16:02,079] [views.py:69] [views:get_history_monitor] [ERROR]- HTTPConnectionPool(host='10.230.13.44', port=4242): Max retries exceeded with url: /api/query?start=1608624358359&end=1608624958359&m=sum:MEM_PERCENT%7BlogicIp=10.10.10.130%7D (Caused by ConnectTimeoutError(<urllib3.connection.HTTPConnection object at 0x7fca53197b80>, 'Connection to 10.230.13.44 timed out. (connect timeout=3)'))
[2020-12-22 16:16:02,080] [log.py:222] [log:log_response] [ERROR]- Internal Server Error: /monitor/api/analysis/history/
[2020-12-22 16:16:03,380] [views.py:69] [views:get_history_monitor] [ERROR]- HTTPConnectionPool(host='10.230.13.44', port=4242): Max retries exceeded with url: /api/query?start=1608624358345&end=1608624958345&m=sum:CPU_PERCENT%7BlogicIp=10.10.10.130%7D (Caused by ConnectTimeoutError(<urllib3.connection.HTTPConnection object at 0x7fca53118af0>, 'Connection to 10.230.13.44 timed out. (connect timeout=3)'))
[2020-12-22 16:16:03,382] [log.py:222] [log:log_response] [ERROR]- Internal Server Error: /monitor/api/analysis/history/
[2020-12-22 16:20:18,410] [views.py:69] [views:get_history_monitor] [ERROR]- HTTPConnectionPool(host='10.230.13.44', port=4242): Max retries exceeded with url: /api/query?start=1608624615265&end=1608625215265&m=sum:MEM_PERCENT%7BlogicIp=10.10.10.130%7D (Caused by ConnectTimeoutError(<urllib3.connection.HTTPConnection object at 0x7fca53103820>, 'Connection to 10.230.13.44 timed out. (connect timeout=3)'))
[2020-12-22 16:20:18,411] [log.py:222] [log:log_response] [ERROR]- Internal Server Error: /monitor/api/analysis/history/
[2020-12-22 16:20:18,467] [views.py:69] [views:get_history_monitor] [ERROR]- HTTPConnectionPool(host='10.230.13.44', port=4242): Max retries exceeded with url: /api/query?start=1608624615263&end=1608625215263&m=sum:CPU_PERCENT%7BlogicIp=10.10.10.130%7D (Caused by ConnectTimeoutError(<urllib3.connection.HTTPConnection object at 0x7fca528c97f0>, 'Connection to 10.230.13.44 timed out. (connect timeout=3)'))
[2020-12-22 16:20:18,467] [log.py:222] [log:log_response] [ERROR]- Internal Server Error: /monitor/api/analysis/history/
[2020-12-22 16:33:12,042] [views.py:69] [views:get_history_monitor] [ERROR]- HTTPConnectionPool(host='10.230.13.44', port=4242): Max retries exceeded with url: /api/query?start=1608625388913&end=1608625988913&m=sum:CPU_PERCENT%7BlogicIp=10.10.10.130%7D (Caused by ConnectTimeoutError(<urllib3.connection.HTTPConnection object at 0x7fca5285f2e0>, 'Connection to 10.230.13.44 timed out. (connect timeout=3)'))
[2020-12-22 16:33:12,063] [log.py:222] [log:log_response] [ERROR]- Internal Server Error: /monitor/api/analysis/history/
[2020-12-22 16:33:12,135] [views.py:69] [views:get_history_monitor] [ERROR]- HTTPConnectionPool(host='10.230.13.44', port=4242): Max retries exceeded with url: /api/query?start=1608625388920&end=1608625988920&m=sum:MEM_PERCENT%7BlogicIp=10.10.10.130%7D (Caused by ConnectTimeoutError(<urllib3.connection.HTTPConnection object at 0x7fca528a44c0>, 'Connection to 10.230.13.44 timed out. (connect timeout=3)'))
[2020-12-22 16:33:12,135] [log.py:222] [log:log_response] [ERROR]- Internal Server Error: /monitor/api/analysis/history/
[2020-12-22 16:51:23,746] [views.py:69] [views:get_history_monitor] [ERROR]- HTTPConnectionPool(host='10.230.13.44', port=4242): Max retries exceeded with url: /api/query?start=1608626480584&end=1608627080584&m=sum:CPU_PERCENT%7BlogicIp=10.10.10.130%7D (Caused by ConnectTimeoutError(<urllib3.connection.HTTPConnection object at 0x7fca528b1220>, 'Connection to 10.230.13.44 timed out. (connect timeout=3)'))
[2020-12-22 16:51:23,748] [log.py:222] [log:log_response] [ERROR]- Internal Server Error: /monitor/api/analysis/history/
[2020-12-22 16:51:24,031] [views.py:69] [views:get_history_monitor] [ERROR]- HTTPConnectionPool(host='10.230.13.44', port=4242): Max retries exceeded with url: /api/query?start=1608626480881&end=1608627080881&m=sum:MEM_PERCENT%7BlogicIp=10.10.10.130%7D (Caused by ConnectTimeoutError(<urllib3.connection.HTTPConnection object at 0x7fca5289ddf0>, 'Connection to 10.230.13.44 timed out. (connect timeout=3)'))
[2020-12-22 16:51:24,034] [log.py:222] [log:log_response] [ERROR]- Internal Server Error: /monitor/api/analysis/history/
[2020-12-22 17:11:09,693] [views.py:69] [views:get_history_monitor] [ERROR]- HTTPConnectionPool(host='10.230.13.44', port=4242): Max retries exceeded with url: /api/query?start=1608627666547&end=1608628266547&m=sum:CPU_PERCENT%7BlogicIp=10.10.10.130%7D (Caused by ConnectTimeoutError(<urllib3.connection.HTTPConnection object at 0x7fca53133070>, 'Connection to 10.230.13.44 timed out. (connect timeout=3)'))
[2020-12-22 17:11:09,741] [log.py:222] [log:log_response] [ERROR]- Internal Server Error: /monitor/api/analysis/history/
[2020-12-22 17:11:09,762] [views.py:69] [views:get_history_monitor] [ERROR]- HTTPConnectionPool(host='10.230.13.44', port=4242): Max retries exceeded with url: /api/query?start=1608627666554&end=1608628266554&m=sum:MEM_PERCENT%7BlogicIp=10.10.10.130%7D (Caused by ConnectTimeoutError(<urllib3.connection.HTTPConnection object at 0x7fca528c11c0>, 'Connection to 10.230.13.44 timed out. (connect timeout=3)'))
[2020-12-22 17:11:09,776] [log.py:222] [log:log_response] [ERROR]- Internal Server Error: /monitor/api/analysis/history/
[2020-12-22 17:35:55,186] [views.py:69] [views:get_history_monitor] [ERROR]- HTTPConnectionPool(host='10.230.13.44', port=4242): Max retries exceeded with url: /api/query?start=1608629152038&end=1608629752038&m=sum:MEM_PERCENT%7BlogicIp=10.10.10.130%7D (Caused by ConnectTimeoutError(<urllib3.connection.HTTPConnection object at 0x7f32867adb80>, 'Connection to 10.230.13.44 timed out. (connect timeout=3)'))
[2020-12-22 17:35:55,188] [log.py:222] [log:log_response] [ERROR]- Internal Server Error: /monitor/api/analysis/history/
[2020-12-22 17:35:55,235] [views.py:69] [views:get_history_monitor] [ERROR]- HTTPConnectionPool(host='10.230.13.44', port=4242): Max retries exceeded with url: /api/query?start=1608629152037&end=1608629752037&m=sum:CPU_PERCENT%7BlogicIp=10.10.10.130%7D (Caused by ConnectTimeoutError(<urllib3.connection.HTTPConnection object at 0x7f328682baf0>, 'Connection to 10.230.13.44 timed out. (connect timeout=3)'))
[2020-12-22 17:35:55,236] [log.py:222] [log:log_response] [ERROR]- Internal Server Error: /monitor/api/analysis/history/
