[2020-11-21 11:49:03,109] [autoreload.py:598] [autoreload:run_with_reloader] [INFO]- Watching for file changes with StatReloader
[2020-11-21 11:50:22,536] [log.py:222] [log:log_response] [ERROR]- Internal Server Error: /monitor/api/alarm_detail/alarm_count/
Traceback (most recent call last):
  File "/home/rock/anaconda3/envs/venv/lib/python3.8/site-packages/django/core/handlers/exception.py", line 34, in inner
    response = get_response(request)
  File "/home/rock/anaconda3/envs/venv/lib/python3.8/site-packages/django/core/handlers/base.py", line 115, in _get_response
    response = self.process_exception_by_middleware(e, request)
  File "/home/rock/anaconda3/envs/venv/lib/python3.8/site-packages/django/core/handlers/base.py", line 113, in _get_response
    response = wrapped_callback(request, *callback_args, **callback_kwargs)
  File "/home/rock/anaconda3/envs/venv/lib/python3.8/site-packages/django/views/decorators/csrf.py", line 54, in wrapped_view
    return view_func(*args, **kwargs)
  File "/home/rock/anaconda3/envs/venv/lib/python3.8/site-packages/rest_framework/viewsets.py", line 114, in view
    return self.dispatch(request, *args, **kwargs)
  File "/home/rock/anaconda3/envs/venv/lib/python3.8/site-packages/rest_framework/views.py", line 505, in dispatch
    response = self.handle_exception(exc)
  File "/home/rock/anaconda3/envs/venv/lib/python3.8/site-packages/rest_framework/views.py", line 465, in handle_exception
    self.raise_uncaught_exception(exc)
  File "/home/rock/anaconda3/envs/venv/lib/python3.8/site-packages/rest_framework/views.py", line 476, in raise_uncaught_exception
    raise exc
  File "/home/rock/anaconda3/envs/venv/lib/python3.8/site-packages/rest_framework/views.py", line 502, in dispatch
    response = handler(request, *args, **kwargs)
  File "/home/rock/quality_inspection/python-workspace/project_monitor/alarm/views.py", line 365, in get_alarm_count
    result['remain_alarm_detail'] = AlarmDetailViewSet.get_remain_alarm_detail()
  File "/home/rock/quality_inspection/python-workspace/project_monitor/alarm/views.py", line 483, in get_remain_alarm_detail
    alarm['server_type'] = dict_[alarm['server_type']]
KeyError: None
[2020-11-21 11:50:22,539] [basehttp.py:157] [basehttp:log_message] [ERROR]- "GET /monitor/api/alarm_detail/alarm_count/ HTTP/1.1" 500 20265
[2020-11-21 11:50:49,690] [autoreload.py:598] [autoreload:run_with_reloader] [INFO]- Watching for file changes with StatReloader
[2020-11-21 11:50:54,383] [log.py:222] [log:log_response] [ERROR]- Internal Server Error: /monitor/api/alarm_detail/alarm_count/
Traceback (most recent call last):
  File "/home/rock/anaconda3/envs/venv/lib/python3.8/site-packages/django/core/handlers/exception.py", line 34, in inner
    response = get_response(request)
  File "/home/rock/anaconda3/envs/venv/lib/python3.8/site-packages/django/core/handlers/base.py", line 115, in _get_response
    response = self.process_exception_by_middleware(e, request)
  File "/home/rock/anaconda3/envs/venv/lib/python3.8/site-packages/django/core/handlers/base.py", line 113, in _get_response
    response = wrapped_callback(request, *callback_args, **callback_kwargs)
  File "/home/rock/anaconda3/envs/venv/lib/python3.8/site-packages/django/views/decorators/csrf.py", line 54, in wrapped_view
    return view_func(*args, **kwargs)
  File "/home/rock/anaconda3/envs/venv/lib/python3.8/site-packages/rest_framework/viewsets.py", line 114, in view
    return self.dispatch(request, *args, **kwargs)
  File "/home/rock/anaconda3/envs/venv/lib/python3.8/site-packages/rest_framework/views.py", line 505, in dispatch
    response = self.handle_exception(exc)
  File "/home/rock/anaconda3/envs/venv/lib/python3.8/site-packages/rest_framework/views.py", line 465, in handle_exception
    self.raise_uncaught_exception(exc)
  File "/home/rock/anaconda3/envs/venv/lib/python3.8/site-packages/rest_framework/views.py", line 476, in raise_uncaught_exception
    raise exc
  File "/home/rock/anaconda3/envs/venv/lib/python3.8/site-packages/rest_framework/views.py", line 502, in dispatch
    response = handler(request, *args, **kwargs)
  File "/home/rock/quality_inspection/python-workspace/project_monitor/alarm/views.py", line 365, in get_alarm_count
    result['remain_alarm_detail'] = AlarmDetailViewSet.get_remain_alarm_detail()
  File "/home/rock/quality_inspection/python-workspace/project_monitor/alarm/views.py", line 485, in get_remain_alarm_detail
    alarm['server_type'] = dict_[alarm['server_type']]
KeyError: None
[2020-11-21 11:50:54,388] [basehttp.py:157] [basehttp:log_message] [ERROR]- "GET /monitor/api/alarm_detail/alarm_count/ HTTP/1.1" 500 20265
[2020-11-21 11:54:07,413] [autoreload.py:598] [autoreload:run_with_reloader] [INFO]- Watching for file changes with StatReloader
[2020-11-21 11:54:13,336] [log.py:222] [log:log_response] [ERROR]- Internal Server Error: /monitor/api/alarm_detail/alarm_count/
Traceback (most recent call last):
  File "/home/rock/anaconda3/envs/venv/lib/python3.8/site-packages/django/core/handlers/exception.py", line 34, in inner
    response = get_response(request)
  File "/home/rock/anaconda3/envs/venv/lib/python3.8/site-packages/django/core/handlers/base.py", line 115, in _get_response
    response = self.process_exception_by_middleware(e, request)
  File "/home/rock/anaconda3/envs/venv/lib/python3.8/site-packages/django/core/handlers/base.py", line 113, in _get_response
    response = wrapped_callback(request, *callback_args, **callback_kwargs)
  File "/home/rock/anaconda3/envs/venv/lib/python3.8/site-packages/django/views/decorators/csrf.py", line 54, in wrapped_view
    return view_func(*args, **kwargs)
  File "/home/rock/anaconda3/envs/venv/lib/python3.8/site-packages/rest_framework/viewsets.py", line 114, in view
    return self.dispatch(request, *args, **kwargs)
  File "/home/rock/anaconda3/envs/venv/lib/python3.8/site-packages/rest_framework/views.py", line 505, in dispatch
    response = self.handle_exception(exc)
  File "/home/rock/anaconda3/envs/venv/lib/python3.8/site-packages/rest_framework/views.py", line 465, in handle_exception
    self.raise_uncaught_exception(exc)
  File "/home/rock/anaconda3/envs/venv/lib/python3.8/site-packages/rest_framework/views.py", line 476, in raise_uncaught_exception
    raise exc
  File "/home/rock/anaconda3/envs/venv/lib/python3.8/site-packages/rest_framework/views.py", line 502, in dispatch
    response = handler(request, *args, **kwargs)
  File "/home/rock/quality_inspection/python-workspace/project_monitor/alarm/views.py", line 365, in get_alarm_count
    result['remain_alarm_detail'] = AlarmDetailViewSet.get_remain_alarm_detail()
  File "/home/rock/quality_inspection/python-workspace/project_monitor/alarm/views.py", line 486, in get_remain_alarm_detail
    alarm['server_type'] = dict_[alarm['server_type']]
KeyError: None
[2020-11-21 11:54:13,339] [basehttp.py:157] [basehttp:log_message] [ERROR]- "GET /monitor/api/alarm_detail/alarm_count/ HTTP/1.1" 500 20265
[2020-11-21 11:55:33,389] [autoreload.py:222] [autoreload:trigger_reload] [INFO]- /home/rock/quality_inspection/python-workspace/project_monitor/alarm/views.py changed, reloading.
[2020-11-21 11:55:34,247] [autoreload.py:598] [autoreload:run_with_reloader] [INFO]- Watching for file changes with StatReloader
[2020-11-21 11:58:08,210] [autoreload.py:598] [autoreload:run_with_reloader] [INFO]- Watching for file changes with StatReloader
[2020-11-21 11:58:17,411] [log.py:222] [log:log_response] [ERROR]- Internal Server Error: /monitor/api/alarm_detail/alarm_count/
Traceback (most recent call last):
  File "/home/rock/anaconda3/envs/venv/lib/python3.8/site-packages/django/core/handlers/exception.py", line 34, in inner
    response = get_response(request)
  File "/home/rock/anaconda3/envs/venv/lib/python3.8/site-packages/django/core/handlers/base.py", line 115, in _get_response
    response = self.process_exception_by_middleware(e, request)
  File "/home/rock/anaconda3/envs/venv/lib/python3.8/site-packages/django/core/handlers/base.py", line 113, in _get_response
    response = wrapped_callback(request, *callback_args, **callback_kwargs)
  File "/home/rock/anaconda3/envs/venv/lib/python3.8/site-packages/django/views/decorators/csrf.py", line 54, in wrapped_view
    return view_func(*args, **kwargs)
  File "/home/rock/anaconda3/envs/venv/lib/python3.8/site-packages/rest_framework/viewsets.py", line 114, in view
    return self.dispatch(request, *args, **kwargs)
  File "/home/rock/anaconda3/envs/venv/lib/python3.8/site-packages/rest_framework/views.py", line 505, in dispatch
    response = self.handle_exception(exc)
  File "/home/rock/anaconda3/envs/venv/lib/python3.8/site-packages/rest_framework/views.py", line 465, in handle_exception
    self.raise_uncaught_exception(exc)
  File "/home/rock/anaconda3/envs/venv/lib/python3.8/site-packages/rest_framework/views.py", line 476, in raise_uncaught_exception
    raise exc
  File "/home/rock/anaconda3/envs/venv/lib/python3.8/site-packages/rest_framework/views.py", line 502, in dispatch
    response = handler(request, *args, **kwargs)
  File "/home/rock/quality_inspection/python-workspace/project_monitor/alarm/views.py", line 365, in get_alarm_count
    result['remain_alarm_detail'] = AlarmDetailViewSet.get_remain_alarm_detail()
  File "/home/rock/quality_inspection/python-workspace/project_monitor/alarm/views.py", line 485, in get_remain_alarm_detail
    alarm['server_type'] = dict_[alarm['server_type']]
KeyError: None
[2020-11-21 11:58:17,413] [basehttp.py:157] [basehttp:log_message] [ERROR]- "GET /monitor/api/alarm_detail/alarm_count/ HTTP/1.1" 500 20265
[2020-11-21 11:59:35,364] [autoreload.py:222] [autoreload:trigger_reload] [INFO]- /home/rock/quality_inspection/python-workspace/project_monitor/alarm/views.py changed, reloading.
[2020-11-21 11:59:36,486] [autoreload.py:598] [autoreload:run_with_reloader] [INFO]- Watching for file changes with StatReloader
[2020-11-21 12:00:22,635] [autoreload.py:598] [autoreload:run_with_reloader] [INFO]- Watching for file changes with StatReloader
[2020-11-21 12:00:33,790] [basehttp.py:157] [basehttp:log_message] [INFO]- "GET /monitor/api/alarm_detail/alarm_count/ HTTP/1.1" 200 9125
[2020-11-21 15:14:38,402] [autoreload.py:598] [autoreload:run_with_reloader] [INFO]- Watching for file changes with StatReloader
[2020-11-21 15:16:13,804] [log.py:222] [log:log_response] [WARNING]- Not Found: /monitor/api/monitor/
[2020-11-21 15:16:13,808] [basehttp.py:157] [basehttp:log_message] [WARNING]- "GET /monitor/api/monitor/ HTTP/1.1" 404 34435
[2020-11-21 15:17:10,915] [log.py:222] [log:log_response] [WARNING]- Bad Request: /monitor/api/storageitem/monitor/
[2020-11-21 15:17:10,917] [basehttp.py:157] [basehttp:log_message] [WARNING]- "GET /monitor/api/storageitem/monitor/ HTTP/1.1" 400 28
[2020-11-21 15:18:05,007] [basehttp.py:157] [basehttp:log_message] [INFO]- "GET /monitor/api/storageitem/monitor?storage=GZ-18500V5-1 HTTP/1.1" 301 0
[2020-11-21 15:18:05,013] [log.py:222] [log:log_response] [WARNING]- Bad Request: /monitor/api/storageitem/monitor/
[2020-11-21 15:18:05,014] [basehttp.py:157] [basehttp:log_message] [WARNING]- "GET /monitor/api/storageitem/monitor/?storage=GZ-18500V5-1 HTTP/1.1" 400 28
[2020-11-21 15:18:11,997] [autoreload.py:598] [autoreload:run_with_reloader] [INFO]- Watching for file changes with StatReloader
[2020-11-21 15:18:21,614] [basehttp.py:157] [basehttp:log_message] [INFO]- "GET /monitor/api/storageitem/monitor?storage_name=GZ-18500V5-1 HTTP/1.1" 301 0
[2020-11-21 15:18:21,929] [basehttp.py:157] [basehttp:log_message] [INFO]- "GET /monitor/api/storageitem/monitor/?storage_name=GZ-18500V5-1 HTTP/1.1" 200 2
[2020-11-21 15:22:42,638] [basehttp.py:157] [basehttp:log_message] [INFO]- "GET /monitor/api/storageitem/history?start=1605899410&end=1605942610&m=sum%3AhwAvgDuty1min HTTP/1.1" 301 0
[2020-11-21 15:22:45,666] [views.py:103] [views:get_history_monitor] [ERROR]- HTTPConnectionPool(host='10.10.10.202', port=4242): Max retries exceeded with url: /api/query?start=1605899410&end=1605942610&m=sum:hwAvgDuty1min (Caused by ConnectTimeoutError(<urllib3.connection.HTTPConnection object at 0x7fcd24529ac0>, 'Connection to 10.10.10.202 timed out. (connect timeout=3)'))
[2020-11-21 15:22:45,667] [log.py:222] [log:log_response] [ERROR]- Internal Server Error: /monitor/api/storageitem/history/
[2020-11-21 15:22:45,668] [basehttp.py:157] [basehttp:log_message] [ERROR]- "GET /monitor/api/storageitem/history/?start=1605899410&end=1605942610&m=sum%3AhwAvgDuty1min HTTP/1.1" 500 28
